Workbook
Name _DLX1.USE: #REF!
Name _DLX2.USE: PopulationByCohort1995!$A$1:$R$4

Sheet FINAL_DATA_for_DelNegro
A1: date | B1: obs_gdp | C1: obs_hours | D1: obs_wages | E1: obs_gdpdeflator | F1: obs_corepce | G1: obs_nominalrate | H1: obs_consumption | I1: obs_investment | J1: obs_BBBspread | K1: obs_longinflation | L1: obs_longrate | M1: obs_tfp | N1: obs_gdi | O1: obs_AAAspread | P1: obs_nominalrate1 | Q1: obs_nominalrate2 | R1: obs_nominalrate3 | S1: obs_nominalrate4 | T1: obs_nominalrate5 | U1: obs_nominalrate6
A2: 25749 | B2: =+Data_input!AO5 -> 1.8683193 | C2: =+Data_input!AW5 -> NaN | D2: =+Data_input!AU5 -> 2.6176958 | E2: =+Data_input!AR5 -> 1.8127385 | F2: =+Data_input!AS5 -> NaN | G2: =+Data_input!AT5 -> 1.98925 | H2: =+Data_input!AP5 -> 0.57886079 | I2: =+Data_input!AQ5 -> 5.6701088 | J2: =+Data_input!AW5 -> NaN | K2: =+Data_input!AX5 -> NaN | L2: =+Data_input!AY5 -> 2.0636 | M2: NaN | N2: =+Data_input!AN5 -> NaN | O2: NaN | P2: NaN | Q2: NaN | R2: NaN | S2: NaN | T2: NaN | U2: NaN
A3: 25841 | B3: =+Data_input!AO6 -> 1.0169411 | C3: =+Data_input!AW6 -> NaN | D3: =+Data_input!AU6 -> 2.0318583 | E3: =+Data_input!AR6 -> 1.7804625 | F3: =+Data_input!AS6 -> NaN | G3: =+Data_input!AT6 -> 1.9005 | H3: =+Data_input!AP6 -> 0.99087964 | I3: =+Data_input!AQ6 -> 0.69820336 | J3: =+Data_input!AW6 -> NaN | K3: =+Data_input!AX6 -> NaN | L3: =+Data_input!AY6 -> 2.0962 | M3: NaN | N3: =+Data_input!AN6 -> NaN | O3: NaN | P3: NaN | Q3: NaN | R3: NaN | S3: NaN | T3: NaN | U3: NaN
A4: 25933 | B4: =+Data_input!AO7 -> 1.043116 | C4: =+Data_input!AW7 -> NaN | D4: =+Data_input!AU7 -> 2.2601571 | E4: =+Data_input!AR7 -> 1.169604 | F4: =+Data_input!AS7 -> NaN | G4: =+Data_input!AT7 -> 1.8105 | H4: =+Data_input!AP7 -> 1.7487773 | I4: =+Data_input!AQ7 -> -0.039820886 | J4: =+Data_input!AW7 -> NaN | K4: =+Data_input!AX7 -> NaN | L4: =+Data_input!AY7 -> 2.085225 | M4: NaN | N4: =+Data_input!AN7 -> NaN | O4: NaN | P4: NaN | Q4: NaN | R4: NaN | S4: NaN | T4: NaN | U4: NaN
A5: 26023 | B5: =+Data_input!AO8 -> -0.37846203 | C5: =+Data_input!AW8 -> NaN | D5: =+Data_input!AU8 -> 0.96647751 | E5: =+Data_input!AR8 -> 2.2989518 | F5: =+Data_input!AS8 -> NaN | G5: =+Data_input!AT8 -> 1.62925 | H5: =+Data_input!AP8 -> -0.106649 | I5: =+Data_input!AQ8 -> -0.81746172 | J5: =+Data_input!AW8 -> NaN | K5: =+Data_input!AX8 -> NaN | L5: =+Data_input!AY8 -> 1.96515 | M5: NaN | N5: =+Data_input!AN8 -> NaN | O5: NaN | P5: NaN | Q5: NaN | R5: NaN | S5: NaN | T5: NaN | U5: NaN
A6: 26114 | B6: =+Data_input!AO9 -> 0.98464723 | C6: =+Data_input!AW9 -> NaN | D6: =+Data_input!AU9 -> 0.83746693 | E6: =+Data_input!AR9 -> 1.1299555 | F6: =+Data_input!AS9 -> NaN | G6: =+Data_input!AT9 -> 1.48475 | H6: =+Data_input!AP9 -> 1.1782578 | I6: =+Data_input!AQ9 -> 2.825207 | J6: =+Data_input!AW9 -> NaN | K6: =+Data_input!AX9 -> NaN | L6: =+Data_input!AY9 -> 1.9827 | M6: NaN | N6: =+Data_input!AN9 -> NaN | O6: NaN | P6: NaN | Q6: NaN | R6: NaN | S6: NaN | T6: NaN | U6: NaN
A7: 26206 | B7: =+Data_input!AO10 -> 1.8406942 | C7: =+Data_input!AW10 -> NaN | D7: =+Data_input!AU10 -> 1.9469213 | E7: =+Data_input!AR10 -> 1.6713481 | F7: =+Data_input!AS10 -> NaN | G7: =+Data_input!AT10 -> 1.5565 | H7: =+Data_input!AP10 -> 1.1525321 | I7: =+Data_input!AQ10 -> 0.16846011 | J7: =+Data_input!AW10 -> NaN | K7: =+Data_input!AX10 -> NaN | L7: =+Data_input!AY10 -> 2.00675 | M7: NaN | N7: =+Data_input!AN10 -> NaN | O7: NaN | P7: NaN | Q7: NaN | R7: NaN | S7: NaN | T7: NaN | U7: NaN
A8: 26298 | B8: =+Data_input!AO11 -> 0.66489089 | C8: =+Data_input!AW11 -> NaN | D8: =+Data_input!AU11 -> 1.6442656 | E8: =+Data_input!AR11 -> 1.0989122 | F8: =+Data_input!AS11 -> NaN | G8: =+Data_input!AT11 -> 1.5015 | H8: =+Data_input!AP11 -> 1.0130494 | I8: =+Data_input!AQ11 -> 1.6042895 | J8: =+Data_input!AW11 -> NaN | K8: =+Data_input!AX11 -> NaN | L8: =+Data_input!AY11 -> 1.9615 | M8: NaN | N8: =+Data_input!AN11 -> NaN | O8: NaN | P8: NaN | Q8: NaN | R8: NaN | S8: NaN | T8: NaN | U8: NaN
A9: 26389 | B9: =+Data_input!AO12 -> 1.250487 | C9: =+Data_input!AW12 -> NaN | D9: =+Data_input!AU12 -> 1.9664668 | E9: =+Data_input!AR12 -> 2.1622464 | F9: =+Data_input!AS12 -> NaN | G9: =+Data_input!AT12 -> 1.26175 | H9: =+Data_input!AP12 -> 0.92275964 | I9: =+Data_input!AQ12 -> 0.36421884 | J9: =+Data_input!AW12 -> NaN | K9: =+Data_input!AX12 -> NaN | L9: =+Data_input!AY12 -> 1.8969 | M9: NaN | N9: =+Data_input!AN12 -> NaN | O9: NaN | P9: NaN | Q9: NaN | R9: NaN | S9: NaN | T9: NaN | U9: NaN
A10: 26480 | B10: =+Data_input!AO13 -> 0.60518929 | C10: =+Data_input!AW13 -> NaN | D10: =+Data_input!AU13 -> 0.43958249 | E10: =+Data_input!AR13 -> 1.5915455 | F10: =+Data_input!AS13 -> NaN | G10: =+Data_input!AT13 -> 1.1885 | H10: =+Data_input!AP13 -> 0.37279123 | I10: =+Data_input!AQ13 -> 1.2797619 | J10: =+Data_input!AW13 -> NaN | K10: =+Data_input!AX13 -> NaN | L10: =+Data_input!AY13 -> 1.887425 | M10: NaN | N10: =+Data_input!AN13 -> NaN | O10: NaN | P10: NaN | Q10: NaN | R10: NaN | S10: NaN | T10: NaN | U10: NaN
A11: 26572 | B11: =+Data_input!AO14 -> 1.1230313 | C11: =+Data_input!AW14 -> NaN | D11: =+Data_input!AU14 -> 0.92436195 | E11: =+Data_input!AR14 -> 1.5666117 | F11: =+Data_input!AS14 -> NaN | G11: =+Data_input!AT14 -> 1.21425 | H11: =+Data_input!AP14 -> 2.0697722 | I11: =+Data_input!AQ14 -> 0.57111497 | J11: =+Data_input!AW14 -> NaN | K11: =+Data_input!AX14 -> NaN | L11: =+Data_input!AY14 -> 1.8957 | M11: NaN | N11: =+Data_input!AN14 -> NaN | O11: NaN | P11: NaN | Q11: NaN | R11: NaN | S11: NaN | T11: NaN | U11: NaN
A12: 26664 | B12: =+Data_input!AO15 -> 1.16364 | C12: =+Data_input!AW15 -> NaN | D12: =+Data_input!AU15 -> 1.4520609 | E12: =+Data_input!AR15 -> 1.542447 | F12: =+Data_input!AS15 -> NaN | G12: =+Data_input!AT15 -> 1.59875 | H12: =+Data_input!AP15 -> 0.70780832 | I12: =+Data_input!AQ15 -> 2.0215344 | J12: =+Data_input!AW15 -> NaN | K12: =+Data_input!AX15 -> NaN | L12: =+Data_input!AY15 -> 1.953675 | M12: NaN | N12: =+Data_input!AN15 -> NaN | O12: NaN | P12: NaN | Q12: NaN | R12: NaN | S12: NaN | T12: NaN | U12: NaN
A13: 26754 | B13: =+Data_input!AO16 -> 1.6539551 | C13: =+Data_input!AW16 -> NaN | D13: =+Data_input!AU16 -> 1.4655741 | E13: =+Data_input!AR16 -> 3.509132 | F13: =+Data_input!AS16 -> NaN | G13: =+Data_input!AT16 -> 1.69775 | H13: =+Data_input!AP16 -> 0.31973793 | I13: =+Data_input!AQ16 -> 1.2620153 | J13: =+Data_input!AW16 -> NaN | K13: =+Data_input!AX16 -> NaN | L13: =+Data_input!AY16 -> 1.993975 | M13: NaN | N13: =+Data_input!AN16 -> NaN | O13: NaN | P13: NaN | Q13: NaN | R13: NaN | S13: NaN | T13: NaN | U13: NaN
... A59: 30955 | B59: =+Data_input!AO62 -> 0.81441567 | C59: =+Data_input!AW62 -> NaN | D59: =+Data_input!AU62 -> 0.36647659 | E59: =+Data_input!AR62 -> 1.6051709 | F59: =+Data_input!AS62 -> NaN | G59: =+Data_input!AT62 -> 2.6035 | H59: =+Data_input!AP62 -> -0.055643632 | I59: =+Data_input!AQ62 -> 0.99961582 | J59: =+Data_input!AW62 -> NaN | K59: =+Data_input!AX62 -> NaN | L59: =+Data_input!AY62 -> 3.0523 | M59: NaN | N59: =+Data_input!AN62 -> NaN | O59: NaN | P59: NaN | Q59: NaN | R59: NaN | S59: NaN | T59: NaN | U59: NaN
A60: 31047 | B60: =+Data_input!AO63 -> 0.41563574 | C60: =+Data_input!AW63 -> NaN | D60: =+Data_input!AU63 -> 0.68857054 | E60: =+Data_input!AR63 -> 1.1084832 | F60: =+Data_input!AS63 -> NaN | G60: =+Data_input!AT63 -> 2.532 | H60: =+Data_input!AP63 -> 0.51023579 | I60: =+Data_input!AQ63 -> 1.2325852 | J60: NaN | K60: =+Data_input!AX63 -> NaN | L60: =+Data_input!AY63 -> 2.854575 | M60: NaN | N60: =+Data_input!AN63 -> NaN | O60: NaN | P60: NaN | Q60: NaN | R60: NaN | S60: NaN | T60: NaN | U60: NaN
A61: 31137 | B61: =+Data_input!AO64 -> 0.15719806 | C61: =+Data_input!AW64 -> 5.5978026 | D61: =+Data_input!AU64 -> 0.42849366 | E61: =+Data_input!AR64 -> 1.5625318 | F61: =+Data_input!AS64 -> NaN | G61: =+Data_input!AT64 -> 2.46575 | H61: =+Data_input!AP64 -> 0.91156536 | I61: =+Data_input!AQ64 -> -1.6384293 | J61: NaN | K61: =+Data_input!AX64 -> NaN | L61: =+Data_input!AY64 -> 2.73685 | M61: NaN | N61: =+Data_input!AN64 -> NaN | O61: NaN | P61: NaN | Q61: NaN | R61: NaN | S61: NaN | T61: NaN | U61: NaN
A62: 31228 | B62: =+Data_input!AO65 -> 0.81002553 | C62: =+Data_input!AW65 -> 5.520391 | D62: =+Data_input!AU65 -> 0.058433534 | E62: =+Data_input!AR65 -> 1.3857035 | F62: =+Data_input!AS65 -> NaN | G62: =+Data_input!AT65 -> 2.4905 | H62: =+Data_input!AP65 -> 0.33825091 | I62: =+Data_input!AQ65 -> 1.3479054 | J62: NaN | K62: =+Data_input!AX65 -> NaN | L62: =+Data_input!AY65 -> 2.711025 | M62: NaN | N62: =+Data_input!AN65 -> NaN | O62: NaN | P62: NaN | Q62: NaN | R62: NaN | S62: NaN | T62: NaN | U62: NaN
A63: 31320 | B63: =+Data_input!AO66 -> 0.62970295 | C63: =+Data_input!AW66 -> 5.3781865 | D63: =+Data_input!AU66 -> 0.49315274 | E63: =+Data_input!AR66 -> 1.5174798 | F63: =+Data_input!AS66 -> NaN | G63: =+Data_input!AT66 -> 2.33675 | H63: =+Data_input!AP66 -> 0.38085288 | I63: =+Data_input!AQ66 -> 1.3035571 | J63: NaN | K63: =+Data_input!AX66 -> NaN | L63: =+Data_input!AY66 -> 2.66725 | M63: NaN | N63: =+Data_input!AN66 -> NaN | O63: NaN | P63: NaN | Q63: NaN | R63: NaN | S63: NaN | T63: NaN | U63: NaN
A64: 31412 | B64: =+Data_input!AO67 -> 0.30455885 | C64: =+Data_input!AW67 -> 5.1799106 | D64: =+Data_input!AU67 -> -0.021903326 | E64: =+Data_input!AR67 -> 1.4947961 | F64: =+Data_input!AS67 -> NaN | G64: =+Data_input!AT67 -> 2.157 | H64: =+Data_input!AP67 -> 0.11889201 | I64: =+Data_input!AQ67 -> 0.91909959 | J64: NaN | K64: =+Data_input!AX67 -> NaN | L64: =+Data_input!AY67 -> 2.572575 | M64: NaN | N64: =+Data_input!AN67 -> NaN | O64: NaN | P64: NaN | Q64: NaN | R64: NaN | S64: NaN | T64: NaN | U64: NaN
A65: 31502 | B65: =+Data_input!AO68 -> -0.62857192 | C65: =+Data_input!AW68 -> 4.9528112 | D65: =+Data_input!AU68 -> -0.39107677 | E65: =+Data_input!AR68 -> 1.7647517 | F65: =+Data_input!AS68 -> NaN | G65: =+Data_input!AT68 -> 2.18725 | H65: =+Data_input!AP68 -> -0.83985339 | I65: =+Data_input!AQ68 -> -2.4798995 | J65: NaN | K65: =+Data_input!AX68 -> NaN | L65: =+Data_input!AY68 -> 2.441575 | M65: NaN | N65: =+Data_input!AN68 -> NaN | O65: NaN | P65: NaN | Q65: NaN | R65: NaN | S65: NaN | T65: NaN | U65: NaN
A66: 31593 | B66: =+Data_input!AO69 -> 1.5520692 | C66: =+Data_input!AW69 -> 4.7847139 | D66: =+Data_input!AU69 -> 0.21563372 | E66: =+Data_input!AR69 -> 1.3034218 | F66: =+Data_input!AS69 -> NaN | G66: =+Data_input!AT69 -> 2.007 | H66: =+Data_input!AP69 -> 0.79713751 | I66: =+Data_input!AQ69 -> 1.9949517 | J66: NaN | K66: =+Data_input!AX69 -> NaN | L66: =+Data_input!AY69 -> 2.14955 | M66: NaN | N66: =+Data_input!AN69 -> NaN | O66: NaN | P66: NaN | Q66: NaN | R66: NaN | S66: NaN | T66: NaN | U66: NaN
A67: 31685 | B67: =+Data_input!AO70 -> 0.17993857 | C67: =+Data_input!AW70 -> 4.6991955 | D67: =+Data_input!AU70 -> 0.12063218 | E67: =+Data_input!AR70 -> 1.1445046 | F67: =+Data_input!AS70 -> NaN | G67: =+Data_input!AT70 -> 1.93825 | H67: =+Data_input!AP70 -> -0.1687724 | I67: =+Data_input!AQ70 -> 0.35558028 | J67: NaN | K67: =+Data_input!AX70 -> NaN | L67: =+Data_input!AY70 -> 2.100925 | M67: NaN | N67: =+Data_input!AN70 -> NaN | O67: NaN | P67: NaN | Q67: NaN | R67: NaN | S67: NaN | T67: NaN | U67: NaN
A68: 31777 | B68: =+Data_input!AO71 -> -0.15538542 | C68: =+Data_input!AW71 -> 4.6741029 | D68: =+Data_input!AU71 -> 0.13742315 | E68: =+Data_input!AR71 -> 0.84986347 | F68: =+Data_input!AS71 -> NaN | G68: =+Data_input!AT71 -> 1.96875 | H68: =+Data_input!AP71 -> 0.49766429 | I68: =+Data_input!AQ71 -> 0.56819114 | J68: NaN | K68: =+Data_input!AX71 -> NaN | L68: =+Data_input!AY71 -> 2.11825 | M68: NaN | N68: =+Data_input!AN71 -> NaN | O68: NaN | P68: NaN | Q68: NaN | R68: NaN | S68: NaN | T68: NaN | U68: NaN
A69: 31867 | B69: =+Data_input!AO72 -> -0.73311494 | C69: =+Data_input!AW72 -> 4.7316413 | D69: =+Data_input!AU72 -> 0.10782261 | E69: =+Data_input!AR72 -> 0.84270162 | F69: =+Data_input!AS72 -> NaN | G69: =+Data_input!AT72 -> 2.02625 | H69: =+Data_input!AP72 -> -0.21567591 | I69: =+Data_input!AQ72 -> -1.8246121 | J69: NaN | K69: =+Data_input!AX72 -> NaN | L69: =+Data_input!AY72 -> 2.1178 | M69: NaN | N69: =+Data_input!AN72 -> NaN | O69: NaN | P69: NaN | Q69: NaN | R69: NaN | S69: NaN | T69: NaN | U69: NaN
A70: 31958 | B70: =+Data_input!AO73 -> 1.3643364 | C70: =+Data_input!AW73 -> 4.7600493 | D70: =+Data_input!AU73 -> 0.96286134 | E70: =+Data_input!AR73 -> 0.83565946 | F70: =+Data_input!AS73 -> NaN | G70: =+Data_input!AT73 -> 2.1065 | H70: =+Data_input!AP73 -> 1.5481834 | I70: =+Data_input!AQ73 -> 2.9212492 | J70: NaN | K70: =+Data_input!AX73 -> NaN | L70: =+Data_input!AY73 -> 2.17225 | M70: NaN | N70: =+Data_input!AN73 -> NaN | O70: NaN | P70: NaN | Q70: NaN | R70: NaN | S70: NaN | T70: NaN | U70: NaN
A71: 32050 | B71: =+Data_input!AO74 -> 0.82396912 | C71: =+Data_input!AW74 -> 4.7343351 | D71: =+Data_input!AU74 -> 0.61028185 | E71: =+Data_input!AR74 -> 0.69108775 | F71: =+Data_input!AS74 -> NaN | G71: =+Data_input!AT74 -> 2.1225 | H71: =+Data_input!AP74 -> 0.75014426 | I71: =+Data_input!AQ74 -> 2.0098641 | J71: NaN | K71: =+Data_input!AX74 -> NaN | L71: =+Data_input!AY74 -> 2.36805 | M71: NaN | N71: =+Data_input!AN74 -> NaN | O71: NaN | P71: NaN | Q71: NaN | R71: NaN | S71: NaN | T71: NaN | U71: NaN
... A111: 35703 | B111: =+Data_input!AO114 -> 0.5654589 | C111: =+Data_input!AW114 -> 1.1282396 | D111: =+Data_input!AU114 -> 0.24862192 | E111: =+Data_input!AR114 -> 0.17587365 | F111: =+Data_input!AS114 -> 0.31662296 | G111: =+Data_input!AT114 -> 1.0725 | H111: =+Data_input!AP114 -> 0.51604853 | I111: =+Data_input!AQ114 -> -0.82142386 | J111: NaN | K111: =+Data_input!AX114 -> NaN | L111: =+Data_input!AY114 -> 1.4525 | M111: NaN | N111: =+Data_input!AN114 -> NaN | O111: NaN | P111: NaN | Q111: NaN | R111: NaN | S111: NaN | T111: NaN | U111: NaN
A112: 35795 | B112: =+Data_input!AO115 -> 0.82901063 | C112: =+Data_input!AW115 -> 1.165307 | D112: =+Data_input!AU115 -> -0.12312815 | E112: =+Data_input!AR115 -> 0.54582936 | F112: =+Data_input!AS115 -> 0.31562362 | G112: =+Data_input!AT115 -> 1.095 | H112: =+Data_input!AP115 -> 0.8166924 | I112: =+Data_input!AQ115 -> 1.3712064 | J112: ='Option Adjusted rate'!O4/4 -> 1.5675 | K112: =+Data_input!AX115 -> NaN | L112: =+Data_input!AY115 -> 1.4 | M112: NaN | N112: =+Data_input!AN115 -> NaN | O112: NaN | P112: NaN | Q112: NaN | R112: NaN | S112: NaN | T112: NaN | U112: NaN
A113: 35885 | B113: =+Data_input!AO116 -> 0.30281109 | C113: =+Data_input!AW116 -> 1.0840195 | D113: =+Data_input!AU116 -> 0.2596156 | E113: =+Data_input!AR116 -> -0.2596156 | F113: =+Data_input!AS116 -> 0.34080515 | G113: =+Data_input!AT116 -> 1.0525 | H113: =+Data_input!AP116 -> -0.01941419 | I113: =+Data_input!AQ116 -> 1.7004603 | J113: ='Option Adjusted rate'!O5/4 -> 1.4453283 | K113: =+Data_input!AX116 -> NaN | L113: =+Data_input!AY116 -> 1.279175 | M113: NaN | N113: =+Data_input!AN116 -> NaN | O113: NaN | P113: NaN | Q113: NaN | R113: NaN | S113: NaN | T113: NaN | U113: NaN
A114: 35976 | B114: =+Data_input!AO117 -> -0.00262313 | C114: =+Data_input!AW117 -> 1.3763298 | D114: =+Data_input!AU117 -> 0.022276693 | E114: =+Data_input!AR117 -> 0.5385598 | F114: =+Data_input!AS117 -> 0.44392291 | G114: =+Data_input!AT117 -> 1.0175 | H114: =+Data_input!AP117 -> -0.031786087 | I114: =+Data_input!AQ117 -> -0.4906888 | J114: ='Option Adjusted rate'!O6/4 -> 1.3649152 | K114: =+Data_input!AX117 -> NaN | L114: =+Data_input!AY117 -> 1.2475 | M114: -0.0076444745 | N114: =+Data_input!AN117 -> NaN | O114: NaN | P114: NaN | Q114: NaN | R114: NaN | S114: NaN | T114: NaN | U114: NaN
A115: 36068 | B115: =+Data_input!AO118 -> 0.1252822 | C115: =+Data_input!AW118 -> 1.6372747 | D115: =+Data_input!AU118 -> -0.017941778 | E115: =+Data_input!AR118 -> 0.4674504 | F115: =+Data_input!AS118 -> 0.32516124 | G115: =+Data_input!AT118 -> 0.9875 | H115: =+Data_input!AP118 -> 0.59588844 | I115: =+Data_input!AQ118 -> 1.2595788 | J115: ='Option Adjusted rate'!O7/4 -> 1.7830613 | K115: =+Data_input!AX118 -> NaN | L115: =+Data_input!AY118 -> 1.14 | M115: -0.0033146378 | N115: =+Data_input!AN118 -> NaN | O115: NaN | P115: NaN | Q115: NaN | R115: NaN | S115: NaN | T115: NaN | U115: NaN
A116: 36160 | B116: =+Data_input!AO119 -> 0.038402457 | C116: =+Data_input!AW119 -> 1.3035559 | D116: =+Data_input!AU119 -> -0.44791865 | E116: =+Data_input!AR119 -> 1.0185116 | F116: =+Data_input!AS119 -> 0.27232073 | G116: =+Data_input!AT119 -> 0.915 | H116: =+Data_input!AP119 -> 0.29856019 | I116: =+Data_input!AQ119 -> 0.36035351 | J116: ='Option Adjusted rate'!O8/4 -> 2.1331477 | K116: =+Data_input!AX119 -> NaN | L116: =+Data_input!AY119 -> 1.036675 | M116: 0.0062073288 | N116: =+Data_input!AN119 -> NaN | O116: NaN | P116: NaN | Q116: NaN | R116: NaN | S116: NaN | T116: NaN | U116: NaN
A117: 36250 | B117: =+Data_input!AO120 -> 0.84265283 | C117: =+Data_input!AW120 -> 1.2310841 | D117: =+Data_input!AU120 -> -0.061541097 | E117: =+Data_input!AR120 -> 0.23055089 | F117: =+Data_input!AS120 -> 0.16820862 | G117: =+Data_input!AT120 -> 0.7775 | H117: =+Data_input!AP120 -> 0.48357053 | I117: =+Data_input!AQ120 -> 1.3717029 | J117: ='Option Adjusted rate'!O9/4 -> 1.8570411 | K117: =+Data_input!AX120 -> 0.475 | L117: =+Data_input!AY120 -> 0.9981 | M117: 0.010277129 | N117: =+Data_input!AN120 -> NaN | O117: NaN | P117: NaN | Q117: NaN | R117: NaN | S117: NaN | T117: NaN | U117: NaN
A118: 36341 | B118: =+Data_input!AO121 -> 0.18693549 | C118: =+Data_input!AW121 -> 2.0081971 | D118: =+Data_input!AU121 -> 0.73969227 | E118: =+Data_input!AR121 -> 0.20760282 | F118: =+Data_input!AS121 -> 0.27112534 | G118: =+Data_input!AT121 -> 0.655 | H118: =+Data_input!AP121 -> 0.69713061 | I118: =+Data_input!AQ121 -> 1.4679547 | J118: ='Option Adjusted rate'!O10/4 -> 1.7022348 | K118: =+Data_input!AX121 -> NaN | L118: =+Data_input!AY121 -> 1.06435 | M118: -0.0051862826 | N118: =+Data_input!AN121 -> NaN | O118: NaN | P118: NaN | Q118: NaN | R118: NaN | S118: NaN | T118: NaN | U118: NaN
A119: 36433 | B119: =+Data_input!AO122 -> 0.92636177 | C119: =+Data_input!AW122 -> 1.5636612 | D119: =+Data_input!AU122 -> 0.42465873 | E119: =+Data_input!AR122 -> 0.091040884 | F119: =+Data_input!AS122 -> 0.25753298 | G119: =+Data_input!AT122 -> 0.6525 | H119: =+Data_input!AP122 -> 0.95113209 | I119: =+Data_input!AQ122 -> 1.5412529 | J119: ='Option Adjusted rate'!O11/4 -> 1.5569648 | K119: =+Data_input!AX122 -> NaN | L119: =+Data_input!AY122 -> 1.262675 | M119: 0.010012727 | N119: =+Data_input!AN122 -> NaN | O119: NaN | P119: NaN | Q119: NaN | R119: NaN | S119: NaN | T119: NaN | U119: NaN
A120: 36525 | B120: =+Data_input!AO123 -> 0.77124127 | C120: =+Data_input!AW123 -> 1.8812739 | D120: =+Data_input!AU123 -> 0.51412695 | E120: =+Data_input!AR123 -> 0.31450303 | F120: =+Data_input!AS123 -> 0.29534532 | G120: =+Data_input!AT123 -> 0.7775 | H120: =+Data_input!AP123 -> 0.61767219 | I120: =+Data_input!AQ123 -> 0.5306946 | J120: ='Option Adjusted rate'!O12/4 -> 1.4585013 | K120: =+Data_input!AX123 -> NaN | L120: =+Data_input!AY123 -> 1.330025 | M120: 0.0012719113 | N120: =+Data_input!AN123 -> NaN | O120: NaN | P120: NaN | Q120: NaN | R120: NaN | S120: NaN | T120: NaN | U120: NaN
A121: 36616 | B121: =+Data_input!AO124 -> 0.81684359 | C121: =+Data_input!AW124 -> 2.0405808 | D121: =+Data_input!AU124 -> 0.25394238 | E121: =+Data_input!AR124 -> 0.46365675 | F121: =+Data_input!AS124 -> 0.19214763 | G121: =+Data_input!AT124 -> 0.8425 | H121: =+Data_input!AP124 -> 0.75601082 | I121: =+Data_input!AQ124 -> 2.5460331 | J121: ='Option Adjusted rate'!O13/4 -> 1.3387698 | K121: =+Data_input!AX124 -> 0.45 | L121: =+Data_input!AY124 -> 1.4044 | M121: 0.0059700813 | N121: =+Data_input!AN124 -> NaN | O121: =AAA_bond_data!I3 -> 0.094783333 | P121: NaN | Q121: NaN | R121: NaN | S121: NaN | T121: NaN | U121: NaN
A122: 36707 | B122: =+Data_input!AO125 -> 0.5885124 | C122: =+Data_input!AW125 -> 2.026313 | D122: =+Data_input!AU125 -> 0.23136427 | E122: =+Data_input!AR125 -> 0.2441902 | F122: =+Data_input!AS125 -> 0.17900529 | G122: =+Data_input!AT125 -> 1.0275 | H122: =+Data_input!AP125 -> 0.6968552 | I122: =+Data_input!AQ125 -> -0.095243287 | J122: ='Option Adjusted rate'!O14/4 -> 1.6417742 | K122: =+Data_input!AX125 -> NaN | L122: =+Data_input!AY125 -> 1.356225 | M122: 0.0022616091 | N122: =+Data_input!AN125 -> NaN | O122: =AAA_bond_data!I4 -> 0.11169167 | P122: NaN | Q122: NaN | R122: NaN | S122: NaN | T122: NaN | U122: NaN
A123: 36799 | B123: =+Data_input!AO126 -> 0.35888118 | C123: =+Data_input!AW126 -> 2.0407133 | D123: =+Data_input!AU126 -> 0.32688075 | E123: =+Data_input!AR126 -> 0.52933943 | F123: =+Data_input!AS126 -> 0.31885749 | G123: =+Data_input!AT126 -> 1.14 | H123: =+Data_input!AP126 -> 0.28066409 | I123: =+Data_input!AQ126 -> 0.46474739 | J123: ='Option Adjusted rate'!O15/4 -> 1.902122 | K123: =+Data_input!AX126 -> NaN | L123: =+Data_input!AY126 -> 1.359925 | M123: 0.00068997365 | N123: =+Data_input!AN126 -> NaN | O123: =AAA_bond_data!I5 -> 0.123675 | P123: NaN | Q123: NaN | R123: NaN | S123: NaN | T123: NaN | U123: NaN
A124: 36891 | B124: =+Data_input!AO127 -> 0.29328572 | C124: =+Data_input!AW127 -> 2.2494962 | D124: =+Data_input!AU127 -> 0.087029855 | E124: =+Data_input!AR127 -> 0.58686663 | F124: =+Data_input!AS127 -> 0.4066596 | G124: =+Data_input!AT127 -> 1.2275 | H124: =+Data_input!AP127 -> 0.27053892 | I124: =+Data_input!AQ127 -> 0.56065532 | J124: ='Option Adjusted rate'!O16/4 -> 2.6170851 | K124: =+Data_input!AX127 -> NaN | L124: =+Data_input!AY127 -> 1.318325 | M124: 0.00019842795 | N124: =+Data_input!AN127 -> NaN | O124: =AAA_bond_data!I6 -> 0.14478333 | P124: NaN | Q124: NaN | R124: NaN | S124: NaN | T124: NaN | U124: NaN
...

Sheet Eur_Productivity_BoEspana
F1: Source: https://www.bde.es/wbe/en/areas-actuacion/analisis-e-investigacion/recursos/europrod-ua.html
A6: country | B6: year | C6: quarter | D6: dZ_Solow | E6: dZ | F6: dZ_Solow_EA | G6: dZ_EA | H6: dZ_interp | I6: dZ_interp_EA | J6: dY | K6: dL | L6: dK | M6: dU | N6: dtotal_hours | O6: alpha_L | P6: alpha_K
A7: DE | B7: 1998 | C7: 1 | M7: 0.0016158154
A8: DE | B8: 1998 | C8: 2 | D8: -0.014616288 | E8: -0.016907867 | F8: -0.0057730451 | G8: -0.0076444745 | H8: -0.016907867 | I8: -0.0076444745 | J8: -0.0088191433 | K8: 0.0064827893 | L8: 0.0041834703 | M8: 0.0022297925 | N8: 0.0061854874 | O8: 0.72867703 | P8: 0.27132297
A9: DE | B9: 1998 | C9: 3 | D9: -0.0014230631 | E9: 4.7634348e-05 | F9: -0.0029452411 | G9: -0.0033146378 | H9: 4.7633424e-05 | I9: -0.0033146383 | J9: 0.0041161883 | K9: 0.0060262503 | L9: 0.0043936088 | M9: -0.0015163539 | N9: 0.0057293619 | O9: 0.72967583 | P9: 0.27032417
A10: DE | B10: 1998 | C10: 4 | D10: -0.00013220015 | E10: 0.0074779023 | F10: 0.00099958212 | G10: 0.0062073288 | H10: 0.0074779028 | I10: 0.0062073292 | J10: 0.00032290738 | K10: -0.0011832172 | L10: 0.0043074507 | M10: -0.0074505541 | N10: -0.0014797393 | O10: 0.73067462 | P10: 0.26932538
A11: DE | B11: 1999 | C11: 1 | D11: 0.011135586 | E11: 0.013945235 | F11: 0.0076715485 | G11: 0.010277129 | H11: 0.013945235 | I11: 0.010277129 | J11: 0.012708548 | K11: -1.9807821e-05 | L11: 0.0053099133 | M11: -0.0026727442 | N11: -0.00031600826 | O11: 0.72684044 | P11: 0.27315956
A12: DE | B12: 1999 | C12: 2 | D12: -0.0021714459 | E12: -0.0014587931 | F12: -0.0055091456 | G12: -0.0051862826 | H12: -0.0014587932 | I12: -0.0051862826 | J12: 2.2983939e-05 | K12: 0.00095612754 | L12: 0.0051117963 | M12: -0.00062481995 | N12: 0.00066035282 | O12: 0.72315657 | P12: 0.2768434
A13: DE | B13: 1999 | C13: 3 | D13: 0.010897027 | E13: 0.0078501739 | F13: 0.011141896 | G13: 0.010012727 | H13: 0.0078501739 | I13: 0.010012728 | J13: 0.014719843 | K13: 0.0031604751 | L13: 0.0054025669 | M13: 0.0030913998 | N13: 0.0026285602 | O13: 0.72445607 | P13: 0.2755439
A14: DE | B14: 1999 | C14: 4 | D14: -0.00054579851 | E14: -0.0024511167 | F14: 0.0046069077 | G14: 0.0012719113 | H14: -0.0024511162 | I14: 0.0012719111 | J14: 0.0029709132 | K14: 0.0028286832 | L14: 0.0051781503 | M14: 0.0019490186 | N14: 0.0022981151 | O14: 0.72575557 | P14: 0.2742444
A15: DE | B15: 2000 | C15: 1 | D15: 0.0092280796 | E15: 0.003720243 | F15: 0.0070113093 | G15: 0.0059700813 | H15: 0.0037202425 | I15: 0.0059700813 | J15: 0.016405847 | K15: 0.0074537271 | L15: 0.0064868559 | M15: 0.005490053 | N15: 0.0069246129 | O15: 0.73297775 | P15: 0.26702225
A16: DE | B16: 2000 | C16: 2 | D16: 0.0032729602 | E16: 0.00061622419 | F16: 0.004099437 | G16: 0.0022616091 | H16: 0.00061622448 | I16: 0.0022616095 | J16: 0.0064134542 | K16: 0.0018105409 | L16: 0.0065814536 | M16: 0.002744935 | N16: 0.0012828393 | O16: 0.73972404 | P16: 0.26027599
A17: DE | B17: 2000 | C17: 3 | D17: 0.0011822217 | E17: -0.0014985532 | F17: 0.0027287528 | G17: 0.00068997365 | H17: -0.001498553 | I17: 0.00068997405 | J17: 0.0041296827 | K17: 0.0013571184 | L17: 0.0070829168 | M17: 0.002782821 | N17: 0.0010994031 | O17: 0.74007183 | P17: 0.2599282
A18: DE | B18: 2000 | C18: 4 | D18: -0.0044390876 | E18: -0.0057701184 | F18: -9.1597089e-05 | G18: 0.00019842795 | H18: -0.0057701184 | I18: 0.00019842743 | J18: -0.0031330602 | K18: -0.00071377051 | L18: 0.0065848245 | M18: 0.0014562565 | N18: -0.0009722517 | O18: 0.74041963 | P18: 0.2595804
A19: DE | B19: 2001 | C19: 1 | D19: 0.023423897 | E19: 0.027066676 | F19: 0.0075819446 | G19: 0.0098689357 | H19: 0.027066676 | I19: 0.0098689357 | J19: 0.023609458 | K19: -0.002159819 | L19: 0.0062043518 | M19: -0.0035057606 | N19: -0.0024191048 | O19: 0.7359736 | P19: 0.2640264
... A116: DE | B116: 2025 | C116: 2 | D116: -0.0019577341 | E116: -0.0047703544 | F116: 0.0016714666 | G116: 0.001334863 | H116: -0.0047703683 | I116: 0.0013348577 | J116: -0.0026081149 | K116: -0.0030395337 | L116: 0.0051833517 | M116: 0.0030136509 | N116: -0.0028698214 | O116: 0.73389846 | P116: 0.26610154
A117: ES | B117: 1998 | C117: 1 | M117: 0.0048643006
A118: ES | B118: 1998 | C118: 2 | D118: -0.0079776561 | E118: -0.012972737 | F118: -0.0057730451 | G118: -0.0076444745 | H118: -0.012972737 | I118: -0.0076444745 | J118: 0.013753803 | K118: 0.027354958 | L118: 0.011133485 | M118: 0.0029896295 | N118: 0.027596211 | O118: 0.77695942 | P118: 0.22304058
A119: ES | B119: 1998 | C119: 3 | D119: -0.012713545 | E119: -0.011286408 | F119: -0.0029452411 | G119: -0.0033146378 | H119: -0.011286408 | I119: -0.0033146383 | J119: 0.0094767949 | K119: 0.027604597 | L119: 0.011937242 | M119: -0.0034138481 | N119: 0.028044645 | O119: 0.78123009 | P119: 0.21876992
A120: ES | B120: 1998 | C120: 4 | D120: 0.011232769 | E120: 0.015455788 | F120: 0.00099958212 | G120: 0.0062073288 | H120: 0.015455788 | I120: 0.0062073292 | J120: 0.011532803 | K120: -0.0061541516 | L120: 0.0125818 | M120: -0.0017876814 | N120: -0.0052036191 | O120: 0.78550076 | P120: 0.21449926
A121: ES | B121: 1999 | C121: 1 | D121: -0.0019116967 | E121: -0.0020340991 | F121: 0.0076715485 | G121: 0.010277129 | H121: -0.0020340988 | I121: 0.010277129 | J121: 0.011863151 | K121: 0.014205856 | L121: 0.012955386 | M121: -5.1561874e-05 | N121: 0.015950095 | O121: 0.79444194 | P121: 0.20555802
A122: ES | B122: 1999 | C122: 2 | D122: -0.012278688 | E122: -0.014158386 | F122: -0.0055091456 | G122: -0.0051862826 | H122: -0.014158386 | I122: -0.0051862826 | J122: 0.012202472 | K122: 0.030042514 | L122: 0.013926527 | M122: -0.00052596541 | N122: 0.030320132 | O122: 0.80418885 | P122: 0.19581115
A123: ES | B123: 1999 | C123: 3 | D123: 0.014693081 | E123: 0.019530658 | F123: 0.011141896 | G123: 0.010012727 | H123: 0.019530658 | I123: 0.010012728 | J123: 0.017590426 | K123: -0.0030831532 | L123: 0.014281319 | M123: -0.0021551009 | N123: -0.0025780462 | O123: 0.81007069 | P123: 0.18992928
A124: ES | B124: 1999 | C124: 4 | D124: -0.005465758 | E124: -0.010100396 | F124: 0.0046069077 | G124: 0.0012719113 | H124: -0.010100396 | I124: 0.0012719111 | J124: 0.01130703 | K124: 0.01796728 | L124: 0.014492263 | M124: 0.0040797153 | N124: 0.020170704 | O124: 0.81595254 | P124: 0.1840474
A125: ES | B125: 2000 | C125: 1 | D125: -0.0017023762 | E125: 0.00012128814 | F125: 0.0070113093 | G125: 0.0059700813 | H125: 0.000121288 | I125: 0.0059700813 | J125: 0.01594029 | K125: 0.019080088 | L125: 0.01486029 | M125: -0.0025222835 | N125: 0.018983684 | O125: 0.82492018 | P125: 0.17507976
A126: ES | B126: 2000 | C126: 2 | D126: 0.0020961999 | E126: -0.0016486609 | F126: 0.004099437 | G126: 0.0022616091 | H126: -0.0016486607 | I126: 0.0022616095 | J126: 0.012224557 | K126: 0.007671921 | L126: 0.014925602 | M126: 0.0049686036 | N126: 0.008545422 | O126: 0.83005965 | P126: 0.16994035
A127: ES | B127: 2000 | C127: 3 | D127: -0.0017041913 | E127: 0.0022158513 | F127: 0.0027287528 | G127: 0.00068997365 | H127: 0.0022158511 | I127: 0.00068997405 | J127: 0.010278716 | K127: 0.010474049 | L127: 0.014909364 | M127: -0.0031727941 | N127: 0.0099302474 | O127: 0.8282851 | P127: 0.17171492
A128: ES | B128: 2000 | C128: 4 | D128: -0.00053393363 | E128: -0.00088808849 | F128: -9.1597089e-05 | G128: 0.00019842795 | H128: -0.00088808872 | I128: 0.00019842743 | J128: 0.01442236 | K128: 0.014952271 | L128: 0.014964041 | M128: 0.00035613467 | N128: 0.015339959 | O128: 0.82651055 | P128: 0.17348948
A129: ES | B129: 2001 | C129: 1 | D129: -0.0026498616 | E129: 0.00078840012 | F129: 0.0075819446 | G129: 0.0098689357 | H129: 0.00078839995 | I129: 0.0098689357 | J129: 0.012822523 | K129: 0.01631872 | L129: 0.01388481 | M129: -0.0038330762 | N129: 0.016071241 | O129: 0.81448758 | P129: 0.18551239
... A226: ES | B226: 2025 | C226: 2 | D226: 0.013459692 | E226: 0.018352261 | F226: 0.0016714666 | G226: 0.001334863 | H226: 0.018352263 | I226: 0.0013348577 | J226: 0.0176723 | K226: 0.003737374 | L226: 0.005284647 | M226: -0.004858261 | N226: 0.0035684288 | O226: 0.71503025 | P226: 0.28496975
A227: FR | B227: 1998 | C227: 1 | M227: -0.00095405424
A228: FR | B228: 1998 | C228: 2 | D228: 0.0045829723 | E228: 0.0040207999 | F228: -0.0057730451 | G228: -0.0076444745 | H228: 0.0040207999 | I228: -0.0076444745 | J228: 0.01030423 | K228: 0.0060490901 | L228: 0.004995842 | M228: 0.00045846612 | N228: 0.006290365 | O228: 0.7872051 | P228: 0.21279491
A229: FR | B229: 1998 | C229: 3 | D229: 0.00031558215 | E229: -0.0024693727 | F229: -0.0029452411 | G229: -0.0033146378 | H229: -0.0024693727 | I229: -0.0033146383 | J229: 0.0069047417 | K229: 0.0074089542 | L229: 0.0047854539 | M229: 0.0025204746 | N229: 0.0076486678 | O229: 0.78833067 | P229: 0.21166934
A230: FR | B230: 1998 | C230: 4 | D230: 0.0058342312 | E230: 0.0073811258 | F230: 0.00099958212 | G230: 0.0062073288 | H230: 0.0073811263 | I230: 0.0062073292 | J230: 0.0094223609 | K230: 0.0031701636 | L230: 0.0045025214 | M230: -0.0014094481 | N230: 0.0034082141 | O230: 0.78945625 | P230: 0.21054377
A231: FR | B231: 1999 | C231: 1 | D231: 0.006893822 | E231: 0.0060754926 | F231: 0.0076715485 | G231: 0.010277129 | H231: 0.0060754921 | I231: 0.010277129 | J231: 0.011089297 | K231: 0.0045464309 | L231: 0.0034239669 | M231: 0.00070736941 | N231: 0.0047828527 | O231: 0.78618824 | P231: 0.21381178
A232: FR | B232: 1999 | C232: 2 | D232: 0.00014138249 | E232: 0.0019630548 | F232: -0.0055091456 | G232: -0.0051862826 | H232: 0.0019630548 | I232: -0.0051862826 | J232: 0.009029787 | K232: 0.01113345 | L232: 0.0039199358 | M232: -0.0025091798 | N232: 0.011005859 | O232: 0.78408056 | P232: 0.21591942
A233: FR | B233: 1999 | C233: 3 | D233: 0.01069246 | E233: 0.0069560753 | F233: 0.011141896 | G233: 0.010012727 | H233: 0.0069560762 | I233: 0.010012728 | J233: 0.017765259 | K233: 0.0082083233 | L233: 0.0045647556 | M233: 0.0033750208 | N233: 0.0080812499 | O233: 0.78752691 | P233: 0.21247308
A234: FR | B234: 1999 | C234: 4 | D234: 0.012083913 | E234: 0.010801884 | F234: 0.0046069077 | G234: 0.0012719113 | H234: 0.010801883 | I234: 0.0012719111 | J234: 0.018129339 | K234: 0.0065537472 | L234: 0.0049249083 | M234: 0.0011141784 | N234: 0.0064273085 | O234: 0.79097325 | P234: 0.20902674
A235: FR | B235: 2000 | C235: 1 | D235: 0.008115924 | E235: 0.0097202919 | F235: 0.0070113093 | G235: 0.0059700813 | H235: 0.0097202919 | I235: 0.0059700813 | J235: 0.012899165 | K235: 0.0036755677 | L235: 0.0072061289 | M235: -0.0011893122 | N235: 0.0035496349 | O235: 0.80382228 | P235: 0.19617769
A236: FR | B236: 2000 | C236: 2 | D236: 0.0091951648 | E236: 0.0089204749 | F236: 0.004099437 | G236: 0.0022616091 | H236: 0.0089204758 | I236: 0.0022616095 | J236: 0.014387998 | K236: 0.0042570806 | L236: 0.0072237896 | M236: 0.00066239043 | N236: 0.0042965901 | O236: 0.81526589 | P236: 0.18473408
...

Sheet PopulationByCohort1995
A1: 95 *Y | B1: A025POP@EUDATA | C1: A025PBAA@EUDATA | D1: A025PBAB@EUDATA | E1: A025PBAC@EUDATA | F1: A025PBAD@EUDATA | G1: A025PBAE@EUDATA | H1: A025PBAF@EUDATA | I1: A025PBAG@EUDATA | J1: A025PBAH@EUDATA | K1: A025PBAI@EUDATA | L1: A025PBAJ@EUDATA | M1: A025PBAK@EUDATA | N1: A025PBAL@EUDATA | O1: A025PBAM@EUDATA | P1: A025PBAN@EUDATA | Q1: A025PBAO@EUDATA | R1: A025PBAP@EUDATA | U1: Population over 15
A2: .DESC | B2: Euro Area 20: Population (Persons) | C2: EA20: Population: Less Than 1 Year (Persons) | D2: EA20: Population: 1 Year (Persons) | E2: EA20: Population: 2 Years (Persons) | F2: EA20: Population: 3 Years (Persons) | G2: EA20: Population: 4 Years (Persons) | H2: EA20: Population: 5 Years (Persons) | I2: EA20: Population: 6 Years (Persons) | J2: EA20: Population: 7 Years (Persons) | K2: EA20: Population: 8 Years (Persons) | L2: EA20: Population: 9 Years (Persons) | M2: EA20: Population: 10 Years (Persons) | N2: EA20: Population: 11 Years (Persons) | O2: EA20: Population: 12 Years (Persons) | P2: EA20: Population: 13 Years (Persons) | Q2: EA20: Population: 14 Years (Persons) | R2: EA20: Population: 15 Years (Persons)
A3: .SOURCE | B3: Eurostat | C3: Eurostat | D3: Eurostat | E3: Eurostat | F3: Eurostat | G3: Eurostat | H3: Eurostat | I3: Eurostat | J3: Eurostat | K3: Eurostat | L3: Eurostat | M3: Eurostat | N3: Eurostat | O3: Eurostat | P3: Eurostat | Q3: Eurostat | R3: Eurostat
A4: .LSOURCE | B4: Statistical Office of the European Communities | C4: Statistical Office of the European Communities | D4: Statistical Office of the European Communities | E4: Statistical Office of the European Communities | F4: Statistical Office of the European Communities | G4: Statistical Office of the European Communities | H4: Statistical Office of the European Communities | I4: Statistical Office of the European Communities | J4: Statistical Office of the European Communities | K4: Statistical Office of the European Communities | L4: Statistical Office of the European Communities | M4: Statistical Office of the European Communities | N4: Statistical Office of the European Communities | O4: Statistical Office of the European Communities | P4: Statistical Office of the European Communities | Q4: Statistical Office of the European Communities | R4: Statistical Office of the European Communities
A5: 95 | B5: 319538165 | C5: #N/A | D5: #N/A | E5: #N/A | F5: #N/A | G5: #N/A | H5: #N/A | I5: #N/A | J5: #N/A | K5: #N/A | L5: #N/A | M5: #N/A | N5: #N/A | O5: #N/A | P5: #N/A | Q5: #N/A | R5: #N/A | U5: =B5-SUM(C5:R5) -> #N/A
A6: 96 | B6: 320260443 | C6: #N/A | D6: #N/A | E6: #N/A | F6: #N/A | G6: #N/A | H6: #N/A | I6: #N/A | J6: #N/A | K6: #N/A | L6: #N/A | M6: #N/A | N6: #N/A | O6: #N/A | P6: #N/A | Q6: #N/A | R6: #N/A | U6: =B6-SUM(C6:R6) -> #N/A
A7: 97 | B7: 320981348 | C7: #N/A | D7: #N/A | E7: #N/A | F7: #N/A | G7: #N/A | H7: #N/A | I7: #N/A | J7: #N/A | K7: #N/A | L7: #N/A | M7: #N/A | N7: #N/A | O7: #N/A | P7: #N/A | Q7: #N/A | R7: #N/A | U7: =B7-SUM(C7:R7) -> #N/A
A8: 98 | B8: 323292356 | C8: #N/A | D8: #N/A | E8: #N/A | F8: #N/A | G8: #N/A | H8: #N/A | I8: #N/A | J8: #N/A | K8: #N/A | L8: #N/A | M8: #N/A | N8: #N/A | O8: #N/A | P8: #N/A | Q8: #N/A | R8: #N/A | U8: =B8-SUM(C8:R8) -> #N/A
A9: 99 | B9: 323901384 | C9: #N/A | D9: #N/A | E9: #N/A | F9: #N/A | G9: #N/A | H9: #N/A | I9: #N/A | J9: #N/A | K9: #N/A | L9: #N/A | M9: #N/A | N9: #N/A | O9: #N/A | P9: #N/A | Q9: #N/A | R9: #N/A | U9: =B9-SUM(C9:R9) -> #N/A
A10: 00 | B10: 324872982 | C10: #N/A | D10: #N/A | E10: #N/A | F10: #N/A | G10: #N/A | H10: #N/A | I10: #N/A | J10: #N/A | K10: #N/A | L10: #N/A | M10: #N/A | N10: #N/A | O10: #N/A | P10: #N/A | Q10: #N/A | R10: #N/A | U10: =B10-SUM(C10:R10) -> #N/A
A11: 01 | B11: 325742537 | C11: 3413888 | D11: 3366430 | E11: 3364066 | F11: 3380967 | G11: 3384817 | H11: 3358690 | I11: 3384304 | J11: 3472646 | K11: 3594947 | L11: 3656027 | M11: 3778016 | N11: 3764270 | O11: 3817487 | P11: 3784664 | Q11: 3824478 | R11: 3829622 | U11: =B11-SUM(C11:R11) -> 268567218
A12: 02 | B12: 327130893 | C12: 3366112 | D12: 3428590 | E12: 3387056 | F12: 3383512 | G12: 3395975 | H12: 3405633 | I12: 3377236 | J12: 3403440 | K12: 3490634 | L12: 3620974 | M12: 3694653 | N12: 3812627 | O12: 3801014 | P12: 3856763 | Q12: 3814776 | R12: 3853794 | U12: =B12-SUM(C12:R12) -> 270038104
A13: 03 | B13: 328935204 | C13: 3361202 | D13: 3385451 | E13: 3449548 | F13: 3407448 | G13: 3405109 | H13: 3418411 | I13: 3425506 | J13: 3396402 | K13: 3423013 | L13: 3511090 | M13: 3641673 | N13: 3714033 | O13: 3831606 | P13: 3820922 | Q13: 3878974 | R13: 3835868 | U13: =B13-SUM(C13:R13) -> 272028948
A14: 04 | B14: 330735833 | C14: 3377858 | D14: 3377565 | E14: 3401647 | F14: 3468906 | G14: 3427886 | H14: 3423465 | I14: 3436804 | J14: 3443054 | K14: 3413242 | L14: 3441094 | M14: 3529166 | N14: 3659619 | O14: 3730886 | P14: 3848628 | Q14: 3838717 | R14: 3898245 | U14: =B14-SUM(C14:R14) -> 274019051
A15: 05 | B15: 332621924 | C15: 3409112 | D15: 3392238 | E15: 3389681 | F15: 3418295 | G15: 3488944 | H15: 3442273 | I15: 3438615 | J15: 3452735 | K15: 3457884 | L15: 3429669 | M15: 3457961 | N15: 3545796 | O15: 3676100 | P15: 3746097 | Q15: 3865448 | R15: 3855330 | U15: =B15-SUM(C15:R15) -> 276155746
A16: 06 | B16: 334222207 | C16: 3398900 | D16: 3420491 | E16: 3402230 | F16: 3403380 | G16: 3435395 | H16: 3506572 | I16: 3456523 | J16: 3454137 | K16: 3468967 | L16: 3474905 | M16: 3445863 | N16: 3474370 | O16: 3562932 | P16: 3691298 | Q16: 3761130 | R16: 3880122 | U16: =B16-SUM(C16:R16) -> 277984992
A17: 07 | B17: 335805090 | C17: 3433172 | D17: 3414905 | E17: 3432560 | F17: 3418004 | G17: 3418873 | H17: 3449789 | I17: 3523250 | J17: 3471760 | K17: 3469779 | L17: 3486269 | M17: 3491245 | N17: 3462937 | O17: 3490421 | P17: 3577268 | Q17: 3706407 | R17: 3776260 | U17: =B17-SUM(C17:R17) -> 279782191
A18: 08 | B18: 337757636 | C18: 3447598 | D18: 3453142 | E18: 3430568 | F18: 3448195 | G18: 3435455 | H18: 3434813 | I18: 3465978 | J18: 3541692 | K18: 3490134 | L18: 3487214 | M18: 3506221 | N18: 3509480 | O18: 3481943 | P18: 3508890 | Q18: 3593918 | R18: 3723952 | U18: =B18-SUM(C18:R18) -> 281798443
A19: 09 | B19: 339200057 | C19: 3520750 | D19: 3466097 | E19: 3464265 | F19: 3444548 | G19: 3459711 | H19: 3446990 | I19: 3445469 | J19: 3476861 | K19: 3557114 | L19: 3503229 | M19: 3501469 | N19: 3522427 | O19: 3525201 | P19: 3498240 | Q19: 3524315 | R19: 3611327 | U19: =B19-SUM(C19:R19) -> 283232044
A20: 10 | B20: 340069444 | C20: 3468073 | D20: 3530078 | E20: 3472989 | F20: 3473503 | G20: 3454223 | H20: 3467468 | I20: 3452816 | J20: 3452141 | K20: 3485921 | L20: 3568908 | M20: 3512790 | N20: 3513086 | O20: 3533871 | P20: 3537062 | Q20: 3509510 | R20: 3537970 | U20: =B20-SUM(C20:R20) -> 284099035
A21: 11 | B21: 339446253 | C21: 3461192 | D21: 3471286 | E21: 3529086 | F21: 3476603 | G21: 3478398 | H21: 3454461 | I21: 3468572 | J21: 3454212 | K21: 3454064 | L21: 3490235 | M21: 3577144 | N21: 3516863 | O21: 3519004 | P21: 3540900 | Q21: 3542836 | R21: 3514887 | U21: =B21-SUM(C21:R21) -> 283496510
A22: 12 | B22: 340292438 | C22: 3382317 | D22: 3465547 | E22: 3474674 | F22: 3534409 | G22: 3487790 | H22: 3489309 | I22: 3466263 | J22: 3478744 | K22: 3463698 | L22: 3461922 | M22: 3497412 | N22: 3586675 | O22: 3523476 | P22: 3526965 | Q22: 3549364 | R22: 3551466 | U22: =B22-SUM(C22:R22) -> 284352407
... A33: 23 | B33: 349665601 | C33: 2942003 | D33: 3119702 | E33: 3094681 | F33: 3184016 | G33: 3268080 | H33: 3354385 | I33: 3440264 | J33: 3463832 | K33: 3511388 | L33: 3490089 | M33: 3581411 | N33: 3602930 | O33: 3697237 | P33: 3694707 | Q33: 3750097 | R33: 3695691 | U33: =B33-SUM(C33:R33) -> 294775088

Sheet Population_compillation
A1: Year | B1: Data 1: Age 15 - 64, EA (Thousands) | C1: Data 2: Age 15 - 64, EA (Thousands) | D1: Data 3: Age 65 and over, EA (Thousands) | E1: Data 4: Age 15 - 64, EA (Thousands) | F1: Data 4: Age 65 and over, EA (Thousands) | G1: Data 5: Age 15 and over, EA (Thansands) | I1: Compiled data | J1: Q023LFN@EUDATA
J2: Labor force NAWM
A3: 1982 | B3: 178626 | G3: =IF(ISNUMBER([1]Sheet2!$B4), [1]Sheet2!$B4/1000, "") | I3: =+I4*J3/J4 -> 2.3033299e+08 | J3: 133.835
A4: 1983 | B4: 180629 | G4: =IF(ISNUMBER([1]Sheet2!$B5), [1]Sheet2!$B5/1000, "") | I4: =+I5*J4/J5 -> 2.3109368e+08 | J4: 134.277
A5: 1984 | B5: 182515 | G5: =IF(ISNUMBER([1]Sheet2!$B6), [1]Sheet2!$B6/1000, "") | I5: =+I6*J5/J6 -> 2.3215039e+08 | J5: 134.891
A6: 1985 | B6: 183666 | G6: =IF(ISNUMBER([1]Sheet2!$B7), [1]Sheet2!$B7/1000, "") | I6: =+I7*J6/J7 -> 2.3340674e+08 | J6: 135.621
A7: 1986 | B7: 184436 | G7: =IF(ISNUMBER([1]Sheet2!$B8), [1]Sheet2!$B8/1000, "") | I7: =+I8*J7/J8 -> 2.3600892e+08 | J7: 137.133
A8: 1987 | B8: 185068 | G8: =IF(ISNUMBER([1]Sheet2!$B9), [1]Sheet2!$B9/1000, "") | I8: =+I9*J8/J9 -> 2.3880903e+08 | J8: 138.76
A9: 1988 | B9: 186205 | G9: =IF(ISNUMBER([1]Sheet2!$B10), [1]Sheet2!$B10/1000, "") | I9: =+I10*J9/J10 -> 2.4125976e+08 | J9: 140.184
A10: 1989 | B10: 186818 | G10: =IF(ISNUMBER([1]Sheet2!$B11), [1]Sheet2!$B11/1000, "") | I10: =+I11*J10/J11 -> 2.439239e+08 | J10: 141.732
A11: 1990 | B11: 187742 | G11: =IF(ISNUMBER([1]Sheet2!$B12), [1]Sheet2!$B12/1000, "") | I11: =+I12*J11/J12 -> 2.4808706e+08 | J11: 144.151
A12: 1991 | B12: 199539 | G12: =IF(ISNUMBER([1]Sheet2!$B13), [1]Sheet2!$B13/1000, "") | I12: =+I13*J12/J13 -> 2.5023489e+08 | J12: 145.399
A13: 1992 | B13: 200189 | G13: =IF(ISNUMBER([1]Sheet2!$B14), [1]Sheet2!$B14/1000, "") | I13: =+I14*J13/J14 -> 2.4994232e+08 | J13: 145.229
A14: 1993 | B14: 200577 | G14: =IF(ISNUMBER([1]Sheet2!$B15), [1]Sheet2!$B15/1000, "") | I14: =+I15*J14/J15 -> 2.5058254e+08 | J14: 145.601
... A17: 1996 | B17: 202015 | G17: =IF(ISNUMBER([1]Sheet2!$B18), [1]Sheet2!$B18/1000, "") | I17: =+I18*J17/J18 -> 2.5470094e+08 | J17: 147.994
A18: 1997 | B18: 202453 | C18: 205396 | G18: =IF(ISNUMBER([1]Sheet2!$B19), [1]Sheet2!$B19/1000, "") | I18: =+I19*J18/J19 -> 2.5699334e+08 | J18: 149.326
A19: 1998 | B19: 202985 | C19: 206115 | G19: =IF(ISNUMBER([1]Sheet2!$B20), [1]Sheet2!$B20/1000, "") | I19: =+I20*J19/J20 -> 2.6040269e+08 | J19: 151.307
A20: 1999 | B20: 203377 | C20: 206634 | G20: =IF(ISNUMBER([1]Sheet2!$B21), [1]Sheet2!$B21/1000, "") | I20: =+I21*J20/J21 -> 2.6337145e+08 | J20: 153.032
A21: 2000 | B21: 203841 | C21: 207387 | D21: 49832 | G21: =IF(ISNUMBER([1]Sheet2!$B22), [1]Sheet2!$B22/1000, "") | I21: =+I22*J21/J22 -> 2.6697355e+08 | J21: 155.125
A22: 2001 | B22: 204527 | C22: 208200 | D22: 50783 | G22: =IF(ISNUMBER([1]Sheet2!$B23), [1]Sheet2!$B23/1000, "") | I22: =PopulationByCohort1995!U11 -> 268567218 | J22: 156.051
A23: 2002 | B23: 205332 | C23: 208935 | D23: 51668 | G23: =IF(ISNUMBER([1]Sheet2!$B24), [1]Sheet2!$B24/1000, "") | I23: =PopulationByCohort1995!U12 -> 270038104 | J23: 157.696
A24: 2003 | B24: 206133 | C24: 210193 | D24: 52456 | G24: =IF(ISNUMBER([1]Sheet2!$B25), [1]Sheet2!$B25/1000, "") | I24: =PopulationByCohort1995!U13 -> 272028948 | J24: 159.074
A25: 2004 | B25: 206429 | C25: 210621 | D25: 53893 | G25: =IF(ISNUMBER([1]Sheet2!$B26), [1]Sheet2!$B26/1000, "") | I25: =PopulationByCohort1995!U14 -> 274019051 | J25: 160.643
A26: 2005 | B26: 207934 | C26: 212301 | D26: 54620 | E26: 217020.2 | F26: 55661.1 | G26: =IF(ISNUMBER([1]Sheet2!$B27), [1]Sheet2!$B27/1000, "") | I26: =PopulationByCohort1995!U15 -> 276155746 | J26: 162.035
A27: 2006 | C27: 213278 | D27: 55628 | E27: 217818.2 | F27: 56669.8 | G27: =IF(ISNUMBER([1]Sheet2!$B28), [1]Sheet2!$B28/1000, "") | I27: =PopulationByCohort1995!U16 -> 277984992 | J27: 163.594
A28: 2007 | C28: 214284 | D28: 56466 | E28: 218709 | F28: 57551.4 | G28: =IF(ISNUMBER([1]Sheet2!$B29), [1]Sheet2!$B29/1000, "") | I28: =PopulationByCohort1995!U17 -> 279782191 | J28: 165.169
A29: 2008 | C29: 215183 | D29: 57165 | E29: 219632.6 | F29: 58286.7 | G29: =IF(ISNUMBER([1]Sheet2!$B30), [1]Sheet2!$B30/1000, "") | I29: =PopulationByCohort1995!U18 -> 281798443 | J29: 166.671
A30: 2009 | C30: 215415 | D30: 57901 | E30: 219826.2 | F30: 59037 | G30: =IF(ISNUMBER([1]Sheet2!$B31), [1]Sheet2!$B31/1000, "") | I30: =PopulationByCohort1995!U19 -> 283232044 | J30: 167.233
A31: 2010 | E31: 218615.5 | F31: 59582.9 | G31: =IF(ISNUMBER([1]Sheet2!$B32), [1]Sheet2!$B32/1000, "") | I31: =PopulationByCohort1995!U20 -> 284099035 | J31: 167.349
A32: 2011 | E32: 218347.1 | F32: 60194.5 | G32: =IF(ISNUMBER([1]Sheet2!$B33), [1]Sheet2!$B33/1000, "") -> 282727.76 | I32: =PopulationByCohort1995!U21 -> 283496510 | J32: 167.61
A33: 2012 | E33: 218138.6 | F33: 61313.4 | G33: =IF(ISNUMBER([1]Sheet2!$B34), [1]Sheet2!$B34/1000, "") -> 283473.88 | I33: =PopulationByCohort1995!U22 -> 284352407 | J33: 169.082
A34: 2013 | E34: 217757.1 | F34: 62542.7 | G34: =IF(ISNUMBER([1]Sheet2!$B35), [1]Sheet2!$B35/1000, "") -> 284253.54 | I34: =PopulationByCohort1995!U23 -> 284979194 | J34: 169.231
A35: 2014 | E35: 218535.9 | F35: 64041.7 | G35: =IF(ISNUMBER([1]Sheet2!$B36), [1]Sheet2!$B36/1000, "") -> 285852.81 | I35: =PopulationByCohort1995!U24 -> 285600306 | J35: 169.516
A36: 2015 | E36: 218336.6 | F36: 65350.8 | G36: =IF(ISNUMBER([1]Sheet2!$B37), [1]Sheet2!$B37/1000, "") -> 286708.94 | I36: =PopulationByCohort1995!U25 -> 286374618 | J36: 169.77
A37: 2016 | E37: 218817.8 | F37: 65902.1 | G37: =IF(ISNUMBER([1]Sheet2!$B38), [1]Sheet2!$B38/1000, "") -> 287971.61 | I37: =PopulationByCohort1995!U26 -> 287524182 | J37: 170.477
A38: 2017 | E38: 218527.6 | F38: 66789.8 | G38: =IF(ISNUMBER([1]Sheet2!$B39), [1]Sheet2!$B39/1000, "") -> 288737.27 | I38: =PopulationByCohort1995!U27 -> 288330927 | J38: 171.399
A39: 2018 | E39: 218152 | F39: 67923.2 | G39: =IF(ISNUMBER([1]Sheet2!$B40), [1]Sheet2!$B40/1000, "") -> 289453.17 | I39: =PopulationByCohort1995!U28 -> 289119880
A40: 2019 | E40: 218198.2 | F40: 68639.8 | G40: =IF(ISNUMBER([1]Sheet2!$B41), [1]Sheet2!$B41/1000, "") -> 290372.87 | I40: =PopulationByCohort1995!U29 -> 290177735
A41: 2020 | G41: =IF(ISNUMBER([1]Sheet2!$B42), [1]Sheet2!$B42/1000, "") | I41: =PopulationByCohort1995!U30 -> 291287854
A42: 2021 | I42: =PopulationByCohort1995!U31 -> 291620824
...

Sheet Core data
C1: P023SHXF@EUDATA | D1: P023SHXU@EUDATA
A3: 109 | B3: 1997 - Q1 | C3: --- | D3: 75.5
A4: 110 | B4: 1997 - Q2 | C4: 0.22 | D4: 75.68 | E4: =100*LN(D4/D3) -> 0.23812685 | F4: =100*LN(Data_input!AD113/Data_input!AD112) -> 0.31864074
A5: 111 | B5: 1997 - Q3 | C5: 0.28 | D5: 75.92 | E5: =100*LN(D5/D4) -> 0.31662296 | F5: =100*LN(Data_input!AD114/Data_input!AD113) -> 0.34405221
A6: 112 | B6: 1997 - Q4 | C6: 0.3 | D6: 76.16 | E6: =100*LN(D6/D5) -> 0.31562362 | F6: =100*LN(Data_input!AD115/Data_input!AD114) -> 0.35603651
A7: 113 | B7: 1998 - Q1 | C7: 0.35 | D7: 76.42 | E7: =100*LN(D7/D6) -> 0.34080515 | F7: =100*LN(Data_input!AD116/Data_input!AD115) -> 0.34165605
A8: 114 | B8: 1998 - Q2 | C8: 0.44 | D8: 76.76 | E8: =100*LN(D8/D7) -> 0.44392291 | F8: =100*LN(Data_input!AD117/Data_input!AD116) -> 0.37970586
A9: 115 | B9: 1998 - Q3 | C9: 0.32 | D9: 77.01 | E9: =100*LN(D9/D8) -> 0.32516124 | F9: =100*LN(Data_input!AD118/Data_input!AD117) -> 0.3392045
A10: 116 | B10: 1998 - Q4 | C10: 0.29 | D10: 77.22 | E10: =100*LN(D10/D9) -> 0.27232073 | F10: =100*LN(Data_input!AD119/Data_input!AD118) -> 0.26014583
A11: 117 | B11: 1999 - Q1 | C11: 0.16 | D11: 77.35 | E11: =100*LN(D11/D10) -> 0.16820862 | F11: =100*LN(Data_input!AD120/Data_input!AD119) -> 0.24651326
A12: 118 | B12: 1999 - Q2 | C12: 0.29 | D12: 77.56 | E12: =100*LN(D12/D11) -> 0.27112534 | F12: =100*LN(Data_input!AD121/Data_input!AD120) -> 0.23297965
A13: 119 | B13: 1999 - Q3 | C13: 0.27 | D13: 77.76 | E13: =100*LN(D13/D12) -> 0.25753298 | F13: =100*LN(Data_input!AD122/Data_input!AD121) -> 0.25823126
A14: 120 | B14: 1999 - Q4 | C14: 0.26 | D14: 77.99 | E14: =100*LN(D14/D13) -> 0.29534532 | F14: =100*LN(Data_input!AD123/Data_input!AD122) -> 0.20610596
A15: 121 | B15: 2000 - Q1 | C15: 0.18 | D15: 78.14 | E15: =100*LN(D15/D14) -> 0.19214763 | F15: =100*LN(Data_input!AD124/Data_input!AD123) -> 0.26987101
... A96: 202 | B96: 2020 - Q2 | C96: 0.18 | D96: 105.38 | E96: =100*LN(D96/D95) -> 0.30412493 | F96: =100*LN(Data_input!AD205/Data_input!AD204) -> 0.27541686
A97: 3q2020 | D97: 105.31 | E97: =100*LN(D97/D96) -> -0.066448339 | F97: =100*LN(Data_input!AD206/Data_input!AD205) -> -0.12336894
A98: 4q2020 | D98: 105.37 | E98: =100*LN(D98/D97) -> 0.056958422 | F98: =100*LN(Data_input!AD207/Data_input!AD206) -> 0
A99: 1q2021 | D99: 106.15 | E99: =100*LN(D99/D98) -> 0.73752225 | F99: =100*LN(Data_input!AD208/Data_input!AD207) -> 0.9356904
A100: 2q2021 | D100: 106.3 | E100: =100*LN(D100/D99) -> 0.14120972 | F100: =100*LN(Data_input!AD209/Data_input!AD208) -> 0.065829692
A101: 3q2021 | D101: 107.04 | E101: =100*LN(D101/D100) -> 0.6937311 | F101: =100*LN(Data_input!AD210/Data_input!AD209) -> 0.50637768
A102: 4q2021 | D102: 107.94 | E102: =100*LN(D102/D101) -> 0.83729208 | F102: =100*LN(Data_input!AD211/Data_input!AD210) -> 0.91248305
A103: 1q2022 | D103: 109.13 | E103: =100*LN(D103/D102) -> 1.0964315 | F103: =100*LN(Data_input!AD212/Data_input!AD211) -> 1.2709694
A104: 2q2022 | D104: 110.84 | E104: =100*LN(D104/D103) -> 1.5547888 | F104: =100*LN(Data_input!AD213/Data_input!AD212) -> 1.4716835
A105: 3q2022 | D105: 112.9 | E105: =100*LN(D105/D104) -> 1.8414751 | F105: =100*LN(Data_input!AD214/Data_input!AD213) -> 1.7166269
A106: 4q2022 | D106: 115.14 | E106: =100*LN(D106/D105) -> 1.9646308 | F106: =100*LN(Data_input!AD215/Data_input!AD214) -> 1.9401039
A107: 1q2023 | D107: 117.2 | E107: =100*LN(D107/D106) -> 1.7733098 | F107: =100*LN(Data_input!AD216/Data_input!AD215) -> 1.9713977
A108: 2q2023 | D108: 118.61 | E108: =100*LN(D108/D107) -> 1.1958923 | F108: =100*LN(Data_input!AD217/Data_input!AD216) -> #NUM!
... A113: 3q2024 | D113: 122.85 | E113: =100*LN(D113/D112) -> 0.74349785 | F113: =100*LN(Data_input!AD222/Data_input!AD221) -> #DIV/0!

Sheet BBB

Sheet Data_input
E1: Haver | N1: NAWM
C2: Long term inflation expectations | D2: Long term inflation expectations | E2: J025GDPT@EUDATA and NAWM data | F2: J025PCN@EUDATA | G2: sa(D025IFN@EUDATA) | H2: J025GDPP@EUDATA | I2: sa(N025PP2T@EUDATA) | K2: L025CESI@EUDATA | L2: I023M1@EUDATA | M2: Labor Force | N2: Q023YER@EUDATA | O2: Q023PCR@EUDATA | P2: Q023PCD@EUDATA | Q2: Q023ITR@EUDATA | R2: Q023ITD@EUDATA | S2: Q023YED@EUDATA | T2: Q023LFN@EUDATA | U2: Q023WIN@EUDATA | V2: Q023LNN@EUDATA | W2: Q023STN@EUDATA | Z2: sa(Q023HEX@EUDATA) | AA2: Q023LEN@EUDATA*1000 | AE2: Constructed data | AN2: Model data | AY2: r10 | AZ2: NDI | BA2: Consumption of fixed capital | BB2: GDI | BC2: real GDI | BD2: 2 year govt bond yield | BF2: 5 year govt bond yield | BG2: 10 year govt bond yield
C3: https://www.ecb.europa.eu/stats/ecb_surveys/survey_of_professional_forecasters/html/table_hist_hicp.en.html | D3: V025IMPL@EUDATA | E3: y | F3: C_nom | G3: I_nom | H3: GDP_deflator | I3: Population older than 15 | K3: Nominal wage (compensation per employee) | L3: Short term interest rate | M3: Q023LFN@EUDATA | N3: y | O3: C_real | P3: C_deflator | Q3: I_real | R3: I_deflator | S3: GDP_deflator | T3: Labor force | U3: Nominal wage bill | V3: Employment | W3: Shor term interest rate | X3: Compensation per employee | Y3: Comp/emp_defl by GDP defl | Z3: CPI ex energy | AA3: Employment | AB3: C_deflated by GDP defl | AC3: I_deflated by GDP defl | AD3: CPI ex energy and unprocessed food | AE3: Y | AF3: C | AG3: I | AH3: GDP_deflator | AI3: Population | AJ3: Real wage (deflated by GDP deflator) | AK3: Hours | AM3: Core | AN3: dgdi | AO3: dy | AP3: dc | AQ3: dinve | AR3: pinfobs | AS3: pinfobs_core | AT3: robs | AU3: dw | AV3: labobs | AW3: labobs2 | AX3: longinflation | AZ3: sa(D025NDIN@EUDATA) | BA3: sa(D025K1N@EUDATA) | BB3: sa(K025EB6G@EUNA) | BD3: I023BY2@EUDATA | BE3: I023T2Y@EUDATA | BF3: I023BY5@EUDATA | BG3: I023BY10@EUDATA
A4: 1q70 | J4: =+J5*M4/M5 -> 211530.09 | M4: 123.288 | N4: 738.304 | O4: 410.134 | P4: 0.167 | Q4: 191.787 | R4: 0.17 | S4: 0.164 | T4: 123.288 | U4: 59.583 | V4: 121.35 | W4: 7.987 | X4: =U4/V4 -> 0.49100124 | Y4: =X4/S4 -> 2.99391 | AA4: 93033 | AB4: =O4*P4/S4 -> 417.63645 | AC4: =Q4*R4/S4 -> 198.8036 | AE4: =AE5*N4/N5 -> 1099310 | AF4: =AF5*AB4/AB5 -> 6124.4051 | AG4: =AG5*AC4/AC5 -> 3015.7208 | AH4: =AH5*S4/S5 -> 11.162468 | AI4: =+J4 -> 211530.09 | AJ4: =AJ5*Y4/Y5 -> 0.50450782 | AK4: =AK5*AA4/AA5 -> 214935.71 | AT4: =W4/4 -> 1.99675 | AV4: NaN | AW4: NaN | AX4: NaN | AY4: =+BG4/4 -> 1.980725 | BG4: 7.9229
A5: 2q70 | J5: =+J6*M5/M6 -> 211605.58 | M5: 123.332 | N5: 752.496 | O5: 415.238 | P5: 0.169 | Q5: 203.177 | R5: 0.173 | S5: 0.167 | T5: 123.332 | U5: 62.335 | V5: 121.453 | W5: 7.957 | X5: =U5/V5 -> 0.51324381 | Y5: =X5/S5 -> 3.0733162 | AA5: 93367 | AB5: =O5*P5/S5 -> 420.21091 | AC5: =Q5*R5/S5 -> 210.47677 | AE5: =AE6*N5/N6 -> 1120441.4 | AF5: =AF6*AB5/AB6 -> 6162.1581 | AG5: =AG6*AC5/AC6 -> 3192.7953 | AH5: =AH6*S5/S6 -> 11.36666 | AI5: =+J5 -> 211605.58 | AJ5: =AJ6*Y5/Y6 -> 0.51788867 | AK5: =AK6*AA5/AA6 -> 215707.36 | AL5: =100*LN(AE5) -> 1392.9233 | AN5: NaN | AO5: =100*LN(AE5/AI5/(AE4/AI4)) -> 1.8683193 | AP5: =100*LN(AF5/AI5/(AF4/AI4)) -> 0.57886079 | AQ5: =100*LN(AG5/AI5/(AG4/AI4)) -> 5.6701088 | AR5: =100*LN(AH5/AH4) -> 1.8127385 | AS5: NaN | AT5: =W5/4 -> 1.98925 | AU5: =100*LN(AJ5/AJ4) -> 2.6176958 | AV5: NaN | AW5: NaN | AX5: NaN | AY5: =+BG5/4 -> 2.0636 | BG5: 8.2544
A6: 3q70 | J6: =+J7*M6/M7 -> 211988.19 | M6: 123.555 | N6: 761.562 | O6: 420.219 | P6: 0.172 | Q6: 206.268 | R6: 0.175 | S6: 0.17 | T6: 123.555 | U6: 64.841 | V6: 121.61 | W6: 7.602 | X6: =U6/V6 -> 0.53318806 | Y6: =X6/S6 -> 3.1364004 | AA6: 93722 | AB6: =O6*P6/S6 -> 425.16275 | AC6: =Q6*R6/S6 -> 212.33471 | AE6: =AE7*N6/N7 -> 1133940.4 | AF6: =AF7*AB6/AB7 -> 6234.7741 | AG6: =AG7*AC6/AC7 -> 3220.9789 | AH6: =AH7*S6/S7 -> 11.570851 | AI6: =+J6 -> 211988.19 | AJ6: =AJ7*Y6/Y7 -> 0.52851906 | AK6: =AK7*AA6/AA7 -> 216527.52 | AL6: =100*LN(AE6) -> 1394.1209 | AN6: NaN | AO6: =100*LN(AE6/AI6/(AE5/AI5)) -> 1.0169411 | AP6: =100*LN(AF6/AI6/(AF5/AI5)) -> 0.99087964 | AQ6: =100*LN(AG6/AI6/(AG5/AI5)) -> 0.69820336 | AR6: =100*LN(AH6/AH5) -> 1.7804625 | AS6: NaN | AT6: =W6/4 -> 1.9005 | AU6: =100*LN(AJ6/AJ5) -> 2.0318583 | AV6: NaN | AW6: NaN | AX6: NaN | AY6: =+BG6/4 -> 2.0962 | BG6: 8.3848
A7: 4q70 | J7: =+J8*M7/M8 -> 212329.62 | M7: 123.754 | N7: 770.787 | O7: 428.379 | P7: 0.174 | Q7: 205.426 | R7: 0.178 | S7: 0.172 | T7: 123.754 | U7: 67.221 | V7: 121.823 | W7: 7.242 | X7: =U7/V7 -> 0.55179235 | Y7: =X7/S7 -> 3.2080951 | AA7: 94173 | AB7: =O7*P7/S7 -> 433.36015 | AC7: =Q7*R7/S7 -> 212.59202 | AE7: =AE8*N7/N8 -> 1147676.1 | AF7: =AF8*AB7/AB8 -> 6354.9844 | AG7: =AG8*AC7/AC8 -> 3224.8823 | AH7: =AH8*S7/S8 -> 11.706979 | AI7: =+J7 -> 212329.62 | AJ7: =AJ8*Y7/Y8 -> 0.54060044 | AK7: =AK8*AA7/AA8 -> 217569.47 | AL7: =100*LN(AE7) -> 1395.325 | AN7: NaN | AO7: =100*LN(AE7/AI7/(AE6/AI6)) -> 1.043116 | AP7: =100*LN(AF7/AI7/(AF6/AI6)) -> 1.7487773 | AQ7: =100*LN(AG7/AI7/(AG6/AI6)) -> -0.039820886 | AR7: =100*LN(AH7/AH6) -> 1.169604 | AS7: NaN | AT7: =W7/4 -> 1.8105 | AU7: =100*LN(AJ7/AJ6) -> 2.2601571 | AV7: NaN | AW7: NaN | AX7: NaN | AY7: =+BG7/4 -> 2.085225 | BG7: 8.3409
A8: 1q71 | J8: =+J9*M8/M9 -> 212761.99 | M8: 124.006 | N8: 769.439 | O8: 431.329 | P8: 0.177 | Q8: 204.325 | R8: 0.182 | S8: 0.176 | T8: 124.006 | U8: 69.576 | V8: 122.04 | W8: 6.517 | X8: =U8/V8 -> 0.57010816 | Y8: =X8/S8 -> 3.2392509 | AA8: 94638 | AB8: =O8*P8/S8 -> 433.77973 | AC8: =Q8*R8/S8 -> 211.29062 | AE8: =AE9*N8/N9 -> 1145669 | AF8: =AF9*AB8/AB9 -> 6361.1373 | AG8: =AG9*AC8/AC9 -> 3205.1409 | AH8: =AH9*S8/S9 -> 11.979234 | AI8: =+J8 -> 212761.99 | AJ8: =AJ9*Y8/Y9 -> 0.54585055 | AK8: =AK9*AA8/AA9 -> 218643.77 | AL8: =100*LN(AE8) -> 1395.1499 | AN8: NaN | AO8: =100*LN(AE8/AI8/(AE7/AI7)) -> -0.37846203 | AP8: =100*LN(AF8/AI8/(AF7/AI7)) -> -0.106649 | AQ8: =100*LN(AG8/AI8/(AG7/AI7)) -> -0.81746172 | AR8: =100*LN(AH8/AH7) -> 2.2989518 | AS8: NaN | AT8: =W8/4 -> 1.62925 | AU8: =100*LN(AJ8/AJ7) -> 0.96647751 | AV8: NaN | AW8: NaN | AX8: NaN | AY8: =+BG8/4 -> 1.96515 | BG8: 7.8606
A9: 2q71 | J9: =+J10*M9/M10 -> 213376.22 | M9: 124.364 | N9: 779.296 | O9: 437.729 | P9: 0.179 | Q9: 209.725 | R9: 0.185 | S9: 0.178 | T9: 124.364 | U9: 71.109 | V9: 122.299 | W9: 5.939 | X9: =U9/V9 -> 0.58143566 | Y9: =X9/S9 -> 3.2664925 | AA9: 94933 | AB9: =O9*P9/S9 -> 440.18815 | AC9: =Q9*R9/S9 -> 217.97261 | AE9: =AE10*N9/N10 -> 1160345.7 | AF9: =AF10*AB9/AB10 -> 6455.1132 | AG9: =AG10*AC9/AC10 -> 3306.5023 | AH9: =AH10*S9/S10 -> 12.115362 | AI9: =+J9 -> 213376.22 | AJ9: =AJ10*Y9/Y10 -> 0.55044106 | AK9: =AK10*AA9/AA10 -> 219325.31 | AL9: =100*LN(AE9) -> 1396.4229 | AN9: NaN | AO9: =100*LN(AE9/AI9/(AE8/AI8)) -> 0.98464723 | AP9: =100*LN(AF9/AI9/(AF8/AI8)) -> 1.1782578 | AQ9: =100*LN(AG9/AI9/(AG8/AI8)) -> 2.825207 | AR9: =100*LN(AH9/AH8) -> 1.1299555 | AS9: NaN | AT9: =W9/4 -> 1.48475 | AU9: =100*LN(AJ9/AJ8) -> 0.83746693 | AV9: NaN | AW9: NaN | AX9: NaN | AY9: =+BG9/4 -> 1.9827 | BG9: 7.9308
A10: 3q71 | J10: =+J11*M10/M11 -> 212751.7 | M10: 124 | N10: 791.45 | O10: 441.548 | P10: 0.182 | Q10: 210.716 | R10: 0.187 | S10: 0.181 | T10: 124 | U10: 73.512 | V10: 121.939 | W10: 6.226 | X10: =U10/V10 -> 0.60285881 | Y10: =X10/S10 -> 3.3307116 | AA10: 95086 | AB10: =O10*P10/S10 -> 443.98749 | AC10: =Q10*R10/S10 -> 217.70106 | AE10: =AE11*N10/N11 -> 1178442.6 | AF10: =AF11*AB10/AB11 -> 6510.8284 | AG10: =AG11*AC10/AC11 -> 3302.383 | AH10: =AH11*S10/S11 -> 12.319553 | AI10: =+J10 -> 212751.7 | AJ10: =AJ11*Y10/Y11 -> 0.56126272 | AK10: =AK11*AA10/AA11 -> 219678.79 | AL10: =100*LN(AE10) -> 1397.9704 | AN10: NaN | AO10: =100*LN(AE10/AI10/(AE9/AI9)) -> 1.8406942 | AP10: =100*LN(AF10/AI10/(AF9/AI9)) -> 1.1525321 | AQ10: =100*LN(AG10/AI10/(AG9/AI9)) -> 0.16846011 | AR10: =100*LN(AH10/AH9) -> 1.6713481 | AS10: NaN | AT10: =W10/4 -> 1.5565 | AU10: =100*LN(AJ10/AJ9) -> 1.9469213 | AV10: NaN | AW10: NaN | AX10: NaN | AY10: =+BG10/4 -> 2.00675 | BG10: 8.027
A11: 4q71 | J11: =+J12*M11/M12 -> 213022.78 | M11: 124.158 | N11: 797.745 | O11: 446.639 | P11: 0.184 | Q11: 213.343 | R11: 0.19 | S11: 0.183 | T11: 124.158 | U11: 75.554 | V11: 121.935 | W11: 6.006 | X11: =U11/V11 -> 0.61962521 | Y11: =X11/S11 -> 3.3859301 | AA11: 95370 | AB11: =O11*P11/S11 -> 449.07965 | AC11: =Q11*R11/S11 -> 221.50366 | AE11: =AE12*N11/N12 -> 1187815.6 | AF11: =AF12*AB11/AB12 -> 6585.502 | AG11: =AG12*AC11/AC12 -> 3360.066 | AH11: =AH12*S11/S12 -> 12.455681 | AI11: =+J11 -> 213022.78 | AJ11: =AJ12*Y11/Y12 -> 0.57056766 | AK11: =AK12*AA11/AA12 -> 220334.92 | AL11: =100*LN(AE11) -> 1398.7627 | AN11: NaN | AO11: =100*LN(AE11/AI11/(AE10/AI10)) -> 0.66489089 | AP11: =100*LN(AF11/AI11/(AF10/AI10)) -> 1.0130494 | AQ11: =100*LN(AG11/AI11/(AG10/AI10)) -> 1.6042895 | AR11: =100*LN(AH11/AH10) -> 1.0989122 | AS11: NaN | AT11: =W11/4 -> 1.5015 | AU11: =100*LN(AJ11/AJ10) -> 1.6442656 | AV11: NaN | AW11: NaN | AX11: NaN | AY11: =+BG11/4 -> 1.9615 | BG11: 7.846
