Workbook
Name BoxPlot: "BoxPlot"
Name Bubble: "Bubble"
Name Candlestick: "Candlestick"
Name Chart: "Chart"
Name ChartImage: "ChartImage"
Name ColumnRange: "ColumnRange"
Name Dumbbell: "Dumbbell"
Name Heatmap: "Heatmap"
Name Histogram: "Histogram"
Name Map: "Map"
Name OHLC: "OHLC"
Name PieChart: "PieChart"
Name Scatter: "Scatter"
Name Series: "Series"
Name Stripe: "Stripe"
Name Table: "Table"
Name TreeMap: "TreeMap"
Name Waterfall: "Waterfall"

Sheet Chart NA - DSGE Raw Data
A2: date | B2: obs_gdp | C2: obs_gdpdeflator | D2: obs_nominalrate | F2: obs_longinflation | G2: obs_longrate
A3: 21823 | B3: -0.30408411 | C3: 0.38618932 | D3: 0.8925
A4: 21915 | B4: -0.085396239 | C4: 0.3912113 | D4: 0.9975
A5: 22006 | B5: 1.8569299 | C5: 0.39616873 | D5: 0.9825
A6: 22097 | B6: -0.91034251 | C6: 0.25246817 | D6: 0.925
A7: 22189 | B7: 0.12315845 | C7: 0.34207927 | D7: 0.735
A8: 22281 | B8: -1.6584688 | C8: 0.29595338 | D8: 0.575
A9: 22371 | B9: 0.30422427 | C9: 0.21818657 | D9: 0.4975
A10: 22462 | B10: 1.3165542 | C10: 0.23050337 | D10: 0.4325
A11: 22554 | B11: 1.5360756 | C11: 0.25549324 | D11: 0.42
A12: 22646 | B12: 1.5758415 | C12: 0.31209223 | D12: 0.6
A13: 22736 | B13: 1.399261 | C13: 0.51378122 | D13: 0.615
A14: 22827 | B14: 0.52884844 | C14: 0.16435935 | D14: 0.6525
... A50: 26114 | B50: -0.010363799 | C50: 1.3054021 | D50: 1.1425
A51: 26206 | B51: 0.2690258 | C51: 1.0125119 | D51: 1.37 | G51: 1.5257
A52: 26298 | B52: -0.32043651 | C52: 0.83057731 | D52: 1.1875 | G52: 1.491925
A53: 26389 | B53: 1.2602782 | C53: 1.5126649 | D53: 0.8875 | G53: 1.5448
A54: 26480 | B54: 1.6860456 | C54: 0.62055319 | D54: 1.075 | G54: 1.53105
A55: 26572 | B55: 0.3852877 | C55: 0.9507066 | D55: 1.185 | G55: 1.5853
A56: 26664 | B56: 1.1057907 | C56: 1.2670582 | D56: 1.2875 | G56: 1.569
A57: 26754 | B57: 1.8936626 | C57: 1.1457007 | D57: 1.635 | G57: 1.645375
A58: 26845 | B58: 0.53249332 | C58: 1.5276802 | D58: 1.955 | G58: 1.66725
A59: 26937 | B59: -1.06861 | C59: 1.9262302 | D59: 2.64 | G59: 1.690725
A60: 27029 | B60: 0.40548359 | C60: 1.9731808 | D60: 2.5 | G60: 1.684425
A61: 27119 | B61: -1.3981815 | C61: 1.869599 | D61: 2.3325 | G61: 1.835475
A62: 27210 | B62: -0.29322437 | C62: 2.3358372 | D62: 2.8125 | G62: 1.929325
... A83: 29128 | B83: 0.32743149 | C83: 2.1632932 | D83: 2.735 | G83: 2.270025
A84: 29220 | B84: -0.15362911 | C84: 1.8384466 | D84: 3.395 | F84: 1.6 | G84: 2.4906
A85: 29311 | B85: -0.08319259 | C85: 2.0793092 | D85: 3.7675 | G85: 2.978425
A86: 29402 | B86: -2.4706014 | C86: 2.3510302 | D86: 3.1675 | F86: 1.8375 | G86: 2.4489
A87: 29494 | B87: -0.49739301 | C87: 2.2090655 | D87: 2.455 | G87: 2.878775
A88: 29586 | B88: 1.4763561 | C88: 2.5713717 | D88: 3.9625 | F88: 1.9375 | G88: 2.96035
A89: 29676 | B89: 1.5757765 | C89: 2.6000618 | D89: 4.15 | G89: 3.210275
A90: 29767 | B90: -1.0984483 | C90: 1.9622379 | D90: 4.4475 | F90: 1.825 | G90: 3.264225
A91: 29859 | B91: 0.8416346 | C91: 1.8647478 | D91: 4.3975 | G91: 3.723025
A92: 29951 | B92: -1.4356505 | C92: 1.7132211 | D92: 3.3975 | F92: 1.6375 | G92: 3.37825
A93: 30041 | B93: -1.8983795 | C93: 1.3662426 | D93: 3.5525 | G93: 3.342825
A94: 30132 | B94: 0.12845338 | C94: 1.2906547 | D94: 3.6275 | F94: 1.3 | G94: 3.398
A95: 30224 | B95: -0.70404248 | C95: 1.4087662 | D95: 2.7525 | G95: 2.90445
A96: 30316 | B96: -0.27615918 | C96: 1.0313596 | D96: 2.32 | F96: 1.2875 | G96: 2.6224
...

Sheet Chart 2 - Real rate gaps
E1: PCECTPI (yoy growth rate inflation) - source:https://fred.stlouisfed.org/series/PCECTPI | F1: GDP percent change yoy | H1: wFG | J1: woFG
A2: observation_date | B2: PCECTPI | C2: NBER Recession | D2: NBER Recession | E2: Inflation (yoy, apr) | F2: GDP (yoy, apr) | G2: Policy rate (%, apr) | H2: Real rate gap - with FG (lhs) | I2: 5-year real rate gap - with FG (rhs) | J2: Real rate gap - without FG (lhs) | K2: 5-year real rate gap - without FG (rhs) | L2: r* (%,apr)
A3: 17258 | B3: 0.8 | F3: 9.3
A4: 17349 | B4: 1.9 | F4: 10.8
A5: 17441 | B5: 2.5 | F5: 11.9
A6: 17533 | B6: 1.1 | E6: 6.4 | F6: 7.9
A7: 17624 | B7: 1 | E7: 6.7 | F7: 3.5
A8: 17715 | B8: 1.5 | E8: 6.3 | F8: -0.4
A9: 17807 | B9: -0.3 | C9: 1 | D9: -1 | E9: 3.4 | F9: -2.3
A10: 17899 | B10: -0.8 | C10: 1 | D10: -1 | E10: 1.4 | F10: -3.5
A11: 17989 | B11: -0.6 | C11: 1 | D11: -1 | E11: -0.2 | F11: 2.1
A12: 18080 | B12: -0.6 | C12: 1 | D12: -1 | E12: -2.3 | F12: 7
A13: 18172 | B13: -0.1 | E13: -2 | F13: 12.9
A14: 18264 | B14: -0.2 | E14: -1.4 | F14: 18.2
A15: 18354 | B15: 0.5 | E15: -0.3 | F15: 19.6
A16: 18445 | B16: 2.1 | E16: 2.3 | F16: 18.5
A17: 18537 | B17: 1.8 | E17: 4.2 | F17: 14
A18: 18629 | B18: 3.2 | E18: 7.7 | F18: 11.3
A19: 18719 | B19: 0.8 | E19: 8.1 | F19: 7.1
A20: 18810 | B20: 0.1 | E20: 6 | F20: 4.9
A21: 18902 | B21: 1.3 | E21: 5.5 | F21: 4.6
A22: 18994 | B22: 0.4 | E22: 2.7 | F22: 6.9
A23: 19085 | B23: 0 | E23: 1.9 | F23: 7.8
A24: 19176 | B24: 0.7 | E24: 2.4 | F24: 8.5
... A27: 19450 | B27: 0.1 | E27: 1.3 | F27: -0.7
A28: 19541 | B28: 0.5 | C28: 1 | D28: -1 | E28: 1.2 | F28: -1.4
A29: 19633 | B29: 0.4 | C29: 1 | D29: -1 | E29: 1.5 | F29: 0
A30: 19725 | B30: 0.5 | C30: 1 | D30: -1 | E30: 1.6 | F30: 3.6
A31: 19815 | B31: -0.1 | E31: 1.3 | F31: 7.2
A32: 19906 | B32: -0.3 | E32: 0.5 | F32: 9.2
A33: 19998 | B33: -0.1 | E33: -0.1 | F33: 10
A34: 20090 | B34: 0.3 | E34: -0.2 | F34: 9.3
A35: 20180 | B35: 0.1 | E35: 0 | F35: 6.5
A36: 20271 | B36: 0.4 | E36: 0.7 | F36: 5.8
A37: 20363 | B37: 0.3 | E37: 1.1 | F37: 4.9
A38: 20455 | B38: 0.4 | E38: 1.2 | F38: 5.3
A39: 20546 | B39: 0.7 | E39: 1.8 | F39: 6.8
A40: 20637 | B40: 1 | E40: 2.4 | F40: 5.8
A41: 20729 | B41: 0.6 | E41: 2.7 | F41: 6.3
A42: 20821 | B42: 0.9 | E42: 3.2 | F42: 3.1
...

Sheet Chart 3 - rstar
A1: Date | B1: DSGE r* (with FG) | C1: DSGE r* (without FG) | D1: HLW r* | E1: LM r* | F1: =+'Chart NA - DSGE Raw Data'!D2 -> obs_nominalrate
A2: =+hist_Forward5YearRNatR_wFG!A2 -> 22006 | B2: =+hist_Forward5YearRNatR_wFG!D2 -> 2.0631498 | C2: =+hist_Forward5YearRNatR_woFG!D2 -> 2.0874644 | F2: =+'Chart NA - DSGE Raw Data'!D5 -> 0.9825
A3: =+hist_Forward5YearRNatR_wFG!A3 -> 22097 | B3: =+hist_Forward5YearRNatR_wFG!D3 -> 2.1205647 | C3: =+hist_Forward5YearRNatR_woFG!D3 -> 2.1450854 | F3: =+'Chart NA - DSGE Raw Data'!D6 -> 0.925
A4: =+hist_Forward5YearRNatR_wFG!A4 -> 22189 | B4: =+hist_Forward5YearRNatR_wFG!D4 -> 2.0224967 | C4: =+hist_Forward5YearRNatR_woFG!D4 -> 2.0472043 | F4: =+'Chart NA - DSGE Raw Data'!D7 -> 0.735
A5: =+hist_Forward5YearRNatR_wFG!A5 -> 22281 | B5: =+hist_Forward5YearRNatR_wFG!D5 -> 2.1038496 | C5: =+hist_Forward5YearRNatR_woFG!D5 -> 2.1287228 | F5: =+'Chart NA - DSGE Raw Data'!D8 -> 0.575
A6: =+hist_Forward5YearRNatR_wFG!A6 -> 22371 | B6: =+hist_Forward5YearRNatR_wFG!D6 -> 2.1590386 | C6: =+hist_Forward5YearRNatR_woFG!D6 -> 2.184054 | D6: =+'HLW - 2025Q2'!K7 -> 5.4405595 | F6: =+'Chart NA - DSGE Raw Data'!D9 -> 0.4975
A7: =+hist_Forward5YearRNatR_wFG!A7 -> 22462 | B7: =+hist_Forward5YearRNatR_wFG!D7 -> 2.1723315 | C7: =+hist_Forward5YearRNatR_woFG!D7 -> 2.1974639 | D7: =+'HLW - 2025Q2'!K8 -> 5.6616372 | F7: =+'Chart NA - DSGE Raw Data'!D10 -> 0.4325
A8: =+hist_Forward5YearRNatR_wFG!A8 -> 22554 | B8: =+hist_Forward5YearRNatR_wFG!D8 -> 2.2626478 | C8: =+hist_Forward5YearRNatR_woFG!D8 -> 2.2878702 | D8: =+'HLW - 2025Q2'!K9 -> 5.56877 | F8: =+'Chart NA - DSGE Raw Data'!D11 -> 0.42
A9: =+hist_Forward5YearRNatR_wFG!A9 -> 22646 | B9: =+hist_Forward5YearRNatR_wFG!D9 -> 2.373264 | C9: =+hist_Forward5YearRNatR_woFG!D9 -> 2.3985468 | D9: =+'HLW - 2025Q2'!K10 -> 5.5381696 | F9: =+'Chart NA - DSGE Raw Data'!D12 -> 0.6
A10: =+hist_Forward5YearRNatR_wFG!A10 -> 22736 | B10: =+hist_Forward5YearRNatR_wFG!D10 -> 2.4914681 | C10: =+hist_Forward5YearRNatR_woFG!D10 -> 2.5167794 | D10: =+'HLW - 2025Q2'!K11 -> 5.3529621 | F10: =+'Chart NA - DSGE Raw Data'!D13 -> 0.615
A11: =+hist_Forward5YearRNatR_wFG!A11 -> 22827 | B11: =+hist_Forward5YearRNatR_wFG!D11 -> 2.4933496 | C11: =+hist_Forward5YearRNatR_woFG!D11 -> 2.5186543 | D11: =+'HLW - 2025Q2'!K12 -> 4.8206328 | F11: =+'Chart NA - DSGE Raw Data'!D14 -> 0.6525
A12: =+hist_Forward5YearRNatR_wFG!A12 -> 22919 | B12: =+hist_Forward5YearRNatR_wFG!D12 -> 2.5797766 | C12: =+hist_Forward5YearRNatR_woFG!D12 -> 2.6050366 | D12: =+'HLW - 2025Q2'!K13 -> 4.7095343 | F12: =+'Chart NA - DSGE Raw Data'!D15 -> 0.7125
A13: =+hist_Forward5YearRNatR_wFG!A13 -> 23011 | B13: =+hist_Forward5YearRNatR_wFG!D13 -> 2.6508134 | C13: =+hist_Forward5YearRNatR_woFG!D13 -> 2.6759866 | D13: =+'HLW - 2025Q2'!K14 -> 4.2590645 | F13: =+'Chart NA - DSGE Raw Data'!D16 -> 0.73
A14: =+hist_Forward5YearRNatR_wFG!A14 -> 23101 | B14: =+hist_Forward5YearRNatR_wFG!D14 -> 2.7580187 | C14: =+hist_Forward5YearRNatR_woFG!D14 -> 2.783059 | D14: =+'HLW - 2025Q2'!K15 -> 4.2440707 | F14: =+'Chart NA - DSGE Raw Data'!D17 -> 0.7425
A15: =+hist_Forward5YearRNatR_wFG!A15 -> 23192 | B15: =+hist_Forward5YearRNatR_wFG!D15 -> 2.8481428 | C15: =+hist_Forward5YearRNatR_woFG!D15 -> 2.8729992 | D15: =+'HLW - 2025Q2'!K16 -> 4.2115101 | F15: =+'Chart NA - DSGE Raw Data'!D18 -> 0.74
A16: =+hist_Forward5YearRNatR_wFG!A16 -> 23284 | B16: =+hist_Forward5YearRNatR_wFG!D16 -> 2.920799 | C16: =+hist_Forward5YearRNatR_woFG!D16 -> 2.9454155 | D16: =+'HLW - 2025Q2'!K17 -> 4.5380331 | F16: =+'Chart NA - DSGE Raw Data'!D19 -> 0.8325
A17: =+hist_Forward5YearRNatR_wFG!A17 -> 23376 | B17: =+hist_Forward5YearRNatR_wFG!D17 -> 3.0040085 | C17: =+hist_Forward5YearRNatR_woFG!D17 -> 3.0283234 | D17: =+'HLW - 2025Q2'!K18 -> 4.2689899 | F17: =+'Chart NA - DSGE Raw Data'!D20 -> 0.8625
... A29: =+hist_Forward5YearRNatR_wFG!A29 -> 24472 | B29: =+hist_Forward5YearRNatR_wFG!D29 -> 2.8636972 | C29: =+hist_Forward5YearRNatR_woFG!D29 -> 2.8868701 | D29: =+'HLW - 2025Q2'!K30 -> 5.0873863 | F29: =+'Chart NA - DSGE Raw Data'!D32 -> 1.39
A30: =+hist_Forward5YearRNatR_wFG!A30 -> 24562 | B30: =+hist_Forward5YearRNatR_wFG!D30 -> 2.8538048 | C30: =+hist_Forward5YearRNatR_woFG!D30 -> 2.8769765 | D30: =+'HLW - 2025Q2'!K31 -> 5.0534309 | E30: =+LM_RealRate!C2 -> 1.6036491 | F30: =+'Chart NA - DSGE Raw Data'!D33 -> 1.205
A31: =+hist_Forward5YearRNatR_wFG!A31 -> 24653 | B31: =+hist_Forward5YearRNatR_wFG!D31 -> 2.8936934 | C31: =+hist_Forward5YearRNatR_woFG!D31 -> 2.9168691 | D31: =+'HLW - 2025Q2'!K32 -> 4.829954 | E31: =+LM_RealRate!C3 -> 1.5611101 | F31: =+'Chart NA - DSGE Raw Data'!D34 -> 0.9975
A32: =+hist_Forward5YearRNatR_wFG!A32 -> 24745 | B32: =+hist_Forward5YearRNatR_wFG!D32 -> 2.8019768 | C32: =+hist_Forward5YearRNatR_woFG!D32 -> 2.8251606 | D32: =+'HLW - 2025Q2'!K33 -> 4.8518558 | E32: =+LM_RealRate!C4 -> 1.5822769 | F32: =+'Chart NA - DSGE Raw Data'!D35 -> 0.9725
A33: =+hist_Forward5YearRNatR_wFG!A33 -> 24837 | B33: =+hist_Forward5YearRNatR_wFG!D33 -> 2.7824148 | C33: =+hist_Forward5YearRNatR_woFG!D33 -> 2.80561 | D33: =+'HLW - 2025Q2'!K34 -> 4.7817679 | E33: =+LM_RealRate!C5 -> 1.5874445 | F33: =+'Chart NA - DSGE Raw Data'!D36 -> 1.0425
A34: =+hist_Forward5YearRNatR_wFG!A34 -> 24928 | B34: =+hist_Forward5YearRNatR_wFG!D34 -> 2.5812702 | C34: =+hist_Forward5YearRNatR_woFG!D34 -> 2.6044794 | D34: =+'HLW - 2025Q2'!K35 -> 5.0033801 | E34: =+LM_RealRate!C6 -> 1.6251452 | F34: =+'Chart NA - DSGE Raw Data'!D37 -> 1.1975
A35: =+hist_Forward5YearRNatR_wFG!A35 -> 25019 | B35: =+hist_Forward5YearRNatR_wFG!D35 -> 2.4793346 | C35: =+hist_Forward5YearRNatR_woFG!D35 -> 2.5025598 | D35: =+'HLW - 2025Q2'!K36 -> 5.0654007 | E35: =+LM_RealRate!C7 -> 1.6449017 | F35: =+'Chart NA - DSGE Raw Data'!D38 -> 1.495
A36: =+hist_Forward5YearRNatR_wFG!A36 -> 25111 | B36: =+hist_Forward5YearRNatR_wFG!D36 -> 2.3898348 | C36: =+hist_Forward5YearRNatR_woFG!D36 -> 2.4130776 | D36: =+'HLW - 2025Q2'!K37 -> 4.9311537 | E36: =+LM_RealRate!C8 -> 1.5864502 | F36: =+'Chart NA - DSGE Raw Data'!D39 -> 1.4875
A37: =+hist_Forward5YearRNatR_wFG!A37 -> 25203 | B37: =+hist_Forward5YearRNatR_wFG!D37 -> 2.4169603 | C37: =+hist_Forward5YearRNatR_woFG!D37 -> 2.4402214 | D37: =+'HLW - 2025Q2'!K38 -> 4.7783574 | E37: =+LM_RealRate!C9 -> 1.5816322 | F37: =+'Chart NA - DSGE Raw Data'!D40 -> 1.48
A38: =+hist_Forward5YearRNatR_wFG!A38 -> 25293 | B38: =+hist_Forward5YearRNatR_wFG!D38 -> 2.4410874 | C38: =+hist_Forward5YearRNatR_woFG!D38 -> 2.4643675 | D38: =+'HLW - 2025Q2'!K39 -> 4.905168 | E38: =+LM_RealRate!C10 -> 1.6453404 | F38: =+'Chart NA - DSGE Raw Data'!D41 -> 1.6425
A39: =+hist_Forward5YearRNatR_wFG!A39 -> 25384 | B39: =+hist_Forward5YearRNatR_wFG!D39 -> 2.2780856 | C39: =+hist_Forward5YearRNatR_woFG!D39 -> 2.3013845 | D39: =+'HLW - 2025Q2'!K40 -> 4.7139562 | E39: =+LM_RealRate!C11 -> 1.712491 | F39: =+'Chart NA - DSGE Raw Data'!D42 -> 2.0825
A40: =+hist_Forward5YearRNatR_wFG!A40 -> 25476 | B40: =+hist_Forward5YearRNatR_wFG!D40 -> 2.2026074 | C40: =+hist_Forward5YearRNatR_woFG!D40 -> 2.2259247 | D40: =+'HLW - 2025Q2'!K41 -> 4.6689004 | E40: =+LM_RealRate!C12 -> 1.700828 | F40: =+'Chart NA - DSGE Raw Data'!D43 -> 2.245
A41: =+hist_Forward5YearRNatR_wFG!A41 -> 25568 | B41: =+hist_Forward5YearRNatR_wFG!D41 -> 2.1943031 | C41: =+hist_Forward5YearRNatR_woFG!D41 -> 2.217638 | D41: =+'HLW - 2025Q2'!K42 -> 4.3921348 | E41: =+LM_RealRate!C13 -> 1.6557247 | F41: =+'Chart NA - DSGE Raw Data'!D44 -> 2.235
... A260: =+hist_Forward5YearRNatR_wFG!A260 -> 45565 | B260: =+hist_Forward5YearRNatR_wFG!D260 -> 1.3305879 | C260: =+hist_Forward5YearRNatR_woFG!D260 -> 1.4693021 | D260: =+'HLW - 2025Q2'!K261 -> 0.81923691 | E260: =+LM_RealRate!C232 -> 2.1404005 | F260: =+'Chart NA - DSGE Raw Data'!D263 -> 1.315
B263: =+CORREL(B2:B260,$F$2:$F$260) -> 0.52477817 | C263: =+CORREL(C2:C260,$F$2:$F$260) -> 0.49861578 | D263: =+CORREL(D2:D260,$F$2:$F$260) -> 0.52995417 | E263: =+CORREL(E2:E260,$F$2:$F$260) -> 0.66706477

Sheet Decomposition
A1: Date | B1: Trend Growth (g), Annualized | C1: Other Determinants (z) | D1: HLW r* | E1: Trend Growth (g), Annualized | F1: Other Determinants (z) | G1: HLW r*
A2: 22282 | B2: =+'HLW - 2025Q2'!C7 -> 4.9495375 | C2: =+'HLW - 2025Q2'!G7 -> 0.005243984 | D2: =+'HLW - 2025Q2'!K7 -> 5.4405595
A3: 22372 | B3: =+'HLW - 2025Q2'!C8 -> 5.1448666 | C3: =+'HLW - 2025Q2'!G8 -> 0.011821837 | D3: =+'HLW - 2025Q2'!K8 -> 5.6616372
A4: 22463 | B4: =+'HLW - 2025Q2'!C9 -> 5.0578663 | C4: =+'HLW - 2025Q2'!G9 -> 0.014493655 | D4: =+'HLW - 2025Q2'!K9 -> 5.56877
A5: 22555 | B5: =+'HLW - 2025Q2'!C10 -> 5.0328481 | C5: =+'HLW - 2025Q2'!G10 -> 0.011366898 | D5: =+'HLW - 2025Q2'!K10 -> 5.5381696
A6: 22647 | B6: =+'HLW - 2025Q2'!C11 -> 4.861899 | C6: =+'HLW - 2025Q2'!G11 -> 0.013886533 | D6: =+'HLW - 2025Q2'!K11 -> 5.3529621
A7: 22737 | B7: =+'HLW - 2025Q2'!C12 -> 4.3830335 | C7: =+'HLW - 2025Q2'!G12 -> 0.0074214461 | D7: =+'HLW - 2025Q2'!K12 -> 4.8206328
A8: 22828 | B8: =+'HLW - 2025Q2'!C13 -> 4.2850229 | C8: =+'HLW - 2025Q2'!G13 -> 0.003952891 | D8: =+'HLW - 2025Q2'!K13 -> 4.7095343
A9: 22920 | B9: =+'HLW - 2025Q2'!C14 -> 3.8884721 | C9: =+'HLW - 2025Q2'!G14 -> -0.011046073 | D9: =+'HLW - 2025Q2'!K14 -> 4.2590645
A10: 23012 | B10: =+'HLW - 2025Q2'!C15 -> 3.8697114 | C10: =+'HLW - 2025Q2'!G15 -> -0.0054378924 | D10: =+'HLW - 2025Q2'!K15 -> 4.2440707
A11: 23102 | B11: =+'HLW - 2025Q2'!C16 -> 3.8368419 | C11: =+'HLW - 2025Q2'!G16 -> -0.0019030078 | D11: =+'HLW - 2025Q2'!K16 -> 4.2115101
A12: 23193 | B12: =+'HLW - 2025Q2'!C17 -> 4.1271433 | C12: =+'HLW - 2025Q2'!G17 -> 0.0058265986 | D12: =+'HLW - 2025Q2'!K17 -> 4.5380331
A13: 23285 | B13: =+'HLW - 2025Q2'!C18 -> 3.8778412 | C13: =+'HLW - 2025Q2'!G18 -> 0.010553546 | D13: =+'HLW - 2025Q2'!K18 -> 4.2689899
... A183: 38808 | B183: =+'HLW - 2025Q2'!C188 -> 2.7416689 | C183: =+'HLW - 2025Q2'!G188 -> -0.3277393 | D183: =+'HLW - 2025Q2'!K188 -> 2.6830138
A184: 38899 | B184: =+'HLW - 2025Q2'!C189 -> 2.7020216 | C184: =+'HLW - 2025Q2'!G189 -> -0.45027647 | D184: =+'HLW - 2025Q2'!K189 -> 2.5169382 | H184: g | I184: z | J184: Growth | K184: Safety+Liquidity | L184: Government | M184: Others
A185: 38991 | B185: =+'HLW - 2025Q2'!C190 -> 2.8096463 | C185: =+'HLW - 2025Q2'!G190 -> -0.5347939 | D185: =+'HLW - 2025Q2'!K190 -> 2.5506084 | E185: =+B185-$B$185 -> 0 | F185: =+C185-$C$185 -> 0 | G185: =+D185-$D$185 -> 0
A186: 39083 | B186: =+'HLW - 2025Q2'!C191 -> 2.7472112 | C186: =+'HLW - 2025Q2'!G191 -> -0.45289724 | D186: =+'HLW - 2025Q2'!K191 -> 2.5639422 | E186: =+B186-$B$185 -> -0.062435073 | F186: =+C186-$C$185 -> 0.081896662 | G186: =+D186-$D$185 -> 0.013333827 | H186: =E186 -> -0.062435073 | I186: =F186 -> 0.081896662 | J186: -0.051272201 | K186: 0.36638119 | L186: -0.091415602 | M186: 0.028175116
A187: 39173 | B187: =+'HLW - 2025Q2'!C192 -> 2.8004912 | C187: =+'HLW - 2025Q2'!G192 -> -0.58665465 | D187: =+'HLW - 2025Q2'!K192 -> 2.4886939 | E187: =+B187-$B$185 -> -0.0091551362 | F187: =+C187-$C$185 -> -0.051860748 | G187: =+D187-$D$185 -> -0.061914425 | H187: =E187 -> -0.0091551362 | I187: =F187 -> -0.051860748 | J187: -0.084617145 | K187: 0.16922339 | L187: -0.095807612 | M187: 0.027817345
A188: 39264 | B188: =+'HLW - 2025Q2'!C193 -> 2.8079719 | C188: =+'HLW - 2025Q2'!G193 -> -0.5772525 | D188: =+'HLW - 2025Q2'!K193 -> 2.5063111 | E188: =+B188-$B$185 -> -0.0016743697 | F188: =+C188-$C$185 -> -0.042458597 | G188: =+D188-$D$185 -> -0.0442973 | H188: =E188 -> -0.0016743697 | I188: =F188 -> -0.042458597 | J188: -0.067763489 | K188: -0.026765674 | L188: -0.092857246 | M188: 0.027464357
A189: 39356 | B189: =+'HLW - 2025Q2'!C194 -> 2.8090337 | C189: =+'HLW - 2025Q2'!G194 -> -0.47714374 | D189: =+'HLW - 2025Q2'!K194 -> 2.6075858 | E189: =+B189-$B$185 -> -0.00061259803 | F189: =+C189-$C$185 -> 0.05765016 | G189: =+D189-$D$185 -> 0.056977438 | H189: =E189 -> -0.00061259803 | I189: =F189 -> 0.05765016 | J189: -0.16942974 | K189: -0.25560965 | L189: -0.094503573 | M189: 0.027116084
A190: 39448 | B190: =+'HLW - 2025Q2'!C195 -> 2.6240108 | C190: =+'HLW - 2025Q2'!G195 -> -0.56349617 | D190: =+'HLW - 2025Q2'!K195 -> 2.3180512 | E190: =+B190-$B$185 -> -0.1856355 | F190: =+C190-$C$185 -> -0.028702265 | G190: =+D190-$D$185 -> -0.23255718 | H190: =E190 -> -0.1856355 | I190: =F190 -> -0.028702265 | J190: -0.2151245 | K190: -0.18959172 | L190: -0.09745303 | M190: 0.026772462
A191: 39539 | B191: =+'HLW - 2025Q2'!C196 -> 2.6679739 | C191: =+'HLW - 2025Q2'!G196 -> -0.61932463 | D191: =+'HLW - 2025Q2'!K196 -> 2.3105006 | E191: =+B191-$B$185 -> -0.14167242 | F191: =+C191-$C$185 -> -0.084530727 | G191: =+D191-$D$185 -> -0.24010775 | H191: =E191 -> -0.14167242 | I191: =F191 -> -0.084530727 | J191: -0.25556557 | K191: -0.32710643 | L191: -0.082949481 | M191: 0.026433429
A192: 39630 | B192: =+'HLW - 2025Q2'!C197 -> 2.4229234 | C192: =+'HLW - 2025Q2'!G197 -> -0.62062313 | D192: =+'HLW - 2025Q2'!K197 -> 2.0401009 | E192: =+B192-$B$185 -> -0.3867229 | F192: =+C192-$C$185 -> -0.085829224 | G192: =+D192-$D$185 -> -0.51050748 | H192: =E192 -> -0.3867229 | I192: =F192 -> -0.085829224 | J192: -0.34029744 | K192: -1.3061164 | L192: -0.050147653 | M192: 0.02609892
A193: 39722 | B193: =+'HLW - 2025Q2'!C198 -> 1.943172 | C193: =+'HLW - 2025Q2'!G198 -> -0.98967899 | D193: =+'HLW - 2025Q2'!K198 -> 1.1442079 | E193: =+B193-$B$185 -> -0.86647427 | F193: =+C193-$C$185 -> -0.45488509 | G193: =+D193-$D$185 -> -1.4064005 | H193: =E193 -> -0.86647427 | I193: =F193 -> -0.45488509 | J193: -0.44568968 | K193: -1.0836385 | L193: -0.035773165 | M193: 0.025768875
A194: 39814 | B194: =+'HLW - 2025Q2'!C199 -> 1.7097646 | C194: =+'HLW - 2025Q2'!G199 -> -1.0492433 | D194: =+'HLW - 2025Q2'!K199 -> 0.82832809 | E194: =+B194-$B$185 -> -1.0998817 | F194: =+C194-$C$185 -> -0.51444939 | G194: =+D194-$D$185 -> -1.7222803 | H194: =E194 -> -1.0998817 | I194: =F194 -> -0.51444939 | J194: -0.4159583 | K194: -0.79361889 | L194: -0.02408911 | M194: 0.025443232
A195: 39904 | B195: =+'HLW - 2025Q2'!C200 -> 1.5954609 | C195: =+'HLW - 2025Q2'!G200 -> -0.87053592 | D195: =+'HLW - 2025Q2'!K200 -> 0.88151327 | E195: =+B195-$B$185 -> -1.2141855 | F195: =+C195-$C$185 -> -0.33574201 | G195: =+D195-$D$185 -> -1.6690951 | H195: =E195 -> -1.2141855 | I195: =F195 -> -0.33574201 | J195: -0.58166051 | K195: -0.53533348 | L195: -0.039925577 | M195: 0.02512193
A196: 39995 | B196: =+'HLW - 2025Q2'!C201 -> 1.5603428 | C196: =+'HLW - 2025Q2'!G201 -> -0.82619721 | D196: =+'HLW - 2025Q2'!K201 -> 0.88728722 | E196: =+B196-$B$185 -> -1.2493035 | F196: =+C196-$C$185 -> -0.2914033 | G196: =+D196-$D$185 -> -1.6633211 | H196: =E196 -> -1.2493035 | I196: =F196 -> -0.2914033 | J196: -0.54156944 | K196: -0.42733054 | L196: -0.027038449 | M196: 0.02480491
A197: 40087 | B197: =+'HLW - 2025Q2'!C202 -> 1.6072745 | C197: =+'HLW - 2025Q2'!G202 -> -0.60830285 | D197: =+'HLW - 2025Q2'!K202 -> 1.1567195 | E197: =+B197-$B$185 -> -1.2023718 | F197: =+C197-$C$185 -> -0.073508945 | G197: =+D197-$D$185 -> -1.3938889 | H197: =E197 -> -1.2023718 | I197: =F197 -> -0.073508945 | J197: -0.81337801 | K197: -0.41276895 | L197: -0.028494114 | M197: 0.024492113
... A259: 45748 | B259: =+'HLW - 2025Q2'!C264 -> 2.4501884 | C259: =+'HLW - 2025Q2'!G264 -> -1.8508269 | D259: =+'HLW - 2025Q2'!K264 -> 0.83983803 | E259: =+B259-$B$185 -> -0.3594579 | F259: =+C259-$C$185 -> -1.316033 | G259: =+D259-$D$185 -> -1.7107703 | H259: =E259 -> -0.3594579 | I259: =F259 -> -1.316033 | J259: -0.45597052 | K259: 0.0704826 | L259: -0.1830374 | M259: 0.011355456
J260: -0.44789026 | K260: 0.067038362 | L260: -0.18085861 | M260: 0.011218732 | N260: 2.73374e-05 | O260: 1.1259527e-06
J261: -0.43939327 | K261: 0.064012899 | L261: -0.17869808 | M261: 0.011083748 | N261: 0.00055720115 | O261: -3.2784654e-05
J262: -0.43057563 | K262: 0.061360536 | L262: -0.17655744 | M262: 0.010950479 | N262: 0.0010264363 | O262: -6.2736088e-05
J263: -0.42152321 | K263: 0.059040063 | L263: -0.17443798 | M263: 0.010818901 | N263: 0.0014429872 | O263: -8.9262324e-05
J264: -0.41231208 | K264: 0.057014312 | L264: -0.17234064 | M264: 0.010688993 | N264: 0.0018133855 | O264: -0.00011280029
J265: -0.4030091 | K265: 0.055249798 | L265: -0.17026615 | M265: 0.01056073 | N265: 0.0021430453 | O265: -0.00013371047
J266: -0.39367252 | K266: 0.053716396 | L266: -0.16821503 | M266: 0.010434092 | N266: 0.0024364891 | O266: -0.00015229263
J267: -0.38435272 | K267: 0.052387042 | L267: -0.16618763 | M267: 0.010309055 | N267: 0.0026975241 | O267: -0.000168798
J268: -0.37509285 | K268: 0.051237465 | L268: -0.16418418 | M268: 0.010185599 | N268: 0.0029293796 | O268: -0.00018343876
J269: -0.36592955 | K269: 0.050245933 | L269: -0.16220482 | M269: 0.010063701 | N269: 0.0031348158 | O269: -0.00019639553
J270: -0.35689359 | K270: 0.049393022 | L270: -0.16024957 | M270: 0.0099433417 | N270: 0.0033162103 | O270: -0.00020782323
...

Sheet DSGE HVD wFG
A1: date | B1: =+wFG_rstar_shock_decomposition!E1 -> g | C1: =+wFG_rstar_shock_decomposition!F1 -> b_liq | D1: =+wFG_rstar_shock_decomposition!G1 -> b_safe | E1: =+wFG_rstar_shock_decomposition!H1 -> FF | F1: =+wFG_rstar_shock_decomposition!I1 -> z | G1: =+wFG_rstar_shock_decomposition!J1 -> p-mkp | H1: =+wFG_rstar_shock_decomposition!K1 -> w-mkp | I1: =+wFG_rstar_shock_decomposition!L1 -> pol | ... T1: =+wFG_rstar_shock_decomposition!W1 -> dt | U1: DSGE r* | X1: Chart | Y1: Date | Z1: Government | AA1: Liquidity | AB1: Safety | AC1: Technology | AD1: Financial Frictions | AE1: Investment Specific Technology | AF1: Price Markups | AG1: Wage Markups | AH1: Others | AI1: DSGE r* (with FG) | AJ1: Growth | AK1: Safety+Liquidity | AL1: Government | AM1: Others | AN1: Total | AO1: Growth | AP1: Safety+Liquidity | AQ1: Government | AR1: Others | AS1: Total
A2: 39172 | B2: =+wFG_rstar_shock_decomposition!E2 -> -0.10116499 | C2: =+wFG_rstar_shock_decomposition!F2 -> -0.14808542 | D2: =+wFG_rstar_shock_decomposition!G2 -> 0.49991388 | E2: =+wFG_rstar_shock_decomposition!H2 -> -0.023433525 | F2: =+wFG_rstar_shock_decomposition!I2 -> 0.13159807 | G2: =+wFG_rstar_shock_decomposition!J2 -> 3.835998e-16 | H2: =+wFG_rstar_shock_decomposition!K2 -> -3.6594233e-15 | I2: =+wFG_rstar_shock_decomposition!L2 -> 1.4552564e-14 | ... T2: =+wFG_rstar_shock_decomposition!W2 -> 0.028537733 | U2: =+wFG_rstar_shock_decomposition!D2 -> 0.35147615 | Y2: =+A2 -> 39172 | Z2: =+B2 -> -0.10116499 | AA2: =+C2 -> -0.14808542 | AB2: =+D2 -> 0.49991388 | AC2: =+F2+S2 -> 0.14174747 | AD2: =+E2 -> -0.023433525 | AE2: =+Q2 -> -0.046038989 | AF2: =+G2 -> 3.835998e-16 | AG2: =+H2 -> -3.6594233e-15 | AH2: =+SUM(T2,I2:P2) -> 0.028537733 | AI2: =+SUM(Z2:AH2) -> 0.35147615 | AJ2: =SUM(AC2+AE2) -> 0.095708486 | AK2: =AB2+AA2+AD2 -> 0.32839493 | AL2: =Z2 -> -0.10116499 | AM2: =AH2 -> 0.028537733 | AN2: =SUM(AJ2:AM2) -> 0.35147615
A3: 39263 | B3: =+wFG_rstar_shock_decomposition!E3 -> -0.091415602 | C3: =+wFG_rstar_shock_decomposition!F3 -> -0.16817797 | D3: =+wFG_rstar_shock_decomposition!G3 -> 0.55181563 | E3: =+wFG_rstar_shock_decomposition!H3 -> -0.017256471 | F3: =+wFG_rstar_shock_decomposition!I3 -> 0.11475644 | G3: =+wFG_rstar_shock_decomposition!J3 -> 5.4879435e-16 | H3: =+wFG_rstar_shock_decomposition!K3 -> -2.4440355e-15 | I3: =+wFG_rstar_shock_decomposition!L3 -> 1.3433653e-14 | ... T3: =+wFG_rstar_shock_decomposition!W3 -> 0.028175116 | U3: =+wFG_rstar_shock_decomposition!D3 -> 0.25186851 | Y3: =+A3 -> 39263 | Z3: =+B3 -> -0.091415602 | AA3: =+C3 -> -0.16817797 | AB3: =+D3 -> 0.55181563 | AC3: =+F3+S3 -> -0.012256044 | AD3: =+E3 -> -0.017256471 | AE3: =+Q3 -> -0.039016157 | AF3: =+G3 -> 5.4879435e-16 | AG3: =+H3 -> -2.4440355e-15 | AH3: =+SUM(T3,I3:P3) -> 0.028175116 | AI3: =+SUM(Z3:AH3) -> 0.25186851 | AJ3: =SUM(AC3+AE3) -> -0.051272201 | AK3: =AB3+AA3+AD3 -> 0.36638119 | AL3: =Z3 -> -0.091415602 | AM3: =AH3 -> 0.028175116 | AN3: =SUM(AJ3:AM3) -> 0.25186851 | AO3: =(AJ3-AJ2)/($AN3-$AN2) -> 1.4755964 | AP3: =(AK3-AK2)/($AN3-$AN2) -> -0.38135894 | AQ3: =(AL3-AL2)/($AN3-$AN2) -> -0.097877908 | AR3: =(AM3-AM2)/($AN3-$AN2) -> 0.0036404606 | AS3: =(AN3-AN2)/($AN3-$AN2) -> 1
A4: 39355 | B4: =+wFG_rstar_shock_decomposition!E4 -> -0.095807612 | C4: =+wFG_rstar_shock_decomposition!F4 -> -0.33979271 | D4: =+wFG_rstar_shock_decomposition!G4 -> 0.56002226 | E4: =+wFG_rstar_shock_decomposition!H4 -> -0.051006152 | F4: =+wFG_rstar_shock_decomposition!I4 -> 0.13362002 | G4: =+wFG_rstar_shock_decomposition!J4 -> 2.5037011e-16 | H4: =+wFG_rstar_shock_decomposition!K4 -> -1.4001092e-15 | I4: =+wFG_rstar_shock_decomposition!L4 -> 1.3980609e-14 | ... T4: =+wFG_rstar_shock_decomposition!W4 -> 0.027817345 | U4: =+wFG_rstar_shock_decomposition!D4 -> 0.016615982 | Y4: =+A4 -> 39355 | Z4: =+B4 -> -0.095807612 | AA4: =+C4 -> -0.33979271 | AB4: =+D4 -> 0.56002226 | AC4: =+F4+S4 -> -0.028311233 | AD4: =+E4 -> -0.051006152 | AE4: =+Q4 -> -0.056305913 | AF4: =+G4 -> 2.5037011e-16 | AG4: =+H4 -> -1.4001092e-15 | AH4: =+SUM(T4,I4:P4) -> 0.027817345 | AI4: =+SUM(Z4:AH4) -> 0.016615982 | AJ4: =SUM(AC4+AE4) -> -0.084617145 | AK4: =AB4+AA4+AD4 -> 0.16922339 | AL4: =Z4 -> -0.095807612 | AM4: =AH4 -> 0.027817345 | AN4: =SUM(AJ4:AM4) -> 0.016615982 | AO4: =(AJ4-AJ3)/($AN4-$AN3) -> 0.14174107 | AP4: =(AK4-AK3)/($AN4-$AN3) -> 0.83806879 | AQ4: =(AL4-AL3)/($AN4-$AN3) -> 0.018669343 | AR4: =(AM4-AM3)/($AN4-$AN3) -> 0.0015207924 | AS4: =(AN4-AN3)/($AN4-$AN3) -> 1
A5: 39447 | B5: =+wFG_rstar_shock_decomposition!E5 -> -0.092857246 | C5: =+wFG_rstar_shock_decomposition!F5 -> -0.47721599 | D5: =+wFG_rstar_shock_decomposition!G5 -> 0.53555175 | E5: =+wFG_rstar_shock_decomposition!H5 -> -0.085101434 | F5: =+wFG_rstar_shock_decomposition!I5 -> 0.13642795 | G5: =+wFG_rstar_shock_decomposition!J5 -> -2.6306488e-16 | H5: =+wFG_rstar_shock_decomposition!K5 -> -7.9837506e-16 | I5: =+wFG_rstar_shock_decomposition!L5 -> 1.5589942e-14 | ... T5: =+wFG_rstar_shock_decomposition!W5 -> 0.027464357 | U5: =+wFG_rstar_shock_decomposition!D5 -> -0.15992205 | Y5: =+A5 -> 39447 | Z5: =+B5 -> -0.092857246 | AA5: =+C5 -> -0.47721599 | AB5: =+D5 -> 0.53555175 | AC5: =+F5+S5 -> 0.0013142414 | AD5: =+E5 -> -0.085101434 | AE5: =+Q5 -> -0.069077731 | AF5: =+G5 -> -2.6306488e-16 | AG5: =+H5 -> -7.9837506e-16 | AH5: =+SUM(T5,I5:P5) -> 0.027464357 | AI5: =+SUM(Z5:AH5) -> -0.15992205 | AJ5: =SUM(AC5+AE5) -> -0.067763489 | AK5: =AB5+AA5+AD5 -> -0.026765674 | AL5: =Z5 -> -0.092857246 | AM5: =AH5 -> 0.027464357 | AN5: =SUM(AJ5:AM5) -> -0.15992205 | AO5: =(AJ5-AJ4)/($AN5-$AN4) -> -0.095467565 | AP5: =(AK5-AK4)/($AN5-$AN4) -> 1.1101804 | AQ5: =(AL5-AL4)/($AN5-$AN4) -> -0.016712354 | AR5: =(AM5-AM4)/($AN5-$AN4) -> 0.0019995064 | AS5: =(AN5-AN4)/($AN5-$AN4) -> 1
A6: 39538 | B6: =+wFG_rstar_shock_decomposition!E6 -> -0.094503573 | C6: =+wFG_rstar_shock_decomposition!F6 -> -0.63793934 | D6: =+wFG_rstar_shock_decomposition!G6 -> 0.48092883 | E6: =+wFG_rstar_shock_decomposition!H6 -> -0.09859914 | F6: =+wFG_rstar_shock_decomposition!I6 -> 0.14786982 | G6: =+wFG_rstar_shock_decomposition!J6 -> 1.4712008e-17 | H6: =+wFG_rstar_shock_decomposition!K6 -> -1.4965976e-16 | I6: =+wFG_rstar_shock_decomposition!L6 -> 1.6862544e-14 | ... T6: =+wFG_rstar_shock_decomposition!W6 -> 0.027116084 | U6: =+wFG_rstar_shock_decomposition!D6 -> -0.49242688 | Y6: =+A6 -> 39538 | Z6: =+B6 -> -0.094503573 | AA6: =+C6 -> -0.63793934 | AB6: =+D6 -> 0.48092883 | AC6: =+F6+S6 -> -0.10652621 | AD6: =+E6 -> -0.09859914 | AE6: =+Q6 -> -0.06290353 | AF6: =+G6 -> 1.4712008e-17 | AG6: =+H6 -> -1.4965976e-16 | AH6: =+SUM(T6,I6:P6) -> 0.027116084 | AI6: =+SUM(Z6:AH6) -> -0.49242688 | AJ6: =SUM(AC6+AE6) -> -0.16942974 | AK6: =AB6+AA6+AD6 -> -0.25560965 | AL6: =Z6 -> -0.094503573 | AM6: =AH6 -> 0.027116084 | AN6: =SUM(AJ6:AM6) -> -0.49242688 | AO6: =(AJ6-AJ5)/($AN6-$AN5) -> 0.30575871 | AP6: =(AK6-AK5)/($AN6-$AN5) -> 0.68824258 | AQ6: =(AL6-AL5)/($AN6-$AN5) -> 0.0049512883 | AR6: =(AM6-AM5)/($AN6-$AN5) -> 0.0010474221 | AS6: =(AN6-AN5)/($AN6-$AN5) -> 1
A7: 39629 | B7: =+wFG_rstar_shock_decomposition!E7 -> -0.09745303 | C7: =+wFG_rstar_shock_decomposition!F7 -> -0.60173872 | D7: =+wFG_rstar_shock_decomposition!G7 -> 0.51265011 | E7: =+wFG_rstar_shock_decomposition!H7 -> -0.10050311 | F7: =+wFG_rstar_shock_decomposition!I7 -> 0.14329593 | G7: =+wFG_rstar_shock_decomposition!J7 -> 1.2858785e-16 | H7: =+wFG_rstar_shock_decomposition!K7 -> 9.4075693e-16 | I7: =+wFG_rstar_shock_decomposition!L7 -> 1.8164319e-14 | ... T7: =+wFG_rstar_shock_decomposition!W7 -> 0.026772462 | U7: =+wFG_rstar_shock_decomposition!D7 -> -0.47539679 | Y7: =+A7 -> 39629 | Z7: =+B7 -> -0.09745303 | AA7: =+C7 -> -0.60173872 | AB7: =+D7 -> 0.51265011 | AC7: =+F7+S7 -> -0.1512325 | AD7: =+E7 -> -0.10050311 | AE7: =+Q7 -> -0.063892001 | AF7: =+G7 -> 1.2858785e-16 | AG7: =+H7 -> 9.4075693e-16 | AH7: =+SUM(T7,I7:P7) -> 0.026772462 | AI7: =+SUM(Z7:AH7) -> -0.47539679 | AJ7: =SUM(AC7+AE7) -> -0.2151245 | AK7: =AB7+AA7+AD7 -> -0.18959172 | AL7: =Z7 -> -0.09745303 | AM7: =AH7 -> 0.026772462 | AN7: =SUM(AJ7:AM7) -> -0.47539679 | AO7: =(AJ7-AJ6)/($AN7-$AN6) -> -2.6831775 | AP7: =(AK7-AK6)/($AN7-$AN6) -> 3.8765457 | AQ7: =(AL7-AL6)/($AN7-$AN6) -> -0.17319089 | AR7: =(AM7-AM6)/($AN7-$AN6) -> -0.020177304 | AS7: =(AN7-AN6)/($AN7-$AN6) -> 1
A8: 39721 | B8: =+wFG_rstar_shock_decomposition!E8 -> -0.082949481 | C8: =+wFG_rstar_shock_decomposition!F8 -> -0.71012197 | D8: =+wFG_rstar_shock_decomposition!G8 -> 0.48282661 | E8: =+wFG_rstar_shock_decomposition!H8 -> -0.09981108 | F8: =+wFG_rstar_shock_decomposition!I8 -> 0.1425402 | G8: =+wFG_rstar_shock_decomposition!J8 -> -4.384962e-16 | H8: =+wFG_rstar_shock_decomposition!K8 -> 1.7607749e-15 | I8: =+wFG_rstar_shock_decomposition!L8 -> 1.6133421e-14 | ... T8: =+wFG_rstar_shock_decomposition!W8 -> 0.026433429 | U8: =+wFG_rstar_shock_decomposition!D8 -> -0.63918806 | Y8: =+A8 -> 39721 | Z8: =+B8 -> -0.082949481 | AA8: =+C8 -> -0.71012197 | AB8: =+D8 -> 0.48282661 | AC8: =+F8+S8 -> -0.1996818 | AD8: =+E8 -> -0.09981108 | AE8: =+Q8 -> -0.055883769 | AF8: =+G8 -> -4.384962e-16 | AG8: =+H8 -> 1.7607749e-15 | AH8: =+SUM(T8,I8:P8) -> 0.026433429 | AI8: =+SUM(Z8:AH8) -> -0.63918806 | AJ8: =SUM(AC8+AE8) -> -0.25556557 | AK8: =AB8+AA8+AD8 -> -0.32710643 | AL8: =Z8 -> -0.082949481 | AM8: =AH8 -> 0.026433429 | AN8: =SUM(AJ8:AM8) -> -0.63918806 | AO8: =(AJ8-AJ7)/($AN8-$AN7) -> 0.24690615 | AP8: =(AK8-AK7)/($AN8-$AN7) -> 0.83957292 | AQ8: =(AL8-AL7)/($AN8-$AN7) -> -0.088548977 | AR8: =(AM8-AM7)/($AN8-$AN7) -> 0.0020699117 | AS8: =(AN8-AN7)/($AN8-$AN7) -> 1
A9: 39813 | B9: =+wFG_rstar_shock_decomposition!E9 -> -0.050147653 | C9: =+wFG_rstar_shock_decomposition!F9 -> -1.3069466 | D9: =+wFG_rstar_shock_decomposition!G9 -> 0.18081285 | E9: =+wFG_rstar_shock_decomposition!H9 -> -0.17998264 | F9: =+wFG_rstar_shock_decomposition!I9 -> 0.20167215 | G9: =+wFG_rstar_shock_decomposition!J9 -> 1.6922843e-15 | H9: =+wFG_rstar_shock_decomposition!K9 -> 2.3099358e-15 | I9: =+wFG_rstar_shock_decomposition!L9 -> 1.4070252e-14 | ... T9: =+wFG_rstar_shock_decomposition!W9 -> 0.02609892 | U9: =+wFG_rstar_shock_decomposition!D9 -> -1.6704626 | Y9: =+A9 -> 39813 | Z9: =+B9 -> -0.050147653 | AA9: =+C9 -> -1.3069466 | AB9: =+D9 -> 0.18081285 | AC9: =+F9+S9 -> -0.34549921 | AD9: =+E9 -> -0.17998264 | AE9: =+Q9 -> 0.0052017786 | AF9: =+G9 -> 1.6922843e-15 | AG9: =+H9 -> 2.3099358e-15 | AH9: =+SUM(T9,I9:P9) -> 0.02609892 | AI9: =+SUM(Z9:AH9) -> -1.6704626 | AJ9: =SUM(AC9+AE9) -> -0.34029744 | AK9: =AB9+AA9+AD9 -> -1.3061164 | AL9: =Z9 -> -0.050147653 | AM9: =AH9 -> 0.02609892 | AN9: =SUM(AJ9:AM9) -> -1.6704626 | AO9: =(AJ9-AJ8)/($AN9-$AN8) -> 0.082162281 | AP9: =(AK9-AK8)/($AN9-$AN8) -> 0.94932043 | AQ9: =(AL9-AL8)/($AN9-$AN8) -> -0.031807077 | AR9: =(AM9-AM8)/($AN9-$AN8) -> 0.00032436405 | AS9: =(AN9-AN8)/($AN9-$AN8) -> 1
A10: 39903 | B10: =+wFG_rstar_shock_decomposition!E10 -> -0.035773165 | C10: =+wFG_rstar_shock_decomposition!F10 -> -1.085552 | D10: =+wFG_rstar_shock_decomposition!G10 -> 0.23032624 | E10: =+wFG_rstar_shock_decomposition!H10 -> -0.22841274 | F10: =+wFG_rstar_shock_decomposition!I10 -> 0.18945894 | G10: =+wFG_rstar_shock_decomposition!J10 -> 1.9281286e-15 | H10: =+wFG_rstar_shock_decomposition!K10 -> 4.6174674e-15 | I10: =+wFG_rstar_shock_decomposition!L10 -> 1.0887621e-14 | ... T10: =+wFG_rstar_shock_decomposition!W10 -> 0.025768875 | U10: =+wFG_rstar_shock_decomposition!D10 -> -1.5393325 | Y10: =+A10 -> 39903 | Z10: =+B10 -> -0.035773165 | AA10: =+C10 -> -1.085552 | AB10: =+D10 -> 0.23032624 | AC10: =+F10+S10 -> -0.36687725 | AD10: =+E10 -> -0.22841274 | AE10: =+Q10 -> -0.078812432 | AF10: =+G10 -> 1.9281286e-15 | AG10: =+H10 -> 4.6174674e-15 | AH10: =+SUM(T10,I10:P10) -> 0.025768875 | AI10: =+SUM(Z10:AH10) -> -1.5393325 | AJ10: =SUM(AC10+AE10) -> -0.44568968 | AK10: =AB10+AA10+AD10 -> -1.0836385 | AL10: =Z10 -> -0.035773165 | AM10: =AH10 -> 0.025768875 | AN10: =SUM(AJ10:AM10) -> -1.5393325 | AO10: =(AJ10-AJ9)/($AN10-$AN9) -> -0.80372286 | AP10: =(AK10-AK9)/($AN10-$AN9) -> 1.6966197 | AQ10: =(AL10-AL9)/($AN10-$AN9) -> 0.10962006 | AR10: =(AM10-AM9)/($AN10-$AN9) -> -0.0025169303 | AS10: =(AN10-AN9)/($AN10-$AN9) -> 1
A11: 39994 | B11: =+wFG_rstar_shock_decomposition!E11 -> -0.02408911 | C11: =+wFG_rstar_shock_decomposition!F11 -> -0.87630027 | D11: =+wFG_rstar_shock_decomposition!G11 -> 0.24041406 | E11: =+wFG_rstar_shock_decomposition!H11 -> -0.15773268 | F11: =+wFG_rstar_shock_decomposition!I11 -> 0.14864202 | G11: =+wFG_rstar_shock_decomposition!J11 -> 1.7068416e-15 | H11: =+wFG_rstar_shock_decomposition!K11 -> 4.4703201e-15 | I11: =+wFG_rstar_shock_decomposition!L11 -> 9.4894502e-15 | ... T11: =+wFG_rstar_shock_decomposition!W11 -> 0.025443232 | U11: =+wFG_rstar_shock_decomposition!D11 -> -1.2082231 | Y11: =+A11 -> 39994 | Z11: =+B11 -> -0.02408911 | AA11: =+C11 -> -0.87630027 | AB11: =+D11 -> 0.24041406 | AC11: =+F11+S11 -> -0.31115498 | AD11: =+E11 -> -0.15773268 | AE11: =+Q11 -> -0.10480332 | AF11: =+G11 -> 1.7068416e-15 | AG11: =+H11 -> 4.4703201e-15 | AH11: =+SUM(T11,I11:P11) -> 0.025443232 | AI11: =+SUM(Z11:AH11) -> -1.2082231 | AJ11: =SUM(AC11+AE11) -> -0.4159583 | AK11: =AB11+AA11+AD11 -> -0.79361889 | AL11: =Z11 -> -0.02408911 | AM11: =AH11 -> 0.025443232 | AN11: =SUM(AJ11:AM11) -> -1.2082231 | AO11: =(AJ11-AJ10)/($AN11-$AN10) -> 0.089793219 | AP11: =(AK11-AK10)/($AN11-$AN10) -> 0.87590268 | AQ11: =(AL11-AL10)/($AN11-$AN10) -> 0.035287597 | AR11: =(AM11-AM10)/($AN11-$AN10) -> -0.00098349179 | AS11: =(AN11-AN10)/($AN11-$AN10) -> 1
A12: 40086 | B12: =+wFG_rstar_shock_decomposition!E12 -> -0.039925577 | C12: =+wFG_rstar_shock_decomposition!F12 -> -0.66815748 | D12: =+wFG_rstar_shock_decomposition!G12 -> 0.19466108 | E12: =+wFG_rstar_shock_decomposition!H12 -> -0.061837083 | F12: =+wFG_rstar_shock_decomposition!I12 -> 0.12092164 | G12: =+wFG_rstar_shock_decomposition!J12 -> 1.5949461e-15 | H12: =+wFG_rstar_shock_decomposition!K12 -> 4.8995216e-15 | I12: =+wFG_rstar_shock_decomposition!L12 -> 9.569358e-15 | ... T12: =+wFG_rstar_shock_decomposition!W12 -> 0.02512193 | U12: =+wFG_rstar_shock_decomposition!D12 -> -1.1317976 | Y12: =+A12 -> 40086 | Z12: =+B12 -> -0.039925577 | AA12: =+C12 -> -0.66815748 | AB12: =+D12 -> 0.19466108 | AC12: =+F12+S12 -> -0.3911912 | AD12: =+E12 -> -0.061837083 | AE12: =+Q12 -> -0.19046931 | AF12: =+G12 -> 1.5949461e-15 | AG12: =+H12 -> 4.8995216e-15 | AH12: =+SUM(T12,I12:P12) -> 0.02512193 | AI12: =+SUM(Z12:AH12) -> -1.1317976 | AJ12: =SUM(AC12+AE12) -> -0.58166051 | AK12: =AB12+AA12+AD12 -> -0.53533348 | AL12: =Z12 -> -0.039925577 | AM12: =AH12 -> 0.02512193 | AN12: =SUM(AJ12:AM12) -> -1.1317976 | AO12: =(AJ12-AJ11)/($AN12-$AN11) -> -2.1681553 | AP12: =(AK12-AK11)/($AN12-$AN11) -> 3.379574 | AQ12: =(AL12-AL11)/($AN12-$AN11) -> -0.20721461 | AR12: =(AM12-AM11)/($AN12-$AN11) -> -0.0042041224 | AS12: =(AN12-AN11)/($AN12-$AN11) -> 1
A13: 40178 | B13: =+wFG_rstar_shock_decomposition!E13 -> -0.027038449 | C13: =+wFG_rstar_shock_decomposition!F13 -> -0.58178559 | D13: =+wFG_rstar_shock_decomposition!G13 -> 0.15426067 | E13: =+wFG_rstar_shock_decomposition!H13 -> 0.00019437639 | F13: =+wFG_rstar_shock_decomposition!I13 -> 0.063221109 | G13: =+wFG_rstar_shock_decomposition!J13 -> 3.2339767e-16 | H13: =+wFG_rstar_shock_decomposition!K13 -> 5.509702e-15 | I13: =+wFG_rstar_shock_decomposition!L13 -> 6.8087841e-15 | ... T13: =+wFG_rstar_shock_decomposition!W13 -> 0.02480491 | U13: =+wFG_rstar_shock_decomposition!D13 -> -0.97113352 | Y13: =+A13 -> 40178 | Z13: =+B13 -> -0.027038449 | AA13: =+C13 -> -0.58178559 | AB13: =+D13 -> 0.15426067 | AC13: =+F13+S13 -> -0.35921644 | AD13: =+E13 -> 0.00019437639 | AE13: =+Q13 -> -0.182353 | AF13: =+G13 -> 3.2339767e-16 | AG13: =+H13 -> 5.509702e-15 | AH13: =+SUM(T13,I13:P13) -> 0.02480491 | AI13: =+SUM(Z13:AH13) -> -0.97113352 | AJ13: =SUM(AC13+AE13) -> -0.54156944 | AK13: =AB13+AA13+AD13 -> -0.42733054 | AL13: =Z13 -> -0.027038449 | AM13: =AH13 -> 0.02480491 | AN13: =SUM(AJ13:AM13) -> -0.97113352 | AO13: =(AJ13-AJ12)/($AN13-$AN12) -> 0.24953347 | AP13: =(AK13-AK12)/($AN13-$AN12) -> 0.6722281 | AQ13: =(AL13-AL12)/($AN13-$AN12) -> 0.080211611 | AR13: =(AM13-AM12)/($AN13-$AN12) -> -0.0019731848 | AS13: =(AN13-AN12)/($AN13-$AN12) -> 1
A14: 40268 | B14: =+wFG_rstar_shock_decomposition!E14 -> -0.028494114 | C14: =+wFG_rstar_shock_decomposition!F14 -> -0.48620876 | D14: =+wFG_rstar_shock_decomposition!G14 -> 0.095901011 | E14: =+wFG_rstar_shock_decomposition!H14 -> -0.022461201 | F14: =+wFG_rstar_shock_decomposition!I14 -> 0.050777858 | G14: =+wFG_rstar_shock_decomposition!J14 -> 4.2929694e-16 | H14: =+wFG_rstar_shock_decomposition!K14 -> 7.012102e-15 | I14: =+wFG_rstar_shock_decomposition!L14 -> 5.9508456e-15 | ... T14: =+wFG_rstar_shock_decomposition!W14 -> 0.024492113 | U14: =+wFG_rstar_shock_decomposition!D14 -> -1.230149 | Y14: =+A14 -> 40268 | Z14: =+B14 -> -0.028494114 | AA14: =+C14 -> -0.48620876 | AB14: =+D14 -> 0.095901011 | AC14: =+F14+S14 -> -0.56956423 | AD14: =+E14 -> -0.022461201 | AE14: =+Q14 -> -0.24381378 | AF14: =+G14 -> 4.2929694e-16 | AG14: =+H14 -> 7.012102e-15 | AH14: =+SUM(T14,I14:P14) -> 0.024492113 | AI14: =+SUM(Z14:AH14) -> -1.230149 | AJ14: =SUM(AC14+AE14) -> -0.81337801 | AK14: =AB14+AA14+AD14 -> -0.41276895 | AL14: =Z14 -> -0.028494114 | AM14: =AH14 -> 0.024492113 | AN14: =SUM(AJ14:AM14) -> -1.230149 | AO14: =(AJ14-AJ13)/($AN14-$AN13) -> 1.0493914 | AP14: =(AK14-AK13)/($AN14-$AN13) -> -0.056219043 | AQ14: =(AL14-AL13)/($AN14-$AN13) -> 0.0056199919 | AR14: =(AM14-AM13)/($AN14-$AN13) -> 0.0012076381 | AS14: =(AN14-AN13)/($AN14-$AN13) -> 1
... A132: 51043 | B132: =+wFG_rstar_shock_decomposition!E132 -> -0.093734333 | C132: =+wFG_rstar_shock_decomposition!F132 -> -0.084772866 | D132: =+wFG_rstar_shock_decomposition!G132 -> 0.14933986 | E132: =+wFG_rstar_shock_decomposition!H132 -> -0.022335447 | F132: =+wFG_rstar_shock_decomposition!I132 -> -0.015784383 | G132: =+wFG_rstar_shock_decomposition!J132 -> -4.1792313e-15 | H132: =+wFG_rstar_shock_decomposition!K132 -> 4.4624542e-14 | I132: =+wFG_rstar_shock_decomposition!L132 -> -5.2442661e-16 | ... T132: =+wFG_rstar_shock_decomposition!W132 -> 0.0058287268 | U132: =+wFG_rstar_shock_decomposition!D132 -> -0.18547251 | Y132: =+A132 -> 51043 | Z132: =+B132 -> -0.093734333 | AA132: =+C132 -> -0.084772866 | AB132: =+D132 -> 0.14933986 | AC132: =+F132+S132 -> -0.16073564 | AD132: =+E132 -> -0.022335447 | AE132: =+Q132 -> 0.020937194 | AF132: =+G132 -> -4.1792313e-15 | AG132: =+H132 -> 4.4624542e-14 | AH132: =+SUM(T132,I132:P132) -> 0.0058287268 | AI132: =+SUM(Z132:AH132) -> -0.18547251 | AJ132: =SUM(AC132+AE132) -> -0.13979845 | AK132: =AB132+AA132+AD132 -> 0.042231546 | AL132: =Z132 -> -0.093734333 | AM132: =AH132 -> 0.0058287268 | AN132: =SUM(AJ132:AM132) -> -0.18547251 | AO132: =(AJ132-AJ131)/($AN132-$AN131) -> 0.7046142 | AP132: =(AK132-AK131)/($AN132-$AN131) -> -0.053914859 | AQ132: =(AL132-AL131)/($AN132-$AN131) -> 0.37252306 | AR132: =(AM132-AM131)/($AN132-$AN131) -> -0.023222401 | AS132: =(AN132-AN131)/($AN132-$AN131) -> 1

Sheet DSGE HVD woFG
A1: date | B1: g | C1: b_liq | D1: b_safe | E1: FF | F1: z | G1: p-mkp | H1: w-mkp | I1: pol | J1: fg1 | K1: fg2 | L1: fg3 | M1: fg4 | N1: fg5 | O1: fg6 | P1: pi-LR | Q1: mu | R1: me | S1: zp | T1: dt | U1: DSGE r* | X1: Chart | Y1: Date | Z1: Government | AA1: Liquidity | AB1: Safety | AC1: Technology | AD1: Financial Frictions | AE1: Investment Specific Technology | AF1: Price Markups | AG1: Wage Markups | AH1: Others | AI1: DSGE r* (with FG) | AJ1: Growth | AK1: Safety+Liquidity | AL1: Government | AM1: Others | AN1: Total | AO1: Growth | AP1: Safety+Liquidity | AQ1: Government | AR1: Others | AS1: Total
A2: 39172 | B2: -0.099978563 | C2: -0.15498592 | D2: 0.25348034 | E2: -0.027181569 | F2: 0.11049296 | G2: 3.3627176e-16 | H2: -3.5538778e-15 | I2: 1.3552662e-14 | J2: 0 | K2: 0 | L2: 0 | M2: 0 | N2: 0 | O2: 0 | P2: 1.5995333e-13 | Q2: -0.053737086 | R2: 0 | S2: -0.084480241 | T2: 0.032328482 | U2: -0.024061599 | V2: =SUM(B2:T2) -> -0.024061599 | Y2: =+A2 -> 39172 | Z2: =+B2 -> -0.099978563 | AA2: =+C2 -> -0.15498592 | AB2: =+D2 -> 0.25348034 | AC2: =+F2+S2 -> 0.026012714 | AD2: =+E2 -> -0.027181569 | AE2: =+Q2 -> -0.053737086 | AF2: =+G2 -> 3.3627176e-16 | AG2: =+H2 -> -3.5538778e-15 | AH2: =+SUM(T2,I2:P2) -> 0.032328482 | AI2: =+SUM(Z2:AH2) -> -0.024061599 | AJ2: =SUM(AC2+AE2) -> -0.027724372 | AK2: =AB2+AA2+AD2 -> 0.071312855 | AL2: =Z2 -> -0.099978563 | AM2: =AH2 -> 0.032328482 | AN2: =SUM(AJ2:AM2) -> -0.024061599
A3: 39263 | B3: -0.090493735 | C3: -0.17989293 | D3: 0.28516778 | E3: -0.02241135 | F3: 0.091292176 | G3: 5.0574402e-16 | H3: -2.3897018e-15 | I3: 1.2532215e-14 | J3: 0 | K3: 0 | L3: 0 | M3: 0 | N3: 0 | O3: 0 | P3: 1.5987653e-13 | Q3: -0.047822202 | R3: 0 | S3: -0.23677861 | T3: 0.031925747 | U3: -0.16901313 | V3: =SUM(B3:T3) -> -0.16901313 | Y3: =+A3 -> 39263 | Z3: =+B3 -> -0.090493735 | AA3: =+C3 -> -0.17989293 | AB3: =+D3 -> 0.28516778 | AC3: =+F3+S3 -> -0.14548643 | AD3: =+E3 -> -0.02241135 | AE3: =+Q3 -> -0.047822202 | AF3: =+G3 -> 5.0574402e-16 | AG3: =+H3 -> -2.3897018e-15 | AH3: =+SUM(T3,I3:P3) -> 0.031925747 | AI3: =+SUM(Z3:AH3) -> -0.16901313 | AJ3: =SUM(AC3+AE3) -> -0.19330864 | AK3: =AB3+AA3+AD3 -> 0.082863497 | AL3: =Z3 -> -0.090493735 | AM3: =AH3 -> 0.031925747 | AN3: =SUM(AJ3:AM3) -> -0.16901313 | AO3: =(AJ3-AJ2)/($AN3-$AN2) -> 1.1423423 | AP3: =(AK3-AK2)/($AN3-$AN2) -> -0.079686237 | AQ3: =(AL3-AL2)/($AN3-$AN2) -> -0.065434481 | AR3: =(AM3-AM2)/($AN3-$AN2) -> 0.0027784056 | AS3: =(AN3-AN2)/($AN3-$AN2) -> 1
A4: 39355 | B4: -0.095177672 | C4: -0.35852263 | D4: 0.27111908 | E4: -0.057796505 | F4: 0.10745203 | G4: 2.1420713e-16 | H4: -1.4061899e-15 | I4: 1.3193762e-14 | J4: 0 | K4: 0 | L4: 0 | M4: 0 | N4: 0 | O4: 0 | P4: 1.5966689e-13 | Q4: -0.066368457 | R4: 0 | S4: -0.28913043 | T4: 0.031528307 | U4: -0.45689628 | V4: =SUM(B4:T4) -> -0.45689628 | Y4: =+A4 -> 39355 | Z4: =+B4 -> -0.095177672 | AA4: =+C4 -> -0.35852263 | AB4: =+D4 -> 0.27111908 | AC4: =+F4+S4 -> -0.1816784 | AD4: =+E4 -> -0.057796505 | AE4: =+Q4 -> -0.066368457 | AF4: =+G4 -> 2.1420713e-16 | AG4: =+H4 -> -1.4061899e-15 | AH4: =+SUM(T4,I4:P4) -> 0.031528307 | AI4: =+SUM(Z4:AH4) -> -0.45689628 | AJ4: =SUM(AC4+AE4) -> -0.24804686 | AK4: =AB4+AA4+AD4 -> -0.14520006 | AL4: =Z4 -> -0.095177672 | AM4: =AH4 -> 0.031528307 | AN4: =SUM(AJ4:AM4) -> -0.45689628 | AO4: =(AJ4-AJ3)/($AN4-$AN3) -> 0.19014041 | AP4: =(AK4-AK3)/($AN4-$AN3) -> 0.79220876 | AQ4: =(AL4-AL3)/($AN4-$AN3) -> 0.016270272 | AR4: =(AM4-AM3)/($AN4-$AN3) -> 0.0013805604 | AS4: =(AN4-AN3)/($AN4-$AN3) -> 1
A5: 39447 | B5: -0.092548084 | C5: -0.50609848 | D5: 0.22217413 | E5: -0.093789741 | F5: 0.10715544 | G5: -2.8771882e-16 | H5: -8.7528509e-16 | I5: 1.4934957e-14 | J5: 0 | K5: 0 | L5: 0 | M5: 0 | N5: 0 | O5: 0 | P5: 1.5828987e-13 | Q5: -0.080581712 | R5: 0 | S5: -0.28249002 | T5: 0.03113609 | U5: -0.69504238 | V5: =SUM(B5:T5) -> -0.69504238 | Y5: =+A5 -> 39447 | Z5: =+B5 -> -0.092548084 | AA5: =+C5 -> -0.50609848 | AB5: =+D5 -> 0.22217413 | AC5: =+F5+S5 -> -0.17533458 | AD5: =+E5 -> -0.093789741 | AE5: =+Q5 -> -0.080581712 | AF5: =+G5 -> -2.8771882e-16 | AG5: =+H5 -> -8.7528509e-16 | AH5: =+SUM(T5,I5:P5) -> 0.03113609 | AI5: =+SUM(Z5:AH5) -> -0.69504238 | AJ5: =SUM(AC5+AE5) -> -0.25591629 | AK5: =AB5+AA5+AD5 -> -0.37771409 | AL5: =Z5 -> -0.092548084 | AM5: =AH5 -> 0.03113609 | AN5: =SUM(AJ5:AM5) -> -0.69504238 | AO5: =(AJ5-AJ4)/($AN5-$AN4) -> 0.033044583 | AP5: =(AK5-AK4)/($AN5-$AN4) -> 0.97635037 | AQ5: =(AL5-AL4)/($AN5-$AN4) -> -0.01104191 | AR5: =(AM5-AM4)/($AN5-$AN4) -> 0.0016469617 | AS5: =(AN5-AN4)/($AN5-$AN4) -> 1
A6: 39538 | B6: -0.094542248 | C6: -0.68145357 | D6: 0.14069022 | E6: -0.1094861 | F6: 0.11501723 | G6: 9.6958303e-18 | H6: -3.0911534e-16 | I6: 1.6357192e-14 | J6: 0 | K6: 0 | L6: 0 | M6: 0 | N6: 0 | O6: 0 | P6: 1.5690382e-13 | Q6: -0.076086186 | R6: 0 | S6: -0.42528638 | T6: 0.030749024 | U6: -1.100398 | V6: =SUM(B6:T6) -> -1.100398 | Y6: =+A6 -> 39538 | Z6: =+B6 -> -0.094542248 | AA6: =+C6 -> -0.68145357 | AB6: =+D6 -> 0.14069022 | AC6: =+F6+S6 -> -0.31026915 | AD6: =+E6 -> -0.1094861 | AE6: =+Q6 -> -0.076086186 | AF6: =+G6 -> 9.6958303e-18 | AG6: =+H6 -> -3.0911534e-16 | AH6: =+SUM(T6,I6:P6) -> 0.030749024 | AI6: =+SUM(Z6:AH6) -> -1.100398 | AJ6: =SUM(AC6+AE6) -> -0.38635534 | AK6: =AB6+AA6+AD6 -> -0.65024945 | AL6: =Z6 -> -0.094542248 | AM6: =AH6 -> 0.030749024 | AN6: =SUM(AJ6:AM6) -> -1.100398 | AO6: =(AJ6-AJ5)/($AN6-$AN5) -> 0.32178914 | AP6: =(AK6-AK5)/($AN6-$AN5) -> 0.67233644 | AQ6: =(AL6-AL5)/($AN6-$AN5) -> 0.0049195403 | AR6: =(AM6-AM5)/($AN6-$AN5) -> 0.00095487878 | AS6: =(AN6-AN5)/($AN6-$AN5) -> 1
A7: 39629 | B7: -0.097854645 | C7: -0.66629665 | D7: 0.1430214 | E7: -0.11393175 | F7: 0.10627694 | G7: 1.5710799e-16 | H7: 6.8567457e-16 | I7: 1.7825543e-14 | J7: 0 | K7: 0 | L7: 0 | M7: 0 | N7: 0 | O7: 0 | P7: 1.5551938e-13 | Q7: -0.079067412 | R7: 0 | S7: -0.49307039 | T7: 0.030367041 | U7: -1.1705555 | V7: =SUM(B7:T7) -> -1.1705555 | Y7: =+A7 -> 39629 | Z7: =+B7 -> -0.097854645 | AA7: =+C7 -> -0.66629665 | AB7: =+D7 -> 0.1430214 | AC7: =+F7+S7 -> -0.38679345 | AD7: =+E7 -> -0.11393175 | AE7: =+Q7 -> -0.079067412 | AF7: =+G7 -> 1.5710799e-16 | AG7: =+H7 -> 6.8567457e-16 | AH7: =+SUM(T7,I7:P7) -> 0.030367041 | AI7: =+SUM(Z7:AH7) -> -1.1705555 | AJ7: =SUM(AC7+AE7) -> -0.46586086 | AK7: =AB7+AA7+AD7 -> -0.637207 | AL7: =Z7 -> -0.097854645 | AM7: =AH7 -> 0.030367041 | AN7: =SUM(AJ7:AM7) -> -1.1705555 | AO7: =(AJ7-AJ6)/($AN7-$AN6) -> 1.1332441 | AP7: =(AK7-AK6)/($AN7-$AN6) -> -0.18590253 | AQ7: =(AL7-AL6)/($AN7-$AN6) -> 0.047213758 | AR7: =(AM7-AM6)/($AN7-$AN6) -> 0.0054446548 | AS7: =(AN7-AN6)/($AN7-$AN6) -> 1
A8: 39721 | B8: -0.083694546 | C8: -0.80494647 | D8: 0.081173996 | E8: -0.11616631 | F8: 0.10059179 | G8: -3.5447993e-16 | H8: 1.3955055e-15 | I8: 1.5975287e-14 | J8: 0 | K8: 0 | L8: 0 | M8: 0 | N8: 0 | O8: 0 | P8: 1.5225991e-13 | Q8: -0.073477843 | R8: 0 | S8: -0.57361505 | T8: 0.029990072 | U8: -1.4401444 | V8: =SUM(B8:T8) -> -1.4401444 | Y8: =+A8 -> 39721 | Z8: =+B8 -> -0.083694546 | AA8: =+C8 -> -0.80494647 | AB8: =+D8 -> 0.081173996 | AC8: =+F8+S8 -> -0.47302326 | AD8: =+E8 -> -0.11616631 | AE8: =+Q8 -> -0.073477843 | AF8: =+G8 -> -3.5447993e-16 | AG8: =+H8 -> 1.3955055e-15 | AH8: =+SUM(T8,I8:P8) -> 0.029990072 | AI8: =+SUM(Z8:AH8) -> -1.4401444 | AJ8: =SUM(AC8+AE8) -> -0.5465011 | AK8: =AB8+AA8+AD8 -> -0.83993878 | AL8: =Z8 -> -0.083694546 | AM8: =AH8 -> 0.029990072 | AN8: =SUM(AJ8:AM8) -> -1.4401444 | AO8: =(AJ8-AJ7)/($AN8-$AN7) -> 0.29912299 | AP8: =(AK8-AK7)/($AN8-$AN7) -> 0.75200348 | AQ8: =(AL8-AL7)/($AN8-$AN7) -> -0.05252479 | AR8: =(AM8-AM7)/($AN8-$AN7) -> 0.0013983126 | AS8: =(AN8-AN7)/($AN8-$AN7) -> 1
A9: 39813 | B9: -0.051162174 | C9: -1.4348626 | D9: -0.25044652 | E9: -0.19974584 | F9: 0.1538426 | G9: 1.8820057e-15 | H9: 1.8210976e-15 | I9: 1.412852e-14 | J9: -5.4457331e-16 | K9: -2.1611639e-16 | L9: 1.368641e-16 | M9: -1.3785038e-16 | N9: -1.0958804e-17 | O9: -4.3720389e-17 | P9: 1.5221413e-13 | Q9: -0.020281188 | R9: 0 | S9: -0.81453912 | T9: 0.029618048 | U9: -2.5875768 | V9: =SUM(B9:T9) -> -2.5875768 | Y9: =+A9 -> 39813 | Z9: =+B9 -> -0.051162174 | AA9: =+C9 -> -1.4348626 | AB9: =+D9 -> -0.25044652 | AC9: =+F9+S9 -> -0.66069652 | AD9: =+E9 -> -0.19974584 | AE9: =+Q9 -> -0.020281188 | AF9: =+G9 -> 1.8820057e-15 | AG9: =+H9 -> 1.8210976e-15 | AH9: =+SUM(T9,I9:P9) -> 0.029618048 | AI9: =+SUM(Z9:AH9) -> -2.5875768 | AJ9: =SUM(AC9+AE9) -> -0.68097771 | AK9: =AB9+AA9+AD9 -> -1.8850549 | AL9: =Z9 -> -0.051162174 | AM9: =AH9 -> 0.029618048 | AN9: =SUM(AJ9:AM9) -> -2.5875768 | AO9: =(AJ9-AJ8)/($AN9-$AN8) -> 0.11719785 | AP9: =(AK9-AK8)/($AN9-$AN8) -> 0.91083025 | AQ9: =(AL9-AL8)/($AN9-$AN8) -> -0.028352321 | AR9: =(AM9-AM8)/($AN9-$AN8) -> 0.00032422285 | AS9: =(AN9-AN8)/($AN9-$AN8) -> 1
A10: 39903 | B10: -0.037464436 | C10: -1.2203241 | D10: -0.1817542 | E10: -0.24990049 | F10: 0.13619796 | G10: 2.1298368e-15 | H10: 3.9846044e-15 | I10: 1.0352372e-14 | J10: -1.0755173e-15 | K10: -4.3361978e-16 | L10: -2.8013837e-16 | M10: -3.9365195e-16 | N10: -2.3549082e-16 | O10: -1.5707528e-16 | P10: 1.533697e-13 | Q10: -0.095038466 | R10: 0 | S10: -0.82281479 | T10: 0.029250903 | U10: -2.4418476 | V10: =SUM(B10:T10) -> -2.4418476 | Y10: =+A10 -> 39903 | Z10: =+B10 -> -0.037464436 | AA10: =+C10 -> -1.2203241 | AB10: =+D10 -> -0.1817542 | AC10: =+F10+S10 -> -0.68661682 | AD10: =+E10 -> -0.24990049 | AE10: =+Q10 -> -0.095038466 | AF10: =+G10 -> 2.1298368e-15 | AG10: =+H10 -> 3.9846044e-15 | AH10: =+SUM(T10,I10:P10) -> 0.029250903 | AI10: =+SUM(Z10:AH10) -> -2.4418476 | AJ10: =SUM(AC10+AE10) -> -0.78165529 | AK10: =AB10+AA10+AD10 -> -1.6519788 | AL10: =Z10 -> -0.037464436 | AM10: =AH10 -> 0.029250903 | AN10: =SUM(AJ10:AM10) -> -2.4418476 | AO10: =(AJ10-AJ9)/($AN10-$AN9) -> -0.69085406 | AP10: =(AK10-AK9)/($AN10-$AN9) -> 1.5993789 | AQ10: =(AL10-AL9)/($AN10-$AN9) -> 0.093994485 | AR10: =(AM10-AM9)/($AN10-$AN9) -> -0.0025193657 | AS10: =(AN10-AN9)/($AN10-$AN9) -> 1
A11: 39994 | B11: -0.026473776 | C11: -0.99360085 | D11: -0.10457848 | E11: -0.18003743 | F11: 0.090604717 | G11: 1.87539e-15 | H11: 3.6850301e-15 | I11: 8.364169e-15 | J11: -1.2011701e-15 | K11: -7.9411366e-16 | L11: -5.4702722e-16 | M11: -7.1514748e-16 | N11: -5.6991559e-16 | O11: -4.5635577e-16 | P11: 1.4886767e-13 | Q11: -0.10050156 | R11: 0 | S11: -0.68818055 | T11: 0.02888857 | U11: -1.9738793 | V11: =SUM(B11:T11) -> -1.9738793 | Y11: =+A11 -> 39994 | Z11: =+B11 -> -0.026473776 | AA11: =+C11 -> -0.99360085 | AB11: =+D11 -> -0.10457848 | AC11: =+F11+S11 -> -0.59757583 | AD11: =+E11 -> -0.18003743 | AE11: =+Q11 -> -0.10050156 | AF11: =+G11 -> 1.87539e-15 | AG11: =+H11 -> 3.6850301e-15 | AH11: =+SUM(T11,I11:P11) -> 0.02888857 | AI11: =+SUM(Z11:AH11) -> -1.9738793 | AJ11: =SUM(AC11+AE11) -> -0.69807739 | AK11: =AB11+AA11+AD11 -> -1.2782168 | AL11: =Z11 -> -0.026473776 | AM11: =AH11 -> 0.02888857 | AN11: =SUM(AJ11:AM11) -> -1.9738793 | AO11: =(AJ11-AJ10)/($AN11-$AN10) -> 0.17859738 | AP11: =(AK11-AK10)/($AN11-$AN10) -> 0.79869097 | AQ11: =(AL11-AL10)/($AN11-$AN10) -> 0.02348591 | AR11: =(AM11-AM10)/($AN11-$AN10) -> -0.0007742671 | AS11: =(AN11-AN10)/($AN11-$AN10) -> 1
A12: 40086 | B12: -0.043317567 | C12: -0.68899371 | D12: 0.033900907 | E12: -0.082437085 | F12: 0.061241773 | G12: 1.5956308e-15 | H12: 3.9661818e-15 | I12: 8.0421596e-15 | J12: -1.4622254e-15 | K12: -1.0238027e-15 | L12: -8.4425511e-16 | M12: -1.0459959e-15 | N12: -9.0225641e-16 | O12: -4.9509332e-16 | P12: 1.4274201e-13 | Q12: -0.13806507 | R12: 0 | S12: -0.60241173 | T12: 0.028530985 | U12: -1.4315515 | V12: =SUM(B12:T12) -> -1.4315515 | Y12: =+A12 -> 40086 | Z12: =+B12 -> -0.043317567 | AA12: =+C12 -> -0.68899371 | AB12: =+D12 -> 0.033900907 | AC12: =+F12+S12 -> -0.54116995 | AD12: =+E12 -> -0.082437085 | AE12: =+Q12 -> -0.13806507 | AF12: =+G12 -> 1.5956308e-15 | AG12: =+H12 -> 3.9661818e-15 | AH12: =+SUM(T12,I12:P12) -> 0.028530985 | AI12: =+SUM(Z12:AH12) -> -1.4315515 | AJ12: =SUM(AC12+AE12) -> -0.67923503 | AK12: =AB12+AA12+AD12 -> -0.73752989 | AL12: =Z12 -> -0.043317567 | AM12: =AH12 -> 0.028530985 | AN12: =SUM(AJ12:AM12) -> -1.4315515 | AO12: =(AJ12-AJ11)/($AN12-$AN11) -> 0.034743483 | AP12: =(AK12-AK11)/($AN12-$AN11) -> 0.99697419 | AQ12: =(AL12-AL11)/($AN12-$AN11) -> -0.031058318 | AR12: =(AM12-AM11)/($AN12-$AN11) -> -0.00065935216 | AS12: =(AN12-AN11)/($AN12-$AN11) -> 1
A13: 40178 | B13: -0.030099008 | C13: -0.60245974 | D13: 0.060911429 | E13: -0.021856784 | F13: 0.00078641999 | G13: 3.9066384e-16 | H13: 4.4551475e-15 | I13: 6.2207741e-15 | J13: -1.7555505e-15 | K13: -1.3605621e-15 | L13: -1.168117e-15 | M13: -1.3450277e-15 | N13: -9.3612443e-16 | O13: -1.0425318e-15 | P13: 1.3591277e-13 | Q13: -0.12254587 | R13: 0 | S13: -0.48058538 | T13: 0.028178083 | U13: -1.1676709 | V13: =SUM(B13:T13) -> -1.1676709 | Y13: =+A13 -> 40178 | Z13: =+B13 -> -0.030099008 | AA13: =+C13 -> -0.60245974 | AB13: =+D13 -> 0.060911429 | AC13: =+F13+S13 -> -0.47979896 | AD13: =+E13 -> -0.021856784 | AE13: =+Q13 -> -0.12254587 | AF13: =+G13 -> 3.9066384e-16 | AG13: =+H13 -> 4.4551475e-15 | AH13: =+SUM(T13,I13:P13) -> 0.028178083 | AI13: =+SUM(Z13:AH13) -> -1.1676709 | AJ13: =SUM(AC13+AE13) -> -0.60234483 | AK13: =AB13+AA13+AD13 -> -0.5634051 | AL13: =Z13 -> -0.030099008 | AM13: =AH13 -> 0.028178083 | AN13: =SUM(AJ13:AM13) -> -1.1676709 | AO13: =(AJ13-AJ12)/($AN13-$AN12) -> 0.29138249 | AP13: =(AK13-AK12)/($AN13-$AN12) -> 0.65986192 | AQ13: =(AL13-AL12)/($AN13-$AN12) -> 0.050092946 | AR13: =(AM13-AM12)/($AN13-$AN12) -> -0.0013373548 | AS13: =(AN13-AN12)/($AN13-$AN12) -> 1
A14: 40268 | B14: -0.031649797 | C14: -0.46842205 | D14: 0.12401342 | E14: -0.044504198 | F14: -0.012096584 | G14: 4.6556231e-16 | H14: 5.843492e-15 | I14: 5.8218777e-15 | J14: -1.8572438e-15 | K14: -1.4689412e-15 | L14: -1.2298706e-15 | M14: -1.1325431e-15 | N14: -1.112011e-15 | O14: -1.3895386e-15 | P14: 1.3662116e-13 | Q14: -0.16200655 | R14: 0 | S14: -0.59961401 | T14: 0.027829801 | U14: -1.16645 | V14: =SUM(B14:T14) -> -1.16645 | Y14: =+A14 -> 40268 | Z14: =+B14 -> -0.031649797 | AA14: =+C14 -> -0.46842205 | AB14: =+D14 -> 0.12401342 | AC14: =+F14+S14 -> -0.61171059 | AD14: =+E14 -> -0.044504198 | AE14: =+Q14 -> -0.16200655 | AF14: =+G14 -> 4.6556231e-16 | AG14: =+H14 -> 5.843492e-15 | AH14: =+SUM(T14,I14:P14) -> 0.027829801 | AI14: =+SUM(Z14:AH14) -> -1.16645 | AJ14: =SUM(AC14+AE14) -> -0.77371714 | AK14: =AB14+AA14+AD14 -> -0.38891283 | AL14: =Z14 -> -0.031649797 | AM14: =AH14 -> 0.027829801 | AN14: =SUM(AJ14:AM14) -> -1.16645 | AO14: =(AJ14-AJ13)/($AN14-$AN13) -> -140.36715 | AP14: =(AK14-AK13)/($AN14-$AN13) -> 142.92264 | AQ14: =(AL14-AL13)/($AN14-$AN13) -> -1.2702165 | AR14: =(AM14-AM13)/($AN14-$AN13) -> -0.28527036 | AS14: =(AN14-AN13)/($AN14-$AN13) -> 1
... A132: 51043 | B132: -0.084608619 | C132: -0.070189722 | D132: 0.26077834 | E132: -0.016689636 | F132: -0.014700397 | G132: -4.2256513e-15 | H132: 4.6129552e-14 | I132: 2.3122145e-15 | J132: -2.4736448e-16 | K132: -3.995226e-16 | L132: -5.8621374e-16 | M132: -8.8535017e-16 | N132: -1.0941128e-15 | O132: -1.2963744e-15 | P132: 6.7566725e-14 | Q132: 0.0017702803 | R132: 0 | S132: -0.20923111 | T132: 0.0068179135 | U132: -0.12605296 | V132: =SUM(B132:T132) -> -0.12605296 | Y132: =+A132 -> 51043 | Z132: =+B132 -> -0.084608619 | AA132: =+C132 -> -0.070189722 | AB132: =+D132 -> 0.26077834 | AC132: =+F132+S132 -> -0.22393151 | AD132: =+E132 -> -0.016689636 | AE132: =+Q132 -> 0.0017702803 | AF132: =+G132 -> -4.2256513e-15 | AG132: =+H132 -> 4.6129552e-14 | AH132: =+SUM(T132,I132:P132) -> 0.0068179135 | AI132: =+SUM(Z132:AH132) -> -0.12605296 | AJ132: =SUM(AC132+AE132) -> -0.22216123 | AK132: =AB132+AA132+AD132 -> 0.17389898 | AL132: =Z132 -> -0.084608619 | AM132: =AH132 -> 0.0068179135 | AN132: =SUM(AJ132:AM132) -> -0.12605296 | AO132: =(AJ132-AJ131)/($AN132-$AN131) -> 1.2758034 | AP132: =(AK132-AK131)/($AN132-$AN131) -> -0.67217438 | AQ132: =(AL132-AL131)/($AN132-$AN131) -> 0.43044311 | AR132: =(AM132-AM131)/($AN132-$AN131) -> -0.034072092 | AS132: =(AN132-AN131)/($AN132-$AN131) -> 1

Sheet US_output_withoutFG
A1: date | B1: g_sh | C1: b_liqtil_sh | D1: b_liqp_sh | E1: b_safetil_sh | F1: b_safep_sh | G1: mu_sh | H1: z_sh | I1: lambda_f_sh | J1: lambda_w_sh | K1: rm_sh | L1: sigma_omega_sh | M1: mu_e_sh | N1: gamma_sh | O1: pi_star_sh | P1: lr_sh | Q1: zp_sh | R1: tfp_sh | S1: gdpdef_sh | T1: corepce_sh | U1: gdp_sh | V1: gdi_sh | W1: BBB_sh | X1: AAA_sh | Y1: rm_shl1 | Z1: rm_shl2 | AA1: rm_shl3 | AB1: rm_shl4 | AC1: rm_shl5 | AD1: rm_shl6 | AE1: dettrend | AF1: detrendedMean | AG1: Ouput | AH1: Output without FG
A2: 39172 | B2: -1.0215877 | C2: 0.14738424 | D2: -0.044907453 | E2: 0.56515568 | F2: 0.33471877 | G2: 1.4053436 | H2: 0.54693072 | I2: -0.65393335 | J2: 0.64232717 | K2: 1.7750614 | L2: 1.2826525 | M2: 0 | N2: 0 | O2: 0.3278555 | P2: 0 | Q2: 0.11087454 | R2: 0 | S2: 0 | T2: 0 | U2: 0 | V2: 0 | W2: 0 | X2: 0 | Y2: 0 | Z2: 0 | AA2: 0 | AB2: 0 | AC2: 0 | AD2: 0 | AE2: 0.13099711 | AF2: 5.5488727 | AG2: =AF2 -> 5.5488727 | AH2: =AG2-SUM(Y2:AD2) -> 5.5488727
A3: 39263 | B3: -0.87702165 | C3: 0.14867978 | D3: -0.050839217 | E3: 0.5967583 | F3: 0.35694143 | G3: 1.4459149 | H3: 0.10615582 | I3: -0.67075329 | J3: 0.60096046 | K3: 1.5688765 | L3: 1.2418066 | M3: 0 | N3: 0 | O3: 0.33267031 | P3: 0 | Q3: 0.070231968 | R3: 0 | S3: 0 | T3: 0 | U3: 0 | V3: 0 | W3: 0 | X3: 0 | Y3: 0 | Z3: 0 | AA3: 0 | AB3: 0 | AC3: 0 | AD3: 0 | AE3: 0.13039267 | AF3: 5.0007746 | AG3: =AF3 -> 5.0007746 | AH3: =AG3-SUM(Y3:AD3) -> 5.0007746
A4: 39355 | B4: -1.040355 | C4: 0.13425109 | D4: -0.14587387 | E4: 0.69031317 | F4: 0.37191894 | G4: 1.4503632 | H4: 0.31183503 | I4: -0.6798581 | J4: 0.61019793 | K4: 1.5086958 | L4: 1.1510338 | M4: 0 | N4: 0 | O4: 0.37118543 | P4: 0 | Q4: 0.037371485 | R4: 0 | S4: 0 | T4: 0 | U4: 0 | V4: 0 | W4: 0 | X4: 0 | Y4: 0 | Z4: 0 | AA4: 0 | AB4: 0 | AC4: 0 | AD4: 0 | AE4: 0.12978091 | AF4: 4.9008599 | AG4: =AF4 -> 4.9008599 | AH4: =AG4-SUM(Y4:AD4) -> 4.9008599
A5: 39447 | B5: -0.99330901 | C5: 0.14258815 | D5: -0.26310356 | E5: 0.73768743 | F5: 0.36639612 | G5: 1.4317096 | H5: 0.21867959 | I5: -0.68920012 | J5: 0.66599438 | K5: 1.7274198 | L5: 1.0093212 | M5: 0 | N5: 0 | O5: 0.40724837 | P5: 0 | Q5: 0.016106972 | R5: 0 | S5: 0 | T5: 0 | U5: 0 | V5: 0 | W5: 0 | X5: 0 | Y5: 0 | Z5: 0 | AA5: 0 | AB5: 0 | AC5: 0 | AD5: 0 | AE5: 0.12916218 | AF5: 4.9067011 | AG5: =AF5 -> 4.9067011 | AH5: =AG5-SUM(Y5:AD5) -> 4.9067011
