Workbook
Name BoxPlot: "BoxPlot"
Name Bubble: "Bubble"
Name Candlestick: "Candlestick"
Name Chart: "Chart"
Name ChartImage: "ChartImage"
Name ColumnRange: "ColumnRange"
Name Dumbbell: "Dumbbell"
Name Heatmap: "Heatmap"
Name Histogram: "Histogram"
Name Map: "Map"
Name OHLC: "OHLC"
Name PieChart: "PieChart"
Name Scatter: "Scatter"
Name Series: "Series"
Name Stripe: "Stripe"
Name Table: "Table"
Name TreeMap: "TreeMap"
Name Waterfall: "Waterfall"

Sheet All Chart

Sheet EA_output_obs_with_text
A1: date | B1: g_sh | C1: b_liqtil_sh | D1: b_liqp_sh | E1: b_safetil_sh | F1: b_safep_sh | G1: mu_sh | H1: z_sh | I1: lambda_f_sh | J1: lambda_w_sh | K1: rm_sh | L1: sigma_omega_sh | M1: mu_e_sh | N1: gamma_sh | O1: pi_star_sh | P1: lr_sh | Q1: zp_sh | R1: tfp_sh | S1: gdpdef_sh | T1: corepce_sh | U1: gdp_sh | V1: gdi_sh | W1: BBB_sh | X1: AAA_sh | Y1: rm_shl1 | Z1: rm_shl2 | AA1: rm_shl3 | AB1: rm_shl4 | AC1: rm_shl5 | AD1: rm_shl6 | AE1: dettrend | AF1: detrendedMean | AH1: rm_sh | AI1: =Y1 -> rm_shl1 | AJ1: =Z1 -> rm_shl2 | AK1: =AA1 -> rm_shl3 | AL1: =AB1 -> rm_shl4 | AM1: =AC1 -> rm_shl5 | AN1: =AD1 -> rm_shl6 | AQ1: Plot | AR1: =A1 -> date | AS1: =AF1 -> detrendedMean | AT1: Monetary Policy | AU1: Fgsum | AV1: FG1 | AW1: FG2 | AX1: FG3 | AY1: FG4 | AZ1: FG5 | BA1: FG6 | BB1: Combined | BC1: date | BD1: rm_sh | BE1: Fgsum
A2: 39172 | B2: 2.5363082 | C2: -0.18049422 | D2: -5.026568 | E2: -0.00051095038 | F2: 6.5669289 | G2: 14.167348 | H2: -0.028136165 | I2: 0.24489409 | J2: -0.05757504 | K2: 2.5748891 | L2: 0.26640205 | M2: 0 | N2: 0 | O2: 0.43018806 | P2: 0 | Q2: -0.017234495 | R2: 0 | S2: 0 | T2: 0 | U2: 0 | V2: 0 | W2: 0 | X2: 0 | Y2: 0 | Z2: 0 | AA2: 0 | AB2: 0 | AC2: 0 | AD2: 0 | AE2: 7.4683269 | AF2: 28.944766 | AH2: =K2+Y2-Y2/100 -> 2.5748891 | AI2: =Y2 -> 0 | AJ2: =Z2 -> 0 | AK2: =AA2 -> 0 | AL2: =AB2 -> 0 | AM2: =AC2 -> 0 | AN2: =AD2 -> 0 | AR2: =A2 -> 39172 | AS2: =AF2*4+2 -> 117.77907 | AU2: =SUM(AV2:BA2) -> 0 | AV2: =AI2 -> 0 | AW2: =AJ2 -> 0 | AX2: =AK2 -> 0 | AY2: =AL2 -> 0 | AZ2: =AM2 -> 0 | BA2: =AN2 -> 0 | BB2: =SUM(AT2:BA2) -> 0 | BC2: =AR2 -> 39172 | BD2: =AT2-$AT$2 -> 0 | BE2: =AU2-$AU$2 -> 0
A3: 39263 | B3: 2.1888377 | C3: -0.10201437 | D3: -5.4151599 | E3: 0.000432913 | F3: 7.4635098 | G3: 14.09681 | H3: -0.017718534 | I3: 0.23729294 | J3: -0.058482715 | K3: 2.6753132 | L3: 0.30577422 | M3: 0 | N3: 0 | O3: 0.44487798 | P3: 0 | Q3: -0.025392488 | R3: 0 | S3: 0 | T3: 0 | U3: 0 | V3: 0 | W3: 0 | X3: 0 | Y3: 0 | Z3: 0 | AA3: 0 | AB3: 0 | AC3: 0 | AD3: 0 | AE3: 7.445194 | AF3: 29.239275 | AH3: =K3+Y3-Y3/100 -> 2.6753132 | AI3: =Y3 -> 0 | AJ3: =Z3 -> 0 | AK3: =AA3 -> 0 | AL3: =AB3 -> 0 | AM3: =AC3 -> 0 | AN3: =AD3 -> 0 | AR3: =A3 -> 39263 | AS3: =AF3*4+2 -> 118.9571 | AU3: =SUM(AV3:BA3) -> 0 | AV3: =AI3 -> 0 | AW3: =AJ3 -> 0 | AX3: =AK3 -> 0 | AY3: =AL3 -> 0 | AZ3: =AM3 -> 0 | BA3: =AN3 -> 0 | BB3: =SUM(AT3:BA3) -> 0 | BC3: =AR3 -> 39263 | BD3: =AT3-$AT$2 -> 0 | BE3: =AU3 -> 0
A4: 39355 | B4: 2.3018784 | C4: -0.18582521 | D4: -5.7797078 | E4: -0.00024449342 | F4: 8.1065585 | G4: 14.1473 | H4: 0.0099248504 | I4: 0.31153154 | J4: -0.061960515 | K4: 2.506994 | L4: 0.30064004 | M4: 0 | N4: 0 | O4: 0.46631618 | P4: 0 | Q4: -0.040553603 | R4: 0 | S4: 0 | T4: 0 | U4: 0 | V4: 0 | W4: 0 | X4: 0 | Y4: 0 | Z4: 0 | AA4: 0 | AB4: 0 | AC4: 0 | AD4: 0 | AE4: 7.4221487 | AF4: 29.505 | AH4: =K4+Y4-Y4/100 -> 2.506994 | AI4: =Y4 -> 0 | AJ4: =Z4 -> 0 | AK4: =AA4 -> 0 | AL4: =AB4 -> 0 | AM4: =AC4 -> 0 | AN4: =AD4 -> 0 | AR4: =A4 -> 39355 | AS4: =AF4*4+2 -> 120.02 | AU4: =SUM(AV4:BA4) -> 0 | AV4: =AI4 -> 0 | AW4: =AJ4 -> 0 | AX4: =AK4 -> 0 | AY4: =AL4 -> 0 | AZ4: =AM4 -> 0 | BA4: =AN4 -> 0 | BB4: =SUM(AT4:BA4) -> 0 | BC4: =AR4 -> 39355 | BD4: =AT4-$AT$2 -> 0 | BE4: =AU4 -> 0
A5: 39447 | B5: 2.0031345 | C5: -0.059805901 | D5: -6.0906698 | E5: 0.00065881996 | F5: 8.5748649 | G5: 14.245587 | H5: 0.01546791 | I5: 0.248964 | J5: -0.063329388 | K5: 2.6392114 | L5: 0.34661216 | M5: 0 | N5: 0 | O5: 0.47709801 | P5: 0 | Q5: -0.045182361 | R5: 0 | S5: 0 | T5: 0 | U5: 0 | V5: 0 | W5: 0 | X5: 0 | Y5: 0 | Z5: 0 | AA5: 0 | AB5: 0 | AC5: 0 | AD5: 0 | AE5: 7.3991902 | AF5: 29.691802 | AH5: =K5+Y5-Y5/100 -> 2.6392114 | AI5: =Y5 -> 0 | AJ5: =Z5 -> 0 | AK5: =AA5 -> 0 | AL5: =AB5 -> 0 | AM5: =AC5 -> 0 | AN5: =AD5 -> 0 | AR5: =A5 -> 39447 | AS5: =AF5*4+2 -> 120.76721 | AU5: =SUM(AV5:BA5) -> 0 | AV5: =AI5 -> 0 | AW5: =AJ5 -> 0 | AX5: =AK5 -> 0 | AY5: =AL5 -> 0 | AZ5: =AM5 -> 0 | BA5: =AN5 -> 0 | BB5: =SUM(AT5:BA5) -> 0 | BC5: =AR5 -> 39447 | BD5: =AT5-$AT$2 -> 0 | BE5: =AU5 -> 0
A6: 39538 | B6: 2.0564368 | C6: -0.17410702 | D6: -6.2409237 | E6: -8.1488331e-05 | F6: 8.7254233 | G6: 14.470225 | H6: -0.053129904 | I6: 0.30778976 | J6: -0.066874845 | K6: 2.9688718 | L6: 0.14427824 | M6: 0 | N6: 0 | O6: 0.49713924 | P6: 0 | Q6: -0.050515251 | R6: 0 | S6: 0 | T6: 0 | U6: 0 | V6: 0 | W6: 0 | X6: 0 | Y6: 0 | Z6: 0 | AA6: 0 | AB6: 0 | AC6: 0 | AD6: 0 | AE6: 7.376318 | AF6: 29.96085 | AH6: =K6+Y6-Y6/100 -> 2.9688718 | AI6: =Y6 -> 0 | AJ6: =Z6 -> 0 | AK6: =AA6 -> 0 | AL6: =AB6 -> 0 | AM6: =AC6 -> 0 | AN6: =AD6 -> 0 | AR6: =A6 -> 39538 | AS6: =AF6*4+2 -> 121.8434 | AU6: =SUM(AV6:BA6) -> 0 | AV6: =AI6 -> 0 | AW6: =AJ6 -> 0 | AX6: =AK6 -> 0 | AY6: =AL6 -> 0 | AZ6: =AM6 -> 0 | BA6: =AN6 -> 0 | BB6: =SUM(AT6:BA6) -> 0 | BC6: =AR6 -> 39538 | BD6: =AT6-$AT$2 -> 0 | BE6: =AU6 -> 0
A7: 39629 | B7: 1.9437086 | C7: -0.25968328 | D7: -6.4409474 | E7: 0.00050280931 | F7: 9.1352305 | G7: 14.602996 | H7: -0.0028221986 | I7: 0.2461009 | J7: -0.063600816 | K7: 2.6992023 | L7: 0.031560885 | M7: 0 | N7: 0 | O7: 0.50964208 | P7: 0 | Q7: -0.07357073 | R7: 0 | S7: 0 | T7: 0 | U7: 0 | V7: 0 | W7: 0 | X7: 0 | Y7: 0 | Z7: 0 | AA7: 0 | AB7: 0 | AC7: 0 | AD7: 0 | AE7: 7.3535315 | AF7: 29.681851 | AH7: =K7+Y7-Y7/100 -> 2.6992023 | AI7: =Y7 -> 0 | AJ7: =Z7 -> 0 | AK7: =AA7 -> 0 | AL7: =AB7 -> 0 | AM7: =AC7 -> 0 | AN7: =AD7 -> 0 | AR7: =A7 -> 39629 | AS7: =AF7*4+2 -> 120.7274 | AU7: =SUM(AV7:BA7) -> 0 | AV7: =AI7 -> 0 | AW7: =AJ7 -> 0 | AX7: =AK7 -> 0 | AY7: =AL7 -> 0 | AZ7: =AM7 -> 0 | BA7: =AN7 -> 0 | BB7: =SUM(AT7:BA7) -> 0 | BC7: =AR7 -> 39629 | BD7: =AT7-$AT$2 -> 0 | BE7: =AU7 -> 0
A8: 39721 | B8: 1.5553725 | C8: -0.47264141 | D8: -6.5811779 | E8: 0.00045985532 | F8: 9.4802157 | G8: 14.927721 | H8: 0.027059605 | I8: 0.29587019 | J8: -0.068185466 | K8: 2.5210749 | L8: -0.16240357 | M8: 0 | N8: 0 | O8: 0.53344519 | P8: 0 | Q8: -0.081467541 | R8: 0 | S8: 0 | T8: 0 | U8: 0 | V8: 0 | W8: 0 | X8: 0 | Y8: 0 | Z8: 0 | AA8: 0 | AB8: 0 | AC8: 0 | AD8: 0 | AE8: 7.3308301 | AF8: 29.306173 | AH8: =K8+Y8-Y8/100 -> 2.5210749 | AI8: =Y8 -> 0 | AJ8: =Z8 -> 0 | AK8: =AA8 -> 0 | AL8: =AB8 -> 0 | AM8: =AC8 -> 0 | AN8: =AD8 -> 0 | AR8: =A8 -> 39721 | AS8: =AF8*4+2 -> 119.22469 | AT8: =AH8-$AH$8 -> 0 | AU8: =SUM(AV8:BA8) -> 0 | AV8: =AI8 -> 0 | AW8: =AJ8 -> 0 | AX8: =AK8 -> 0 | AY8: =AL8 -> 0 | AZ8: =AM8 -> 0 | BA8: =AN8 -> 0 | BB8: =SUM(AT8:BA8) -> 0 | BC8: =AR8 -> 39721 | BD8: =AT8-$AT$2 -> 0 | BE8: =AU8 -> 0
A9: 39813 | B9: 2.2206634 | C9: -0.98689403 | D9: -6.9466266 | E9: -0.0002896115 | F9: 8.9449095 | G9: 15.944444 | H9: 0.11808668 | I9: 0.33695797 | J9: -0.065994594 | K9: 2.2587813 | L9: -0.68091049 | M9: 0 | N9: 0 | O9: 0.55671627 | P9: 0 | Q9: -0.073561543 | R9: 0 | S9: 0 | T9: 0 | U9: 0 | V9: 0 | W9: 0 | X9: 0 | Y9: 0.073690921 | Z9: -0.13359577 | AA9: 0.092384556 | AB9: -0.0071129062 | AC9: -0.014969052 | AD9: -0.028973438 | AE9: 7.3082133 | AF9: 28.91592 | AH9: =K9+Y9-Y9/100 -> 2.3317353 | AI9: =Y9/1010 -> 7.2961308e-05 | AJ9: =Z9 -> -0.13359577 | AK9: =AA9 -> 0.092384556 | AL9: =AB9 -> -0.0071129062 | AM9: =AC9 -> -0.014969052 | AN9: =AD9 -> -0.028973438 | AR9: =A9 -> 39813 | AS9: =AF9*4+2 -> 117.66368 | AT9: =AH9-$AH$8 -> -0.18933955 | AU9: =SUM(AV9:BA9) -> -0.092193645 | AV9: =AI9 -> 7.2961308e-05 | AW9: =AJ9 -> -0.13359577 | AX9: =AK9 -> 0.092384556 | AY9: =AL9 -> -0.0071129062 | AZ9: =AM9 -> -0.014969052 | BA9: =AN9 -> -0.028973438 | BB9: =SUM(AT9:BA9) -> -0.37372684 | BC9: =AR9 -> 39813 | BD9: =AT9-$AT$2 -> -0.18933955 | BE9: =AU9 -> -0.092193645
A10: 39903 | B10: 2.4024061 | C10: -1.2606797 | D10: -6.8199197 | E10: -0.0001738059 | F10: 8.6027343 | G10: 16.652521 | H10: 0.06749249 | I10: 0.27634318 | J10: -0.060941639 | K10: 2.7785999 | L10: -1.1798196 | M10: 0 | N10: 0 | O10: 0.57206768 | P10: 0 | Q10: -0.025279014 | R10: 0 | S10: 0 | T10: 0 | U10: 0 | V10: 0 | W10: 0 | X10: 0 | Y10: -1.7973575 | Z10: 0.013721478 | AA10: 0.12529789 | AB10: -0.030395868 | AC10: -0.051108838 | AD10: -0.13660702 | AE10: 7.2856806 | AF10: 27.414582 | AH10: =K10+Y10-Y10/100 -> 0.99921591 | AI10: =Y10/1010 -> -0.0017795619 | AJ10: =Z10 -> 0.013721478 | AK10: =AA10 -> 0.12529789 | AL10: =AB10 -> -0.030395868 | AM10: =AC10 -> -0.051108838 | AN10: =AD10 -> -0.13660702 | AR10: =A10 -> 39903 | AS10: =AF10*4+2 -> 111.65833 | AT10: =AH10-$AH$8 -> -1.521859 | AU10: =SUM(AV10:BA10) -> -0.080871912 | AV10: =AI10 -> -0.0017795619 | AW10: =AJ10 -> 0.013721478 | AX10: =AK10 -> 0.12529789 | AY10: =AL10 -> -0.030395868 | AZ10: =AM10 -> -0.051108838 | BA10: =AN10 -> -0.13660702 | BB10: =SUM(AT10:BA10) -> -1.6836028 | BC10: =AR10 -> 39903 | BD10: =AT10-$AT$2 -> -1.521859 | BE10: =AU10 -> -0.080871912
A11: 39994 | B11: 2.4277616 | C11: -1.6490085 | D11: -6.3861468 | E11: -0.00049595052 | F11: 7.9593532 | G11: 17.059181 | H11: -0.089907165 | I11: 0.25785819 | J11: -0.059151639 | K11: 5.406976 | L11: -1.4181606 | M11: 0 | N11: 0 | O11: 0.58667403 | P11: 0 | Q11: 0.016546462 | R11: 0 | S11: 0 | T11: 0 | U11: 0 | V11: 0 | W11: 0 | X11: 0 | Y11: -4.5109297 | Z11: 0.25520858 | AA11: 0.13462049 | AB11: -0.078483828 | AC11: -0.067382708 | AD11: -0.30713781 | AE11: 7.2632314 | AF11: 26.800606 | AH11: =K11+Y11-Y11/100 -> 0.94115568 | AI11: =Y11/1010 -> -0.004466267 | AJ11: =Z11 -> 0.25520858 | AK11: =AA11 -> 0.13462049 | AL11: =AB11 -> -0.078483828 | AM11: =AC11 -> -0.067382708 | AN11: =AD11 -> -0.30713781 | AR11: =A11 -> 39994 | AS11: =AF11*4+2 -> 109.20242 | AT11: =AH11-$AH$8 -> -1.5799192 | AU11: =SUM(AV11:BA11) -> -0.067641554 | AV11: =AI11 -> -0.004466267 | AW11: =AJ11 -> 0.25520858 | AX11: =AK11 -> 0.13462049 | AY11: =AL11 -> -0.078483828 | AZ11: =AM11 -> -0.067382708 | BA11: =AN11 -> -0.30713781 | BB11: =SUM(AT11:BA11) -> -1.7152023 | BC11: =AR11 -> 39994 | BD11: =AT11-$AT$2 -> -1.5799192 | BE11: =AU11 -> -0.067641554
A12: 40086 | B12: 2.4217085 | C12: -2.0203722 | D12: -5.5802494 | E12: -0.0013006478 | F12: 7.1417549 | G12: 17.135333 | H12: -0.0426744 | I12: 0.322457 | J12: -0.056528372 | K12: 7.9652821 | L12: -1.4766757 | M12: 0 | N12: 0 | O12: 0.60460848 | P12: 0 | Q12: 0.00073509913 | R12: 0 | S12: 0 | T12: 0 | U12: 0 | V12: 0 | W12: 0 | X12: 0 | Y12: -6.6481835 | Z12: 0.43002849 | AA12: 0.11092325 | AB12: -0.16598199 | AC12: -0.11796388 | AD12: -0.56485065 | AE12: 7.2408652 | AF12: 26.698915 | AH12: =K12+Y12-Y12/100 -> 1.3835804 | AI12: =Y12/1010 -> -0.0065823599 | AJ12: =Z12 -> 0.43002849 | AK12: =AA12 -> 0.11092325 | AL12: =AB12 -> -0.16598199 | AM12: =AC12 -> -0.11796388 | AN12: =AD12 -> -0.56485065 | AR12: =A12 -> 40086 | AS12: =AF12*4+2 -> 108.79566 | AT12: =AH12-$AH$8 -> -1.1374945 | AU12: =SUM(AV12:BA12) -> -0.31442715 | AV12: =AI12 -> -0.0065823599 | AW12: =AJ12 -> 0.43002849 | AX12: =AK12 -> 0.11092325 | AY12: =AL12 -> -0.16598199 | AZ12: =AM12 -> -0.11796388 | BA12: =AN12 -> -0.56485065 | BB12: =SUM(AT12:BA12) -> -1.7663488 | BC12: =AR12 -> 40086 | BD12: =AT12-$AT$2 -> -1.1374945 | BE12: =AU12 -> -0.31442715
A13: 40178 | B13: 2.0701525 | C13: -1.9632677 | D13: -4.963927 | E13: -0.00080920876 | F13: 6.7932403 | G13: 17.165547 | H13: 0.018838774 | I13: 0.252927 | J13: -0.046777776 | K13: 9.6680861 | L13: -1.4944411 | M13: 0 | N13: 0 | O13: 0.61475522 | P13: 0 | Q13: -0.017101425 | R13: 0 | S13: 0 | T13: 0 | U13: 0 | V13: 0 | W13: 0 | X13: 0 | Y13: -8.2298802 | Z13: 0.64538339 | AA13: 0.075587373 | AB13: -0.24389615 | AC13: -0.13783327 | AD13: -0.86962231 | AE13: 7.2185815 | AF13: 26.555543 | AH13: =K13+Y13-Y13/100 -> 1.5205047 | AI13: =Y13/1010 -> -0.0081483962 | AJ13: =Z13 -> 0.64538339 | AK13: =AA13 -> 0.075587373 | AL13: =AB13 -> -0.24389615 | AM13: =AC13 -> -0.13783327 | AN13: =AD13 -> -0.86962231 | AR13: =A13 -> 40178 | AS13: =AF13*4+2 -> 108.22217 | AT13: =AH13-$AH$8 -> -1.0005702 | AU13: =SUM(AV13:BA13) -> -0.53852936 | AV13: =AI13 -> -0.0081483962 | AW13: =AJ13 -> 0.64538339 | AX13: =AK13 -> 0.075587373 | AY13: =AL13 -> -0.24389615 | AZ13: =AM13 -> -0.13783327 | BA13: =AN13 -> -0.86962231 | BB13: =SUM(AT13:BA13) -> -2.0776289 | BC13: =AR13 -> 40178 | BD13: =AT13-$AT$2 -> -1.0005702 | BE13: =AU13 -> -0.53852936
A14: 40268 | B14: 1.9292619 | C14: -1.9152574 | D14: -4.6209409 | E14: -9.3285765e-05 | F14: 6.2885873 | G14: 17.194811 | H14: -0.0097242431 | I14: 0.24468576 | J14: -0.033630541 | K14: 11.391705 | L14: -1.5295778 | M14: 0 | N14: 0 | O14: 0.62748077 | P14: 0 | Q14: -0.021055782 | R14: 0 | S14: 0 | T14: 0 | U14: 0 | V14: 0 | W14: 0 | X14: 0 | Y14: -9.2842199 | Z14: 0.93375033 | AA14: 0.13528553 | AB14: -0.26251041 | AC14: -0.11896933 | AD14: -1.185558 | AE14: 7.1963798 | AF14: 26.96041 | AH14: =K14+Y14-Y14/100 -> 2.2003272 | AI14: =Y14/1010 -> -0.0091922969 | AJ14: =Z14 -> 0.93375033 | AK14: =AA14 -> 0.13528553 | AL14: =AB14 -> -0.26251041 | AM14: =AC14 -> -0.11896933 | AN14: =AD14 -> -1.185558 | AR14: =A14 -> 40268 | AS14: =AF14*4+2 -> 109.84164 | AT14: =AH14-$AH$8 -> -0.32074769 | AU14: =SUM(AV14:BA14) -> -0.50719413 | AV14: =AI14 -> -0.0091922969 | AW14: =AJ14 -> 0.93375033 | AX14: =AK14 -> 0.13528553 | AY14: =AL14 -> -0.26251041 | AZ14: =AM14 -> -0.11896933 | BA14: =AN14 -> -1.185558 | BB14: =SUM(AT14:BA14) -> -1.3351359 | BC14: =AR14 -> 40268 | BD14: =AT14-$AT$2 -> -0.32074769 | BE14: =AU14 -> -0.50719413
A15: 40359 | B15: 1.7114594 | C15: -1.7910189 | D15: -4.417112 | E15: -0.00034034385 | F15: 5.508496 | G15: 17.284895 | H15: 0.036125033 | I15: 0.25452995 | J15: -0.025443457 | K15: 12.624267 | L15: -1.4630845 | M15: 0 | N15: 0 | O15: 0.64041987 | P15: 0 | Q15: -0.024373029 | R15: 0 | S15: 0 | T15: 0 | U15: 0 | V15: 0 | W15: 0 | X15: 0 | Y15: -10.235004 | Z15: 1.2587611 | AA15: 0.30474392 | AB15: -0.17869597 | AC15: -0.03951587 | AD15: -1.4723622 | AE15: 7.1742596 | AF15: 27.151007 | AH15: =K15+Y15-Y15/100 -> 2.4916135 | AI15: =Y15/1010 -> -0.010133667 | AJ15: =Z15 -> 1.2587611 | AK15: =AA15 -> 0.30474392 | AL15: =AB15 -> -0.17869597 | AM15: =AC15 -> -0.03951587 | AN15: =AD15 -> -1.4723622 | AR15: =A15 -> 40359 | AS15: =AF15*4+2 -> 110.60403 | AT15: =AH15-$AH$8 -> -0.029461387 | AU15: =SUM(AV15:BA15) -> -0.13720259 | AV15: =AI15 -> -0.010133667 | AW15: =AJ15 -> 1.2587611 | AX15: =AK15 -> 0.30474392 | AY15: =AL15 -> -0.17869597 | AZ15: =AM15 -> -0.03951587 | BA15: =AN15 -> -1.4723622 | BB15: =SUM(AT15:BA15) -> -0.30386656 | BC15: =AR15 -> 40359 | BD15: =AT15-$AT$2 -> -0.029461387 | BE15: =AU15 -> -0.13720259
A16: 40451 | B16: 1.6689236 | C16: -1.669287 | D16: -4.2631128 | E16: -0.00047472158 | F16: 5.3252985 | G16: 17.33458 | H16: 0.0056531455 | I16: 0.3395956 | J16: -0.01579766 | K16: 13.592728 | L16: -1.5563826 | M16: 0 | N16: 0 | O16: 0.65967139 | P16: 0 | Q16: -0.017203497 | R16: 0 | S16: 0 | T16: 0 | U16: 0 | V16: 0 | W16: 0 | X16: 0 | Y16: -11.450592 | Z16: 1.4891879 | AA16: 0.38887175 | AB16: -0.13286861 | AC16: 0.019233067 | AD16: -1.7498602 | AE16: 7.1522205 | AF16: 27.120385 | AH16: =K16+Y16-Y16/100 -> 2.2566424 | AI16: =Y16/1010 -> -0.011337219 | AJ16: =Z16 -> 1.4891879 | AK16: =AA16 -> 0.38887175 | AL16: =AB16 -> -0.13286861 | AM16: =AC16 -> 0.019233067 | AN16: =AD16 -> -1.7498602 | AR16: =A16 -> 40451 | AS16: =AF16*4+2 -> 110.48154 | AT16: =AH16-$AH$8 -> -0.26443245 | AU16: =SUM(AV16:BA16) -> 0.0032267014 | AV16: =AI16 -> -0.011337219 | AW16: =AJ16 -> 1.4891879 | AX16: =AK16 -> 0.38887175 | AY16: =AL16 -> -0.13286861 | AZ16: =AM16 -> 0.019233067 | BA16: =AN16 -> -1.7498602 | BB16: =SUM(AT16:BA16) -> -0.25797905 | BC16: =AR16 -> 40451 | BD16: =AT16-$AT$2 -> -0.26443245 | BE16: =AU16 -> 0.0032267014
A17: 40543 | B17: 1.3754459 | C17: -1.4731984 | D17: -4.3372803 | E17: -0.00016910156 | F17: 6.0283243 | G17: 17.375538 | H17: -0.03695678 | I17: 0.26961923 | J17: -0.0084062676 | K17: 14.927038 | L17: -1.5514464 | M17: 0 | N17: 0 | O17: 0.6729625 | P17: 0 | Q17: -0.010960892 | R17: 0 | S17: 0 | T17: 0 | U17: 0 | V17: 0 | W17: 0 | X17: 0 | Y17: -13.193123 | Z17: 1.6728789 | AA17: 0.4341946 | AB17: -0.11512471 | AC17: 0.031882889 | AD17: -2.0389967 | AE17: 7.1302619 | AF17: 27.152484 | AH17: =K17+Y17-Y17/100 -> 1.8658466 | AI17: =Y17/1010 -> -0.013062498 | AJ17: =Z17 -> 1.6728789 | AK17: =AA17 -> 0.4341946 | AL17: =AB17 -> -0.11512471 | AM17: =AC17 -> 0.031882889 | AN17: =AD17 -> -2.0389967 | AR17: =A17 -> 40543 | AS17: =AF17*4+2 -> 110.60994 | AT17: =AH17-$AH$8 -> -0.65522828 | AU17: =SUM(AV17:BA17) -> -0.028227444 | AV17: =AI17 -> -0.013062498 | AW17: =AJ17 -> 1.6728789 | AX17: =AK17 -> 0.4341946 | AY17: =AL17 -> -0.11512471 | AZ17: =AM17 -> 0.031882889 | BA17: =AN17 -> -2.0389967 | BB17: =SUM(AT17:BA17) -> -0.71168317 | BC17: =AR17 -> 40543 | BD17: =AT17-$AT$2 -> -0.65522828 | BE17: =AU17 -> -0.028227444
A18: 40633 | B18: 1.9043017 | C18: -1.5433038 | D18: -4.5069513 | E18: -0.0012869151 | F18: 7.4268885 | G18: 17.45478 | H18: -0.036961388 | I18: 0.30813711 | J18: -0.0078414583 | K18: 16.675365 | L18: -1.4894906 | M18: 0 | N18: 0 | O18: 0.69313123 | P18: 0 | Q18: -0.023400021 | R18: 0 | S18: 0 | T18: 0 | U18: 0 | V18: 0 | W18: 0 | X18: 0 | Y18: -15.514005 | Z18: 1.6560904 | AA18: 0.29727136 | AB18: -0.20292069 | AC18: -0.027254571 | AD18: -2.3847288 | AE18: 7.1083835 | AF18: 27.786204 | AH18: =K18+Y18-Y18/100 -> 1.3164998 | AI18: =Y18/1010 -> -0.015360401 | AJ18: =Z18 -> 1.6560904 | AK18: =AA18 -> 0.29727136 | AL18: =AB18 -> -0.20292069 | AM18: =AC18 -> -0.027254571 | AN18: =AD18 -> -2.3847288 | AR18: =A18 -> 40633 | AS18: =AF18*4+2 -> 113.14482 | AT18: =AH18-$AH$8 -> -1.2045751 | AU18: =SUM(AV18:BA18) -> -0.67690276 | AV18: =AI18 -> -0.015360401 | AW18: =AJ18 -> 1.6560904 | AX18: =AK18 -> 0.29727136 | AY18: =AL18 -> -0.20292069 | AZ18: =AM18 -> -0.027254571 | BA18: =AN18 -> -2.3847288 | BB18: =SUM(AT18:BA18) -> -2.5583806 | BC18: =AR18 -> 40633 | BD18: =AT18-$AT$2 -> -1.2045751 | BE18: =AU18 -> -0.67690276
A19: 40724 | B19: 1.467808 | C19: -1.2043497 | D19: -4.3924235 | E19: -0.0010583469 | F19: 8.406255 | G19: 17.546427 | H19: 0.07324742 | I19: 0.30268883 | J19: -0.0051230818 | K19: 18.729266 | L19: -1.555679 | M19: 0 | N19: 0 | O19: 0.71288761 | P19: 0 | Q19: -0.035226888 | R19: 0 | S19: 0 | T19: 0 | U19: 0 | V19: 0 | W19: 0 | X19: 0 | Y19: -18.615704 | Z19: 1.7520007 | AA19: 0.18453734 | AB19: -0.23254533 | AC19: -0.029947737 | AD19: -2.709168 | AE19: 7.0865847 | AF19: 27.480477 | AH19: =K19+Y19-Y19/100 -> 0.29971978 | AI19: =Y19/1010 -> -0.01843139 | AJ19: =Z19 -> 1.7520007 | AK19: =AA19 -> 0.18453734 | AL19: =AB19 -> -0.23254533 | AM19: =AC19 -> -0.029947737 | AN19: =AD19 -> -2.709168 | AR19: =A19 -> 40724 | AS19: =AF19*4+2 -> 111.92191 | AT19: =AH19-$AH$8 -> -2.2213551 | AU19: =SUM(AV19:BA19) -> -1.0535544 | AV19: =AI19 -> -0.01843139 | AW19: =AJ19 -> 1.7520007 | AX19: =AK19 -> 0.18453734 | AY19: =AL19 -> -0.23254533 | AZ19: =AM19 -> -0.029947737 | BA19: =AN19 -> -2.709168 | BB19: =SUM(AT19:BA19) -> -4.3284639 | BC19: =AR19 -> 40724 | BD19: =AT19-$AT$2 -> -2.2213551 | BE19: =AU19 -> -1.0535544
A20: 40816 | B20: 1.8241286 | C20: -1.0959542 | D20: -4.2580249 | E20: -0.00028471595 | F20: 6.5846466 | G20: 17.671886 | H20: -0.047348455 | I20: 0.34776192 | J20: 0.0012598254 | K20: 21.668795 | L20: -1.6269307 | M20: 0 | N20: 0 | O20: 0.72603408 | P20: 0 | Q20: -0.021518547 | R20: 0 | S20: 0 | T20: 0 | U20: 0 | V20: 0 | W20: 0 | X20: 0 | Y20: -21.294037 | Z20: 2.3087563 | AA20: 0.35473861 | AB20: -0.080751504 | AC20: 0.099261868 | AD20: -2.8984711 | AE20: 7.0648651 | AF20: 27.328812 | AH20: =K20+Y20-Y20/100 -> 0.58769775 | AI20: =Y20/1010 -> -0.021083205 | AJ20: =Z20 -> 2.3087563 | AK20: =AA20 -> 0.35473861 | AL20: =AB20 -> -0.080751504 | AM20: =AC20 -> 0.099261868 | AN20: =AD20 -> -2.8984711 | AR20: =A20 -> 40816 | AS20: =AF20*4+2 -> 111.31525 | AT20: =AH20-$AH$8 -> -1.9333771 | AU20: =SUM(AV20:BA20) -> -0.23754899 | AV20: =AI20 -> -0.021083205 | AW20: =AJ20 -> 2.3087563 | AX20: =AK20 -> 0.35473861 | AY20: =AL20 -> -0.080751504 | AZ20: =AM20 -> 0.099261868 | BA20: =AN20 -> -2.8984711 | BB20: =SUM(AT20:BA20) -> -2.4084751 | BC20: =AR20 -> 40816 | BD20: =AT20-$AT$2 -> -1.9333771 | BE20: =AU20 -> -0.23754899
... A132: 51043 | B132: -0.043141873 | C132: -0.00014191675 | D132: -0.060150045 | E132: 0.00016375639 | F132: 0.077003819 | G132: -0.017761409 | H132: 0.10657899 | I132: -0.12938709 | J132: -0.23383062 | K132: -0.0013647494 | L132: 0.028622522 | M132: 0 | N132: 0 | O132: 0.44750605 | P132: 0 | Q132: 0.30446726 | R132: 0 | S132: 0 | T132: 0 | U132: 0 | V132: 0 | W132: 0 | X132: 0 | Y132: 0.0014171204 | Z132: -0.0014470184 | AA132: 0.00054189822 | AB132: -0.00029329794 | AC132: 0.0013717805 | AD132: 0.0037302372 | AE132: -0.072867892 | AF132: 0.418171 | AH132: =K132+Y132-Y132/100 -> 3.8199787e-05 | AI132: =Y132/1010 -> 1.4030895e-06 | AJ132: =Z132 -> -0.0014470184 | AK132: =AA132 -> 0.00054189822 | AL132: =AB132 -> -0.00029329794 | AM132: =AC132 -> 0.0013717805 | AN132: =AD132 -> 0.0037302372 | AR132: =A132 -> 51043 | AS132: =AF132*4+2 -> 3.672684 | AT132: =AH132-$AH$8 -> -2.5210367 | AU132: =SUM(AV132:BA132) -> 0.0039050027 | AV132: =AI132 -> 1.4030895e-06 | AW132: =AJ132 -> -0.0014470184 | AX132: =AK132 -> 0.00054189822 | AY132: =AL132 -> -0.00029329794 | AZ132: =AM132 -> 0.0013717805 | BA132: =AN132 -> 0.0037302372 | BB132: =SUM(AT132:BA132) -> -2.5132267 | BC132: =AR132 -> 51043 | BD132: =AT132-$AT$2 -> -2.5210367 | BE132: =AU132 -> 0.0039050027

Sheet EA_output_obs_with_text_backup
A1: date | B1: g_sh | C1: b_liqtil_sh | D1: b_liqp_sh | E1: b_safetil_sh | F1: b_safep_sh | G1: mu_sh | H1: z_sh | I1: lambda_f_sh | J1: lambda_w_sh | K1: rm_sh | L1: sigma_omega_sh | M1: mu_e_sh | N1: gamma_sh | O1: pi_star_sh | P1: lr_sh | Q1: zp_sh | R1: tfp_sh | S1: gdpdef_sh | T1: corepce_sh | U1: gdp_sh | V1: gdi_sh | W1: BBB_sh | X1: AAA_sh | Y1: rm_shl1 | Z1: rm_shl2 | AA1: rm_shl3 | AB1: rm_shl4 | AC1: rm_shl5 | AD1: rm_shl6 | AE1: dettrend | AF1: detrendedMean | AH1: rm_sh | AI1: =Y1 -> rm_shl1 | AJ1: =Z1 -> rm_shl2 | AK1: =AA1 -> rm_shl3 | AL1: =AB1 -> rm_shl4 | AM1: =AC1 -> rm_shl5 | AN1: =AD1 -> rm_shl6 | AQ1: Plot | AR1: =A1 -> date | AS1: =AF1 -> detrendedMean | AT1: Monetary Policy | AU1: Fgsum | AV1: FG1 | AW1: FG2 | AX1: FG3 | AY1: FG4 | AZ1: FG5 | BA1: FG6 | BC1: date | BD1: rm_sh | BE1: Fgsum
A2: 39172 | B2: 2.5363082 | C2: -0.18049422 | D2: -5.026568 | E2: -0.00051095038 | F2: 6.5669289 | G2: 14.167348 | H2: -0.028136165 | I2: 0.24489409 | J2: -0.05757504 | K2: 2.5748891 | L2: 0.26640205 | M2: 0 | N2: 0 | O2: 0.43018806 | P2: 0 | Q2: -0.017234495 | R2: 0 | S2: 0 | T2: 0 | U2: 0 | V2: 0 | W2: 0 | X2: 0 | Y2: 0 | Z2: 0 | AA2: 0 | AB2: 0 | AC2: 0 | AD2: 0 | AE2: 7.4683269 | AF2: 28.944766 | AH2: =K2+Y2-Y2/100 -> 2.5748891 | AI2: =Y2 -> 0 | AJ2: =Z2 -> 0 | AK2: =AA2 -> 0 | AL2: =AB2 -> 0 | AM2: =AC2 -> 0 | AN2: =AD2 -> 0 | AR2: =A2 -> 39172 | AS2: =AF2*4+2 -> 117.77907 | AT2: =AH2 -> 2.5748891 | AU2: =SUM(AV2:BA2) -> 0 | AV2: =AI2 -> 0 | AW2: =AJ2 -> 0 | AX2: =AK2 -> 0 | AY2: =AL2 -> 0 | AZ2: =AM2 -> 0 | BA2: =AN2 -> 0 | BC2: =AR2 -> 39172 | BD2: =AT2-$AT$2 -> 0 | BE2: =AU2-$AU$2 -> 0
A3: 39263 | B3: 2.1888377 | C3: -0.10201437 | D3: -5.4151599 | E3: 0.000432913 | F3: 7.4635098 | G3: 14.09681 | H3: -0.017718534 | I3: 0.23729294 | J3: -0.058482715 | K3: 2.6753132 | L3: 0.30577422 | M3: 0 | N3: 0 | O3: 0.44487798 | P3: 0 | Q3: -0.025392488 | R3: 0 | S3: 0 | T3: 0 | U3: 0 | V3: 0 | W3: 0 | X3: 0 | Y3: 0 | Z3: 0 | AA3: 0 | AB3: 0 | AC3: 0 | AD3: 0 | AE3: 7.445194 | AF3: 29.239275 | AH3: =K3+Y3-Y3/100 -> 2.6753132 | AI3: =Y3 -> 0 | AJ3: =Z3 -> 0 | AK3: =AA3 -> 0 | AL3: =AB3 -> 0 | AM3: =AC3 -> 0 | AN3: =AD3 -> 0 | AR3: =A3 -> 39263 | AS3: =AF3*4+2 -> 118.9571 | AT3: =AH3 -> 2.6753132 | AU3: =SUM(AV3:BA3) -> 0 | AV3: =AI3 -> 0 | AW3: =AJ3 -> 0 | AX3: =AK3 -> 0 | AY3: =AL3 -> 0 | AZ3: =AM3 -> 0 | BA3: =AN3 -> 0 | BC3: =AR3 -> 39263 | BD3: =AT3-$AT$2 -> 0.10042406 | BE3: =AU3 -> 0
A4: 39355 | B4: 2.3018784 | C4: -0.18582521 | D4: -5.7797078 | E4: -0.00024449342 | F4: 8.1065585 | G4: 14.1473 | H4: 0.0099248504 | I4: 0.31153154 | J4: -0.061960515 | K4: 2.506994 | L4: 0.30064004 | M4: 0 | N4: 0 | O4: 0.46631618 | P4: 0 | Q4: -0.040553603 | R4: 0 | S4: 0 | T4: 0 | U4: 0 | V4: 0 | W4: 0 | X4: 0 | Y4: 0 | Z4: 0 | AA4: 0 | AB4: 0 | AC4: 0 | AD4: 0 | AE4: 7.4221487 | AF4: 29.505 | AH4: =K4+Y4-Y4/100 -> 2.506994 | AI4: =Y4 -> 0 | AJ4: =Z4 -> 0 | AK4: =AA4 -> 0 | AL4: =AB4 -> 0 | AM4: =AC4 -> 0 | AN4: =AD4 -> 0 | AR4: =A4 -> 39355 | AS4: =AF4*4+2 -> 120.02 | AT4: =AH4 -> 2.506994 | AU4: =SUM(AV4:BA4) -> 0 | AV4: =AI4 -> 0 | AW4: =AJ4 -> 0 | AX4: =AK4 -> 0 | AY4: =AL4 -> 0 | AZ4: =AM4 -> 0 | BA4: =AN4 -> 0 | BC4: =AR4 -> 39355 | BD4: =AT4-$AT$2 -> -0.067895149 | BE4: =AU4 -> 0
A5: 39447 | B5: 2.0031345 | C5: -0.059805901 | D5: -6.0906698 | E5: 0.00065881996 | F5: 8.5748649 | G5: 14.245587 | H5: 0.01546791 | I5: 0.248964 | J5: -0.063329388 | K5: 2.6392114 | L5: 0.34661216 | M5: 0 | N5: 0 | O5: 0.47709801 | P5: 0 | Q5: -0.045182361 | R5: 0 | S5: 0 | T5: 0 | U5: 0 | V5: 0 | W5: 0 | X5: 0 | Y5: 0 | Z5: 0 | AA5: 0 | AB5: 0 | AC5: 0 | AD5: 0 | AE5: 7.3991902 | AF5: 29.691802 | AH5: =K5+Y5-Y5/100 -> 2.6392114 | AI5: =Y5 -> 0 | AJ5: =Z5 -> 0 | AK5: =AA5 -> 0 | AL5: =AB5 -> 0 | AM5: =AC5 -> 0 | AN5: =AD5 -> 0 | AR5: =A5 -> 39447 | AS5: =AF5*4+2 -> 120.76721 | AT5: =AH5 -> 2.6392114 | AU5: =SUM(AV5:BA5) -> 0 | AV5: =AI5 -> 0 | AW5: =AJ5 -> 0 | AX5: =AK5 -> 0 | AY5: =AL5 -> 0 | AZ5: =AM5 -> 0 | BA5: =AN5 -> 0 | BC5: =AR5 -> 39447 | BD5: =AT5-$AT$2 -> 0.064322263 | BE5: =AU5 -> 0
A6: 39538 | B6: 2.0564368 | C6: -0.17410702 | D6: -6.2409237 | E6: -8.1488331e-05 | F6: 8.7254233 | G6: 14.470225 | H6: -0.053129904 | I6: 0.30778976 | J6: -0.066874845 | K6: 2.9688718 | L6: 0.14427824 | M6: 0 | N6: 0 | O6: 0.49713924 | P6: 0 | Q6: -0.050515251 | R6: 0 | S6: 0 | T6: 0 | U6: 0 | V6: 0 | W6: 0 | X6: 0 | Y6: 0 | Z6: 0 | AA6: 0 | AB6: 0 | AC6: 0 | AD6: 0 | AE6: 7.376318 | AF6: 29.96085 | AH6: =K6+Y6-Y6/100 -> 2.9688718 | AI6: =Y6 -> 0 | AJ6: =Z6 -> 0 | AK6: =AA6 -> 0 | AL6: =AB6 -> 0 | AM6: =AC6 -> 0 | AN6: =AD6 -> 0 | AR6: =A6 -> 39538 | AS6: =AF6*4+2 -> 121.8434 | AT6: =AH6 -> 2.9688718 | AU6: =SUM(AV6:BA6) -> 0 | AV6: =AI6 -> 0 | AW6: =AJ6 -> 0 | AX6: =AK6 -> 0 | AY6: =AL6 -> 0 | AZ6: =AM6 -> 0 | BA6: =AN6 -> 0 | BC6: =AR6 -> 39538 | BD6: =AT6-$AT$2 -> 0.39398266 | BE6: =AU6 -> 0
A7: 39629 | B7: 1.9437086 | C7: -0.25968328 | D7: -6.4409474 | E7: 0.00050280931 | F7: 9.1352305 | G7: 14.602996 | H7: -0.0028221986 | I7: 0.2461009 | J7: -0.063600816 | K7: 2.6992023 | L7: 0.031560885 | M7: 0 | N7: 0 | O7: 0.50964208 | P7: 0 | Q7: -0.07357073 | R7: 0 | S7: 0 | T7: 0 | U7: 0 | V7: 0 | W7: 0 | X7: 0 | Y7: 0 | Z7: 0 | AA7: 0 | AB7: 0 | AC7: 0 | AD7: 0 | AE7: 7.3535315 | AF7: 29.681851 | AH7: =K7+Y7-Y7/100 -> 2.6992023 | AI7: =Y7 -> 0 | AJ7: =Z7 -> 0 | AK7: =AA7 -> 0 | AL7: =AB7 -> 0 | AM7: =AC7 -> 0 | AN7: =AD7 -> 0 | AR7: =A7 -> 39629 | AS7: =AF7*4+2 -> 120.7274 | AT7: =AH7 -> 2.6992023 | AU7: =SUM(AV7:BA7) -> 0 | AV7: =AI7 -> 0 | AW7: =AJ7 -> 0 | AX7: =AK7 -> 0 | AY7: =AL7 -> 0 | AZ7: =AM7 -> 0 | BA7: =AN7 -> 0 | BC7: =AR7 -> 39629 | BD7: =AT7-$AT$2 -> 0.12431319 | BE7: =AU7 -> 0
A8: 39721 | B8: 1.5553725 | C8: -0.47264141 | D8: -6.5811779 | E8: 0.00045985532 | F8: 9.4802157 | G8: 14.927721 | H8: 0.027059605 | I8: 0.29587019 | J8: -0.068185466 | K8: 2.5210749 | L8: -0.16240357 | M8: 0 | N8: 0 | O8: 0.53344519 | P8: 0 | Q8: -0.081467541 | R8: 0 | S8: 0 | T8: 0 | U8: 0 | V8: 0 | W8: 0 | X8: 0 | Y8: 0 | Z8: 0 | AA8: 0 | AB8: 0 | AC8: 0 | AD8: 0 | AE8: 7.3308301 | AF8: 29.306173 | AH8: =K8+Y8-Y8/100 -> 2.5210749 | AI8: =Y8 -> 0 | AJ8: =Z8 -> 0 | AK8: =AA8 -> 0 | AL8: =AB8 -> 0 | AM8: =AC8 -> 0 | AN8: =AD8 -> 0 | AR8: =A8 -> 39721 | AS8: =AF8*4+2 -> 119.22469 | AT8: =AH8 -> 2.5210749 | AU8: =SUM(AV8:BA8) -> 0 | AV8: =AI8 -> 0 | AW8: =AJ8 -> 0 | AX8: =AK8 -> 0 | AY8: =AL8 -> 0 | AZ8: =AM8 -> 0 | BA8: =AN8 -> 0 | BC8: =AR8 -> 39721 | BD8: =AT8-$AT$2 -> -0.05381425 | BE8: =AU8 -> 0
A9: 39813 | B9: 2.2206634 | C9: -0.98689403 | D9: -6.9466266 | E9: -0.0002896115 | F9: 8.9449095 | G9: 15.944444 | H9: 0.11808668 | I9: 0.33695797 | J9: -0.065994594 | K9: 2.2587813 | L9: -0.68091049 | M9: 0 | N9: 0 | O9: 0.55671627 | P9: 0 | Q9: -0.073561543 | R9: 0 | S9: 0 | T9: 0 | U9: 0 | V9: 0 | W9: 0 | X9: 0 | Y9: 0.073690921 | Z9: -0.13359577 | AA9: 0.092384556 | AB9: -0.0071129062 | AC9: -0.014969052 | AD9: -0.028973438 | AE9: 7.3082133 | AF9: 28.91592 | AH9: =K9+Y9-Y9/100 -> 2.3317353 | AI9: =Y9/1010 -> 7.2961308e-05 | AJ9: =Z9 -> -0.13359577 | AK9: =AA9 -> 0.092384556 | AL9: =AB9 -> -0.0071129062 | AM9: =AC9 -> -0.014969052 | AN9: =AD9 -> -0.028973438 | AR9: =A9 -> 39813 | AS9: =AF9*4+2 -> 117.66368 | AT9: =AH9 -> 2.3317353 | AU9: =SUM(AV9:BA9) -> -0.092193645 | AV9: =AI9 -> 7.2961308e-05 | AW9: =AJ9 -> -0.13359577 | AX9: =AK9 -> 0.092384556 | AY9: =AL9 -> -0.0071129062 | AZ9: =AM9 -> -0.014969052 | BA9: =AN9 -> -0.028973438 | BC9: =AR9 -> 39813 | BD9: =AT9-$AT$2 -> -0.2431538 | BE9: =AU9 -> -0.092193645
A10: 39903 | B10: 2.4024061 | C10: -1.2606797 | D10: -6.8199197 | E10: -0.0001738059 | F10: 8.6027343 | G10: 16.652521 | H10: 0.06749249 | I10: 0.27634318 | J10: -0.060941639 | K10: 2.7785999 | L10: -1.1798196 | M10: 0 | N10: 0 | O10: 0.57206768 | P10: 0 | Q10: -0.025279014 | R10: 0 | S10: 0 | T10: 0 | U10: 0 | V10: 0 | W10: 0 | X10: 0 | Y10: -1.7973575 | Z10: 0.013721478 | AA10: 0.12529789 | AB10: -0.030395868 | AC10: -0.051108838 | AD10: -0.13660702 | AE10: 7.2856806 | AF10: 27.414582 | AH10: =K10+Y10-Y10/100 -> 0.99921591 | AI10: =Y10/1010 -> -0.0017795619 | AJ10: =Z10 -> 0.013721478 | AK10: =AA10 -> 0.12529789 | AL10: =AB10 -> -0.030395868 | AM10: =AC10 -> -0.051108838 | AN10: =AD10 -> -0.13660702 | AR10: =A10 -> 39903 | AS10: =AF10*4+2 -> 111.65833 | AT10: =AH10 -> 0.99921591 | AU10: =SUM(AV10:BA10) -> -0.080871912 | AV10: =AI10 -> -0.0017795619 | AW10: =AJ10 -> 0.013721478 | AX10: =AK10 -> 0.12529789 | AY10: =AL10 -> -0.030395868 | AZ10: =AM10 -> -0.051108838 | BA10: =AN10 -> -0.13660702 | BC10: =AR10 -> 39903 | BD10: =AT10-$AT$2 -> -1.5756732 | BE10: =AU10 -> -0.080871912
A11: 39994 | B11: 2.4277616 | C11: -1.6490085 | D11: -6.3861468 | E11: -0.00049595052 | F11: 7.9593532 | G11: 17.059181 | H11: -0.089907165 | I11: 0.25785819 | J11: -0.059151639 | K11: 5.406976 | L11: -1.4181606 | M11: 0 | N11: 0 | O11: 0.58667403 | P11: 0 | Q11: 0.016546462 | R11: 0 | S11: 0 | T11: 0 | U11: 0 | V11: 0 | W11: 0 | X11: 0 | Y11: -4.5109297 | Z11: 0.25520858 | AA11: 0.13462049 | AB11: -0.078483828 | AC11: -0.067382708 | AD11: -0.30713781 | AE11: 7.2632314 | AF11: 26.800606 | AH11: =K11+Y11-Y11/100 -> 0.94115568 | AI11: =Y11/1010 -> -0.004466267 | AJ11: =Z11 -> 0.25520858 | AK11: =AA11 -> 0.13462049 | AL11: =AB11 -> -0.078483828 | AM11: =AC11 -> -0.067382708 | AN11: =AD11 -> -0.30713781 | AR11: =A11 -> 39994 | AS11: =AF11*4+2 -> 109.20242 | AT11: =AH11 -> 0.94115568 | AU11: =SUM(AV11:BA11) -> -0.067641554 | AV11: =AI11 -> -0.004466267 | AW11: =AJ11 -> 0.25520858 | AX11: =AK11 -> 0.13462049 | AY11: =AL11 -> -0.078483828 | AZ11: =AM11 -> -0.067382708 | BA11: =AN11 -> -0.30713781 | BC11: =AR11 -> 39994 | BD11: =AT11-$AT$2 -> -1.6337335 | BE11: =AU11 -> -0.067641554
A12: 40086 | B12: 2.4217085 | C12: -2.0203722 | D12: -5.5802494 | E12: -0.0013006478 | F12: 7.1417549 | G12: 17.135333 | H12: -0.0426744 | I12: 0.322457 | J12: -0.056528372 | K12: 7.9652821 | L12: -1.4766757 | M12: 0 | N12: 0 | O12: 0.60460848 | P12: 0 | Q12: 0.00073509913 | R12: 0 | S12: 0 | T12: 0 | U12: 0 | V12: 0 | W12: 0 | X12: 0 | Y12: -6.6481835 | Z12: 0.43002849 | AA12: 0.11092325 | AB12: -0.16598199 | AC12: -0.11796388 | AD12: -0.56485065 | AE12: 7.2408652 | AF12: 26.698915 | AH12: =K12+Y12-Y12/100 -> 1.3835804 | AI12: =Y12/1010 -> -0.0065823599 | AJ12: =Z12 -> 0.43002849 | AK12: =AA12 -> 0.11092325 | AL12: =AB12 -> -0.16598199 | AM12: =AC12 -> -0.11796388 | AN12: =AD12 -> -0.56485065 | AR12: =A12 -> 40086 | AS12: =AF12*4+2 -> 108.79566 | AT12: =AH12 -> 1.3835804 | AU12: =SUM(AV12:BA12) -> -0.31442715 | AV12: =AI12 -> -0.0065823599 | AW12: =AJ12 -> 0.43002849 | AX12: =AK12 -> 0.11092325 | AY12: =AL12 -> -0.16598199 | AZ12: =AM12 -> -0.11796388 | BA12: =AN12 -> -0.56485065 | BC12: =AR12 -> 40086 | BD12: =AT12-$AT$2 -> -1.1913087 | BE12: =AU12 -> -0.31442715
A13: 40178 | B13: 2.0701525 | C13: -1.9632677 | D13: -4.963927 | E13: -0.00080920876 | F13: 6.7932403 | G13: 17.165547 | H13: 0.018838774 | I13: 0.252927 | J13: -0.046777776 | K13: 9.6680861 | L13: -1.4944411 | M13: 0 | N13: 0 | O13: 0.61475522 | P13: 0 | Q13: -0.017101425 | R13: 0 | S13: 0 | T13: 0 | U13: 0 | V13: 0 | W13: 0 | X13: 0 | Y13: -8.2298802 | Z13: 0.64538339 | AA13: 0.075587373 | AB13: -0.24389615 | AC13: -0.13783327 | AD13: -0.86962231 | AE13: 7.2185815 | AF13: 26.555543 | AH13: =K13+Y13-Y13/100 -> 1.5205047 | AI13: =Y13/1010 -> -0.0081483962 | AJ13: =Z13 -> 0.64538339 | AK13: =AA13 -> 0.075587373 | AL13: =AB13 -> -0.24389615 | AM13: =AC13 -> -0.13783327 | AN13: =AD13 -> -0.86962231 | AR13: =A13 -> 40178 | AS13: =AF13*4+2 -> 108.22217 | AT13: =AH13 -> 1.5205047 | AU13: =SUM(AV13:BA13) -> -0.53852936 | AV13: =AI13 -> -0.0081483962 | AW13: =AJ13 -> 0.64538339 | AX13: =AK13 -> 0.075587373 | AY13: =AL13 -> -0.24389615 | AZ13: =AM13 -> -0.13783327 | BA13: =AN13 -> -0.86962231 | BC13: =AR13 -> 40178 | BD13: =AT13-$AT$2 -> -1.0543844 | BE13: =AU13 -> -0.53852936
A14: 40268 | B14: 1.9292619 | C14: -1.9152574 | D14: -4.6209409 | E14: -9.3285765e-05 | F14: 6.2885873 | G14: 17.194811 | H14: -0.0097242431 | I14: 0.24468576 | J14: -0.033630541 | K14: 11.391705 | L14: -1.5295778 | M14: 0 | N14: 0 | O14: 0.62748077 | P14: 0 | Q14: -0.021055782 | R14: 0 | S14: 0 | T14: 0 | U14: 0 | V14: 0 | W14: 0 | X14: 0 | Y14: -9.2842199 | Z14: 0.93375033 | AA14: 0.13528553 | AB14: -0.26251041 | AC14: -0.11896933 | AD14: -1.185558 | AE14: 7.1963798 | AF14: 26.96041 | AH14: =K14+Y14-Y14/100 -> 2.2003272 | AI14: =Y14/1010 -> -0.0091922969 | AJ14: =Z14 -> 0.93375033 | AK14: =AA14 -> 0.13528553 | AL14: =AB14 -> -0.26251041 | AM14: =AC14 -> -0.11896933 | AN14: =AD14 -> -1.185558 | AR14: =A14 -> 40268 | AS14: =AF14*4+2 -> 109.84164 | AT14: =AH14 -> 2.2003272 | AU14: =SUM(AV14:BA14) -> -0.50719413 | AV14: =AI14 -> -0.0091922969 | AW14: =AJ14 -> 0.93375033 | AX14: =AK14 -> 0.13528553 | AY14: =AL14 -> -0.26251041 | AZ14: =AM14 -> -0.11896933 | BA14: =AN14 -> -1.185558 | BC14: =AR14 -> 40268 | BD14: =AT14-$AT$2 -> -0.37456194 | BE14: =AU14 -> -0.50719413
A15: 40359 | B15: 1.7114594 | C15: -1.7910189 | D15: -4.417112 | E15: -0.00034034385 | F15: 5.508496 | G15: 17.284895 | H15: 0.036125033 | I15: 0.25452995 | J15: -0.025443457 | K15: 12.624267 | L15: -1.4630845 | M15: 0 | N15: 0 | O15: 0.64041987 | P15: 0 | Q15: -0.024373029 | R15: 0 | S15: 0 | T15: 0 | U15: 0 | V15: 0 | W15: 0 | X15: 0 | Y15: -10.235004 | Z15: 1.2587611 | AA15: 0.30474392 | AB15: -0.17869597 | AC15: -0.03951587 | AD15: -1.4723622 | AE15: 7.1742596 | AF15: 27.151007 | AH15: =K15+Y15-Y15/100 -> 2.4916135 | AI15: =Y15/1010 -> -0.010133667 | AJ15: =Z15 -> 1.2587611 | AK15: =AA15 -> 0.30474392 | AL15: =AB15 -> -0.17869597 | AM15: =AC15 -> -0.03951587 | AN15: =AD15 -> -1.4723622 | AR15: =A15 -> 40359 | AS15: =AF15*4+2 -> 110.60403 | AT15: =AH15 -> 2.4916135 | AU15: =SUM(AV15:BA15) -> -0.13720259 | AV15: =AI15 -> -0.010133667 | AW15: =AJ15 -> 1.2587611 | AX15: =AK15 -> 0.30474392 | AY15: =AL15 -> -0.17869597 | AZ15: =AM15 -> -0.03951587 | BA15: =AN15 -> -1.4723622 | BC15: =AR15 -> 40359 | BD15: =AT15-$AT$2 -> -0.083275637 | BE15: =AU15 -> -0.13720259
A16: 40451 | B16: 1.6689236 | C16: -1.669287 | D16: -4.2631128 | E16: -0.00047472158 | F16: 5.3252985 | G16: 17.33458 | H16: 0.0056531455 | I16: 0.3395956 | J16: -0.01579766 | K16: 13.592728 | L16: -1.5563826 | M16: 0 | N16: 0 | O16: 0.65967139 | P16: 0 | Q16: -0.017203497 | R16: 0 | S16: 0 | T16: 0 | U16: 0 | V16: 0 | W16: 0 | X16: 0 | Y16: -11.450592 | Z16: 1.4891879 | AA16: 0.38887175 | AB16: -0.13286861 | AC16: 0.019233067 | AD16: -1.7498602 | AE16: 7.1522205 | AF16: 27.120385 | AH16: =K16+Y16-Y16/100 -> 2.2566424 | AI16: =Y16/1010 -> -0.011337219 | AJ16: =Z16 -> 1.4891879 | AK16: =AA16 -> 0.38887175 | AL16: =AB16 -> -0.13286861 | AM16: =AC16 -> 0.019233067 | AN16: =AD16 -> -1.7498602 | AR16: =A16 -> 40451 | AS16: =AF16*4+2 -> 110.48154 | AT16: =AH16 -> 2.2566424 | AU16: =SUM(AV16:BA16) -> 0.0032267014 | AV16: =AI16 -> -0.011337219 | AW16: =AJ16 -> 1.4891879 | AX16: =AK16 -> 0.38887175 | AY16: =AL16 -> -0.13286861 | AZ16: =AM16 -> 0.019233067 | BA16: =AN16 -> -1.7498602 | BC16: =AR16 -> 40451 | BD16: =AT16-$AT$2 -> -0.3182467 | BE16: =AU16 -> 0.0032267014
A17: 40543 | B17: 1.3754459 | C17: -1.4731984 | D17: -4.3372803 | E17: -0.00016910156 | F17: 6.0283243 | G17: 17.375538 | H17: -0.03695678 | I17: 0.26961923 | J17: -0.0084062676 | K17: 14.927038 | L17: -1.5514464 | M17: 0 | N17: 0 | O17: 0.6729625 | P17: 0 | Q17: -0.010960892 | R17: 0 | S17: 0 | T17: 0 | U17: 0 | V17: 0 | W17: 0 | X17: 0 | Y17: -13.193123 | Z17: 1.6728789 | AA17: 0.4341946 | AB17: -0.11512471 | AC17: 0.031882889 | AD17: -2.0389967 | AE17: 7.1302619 | AF17: 27.152484 | AH17: =K17+Y17-Y17/100 -> 1.8658466 | AI17: =Y17/1010 -> -0.013062498 | AJ17: =Z17 -> 1.6728789 | AK17: =AA17 -> 0.4341946 | AL17: =AB17 -> -0.11512471 | AM17: =AC17 -> 0.031882889 | AN17: =AD17 -> -2.0389967 | AR17: =A17 -> 40543 | AS17: =AF17*4+2 -> 110.60994 | AT17: =AH17 -> 1.8658466 | AU17: =SUM(AV17:BA17) -> -0.028227444 | AV17: =AI17 -> -0.013062498 | AW17: =AJ17 -> 1.6728789 | AX17: =AK17 -> 0.4341946 | AY17: =AL17 -> -0.11512471 | AZ17: =AM17 -> 0.031882889 | BA17: =AN17 -> -2.0389967 | BC17: =AR17 -> 40543 | BD17: =AT17-$AT$2 -> -0.70904253 | BE17: =AU17 -> -0.028227444
A18: 40633 | B18: 1.9043017 | C18: -1.5433038 | D18: -4.5069513 | E18: -0.0012869151 | F18: 7.4268885 | G18: 17.45478 | H18: -0.036961388 | I18: 0.30813711 | J18: -0.0078414583 | K18: 16.675365 | L18: -1.4894906 | M18: 0 | N18: 0 | O18: 0.69313123 | P18: 0 | Q18: -0.023400021 | R18: 0 | S18: 0 | T18: 0 | U18: 0 | V18: 0 | W18: 0 | X18: 0 | Y18: -15.514005 | Z18: 1.6560904 | AA18: 0.29727136 | AB18: -0.20292069 | AC18: -0.027254571 | AD18: -2.3847288 | AE18: 7.1083835 | AF18: 27.786204 | AH18: =K18+Y18-Y18/100 -> 1.3164998 | AI18: =Y18/1010 -> -0.015360401 | AJ18: =Z18 -> 1.6560904 | AK18: =AA18 -> 0.29727136 | AL18: =AB18 -> -0.20292069 | AM18: =AC18 -> -0.027254571 | AN18: =AD18 -> -2.3847288 | AR18: =A18 -> 40633 | AS18: =AF18*4+2 -> 113.14482 | AT18: =AH18 -> 1.3164998 | AU18: =SUM(AV18:BA18) -> -0.67690276 | AV18: =AI18 -> -0.015360401 | AW18: =AJ18 -> 1.6560904 | AX18: =AK18 -> 0.29727136 | AY18: =AL18 -> -0.20292069 | AZ18: =AM18 -> -0.027254571 | BA18: =AN18 -> -2.3847288 | BC18: =AR18 -> 40633 | BD18: =AT18-$AT$2 -> -1.2583893 | BE18: =AU18 -> -0.67690276
A19: 40724 | B19: 1.467808 | C19: -1.2043497 | D19: -4.3924235 | E19: -0.0010583469 | F19: 8.406255 | G19: 17.546427 | H19: 0.07324742 | I19: 0.30268883 | J19: -0.0051230818 | K19: 18.729266 | L19: -1.555679 | M19: 0 | N19: 0 | O19: 0.71288761 | P19: 0 | Q19: -0.035226888 | R19: 0 | S19: 0 | T19: 0 | U19: 0 | V19: 0 | W19: 0 | X19: 0 | Y19: -18.615704 | Z19: 1.7520007 | AA19: 0.18453734 | AB19: -0.23254533 | AC19: -0.029947737 | AD19: -2.709168 | AE19: 7.0865847 | AF19: 27.480477 | AH19: =K19+Y19-Y19/100 -> 0.29971978 | AI19: =Y19/1010 -> -0.01843139 | AJ19: =Z19 -> 1.7520007 | AK19: =AA19 -> 0.18453734 | AL19: =AB19 -> -0.23254533 | AM19: =AC19 -> -0.029947737 | AN19: =AD19 -> -2.709168 | AR19: =A19 -> 40724 | AS19: =AF19*4+2 -> 111.92191 | AT19: =AH19 -> 0.29971978 | AU19: =SUM(AV19:BA19) -> -1.0535544 | AV19: =AI19 -> -0.01843139 | AW19: =AJ19 -> 1.7520007 | AX19: =AK19 -> 0.18453734 | AY19: =AL19 -> -0.23254533 | AZ19: =AM19 -> -0.029947737 | BA19: =AN19 -> -2.709168 | BC19: =AR19 -> 40724 | BD19: =AT19-$AT$2 -> -2.2751694 | BE19: =AU19 -> -1.0535544
A20: 40816 | B20: 1.8241286 | C20: -1.0959542 | D20: -4.2580249 | E20: -0.00028471595 | F20: 6.5846466 | G20: 17.671886 | H20: -0.047348455 | I20: 0.34776192 | J20: 0.0012598254 | K20: 21.668795 | L20: -1.6269307 | M20: 0 | N20: 0 | O20: 0.72603408 | P20: 0 | Q20: -0.021518547 | R20: 0 | S20: 0 | T20: 0 | U20: 0 | V20: 0 | W20: 0 | X20: 0 | Y20: -21.294037 | Z20: 2.3087563 | AA20: 0.35473861 | AB20: -0.080751504 | AC20: 0.099261868 | AD20: -2.8984711 | AE20: 7.0648651 | AF20: 27.328812 | AH20: =K20+Y20-Y20/100 -> 0.58769775 | AI20: =Y20/1010 -> -0.021083205 | AJ20: =Z20 -> 2.3087563 | AK20: =AA20 -> 0.35473861 | AL20: =AB20 -> -0.080751504 | AM20: =AC20 -> 0.099261868 | AN20: =AD20 -> -2.8984711 | AR20: =A20 -> 40816 | AS20: =AF20*4+2 -> 111.31525 | AT20: =AH20 -> 0.58769775 | AU20: =SUM(AV20:BA20) -> -0.23754899 | AV20: =AI20 -> -0.021083205 | AW20: =AJ20 -> 2.3087563 | AX20: =AK20 -> 0.35473861 | AY20: =AL20 -> -0.080751504 | AZ20: =AM20 -> 0.099261868 | BA20: =AN20 -> -2.8984711 | BC20: =AR20 -> 40816 | BD20: =AT20-$AT$2 -> -1.9871914 | BE20: =AU20 -> -0.23754899
... A132: 51043 | B132: -0.043141873 | C132: -0.00014191675 | D132: -0.060150045 | E132: 0.00016375639 | F132: 0.077003819 | G132: -0.017761409 | H132: 0.10657899 | I132: -0.12938709 | J132: -0.23383062 | K132: -0.0013647494 | L132: 0.028622522 | M132: 0 | N132: 0 | O132: 0.44750605 | P132: 0 | Q132: 0.30446726 | R132: 0 | S132: 0 | T132: 0 | U132: 0 | V132: 0 | W132: 0 | X132: 0 | Y132: 0.0014171204 | Z132: -0.0014470184 | AA132: 0.00054189822 | AB132: -0.00029329794 | AC132: 0.0013717805 | AD132: 0.0037302372 | AE132: -0.072867892 | AF132: 0.418171 | AH132: =K132+Y132-Y132/100 -> 3.8199787e-05 | AI132: =Y132/1010 -> 1.4030895e-06 | AJ132: =Z132 -> -0.0014470184 | AK132: =AA132 -> 0.00054189822 | AL132: =AB132 -> -0.00029329794 | AM132: =AC132 -> 0.0013717805 | AN132: =AD132 -> 0.0037302372 | AR132: =A132 -> 51043 | AS132: =AF132*4+2 -> 3.672684 | AT132: =AH132 -> 3.8199787e-05 | AU132: =SUM(AV132:BA132) -> 0.0039050027 | AV132: =AI132 -> 1.4030895e-06 | AW132: =AJ132 -> -0.0014470184 | AX132: =AK132 -> 0.00054189822 | AY132: =AL132 -> -0.00029329794 | AZ132: =AM132 -> 0.0013717805 | BA132: =AN132 -> 0.0037302372 | BC132: =AR132 -> 51043 | BD132: =AT132-$AT$2 -> -2.5748509 | BE132: =AU132 -> 0.0039050027

Sheet EA_output_policy
A1: date | B1: g_sh | C1: b_liqtil_sh | D1: b_liqp_sh | E1: b_safetil_sh | F1: b_safep_sh | G1: mu_sh | H1: z_sh | I1: lambda_f_sh | J1: lambda_w_sh | K1: rm_sh | L1: sigma_omega_sh | M1: mu_e_sh | N1: gamma_sh | O1: pi_star_sh | P1: lr_sh | Q1: zp_sh | R1: tfp_sh | S1: gdpdef_sh | T1: corepce_sh | U1: gdp_sh | V1: gdi_sh | W1: BBB_sh | X1: AAA_sh | Y1: rm_shl1 | Z1: rm_shl2 | AA1: rm_shl3 | AB1: rm_shl4 | AC1: rm_shl5 | AD1: rm_shl6 | AE1: dettrend | AF1: detrendedMean | AH1: rm_sh | AI1: =Y1 -> rm_shl1 | AJ1: =Z1 -> rm_shl2 | AK1: =AA1 -> rm_shl3 | AL1: =AB1 -> rm_shl4 | AM1: =AC1 -> rm_shl5 | AN1: =AD1 -> rm_shl6 | AQ1: Plot | AR1: =A1 -> date | AS1: =AF1 -> detrendedMean | AT1: Monetary Policy | AU1: Fgsum | AV1: FG1 | AW1: FG2 | AX1: FG3 | AY1: FG4 | AZ1: FG5 | BA1: FG6 | BC1: date | BD1: rm_sh | BE1: Fgsum
A2: 39172 | B2: 2.5363082 | C2: -0.18049422 | D2: -5.026568 | E2: -0.00051095038 | F2: 6.5669289 | G2: 14.167348 | H2: -0.028136165 | I2: 0.24489409 | J2: -0.05757504 | K2: 2.5748891 | L2: 0.26640205 | M2: 0 | N2: 0 | O2: 0.43018806 | P2: 0 | Q2: -0.017234495 | R2: 0 | S2: 0 | T2: 0 | U2: 0 | V2: 0 | W2: 0 | X2: 0 | Y2: 0 | Z2: 0 | AA2: 0 | AB2: 0 | AC2: 0 | AD2: 0 | AE2: 7.4683269 | AF2: 28.944766 | AH2: =K2+Y2-Y2/100 -> 2.5748891 | AI2: =Y2 -> 0 | AJ2: =Z2 -> 0 | AK2: =AA2 -> 0 | AL2: =AB2 -> 0 | AM2: =AC2 -> 0 | AN2: =AD2 -> 0 | AR2: =A2 -> 39172 | AS2: =AF2*4+2 -> 117.77907 | AT2: =AH2-$AH$2 -> 0 | AU2: =SUM(AV2:BA2) -> 0 | AV2: =AI2 -> 0 | AW2: =AJ2 -> 0 | AX2: =AK2 -> 0 | AY2: =AL2 -> 0 | AZ2: =AM2 -> 0 | BA2: =AN2 -> 0 | BC2: =AR2 -> 39172 | BD2: =AT2 -> 0 | BE2: =AU2 -> 0
A3: 39263 | B3: 2.1888377 | C3: -0.10201437 | D3: -5.4151599 | E3: 0.000432913 | F3: 7.4635098 | G3: 14.09681 | H3: -0.017718534 | I3: 0.23729294 | J3: -0.058482715 | K3: 2.6753132 | L3: 0.30577422 | M3: 0 | N3: 0 | O3: 0.44487798 | P3: 0 | Q3: -0.025392488 | R3: 0 | S3: 0 | T3: 0 | U3: 0 | V3: 0 | W3: 0 | X3: 0 | Y3: 0 | Z3: 0 | AA3: 0 | AB3: 0 | AC3: 0 | AD3: 0 | AE3: 7.445194 | AF3: 29.239275 | AH3: =K3+Y3-Y3/100 -> 2.6753132 | AI3: =Y3 -> 0 | AJ3: =Z3 -> 0 | AK3: =AA3 -> 0 | AL3: =AB3 -> 0 | AM3: =AC3 -> 0 | AN3: =AD3 -> 0 | AR3: =A3 -> 39263 | AS3: =AF3*4+2 -> 118.9571 | AT3: =AH3-$AH$2 -> 0.10042406 | AU3: =SUM(AV3:BA3) -> 0 | AV3: =AI3 -> 0 | AW3: =AJ3 -> 0 | AX3: =AK3 -> 0 | AY3: =AL3 -> 0 | AZ3: =AM3 -> 0 | BA3: =AN3 -> 0 | BC3: =AR3 -> 39263 | BD3: =AT3 -> 0.10042406 | BE3: =AU3 -> 0
A4: 39355 | B4: 2.3018784 | C4: -0.18582521 | D4: -5.7797078 | E4: -0.00024449342 | F4: 8.1065585 | G4: 14.1473 | H4: 0.0099248504 | I4: 0.31153154 | J4: -0.061960515 | K4: 2.506994 | L4: 0.30064004 | M4: 0 | N4: 0 | O4: 0.46631618 | P4: 0 | Q4: -0.040553603 | R4: 0 | S4: 0 | T4: 0 | U4: 0 | V4: 0 | W4: 0 | X4: 0 | Y4: 0 | Z4: 0 | AA4: 0 | AB4: 0 | AC4: 0 | AD4: 0 | AE4: 7.4221487 | AF4: 29.505 | AH4: =K4+Y4-Y4/100 -> 2.506994 | AI4: =Y4 -> 0 | AJ4: =Z4 -> 0 | AK4: =AA4 -> 0 | AL4: =AB4 -> 0 | AM4: =AC4 -> 0 | AN4: =AD4 -> 0 | AR4: =A4 -> 39355 | AS4: =AF4*4+2 -> 120.02 | AT4: =AH4-$AH$2 -> -0.067895149 | AU4: =SUM(AV4:BA4) -> 0 | AV4: =AI4 -> 0 | AW4: =AJ4 -> 0 | AX4: =AK4 -> 0 | AY4: =AL4 -> 0 | AZ4: =AM4 -> 0 | BA4: =AN4 -> 0 | BC4: =AR4 -> 39355 | BD4: =AT4 -> -0.067895149 | BE4: =AU4 -> 0
A5: 39447 | B5: 2.0031345 | C5: -0.059805901 | D5: -6.0906698 | E5: 0.00065881996 | F5: 8.5748649 | G5: 14.245587 | H5: 0.01546791 | I5: 0.248964 | J5: -0.063329388 | K5: 2.6392114 | L5: 0.34661216 | M5: 0 | N5: 0 | O5: 0.47709801 | P5: 0 | Q5: -0.045182361 | R5: 0 | S5: 0 | T5: 0 | U5: 0 | V5: 0 | W5: 0 | X5: 0 | Y5: 0 | Z5: 0 | AA5: 0 | AB5: 0 | AC5: 0 | AD5: 0 | AE5: 7.3991902 | AF5: 29.691802 | AH5: =K5+Y5-Y5/100 -> 2.6392114 | AI5: =Y5 -> 0 | AJ5: =Z5 -> 0 | AK5: =AA5 -> 0 | AL5: =AB5 -> 0 | AM5: =AC5 -> 0 | AN5: =AD5 -> 0 | AR5: =A5 -> 39447 | AS5: =AF5*4+2 -> 120.76721 | AT5: =AH5-$AH$2 -> 0.064322263 | AU5: =SUM(AV5:BA5) -> 0 | AV5: =AI5 -> 0 | AW5: =AJ5 -> 0 | AX5: =AK5 -> 0 | AY5: =AL5 -> 0 | AZ5: =AM5 -> 0 | BA5: =AN5 -> 0 | BC5: =AR5 -> 39447 | BD5: =AT5 -> 0.064322263 | BE5: =AU5 -> 0
A6: 39538 | B6: 2.0564368 | C6: -0.17410702 | D6: -6.2409237 | E6: -8.1488331e-05 | F6: 8.7254233 | G6: 14.470225 | H6: -0.053129904 | I6: 0.30778976 | J6: -0.066874845 | K6: 2.9688718 | L6: 0.14427824 | M6: 0 | N6: 0 | O6: 0.49713924 | P6: 0 | Q6: -0.050515251 | R6: 0 | S6: 0 | T6: 0 | U6: 0 | V6: 0 | W6: 0 | X6: 0 | Y6: 0 | Z6: 0 | AA6: 0 | AB6: 0 | AC6: 0 | AD6: 0 | AE6: 7.376318 | AF6: 29.96085 | AH6: =K6+Y6-Y6/100 -> 2.9688718 | AI6: =Y6 -> 0 | AJ6: =Z6 -> 0 | AK6: =AA6 -> 0 | AL6: =AB6 -> 0 | AM6: =AC6 -> 0 | AN6: =AD6 -> 0 | AR6: =A6 -> 39538 | AS6: =AF6*4+2 -> 121.8434 | AT6: =AH6-$AH$2 -> 0.39398266 | AU6: =SUM(AV6:BA6) -> 0 | AV6: =AI6 -> 0 | AW6: =AJ6 -> 0 | AX6: =AK6 -> 0 | AY6: =AL6 -> 0 | AZ6: =AM6 -> 0 | BA6: =AN6 -> 0 | BC6: =AR6 -> 39538 | BD6: =AT6 -> 0.39398266 | BE6: =AU6 -> 0
A7: 39629 | B7: 1.9437086 | C7: -0.25968328 | D7: -6.4409474 | E7: 0.00050280931 | F7: 9.1352305 | G7: 14.602996 | H7: -0.0028221986 | I7: 0.2461009 | J7: -0.063600816 | K7: 2.6992023 | L7: 0.031560885 | M7: 0 | N7: 0 | O7: 0.50964208 | P7: 0 | Q7: -0.07357073 | R7: 0 | S7: 0 | T7: 0 | U7: 0 | V7: 0 | W7: 0 | X7: 0 | Y7: 0 | Z7: 0 | AA7: 0 | AB7: 0 | AC7: 0 | AD7: 0 | AE7: 7.3535315 | AF7: 29.681851 | AH7: =K7+Y7-Y7/100 -> 2.6992023 | AI7: =Y7 -> 0 | AJ7: =Z7 -> 0 | AK7: =AA7 -> 0 | AL7: =AB7 -> 0 | AM7: =AC7 -> 0 | AN7: =AD7 -> 0 | AR7: =A7 -> 39629 | AS7: =AF7*4+2 -> 120.7274 | AT7: =AH7-$AH$2 -> 0.12431319 | AU7: =SUM(AV7:BA7) -> 0 | AV7: =AI7 -> 0 | AW7: =AJ7 -> 0 | AX7: =AK7 -> 0 | AY7: =AL7 -> 0 | AZ7: =AM7 -> 0 | BA7: =AN7 -> 0 | BC7: =AR7 -> 39629 | BD7: =AT7 -> 0.12431319 | BE7: =AU7 -> 0
A8: 39721 | B8: 1.5553725 | C8: -0.47264141 | D8: -6.5811779 | E8: 0.00045985532 | F8: 9.4802157 | G8: 14.927721 | H8: 0.027059605 | I8: 0.29587019 | J8: -0.068185466 | K8: 2.5210749 | L8: -0.16240357 | M8: 0 | N8: 0 | O8: 0.53344519 | P8: 0 | Q8: -0.081467541 | R8: 0 | S8: 0 | T8: 0 | U8: 0 | V8: 0 | W8: 0 | X8: 0 | Y8: 0 | Z8: 0 | AA8: 0 | AB8: 0 | AC8: 0 | AD8: 0 | AE8: 7.3308301 | AF8: 29.306173 | AH8: =K8+Y8-Y8/100 -> 2.5210749 | AI8: =Y8 -> 0 | AJ8: =Z8 -> 0 | AK8: =AA8 -> 0 | AL8: =AB8 -> 0 | AM8: =AC8 -> 0 | AN8: =AD8 -> 0 | AR8: =A8 -> 39721 | AS8: =AF8*4+2 -> 119.22469 | AT8: =AH8-$AH$2 -> -0.05381425 | AU8: =SUM(AV8:BA8) -> 0 | AV8: =AI8 -> 0 | AW8: =AJ8 -> 0 | AX8: =AK8 -> 0 | AY8: =AL8 -> 0 | AZ8: =AM8 -> 0 | BA8: =AN8 -> 0 | BC8: =AR8 -> 39721 | BD8: =AT8 -> -0.05381425 | BE8: =AU8 -> 0
A9: 39813 | B9: 2.2206634 | C9: -0.98689403 | D9: -6.9466266 | E9: -0.0002896115 | F9: 8.9449095 | G9: 15.944444 | H9: 0.11808668 | I9: 0.33695797 | J9: -0.065994594 | K9: 2.2587813 | L9: -0.68091049 | M9: 0 | N9: 0 | O9: 0.55671627 | P9: 0 | Q9: -0.073561543 | R9: 0 | S9: 0 | T9: 0 | U9: 0 | V9: 0 | W9: 0 | X9: 0 | Y9: 0.073690921 | Z9: -0.13359577 | AA9: 0.092384556 | AB9: -0.0071129062 | AC9: -0.014969052 | AD9: -0.028973438 | AE9: 7.3082133 | AF9: 28.91592 | AH9: =K9+Y9-Y9/100 -> 2.3317353 | AI9: =Y9/1010 -> 7.2961308e-05 | AJ9: =Z9 -> -0.13359577 | AK9: =AA9 -> 0.092384556 | AL9: =AB9 -> -0.0071129062 | AM9: =AC9 -> -0.014969052 | AN9: =AD9 -> -0.028973438 | AR9: =A9 -> 39813 | AS9: =AF9*4+2 -> 117.66368 | AT9: =AH9-$AH$2 -> -0.2431538 | AU9: =SUM(AV9:BA9) -> -0.092193645 | AV9: =AI9 -> 7.2961308e-05 | AW9: =AJ9 -> -0.13359577 | AX9: =AK9 -> 0.092384556 | AY9: =AL9 -> -0.0071129062 | AZ9: =AM9 -> -0.014969052 | BA9: =AN9 -> -0.028973438 | BC9: =AR9 -> 39813 | BD9: =AT9 -> -0.2431538 | BE9: =AU9 -> -0.092193645
A10: 39903 | B10: 2.4024061 | C10: -1.2606797 | D10: -6.8199197 | E10: -0.0001738059 | F10: 8.6027343 | G10: 16.652521 | H10: 0.06749249 | I10: 0.27634318 | J10: -0.060941639 | K10: 2.7785999 | L10: -1.1798196 | M10: 0 | N10: 0 | O10: 0.57206768 | P10: 0 | Q10: -0.025279014 | R10: 0 | S10: 0 | T10: 0 | U10: 0 | V10: 0 | W10: 0 | X10: 0 | Y10: -1.7973575 | Z10: 0.013721478 | AA10: 0.12529789 | AB10: -0.030395868 | AC10: -0.051108838 | AD10: -0.13660702 | AE10: 7.2856806 | AF10: 27.414582 | AH10: =K10+Y10-Y10/100 -> 0.99921591 | AI10: =Y10/1010 -> -0.0017795619 | AJ10: =Z10 -> 0.013721478 | AK10: =AA10 -> 0.12529789 | AL10: =AB10 -> -0.030395868 | AM10: =AC10 -> -0.051108838 | AN10: =AD10 -> -0.13660702 | AR10: =A10 -> 39903 | AS10: =AF10*4+2 -> 111.65833 | AT10: =AH10-$AH$2 -> -1.5756732 | AU10: =SUM(AV10:BA10) -> -0.080871912 | AV10: =AI10 -> -0.0017795619 | AW10: =AJ10 -> 0.013721478 | AX10: =AK10 -> 0.12529789 | AY10: =AL10 -> -0.030395868 | AZ10: =AM10 -> -0.051108838 | BA10: =AN10 -> -0.13660702 | BC10: =AR10 -> 39903 | BD10: =AT10 -> -1.5756732 | BE10: =AU10 -> -0.080871912
A11: 39994 | B11: 2.4277616 | C11: -1.6490085 | D11: -6.3861468 | E11: -0.00049595052 | F11: 7.9593532 | G11: 17.059181 | H11: -0.089907165 | I11: 0.25785819 | J11: -0.059151639 | K11: 5.406976 | L11: -1.4181606 | M11: 0 | N11: 0 | O11: 0.58667403 | P11: 0 | Q11: 0.016546462 | R11: 0 | S11: 0 | T11: 0 | U11: 0 | V11: 0 | W11: 0 | X11: 0 | Y11: -4.5109297 | Z11: 0.25520858 | AA11: 0.13462049 | AB11: -0.078483828 | AC11: -0.067382708 | AD11: -0.30713781 | AE11: 7.2632314 | AF11: 26.800606 | AH11: =K11+Y11-Y11/100 -> 0.94115568 | AI11: =Y11/1010 -> -0.004466267 | AJ11: =Z11 -> 0.25520858 | AK11: =AA11 -> 0.13462049 | AL11: =AB11 -> -0.078483828 | AM11: =AC11 -> -0.067382708 | AN11: =AD11 -> -0.30713781 | AR11: =A11 -> 39994 | AS11: =AF11*4+2 -> 109.20242 | AT11: =AH11-$AH$2 -> -1.6337335 | AU11: =SUM(AV11:BA11) -> -0.067641554 | AV11: =AI11 -> -0.004466267 | AW11: =AJ11 -> 0.25520858 | AX11: =AK11 -> 0.13462049 | AY11: =AL11 -> -0.078483828 | AZ11: =AM11 -> -0.067382708 | BA11: =AN11 -> -0.30713781 | BC11: =AR11 -> 39994 | BD11: =AT11 -> -1.6337335 | BE11: =AU11 -> -0.067641554
A12: 40086 | B12: 2.4217085 | C12: -2.0203722 | D12: -5.5802494 | E12: -0.0013006478 | F12: 7.1417549 | G12: 17.135333 | H12: -0.0426744 | I12: 0.322457 | J12: -0.056528372 | K12: 7.9652821 | L12: -1.4766757 | M12: 0 | N12: 0 | O12: 0.60460848 | P12: 0 | Q12: 0.00073509913 | R12: 0 | S12: 0 | T12: 0 | U12: 0 | V12: 0 | W12: 0 | X12: 0 | Y12: -6.6481835 | Z12: 0.43002849 | AA12: 0.11092325 | AB12: -0.16598199 | AC12: -0.11796388 | AD12: -0.56485065 | AE12: 7.2408652 | AF12: 26.698915 | AH12: =K12+Y12-Y12/100 -> 1.3835804 | AI12: =Y12/1010 -> -0.0065823599 | AJ12: =Z12 -> 0.43002849 | AK12: =AA12 -> 0.11092325 | AL12: =AB12 -> -0.16598199 | AM12: =AC12 -> -0.11796388 | AN12: =AD12 -> -0.56485065 | AR12: =A12 -> 40086 | AS12: =AF12*4+2 -> 108.79566 | AT12: =AH12-$AH$2 -> -1.1913087 | AU12: =SUM(AV12:BA12) -> -0.31442715 | AV12: =AI12 -> -0.0065823599 | AW12: =AJ12 -> 0.43002849 | AX12: =AK12 -> 0.11092325 | AY12: =AL12 -> -0.16598199 | AZ12: =AM12 -> -0.11796388 | BA12: =AN12 -> -0.56485065 | BC12: =AR12 -> 40086 | BD12: =AT12 -> -1.1913087 | BE12: =AU12 -> -0.31442715
A13: 40178 | B13: 2.0701525 | C13: -1.9632677 | D13: -4.963927 | E13: -0.00080920876 | F13: 6.7932403 | G13: 17.165547 | H13: 0.018838774 | I13: 0.252927 | J13: -0.046777776 | K13: 9.6680861 | L13: -1.4944411 | M13: 0 | N13: 0 | O13: 0.61475522 | P13: 0 | Q13: -0.017101425 | R13: 0 | S13: 0 | T13: 0 | U13: 0 | V13: 0 | W13: 0 | X13: 0 | Y13: -8.2298802 | Z13: 0.64538339 | AA13: 0.075587373 | AB13: -0.24389615 | AC13: -0.13783327 | AD13: -0.86962231 | AE13: 7.2185815 | AF13: 26.555543 | AH13: =K13+Y13-Y13/100 -> 1.5205047 | AI13: =Y13/1010 -> -0.0081483962 | AJ13: =Z13 -> 0.64538339 | AK13: =AA13 -> 0.075587373 | AL13: =AB13 -> -0.24389615 | AM13: =AC13 -> -0.13783327 | AN13: =AD13 -> -0.86962231 | AR13: =A13 -> 40178 | AS13: =AF13*4+2 -> 108.22217 | AT13: =AH13-$AH$2 -> -1.0543844 | AU13: =SUM(AV13:BA13) -> -0.53852936 | AV13: =AI13 -> -0.0081483962 | AW13: =AJ13 -> 0.64538339 | AX13: =AK13 -> 0.075587373 | AY13: =AL13 -> -0.24389615 | AZ13: =AM13 -> -0.13783327 | BA13: =AN13 -> -0.86962231 | BC13: =AR13 -> 40178 | BD13: =AT13 -> -1.0543844 | BE13: =AU13 -> -0.53852936
A14: 40268 | B14: 1.9292619 | C14: -1.9152574 | D14: -4.6209409 | E14: -9.3285765e-05 | F14: 6.2885873 | G14: 17.194811 | H14: -0.0097242431 | I14: 0.24468576 | J14: -0.033630541 | K14: 11.391705 | L14: -1.5295778 | M14: 0 | N14: 0 | O14: 0.62748077 | P14: 0 | Q14: -0.021055782 | R14: 0 | S14: 0 | T14: 0 | U14: 0 | V14: 0 | W14: 0 | X14: 0 | Y14: -9.2842199 | Z14: 0.93375033 | AA14: 0.13528553 | AB14: -0.26251041 | AC14: -0.11896933 | AD14: -1.185558 | AE14: 7.1963798 | AF14: 26.96041 | AH14: =K14+Y14-Y14/100 -> 2.2003272 | AI14: =Y14/1010 -> -0.0091922969 | AJ14: =Z14 -> 0.93375033 | AK14: =AA14 -> 0.13528553 | AL14: =AB14 -> -0.26251041 | AM14: =AC14 -> -0.11896933 | AN14: =AD14 -> -1.185558 | AR14: =A14 -> 40268 | AS14: =AF14*4+2 -> 109.84164 | AT14: =AH14-$AH$2 -> -0.37456194 | AU14: =SUM(AV14:BA14) -> -0.50719413 | AV14: =AI14 -> -0.0091922969 | AW14: =AJ14 -> 0.93375033 | AX14: =AK14 -> 0.13528553 | AY14: =AL14 -> -0.26251041 | AZ14: =AM14 -> -0.11896933 | BA14: =AN14 -> -1.185558 | BC14: =AR14 -> 40268 | BD14: =AT14 -> -0.37456194 | BE14: =AU14 -> -0.50719413
A15: 40359 | B15: 1.7114594 | C15: -1.7910189 | D15: -4.417112 | E15: -0.00034034385 | F15: 5.508496 | G15: 17.284895 | H15: 0.036125033 | I15: 0.25452995 | J15: -0.025443457 | K15: 12.624267 | L15: -1.4630845 | M15: 0 | N15: 0 | O15: 0.64041987 | P15: 0 | Q15: -0.024373029 | R15: 0 | S15: 0 | T15: 0 | U15: 0 | V15: 0 | W15: 0 | X15: 0 | Y15: -10.235004 | Z15: 1.2587611 | AA15: 0.30474392 | AB15: -0.17869597 | AC15: -0.03951587 | AD15: -1.4723622 | AE15: 7.1742596 | AF15: 27.151007 | AH15: =K15+Y15-Y15/100 -> 2.4916135 | AI15: =Y15/1010 -> -0.010133667 | AJ15: =Z15 -> 1.2587611 | AK15: =AA15 -> 0.30474392 | AL15: =AB15 -> -0.17869597 | AM15: =AC15 -> -0.03951587 | AN15: =AD15 -> -1.4723622 | AR15: =A15 -> 40359 | AS15: =AF15*4+2 -> 110.60403 | AT15: =AH15-$AH$2 -> -0.083275637 | AU15: =SUM(AV15:BA15) -> -0.13720259 | AV15: =AI15 -> -0.010133667 | AW15: =AJ15 -> 1.2587611 | AX15: =AK15 -> 0.30474392 | AY15: =AL15 -> -0.17869597 | AZ15: =AM15 -> -0.03951587 | BA15: =AN15 -> -1.4723622 | BC15: =AR15 -> 40359 | BD15: =AT15 -> -0.083275637 | BE15: =AU15 -> -0.13720259
A16: 40451 | B16: 1.6689236 | C16: -1.669287 | D16: -4.2631128 | E16: -0.00047472158 | F16: 5.3252985 | G16: 17.33458 | H16: 0.0056531455 | I16: 0.3395956 | J16: -0.01579766 | K16: 13.592728 | L16: -1.5563826 | M16: 0 | N16: 0 | O16: 0.65967139 | P16: 0 | Q16: -0.017203497 | R16: 0 | S16: 0 | T16: 0 | U16: 0 | V16: 0 | W16: 0 | X16: 0 | Y16: -11.450592 | Z16: 1.4891879 | AA16: 0.38887175 | AB16: -0.13286861 | AC16: 0.019233067 | AD16: -1.7498602 | AE16: 7.1522205 | AF16: 27.120385 | AH16: =K16+Y16-Y16/100 -> 2.2566424 | AI16: =Y16/1010 -> -0.011337219 | AJ16: =Z16 -> 1.4891879 | AK16: =AA16 -> 0.38887175 | AL16: =AB16 -> -0.13286861 | AM16: =AC16 -> 0.019233067 | AN16: =AD16 -> -1.7498602 | AR16: =A16 -> 40451 | AS16: =AF16*4+2 -> 110.48154 | AT16: =AH16-$AH$2 -> -0.3182467 | AU16: =SUM(AV16:BA16) -> 0.0032267014 | AV16: =AI16 -> -0.011337219 | AW16: =AJ16 -> 1.4891879 | AX16: =AK16 -> 0.38887175 | AY16: =AL16 -> -0.13286861 | AZ16: =AM16 -> 0.019233067 | BA16: =AN16 -> -1.7498602 | BC16: =AR16 -> 40451 | BD16: =AT16 -> -0.3182467 | BE16: =AU16 -> 0.0032267014
A17: 40543 | B17: 1.3754459 | C17: -1.4731984 | D17: -4.3372803 | E17: -0.00016910156 | F17: 6.0283243 | G17: 17.375538 | H17: -0.03695678 | I17: 0.26961923 | J17: -0.0084062676 | K17: 14.927038 | L17: -1.5514464 | M17: 0 | N17: 0 | O17: 0.6729625 | P17: 0 | Q17: -0.010960892 | R17: 0 | S17: 0 | T17: 0 | U17: 0 | V17: 0 | W17: 0 | X17: 0 | Y17: -13.193123 | Z17: 1.6728789 | AA17: 0.4341946 | AB17: -0.11512471 | AC17: 0.031882889 | AD17: -2.0389967 | AE17: 7.1302619 | AF17: 27.152484 | AH17: =K17+Y17-Y17/100 -> 1.8658466 | AI17: =Y17/1010 -> -0.013062498 | AJ17: =Z17 -> 1.6728789 | AK17: =AA17 -> 0.4341946 | AL17: =AB17 -> -0.11512471 | AM17: =AC17 -> 0.031882889 | AN17: =AD17 -> -2.0389967 | AR17: =A17 -> 40543 | AS17: =AF17*4+2 -> 110.60994 | AT17: =AH17-$AH$2 -> -0.70904253 | AU17: =SUM(AV17:BA17) -> -0.028227444 | AV17: =AI17 -> -0.013062498 | AW17: =AJ17 -> 1.6728789 | AX17: =AK17 -> 0.4341946 | AY17: =AL17 -> -0.11512471 | AZ17: =AM17 -> 0.031882889 | BA17: =AN17 -> -2.0389967 | BC17: =AR17 -> 40543 | BD17: =AT17 -> -0.70904253 | BE17: =AU17 -> -0.028227444
A18: 40633 | B18: 1.9043017 | C18: -1.5433038 | D18: -4.5069513 | E18: -0.0012869151 | F18: 7.4268885 | G18: 17.45478 | H18: -0.036961388 | I18: 0.30813711 | J18: -0.0078414583 | K18: 16.675365 | L18: -1.4894906 | M18: 0 | N18: 0 | O18: 0.69313123 | P18: 0 | Q18: -0.023400021 | R18: 0 | S18: 0 | T18: 0 | U18: 0 | V18: 0 | W18: 0 | X18: 0 | Y18: -15.514005 | Z18: 1.6560904 | AA18: 0.29727136 | AB18: -0.20292069 | AC18: -0.027254571 | AD18: -2.3847288 | AE18: 7.1083835 | AF18: 27.786204 | AH18: =K18+Y18-Y18/100 -> 1.3164998 | AI18: =Y18/1010 -> -0.015360401 | AJ18: =Z18 -> 1.6560904 | AK18: =AA18 -> 0.29727136 | AL18: =AB18 -> -0.20292069 | AM18: =AC18 -> -0.027254571 | AN18: =AD18 -> -2.3847288 | AR18: =A18 -> 40633 | AS18: =AF18*4+2 -> 113.14482 | AT18: =AH18-$AH$2 -> -1.2583893 | AU18: =SUM(AV18:BA18) -> -0.67690276 | AV18: =AI18 -> -0.015360401 | AW18: =AJ18 -> 1.6560904 | AX18: =AK18 -> 0.29727136 | AY18: =AL18 -> -0.20292069 | AZ18: =AM18 -> -0.027254571 | BA18: =AN18 -> -2.3847288 | BC18: =AR18 -> 40633 | BD18: =AT18 -> -1.2583893 | BE18: =AU18 -> -0.67690276
