Workbook
Name BoxPlot: "BoxPlot"
Name Bubble: "Bubble"
Name Candlestick: "Candlestick"
Name Chart: "Chart"
Name ChartImage: "ChartImage"
Name ColumnRange: "ColumnRange"
Name Dumbbell: "Dumbbell"
Name Heatmap: "Heatmap"
Name Histogram: "Histogram"
Name Map: "Map"
Name OHLC: "OHLC"
Name PieChart: "PieChart"
Name Scatter: "Scatter"
Name Series: "Series"
Name Stripe: "Stripe"
Name Table: "Table"
Name TreeMap: "TreeMap"
Name Waterfall: "Waterfall"

Sheet All Chart

Sheet EA_output_policy
A1: date | B1: g_sh | C1: b_liqtil_sh | D1: b_liqp_sh | E1: b_safetil_sh | F1: b_safep_sh | G1: mu_sh | H1: z_sh | I1: lambda_f_sh | J1: lambda_w_sh | K1: rm_sh | L1: sigma_omega_sh | M1: mu_e_sh | N1: gamma_sh | O1: pi_star_sh | P1: lr_sh | Q1: zp_sh | R1: tfp_sh | S1: gdpdef_sh | T1: corepce_sh | U1: gdp_sh | V1: gdi_sh | W1: BBB_sh | X1: AAA_sh | Y1: rm_shl1 | Z1: rm_shl2 | AA1: rm_shl3 | AB1: rm_shl4 | AC1: rm_shl5 | AD1: rm_shl6 | AE1: dettrend | AF1: detrendedMean | AH1: rm_sh | AI1: =Y1 -> rm_shl1 | AJ1: =Z1 -> rm_shl2 | AK1: =AA1 -> rm_shl3 | AL1: =AB1 -> rm_shl4 | AM1: =AC1 -> rm_shl5 | AN1: =AD1 -> rm_shl6 | AQ1: Plot | AR1: =A1 -> date | AS1: =AF1 -> detrendedMean | AT1: Monetary Policy | AU1: Fgsum | AV1: FG1 | AW1: FG2 | AX1: FG3 | AY1: FG4 | AZ1: FG5 | BA1: FG6 | BC1: date | BD1: rm_sh | BE1: Fgsum
A2: 39172 | B2: 2.5363082 | C2: -0.18049422 | D2: -5.026568 | E2: -0.00051095038 | F2: 6.5669289 | G2: 14.167348 | H2: -0.028136165 | I2: 0.24489409 | J2: -0.05757504 | K2: 2.5748891 | L2: 0.26640205 | M2: 0 | N2: 0 | O2: 0.43018806 | P2: 0 | Q2: -0.017234495 | R2: 0 | S2: 0 | T2: 0 | U2: 0 | V2: 0 | W2: 0 | X2: 0 | Y2: 0 | Z2: 0 | AA2: 0 | AB2: 0 | AC2: 0 | AD2: 0 | AE2: 7.4683269 | AF2: 28.944766 | AH2: =K2+Y2-Y2/100 -> 2.5748891 | AI2: =Y2 -> 0 | AJ2: =Z2 -> 0 | AK2: =AA2 -> 0 | AL2: =AB2 -> 0 | AM2: =AC2 -> 0 | AN2: =AD2 -> 0 | AR2: =A2 -> 39172 | AS2: =AF2*4+2 -> 117.77907 | AT2: =AH2 -> 2.5748891 | AU2: =SUM(AV2:BA2) -> 0 | AV2: =AI2 -> 0 | AW2: =AJ2 -> 0 | AX2: =AK2 -> 0 | AY2: =AL2 -> 0 | AZ2: =AM2 -> 0 | BA2: =AN2 -> 0 | BC2: =AR2 -> 39172 | BD2: =AT2 -> 2.5748891 | BE2: =AU2 -> 0
A3: 39263 | B3: 2.1888377 | C3: -0.10201437 | D3: -5.4151599 | E3: 0.000432913 | F3: 7.4635098 | G3: 14.09681 | H3: -0.017718534 | I3: 0.23729294 | J3: -0.058482715 | K3: 2.6753132 | L3: 0.30577422 | M3: 0 | N3: 0 | O3: 0.44487798 | P3: 0 | Q3: -0.025392488 | R3: 0 | S3: 0 | T3: 0 | U3: 0 | V3: 0 | W3: 0 | X3: 0 | Y3: 0 | Z3: 0 | AA3: 0 | AB3: 0 | AC3: 0 | AD3: 0 | AE3: 7.445194 | AF3: 29.239275 | AH3: =K3+Y3-Y3/100 -> 2.6753132 | AI3: =Y3 -> 0 | AJ3: =Z3 -> 0 | AK3: =AA3 -> 0 | AL3: =AB3 -> 0 | AM3: =AC3 -> 0 | AN3: =AD3 -> 0 | AR3: =A3 -> 39263 | AS3: =AF3*4+2 -> 118.9571 | AT3: =AH3 -> 2.6753132 | AU3: =SUM(AV3:BA3) -> 0 | AV3: =AI3 -> 0 | AW3: =AJ3 -> 0 | AX3: =AK3 -> 0 | AY3: =AL3 -> 0 | AZ3: =AM3 -> 0 | BA3: =AN3 -> 0 | BC3: =AR3 -> 39263 | BD3: =AT3 -> 2.6753132 | BE3: =AU3 -> 0
A4: 39355 | B4: 2.3018784 | C4: -0.18582521 | D4: -5.7797078 | E4: -0.00024449342 | F4: 8.1065585 | G4: 14.1473 | H4: 0.0099248504 | I4: 0.31153154 | J4: -0.061960515 | K4: 2.506994 | L4: 0.30064004 | M4: 0 | N4: 0 | O4: 0.46631618 | P4: 0 | Q4: -0.040553603 | R4: 0 | S4: 0 | T4: 0 | U4: 0 | V4: 0 | W4: 0 | X4: 0 | Y4: 0 | Z4: 0 | AA4: 0 | AB4: 0 | AC4: 0 | AD4: 0 | AE4: 7.4221487 | AF4: 29.505 | AH4: =K4+Y4-Y4/100 -> 2.506994 | AI4: =Y4 -> 0 | AJ4: =Z4 -> 0 | AK4: =AA4 -> 0 | AL4: =AB4 -> 0 | AM4: =AC4 -> 0 | AN4: =AD4 -> 0 | AR4: =A4 -> 39355 | AS4: =AF4*4+2 -> 120.02 | AT4: =AH4 -> 2.506994 | AU4: =SUM(AV4:BA4) -> 0 | AV4: =AI4 -> 0 | AW4: =AJ4 -> 0 | AX4: =AK4 -> 0 | AY4: =AL4 -> 0 | AZ4: =AM4 -> 0 | BA4: =AN4 -> 0 | BC4: =AR4 -> 39355 | BD4: =AT4 -> 2.506994 | BE4: =AU4 -> 0
A5: 39447 | B5: 2.0031345 | C5: -0.059805901 | D5: -6.0906698 | E5: 0.00065881996 | F5: 8.5748649 | G5: 14.245587 | H5: 0.01546791 | I5: 0.248964 | J5: -0.063329388 | K5: 2.6392114 | L5: 0.34661216 | M5: 0 | N5: 0 | O5: 0.47709801 | P5: 0 | Q5: -0.045182361 | R5: 0 | S5: 0 | T5: 0 | U5: 0 | V5: 0 | W5: 0 | X5: 0 | Y5: 0 | Z5: 0 | AA5: 0 | AB5: 0 | AC5: 0 | AD5: 0 | AE5: 7.3991902 | AF5: 29.691802 | AH5: =K5+Y5-Y5/100 -> 2.6392114 | AI5: =Y5 -> 0 | AJ5: =Z5 -> 0 | AK5: =AA5 -> 0 | AL5: =AB5 -> 0 | AM5: =AC5 -> 0 | AN5: =AD5 -> 0 | AR5: =A5 -> 39447 | AS5: =AF5*4+2 -> 120.76721 | AT5: =AH5 -> 2.6392114 | AU5: =SUM(AV5:BA5) -> 0 | AV5: =AI5 -> 0 | AW5: =AJ5 -> 0 | AX5: =AK5 -> 0 | AY5: =AL5 -> 0 | AZ5: =AM5 -> 0 | BA5: =AN5 -> 0 | BC5: =AR5 -> 39447 | BD5: =AT5 -> 2.6392114 | BE5: =AU5 -> 0
A6: 39538 | B6: 2.0564368 | C6: -0.17410702 | D6: -6.2409237 | E6: -8.1488331e-05 | F6: 8.7254233 | G6: 14.470225 | H6: -0.053129904 | I6: 0.30778976 | J6: -0.066874845 | K6: 2.9688718 | L6: 0.14427824 | M6: 0 | N6: 0 | O6: 0.49713924 | P6: 0 | Q6: -0.050515251 | R6: 0 | S6: 0 | T6: 0 | U6: 0 | V6: 0 | W6: 0 | X6: 0 | Y6: 0 | Z6: 0 | AA6: 0 | AB6: 0 | AC6: 0 | AD6: 0 | AE6: 7.376318 | AF6: 29.96085 | AH6: =K6+Y6-Y6/100 -> 2.9688718 | AI6: =Y6 -> 0 | AJ6: =Z6 -> 0 | AK6: =AA6 -> 0 | AL6: =AB6 -> 0 | AM6: =AC6 -> 0 | AN6: =AD6 -> 0 | AR6: =A6 -> 39538 | AS6: =AF6*4+2 -> 121.8434 | AT6: =AH6 -> 2.9688718 | AU6: =SUM(AV6:BA6) -> 0 | AV6: =AI6 -> 0 | AW6: =AJ6 -> 0 | AX6: =AK6 -> 0 | AY6: =AL6 -> 0 | AZ6: =AM6 -> 0 | BA6: =AN6 -> 0 | BC6: =AR6 -> 39538 | BD6: =AT6 -> 2.9688718 | BE6: =AU6 -> 0
A7: 39629 | B7: 1.9437086 | C7: -0.25968328 | D7: -6.4409474 | E7: 0.00050280931 | F7: 9.1352305 | G7: 14.602996 | H7: -0.0028221986 | I7: 0.2461009 | J7: -0.063600816 | K7: 2.6992023 | L7: 0.031560885 | M7: 0 | N7: 0 | O7: 0.50964208 | P7: 0 | Q7: -0.07357073 | R7: 0 | S7: 0 | T7: 0 | U7: 0 | V7: 0 | W7: 0 | X7: 0 | Y7: 0 | Z7: 0 | AA7: 0 | AB7: 0 | AC7: 0 | AD7: 0 | AE7: 7.3535315 | AF7: 29.681851 | AH7: =K7+Y7-Y7/100 -> 2.6992023 | AI7: =Y7 -> 0 | AJ7: =Z7 -> 0 | AK7: =AA7 -> 0 | AL7: =AB7 -> 0 | AM7: =AC7 -> 0 | AN7: =AD7 -> 0 | AR7: =A7 -> 39629 | AS7: =AF7*4+2 -> 120.7274 | AT7: =AH7 -> 2.6992023 | AU7: =SUM(AV7:BA7) -> 0 | AV7: =AI7 -> 0 | AW7: =AJ7 -> 0 | AX7: =AK7 -> 0 | AY7: =AL7 -> 0 | AZ7: =AM7 -> 0 | BA7: =AN7 -> 0 | BC7: =AR7 -> 39629 | BD7: =AT7 -> 2.6992023 | BE7: =AU7 -> 0
A8: 39721 | B8: 1.5553725 | C8: -0.47264141 | D8: -6.5811779 | E8: 0.00045985532 | F8: 9.4802157 | G8: 14.927721 | H8: 0.027059605 | I8: 0.29587019 | J8: -0.068185466 | K8: 2.5210749 | L8: -0.16240357 | M8: 0 | N8: 0 | O8: 0.53344519 | P8: 0 | Q8: -0.081467541 | R8: 0 | S8: 0 | T8: 0 | U8: 0 | V8: 0 | W8: 0 | X8: 0 | Y8: 0 | Z8: 0 | AA8: 0 | AB8: 0 | AC8: 0 | AD8: 0 | AE8: 7.3308301 | AF8: 29.306173 | AH8: =K8+Y8-Y8/100 -> 2.5210749 | AI8: =Y8 -> 0 | AJ8: =Z8 -> 0 | AK8: =AA8 -> 0 | AL8: =AB8 -> 0 | AM8: =AC8 -> 0 | AN8: =AD8 -> 0 | AR8: =A8 -> 39721 | AS8: =AF8*4+2 -> 119.22469 | AT8: =AH8 -> 2.5210749 | AU8: =SUM(AV8:BA8) -> 0 | AV8: =AI8 -> 0 | AW8: =AJ8 -> 0 | AX8: =AK8 -> 0 | AY8: =AL8 -> 0 | AZ8: =AM8 -> 0 | BA8: =AN8 -> 0 | BC8: =AR8 -> 39721 | BD8: =AT8 -> 2.5210749 | BE8: =AU8 -> 0
A9: 39813 | B9: 2.2206634 | C9: -0.98689403 | D9: -6.9466266 | E9: -0.0002896115 | F9: 8.9449095 | G9: 15.944444 | H9: 0.11808668 | I9: 0.33695797 | J9: -0.065994594 | K9: 2.2587813 | L9: -0.68091049 | M9: 0 | N9: 0 | O9: 0.55671627 | P9: 0 | Q9: -0.073561543 | R9: 0 | S9: 0 | T9: 0 | U9: 0 | V9: 0 | W9: 0 | X9: 0 | Y9: 0.073690921 | Z9: -0.13359577 | AA9: 0.092384556 | AB9: -0.0071129062 | AC9: -0.014969052 | AD9: -0.028973438 | AE9: 7.3082133 | AF9: 28.91592 | AH9: =K9+Y9-Y9/100 -> 2.3317353 | AI9: =Y9/1010 -> 7.2961308e-05 | AJ9: =Z9 -> -0.13359577 | AK9: =AA9 -> 0.092384556 | AL9: =AB9 -> -0.0071129062 | AM9: =AC9 -> -0.014969052 | AN9: =AD9 -> -0.028973438 | AR9: =A9 -> 39813 | AS9: =AF9*4+2 -> 117.66368 | AT9: =AH9 -> 2.3317353 | AU9: =SUM(AV9:BA9) -> -0.092193645 | AV9: =AI9 -> 7.2961308e-05 | AW9: =AJ9 -> -0.13359577 | AX9: =AK9 -> 0.092384556 | AY9: =AL9 -> -0.0071129062 | AZ9: =AM9 -> -0.014969052 | BA9: =AN9 -> -0.028973438 | BC9: =AR9 -> 39813 | BD9: =AT9 -> 2.3317353 | BE9: =AU9 -> -0.092193645
A10: 39903 | B10: 2.4024061 | C10: -1.2606797 | D10: -6.8199197 | E10: -0.0001738059 | F10: 8.6027343 | G10: 16.652521 | H10: 0.06749249 | I10: 0.27634318 | J10: -0.060941639 | K10: 2.7785999 | L10: -1.1798196 | M10: 0 | N10: 0 | O10: 0.57206768 | P10: 0 | Q10: -0.025279014 | R10: 0 | S10: 0 | T10: 0 | U10: 0 | V10: 0 | W10: 0 | X10: 0 | Y10: -1.7973575 | Z10: 0.013721478 | AA10: 0.12529789 | AB10: -0.030395868 | AC10: -0.051108838 | AD10: -0.13660702 | AE10: 7.2856806 | AF10: 27.414582 | AH10: =K10+Y10-Y10/100 -> 0.99921591 | AI10: =Y10/1010 -> -0.0017795619 | AJ10: =Z10 -> 0.013721478 | AK10: =AA10 -> 0.12529789 | AL10: =AB10 -> -0.030395868 | AM10: =AC10 -> -0.051108838 | AN10: =AD10 -> -0.13660702 | AR10: =A10 -> 39903 | AS10: =AF10*4+2 -> 111.65833 | AT10: =AH10 -> 0.99921591 | AU10: =SUM(AV10:BA10) -> -0.080871912 | AV10: =AI10 -> -0.0017795619 | AW10: =AJ10 -> 0.013721478 | AX10: =AK10 -> 0.12529789 | AY10: =AL10 -> -0.030395868 | AZ10: =AM10 -> -0.051108838 | BA10: =AN10 -> -0.13660702 | BC10: =AR10 -> 39903 | BD10: =AT10 -> 0.99921591 | BE10: =AU10 -> -0.080871912
A11: 39994 | B11: 2.4277616 | C11: -1.6490085 | D11: -6.3861468 | E11: -0.00049595052 | F11: 7.9593532 | G11: 17.059181 | H11: -0.089907165 | I11: 0.25785819 | J11: -0.059151639 | K11: 5.406976 | L11: -1.4181606 | M11: 0 | N11: 0 | O11: 0.58667403 | P11: 0 | Q11: 0.016546462 | R11: 0 | S11: 0 | T11: 0 | U11: 0 | V11: 0 | W11: 0 | X11: 0 | Y11: -4.5109297 | Z11: 0.25520858 | AA11: 0.13462049 | AB11: -0.078483828 | AC11: -0.067382708 | AD11: -0.30713781 | AE11: 7.2632314 | AF11: 26.800606 | AH11: =K11+Y11-Y11/100 -> 0.94115568 | AI11: =Y11/1010 -> -0.004466267 | AJ11: =Z11 -> 0.25520858 | AK11: =AA11 -> 0.13462049 | AL11: =AB11 -> -0.078483828 | AM11: =AC11 -> -0.067382708 | AN11: =AD11 -> -0.30713781 | AR11: =A11 -> 39994 | AS11: =AF11*4+2 -> 109.20242 | AT11: =AH11 -> 0.94115568 | AU11: =SUM(AV11:BA11) -> -0.067641554 | AV11: =AI11 -> -0.004466267 | AW11: =AJ11 -> 0.25520858 | AX11: =AK11 -> 0.13462049 | AY11: =AL11 -> -0.078483828 | AZ11: =AM11 -> -0.067382708 | BA11: =AN11 -> -0.30713781 | BC11: =AR11 -> 39994 | BD11: =AT11 -> 0.94115568 | BE11: =AU11 -> -0.067641554
A12: 40086 | B12: 2.4217085 | C12: -2.0203722 | D12: -5.5802494 | E12: -0.0013006478 | F12: 7.1417549 | G12: 17.135333 | H12: -0.0426744 | I12: 0.322457 | J12: -0.056528372 | K12: 7.9652821 | L12: -1.4766757 | M12: 0 | N12: 0 | O12: 0.60460848 | P12: 0 | Q12: 0.00073509913 | R12: 0 | S12: 0 | T12: 0 | U12: 0 | V12: 0 | W12: 0 | X12: 0 | Y12: -6.6481835 | Z12: 0.43002849 | AA12: 0.11092325 | AB12: -0.16598199 | AC12: -0.11796388 | AD12: -0.56485065 | AE12: 7.2408652 | AF12: 26.698915 | AH12: =K12+Y12-Y12/100 -> 1.3835804 | AI12: =Y12/1010 -> -0.0065823599 | AJ12: =Z12 -> 0.43002849 | AK12: =AA12 -> 0.11092325 | AL12: =AB12 -> -0.16598199 | AM12: =AC12 -> -0.11796388 | AN12: =AD12 -> -0.56485065 | AR12: =A12 -> 40086 | AS12: =AF12*4+2 -> 108.79566 | AT12: =AH12 -> 1.3835804 | AU12: =SUM(AV12:BA12) -> -0.31442715 | AV12: =AI12 -> -0.0065823599 | AW12: =AJ12 -> 0.43002849 | AX12: =AK12 -> 0.11092325 | AY12: =AL12 -> -0.16598199 | AZ12: =AM12 -> -0.11796388 | BA12: =AN12 -> -0.56485065 | BC12: =AR12 -> 40086 | BD12: =AT12 -> 1.3835804 | BE12: =AU12 -> -0.31442715
A13: 40178 | B13: 2.0701525 | C13: -1.9632677 | D13: -4.963927 | E13: -0.00080920876 | F13: 6.7932403 | G13: 17.165547 | H13: 0.018838774 | I13: 0.252927 | J13: -0.046777776 | K13: 9.6680861 | L13: -1.4944411 | M13: 0 | N13: 0 | O13: 0.61475522 | P13: 0 | Q13: -0.017101425 | R13: 0 | S13: 0 | T13: 0 | U13: 0 | V13: 0 | W13: 0 | X13: 0 | Y13: -8.2298802 | Z13: 0.64538339 | AA13: 0.075587373 | AB13: -0.24389615 | AC13: -0.13783327 | AD13: -0.86962231 | AE13: 7.2185815 | AF13: 26.555543 | AH13: =K13+Y13-Y13/100 -> 1.5205047 | AI13: =Y13/1010 -> -0.0081483962 | AJ13: =Z13 -> 0.64538339 | AK13: =AA13 -> 0.075587373 | AL13: =AB13 -> -0.24389615 | AM13: =AC13 -> -0.13783327 | AN13: =AD13 -> -0.86962231 | AR13: =A13 -> 40178 | AS13: =AF13*4+2 -> 108.22217 | AT13: =AH13 -> 1.5205047 | AU13: =SUM(AV13:BA13) -> -0.53852936 | AV13: =AI13 -> -0.0081483962 | AW13: =AJ13 -> 0.64538339 | AX13: =AK13 -> 0.075587373 | AY13: =AL13 -> -0.24389615 | AZ13: =AM13 -> -0.13783327 | BA13: =AN13 -> -0.86962231 | BC13: =AR13 -> 40178 | BD13: =AT13 -> 1.5205047 | BE13: =AU13 -> -0.53852936
A14: 40268 | B14: 1.9292619 | C14: -1.9152574 | D14: -4.6209409 | E14: -9.3285765e-05 | F14: 6.2885873 | G14: 17.194811 | H14: -0.0097242431 | I14: 0.24468576 | J14: -0.033630541 | K14: 11.391705 | L14: -1.5295778 | M14: 0 | N14: 0 | O14: 0.62748077 | P14: 0 | Q14: -0.021055782 | R14: 0 | S14: 0 | T14: 0 | U14: 0 | V14: 0 | W14: 0 | X14: 0 | Y14: -9.2842199 | Z14: 0.93375033 | AA14: 0.13528553 | AB14: -0.26251041 | AC14: -0.11896933 | AD14: -1.185558 | AE14: 7.1963798 | AF14: 26.96041 | AH14: =K14+Y14-Y14/100 -> 2.2003272 | AI14: =Y14/1010 -> -0.0091922969 | AJ14: =Z14 -> 0.93375033 | AK14: =AA14 -> 0.13528553 | AL14: =AB14 -> -0.26251041 | AM14: =AC14 -> -0.11896933 | AN14: =AD14 -> -1.185558 | AR14: =A14 -> 40268 | AS14: =AF14*4+2 -> 109.84164 | AT14: =AH14 -> 2.2003272 | AU14: =SUM(AV14:BA14) -> -0.50719413 | AV14: =AI14 -> -0.0091922969 | AW14: =AJ14 -> 0.93375033 | AX14: =AK14 -> 0.13528553 | AY14: =AL14 -> -0.26251041 | AZ14: =AM14 -> -0.11896933 | BA14: =AN14 -> -1.185558 | BC14: =AR14 -> 40268 | BD14: =AT14 -> 2.2003272 | BE14: =AU14 -> -0.50719413
A15: 40359 | B15: 1.7114594 | C15: -1.7910189 | D15: -4.417112 | E15: -0.00034034385 | F15: 5.508496 | G15: 17.284895 | H15: 0.036125033 | I15: 0.25452995 | J15: -0.025443457 | K15: 12.624267 | L15: -1.4630845 | M15: 0 | N15: 0 | O15: 0.64041987 | P15: 0 | Q15: -0.024373029 | R15: 0 | S15: 0 | T15: 0 | U15: 0 | V15: 0 | W15: 0 | X15: 0 | Y15: -10.235004 | Z15: 1.2587611 | AA15: 0.30474392 | AB15: -0.17869597 | AC15: -0.03951587 | AD15: -1.4723622 | AE15: 7.1742596 | AF15: 27.151007 | AH15: =K15+Y15-Y15/100 -> 2.4916135 | AI15: =Y15/1010 -> -0.010133667 | AJ15: =Z15 -> 1.2587611 | AK15: =AA15 -> 0.30474392 | AL15: =AB15 -> -0.17869597 | AM15: =AC15 -> -0.03951587 | AN15: =AD15 -> -1.4723622 | AR15: =A15 -> 40359 | AS15: =AF15*4+2 -> 110.60403 | AT15: =AH15 -> 2.4916135 | AU15: =SUM(AV15:BA15) -> -0.13720259 | AV15: =AI15 -> -0.010133667 | AW15: =AJ15 -> 1.2587611 | AX15: =AK15 -> 0.30474392 | AY15: =AL15 -> -0.17869597 | AZ15: =AM15 -> -0.03951587 | BA15: =AN15 -> -1.4723622 | BC15: =AR15 -> 40359 | BD15: =AT15 -> 2.4916135 | BE15: =AU15 -> -0.13720259
A16: 40451 | B16: 1.6689236 | C16: -1.669287 | D16: -4.2631128 | E16: -0.00047472158 | F16: 5.3252985 | G16: 17.33458 | H16: 0.0056531455 | I16: 0.3395956 | J16: -0.01579766 | K16: 13.592728 | L16: -1.5563826 | M16: 0 | N16: 0 | O16: 0.65967139 | P16: 0 | Q16: -0.017203497 | R16: 0 | S16: 0 | T16: 0 | U16: 0 | V16: 0 | W16: 0 | X16: 0 | Y16: -11.450592 | Z16: 1.4891879 | AA16: 0.38887175 | AB16: -0.13286861 | AC16: 0.019233067 | AD16: -1.7498602 | AE16: 7.1522205 | AF16: 27.120385 | AH16: =K16+Y16-Y16/100 -> 2.2566424 | AI16: =Y16/1010 -> -0.011337219 | AJ16: =Z16 -> 1.4891879 | AK16: =AA16 -> 0.38887175 | AL16: =AB16 -> -0.13286861 | AM16: =AC16 -> 0.019233067 | AN16: =AD16 -> -1.7498602 | AR16: =A16 -> 40451 | AS16: =AF16*4+2 -> 110.48154 | AT16: =AH16 -> 2.2566424 | AU16: =SUM(AV16:BA16) -> 0.0032267014 | AV16: =AI16 -> -0.011337219 | AW16: =AJ16 -> 1.4891879 | AX16: =AK16 -> 0.38887175 | AY16: =AL16 -> -0.13286861 | AZ16: =AM16 -> 0.019233067 | BA16: =AN16 -> -1.7498602 | BC16: =AR16 -> 40451 | BD16: =AT16 -> 2.2566424 | BE16: =AU16 -> 0.0032267014
A17: 40543 | B17: 1.3754459 | C17: -1.4731984 | D17: -4.3372803 | E17: -0.00016910156 | F17: 6.0283243 | G17: 17.375538 | H17: -0.03695678 | I17: 0.26961923 | J17: -0.0084062676 | K17: 14.927038 | L17: -1.5514464 | M17: 0 | N17: 0 | O17: 0.6729625 | P17: 0 | Q17: -0.010960892 | R17: 0 | S17: 0 | T17: 0 | U17: 0 | V17: 0 | W17: 0 | X17: 0 | Y17: -13.193123 | Z17: 1.6728789 | AA17: 0.4341946 | AB17: -0.11512471 | AC17: 0.031882889 | AD17: -2.0389967 | AE17: 7.1302619 | AF17: 27.152484 | AH17: =K17+Y17-Y17/100 -> 1.8658466 | AI17: =Y17/1010 -> -0.013062498 | AJ17: =Z17 -> 1.6728789 | AK17: =AA17 -> 0.4341946 | AL17: =AB17 -> -0.11512471 | AM17: =AC17 -> 0.031882889 | AN17: =AD17 -> -2.0389967 | AR17: =A17 -> 40543 | AS17: =AF17*4+2 -> 110.60994 | AT17: =AH17 -> 1.8658466 | AU17: =SUM(AV17:BA17) -> -0.028227444 | AV17: =AI17 -> -0.013062498 | AW17: =AJ17 -> 1.6728789 | AX17: =AK17 -> 0.4341946 | AY17: =AL17 -> -0.11512471 | AZ17: =AM17 -> 0.031882889 | BA17: =AN17 -> -2.0389967 | BC17: =AR17 -> 40543 | BD17: =AT17 -> 1.8658466 | BE17: =AU17 -> -0.028227444
A18: 40633 | B18: 1.9043017 | C18: -1.5433038 | D18: -4.5069513 | E18: -0.0012869151 | F18: 7.4268885 | G18: 17.45478 | H18: -0.036961388 | I18: 0.30813711 | J18: -0.0078414583 | K18: 16.675365 | L18: -1.4894906 | M18: 0 | N18: 0 | O18: 0.69313123 | P18: 0 | Q18: -0.023400021 | R18: 0 | S18: 0 | T18: 0 | U18: 0 | V18: 0 | W18: 0 | X18: 0 | Y18: -15.514005 | Z18: 1.6560904 | AA18: 0.29727136 | AB18: -0.20292069 | AC18: -0.027254571 | AD18: -2.3847288 | AE18: 7.1083835 | AF18: 27.786204 | AH18: =K18+Y18-Y18/100 -> 1.3164998 | AI18: =Y18/1010 -> -0.015360401 | AJ18: =Z18 -> 1.6560904 | AK18: =AA18 -> 0.29727136 | AL18: =AB18 -> -0.20292069 | AM18: =AC18 -> -0.027254571 | AN18: =AD18 -> -2.3847288 | AR18: =A18 -> 40633 | AS18: =AF18*4+2 -> 113.14482 | AT18: =AH18 -> 1.3164998 | AU18: =SUM(AV18:BA18) -> -0.67690276 | AV18: =AI18 -> -0.015360401 | AW18: =AJ18 -> 1.6560904 | AX18: =AK18 -> 0.29727136 | AY18: =AL18 -> -0.20292069 | AZ18: =AM18 -> -0.027254571 | BA18: =AN18 -> -2.3847288 | BC18: =AR18 -> 40633 | BD18: =AT18 -> 1.3164998 | BE18: =AU18 -> -0.67690276
A19: 40724 | B19: 1.467808 | C19: -1.2043497 | D19: -4.3924235 | E19: -0.0010583469 | F19: 8.406255 | G19: 17.546427 | H19: 0.07324742 | I19: 0.30268883 | J19: -0.0051230818 | K19: 18.729266 | L19: -1.555679 | M19: 0 | N19: 0 | O19: 0.71288761 | P19: 0 | Q19: -0.035226888 | R19: 0 | S19: 0 | T19: 0 | U19: 0 | V19: 0 | W19: 0 | X19: 0 | Y19: -18.615704 | Z19: 1.7520007 | AA19: 0.18453734 | AB19: -0.23254533 | AC19: -0.029947737 | AD19: -2.709168 | AE19: 7.0865847 | AF19: 27.480477 | AH19: =K19+Y19-Y19/100 -> 0.29971978 | AI19: =Y19/1010 -> -0.01843139 | AJ19: =Z19 -> 1.7520007 | AK19: =AA19 -> 0.18453734 | AL19: =AB19 -> -0.23254533 | AM19: =AC19 -> -0.029947737 | AN19: =AD19 -> -2.709168 | AR19: =A19 -> 40724 | AS19: =AF19*4+2 -> 111.92191 | AT19: =AH19 -> 0.29971978 | AU19: =SUM(AV19:BA19) -> -1.0535544 | AV19: =AI19 -> -0.01843139 | AW19: =AJ19 -> 1.7520007 | AX19: =AK19 -> 0.18453734 | AY19: =AL19 -> -0.23254533 | AZ19: =AM19 -> -0.029947737 | BA19: =AN19 -> -2.709168 | BC19: =AR19 -> 40724 | BD19: =AT19 -> 0.29971978 | BE19: =AU19 -> -1.0535544
A20: 40816 | B20: 1.8241286 | C20: -1.0959542 | D20: -4.2580249 | E20: -0.00028471595 | F20: 6.5846466 | G20: 17.671886 | H20: -0.047348455 | I20: 0.34776192 | J20: 0.0012598254 | K20: 21.668795 | L20: -1.6269307 | M20: 0 | N20: 0 | O20: 0.72603408 | P20: 0 | Q20: -0.021518547 | R20: 0 | S20: 0 | T20: 0 | U20: 0 | V20: 0 | W20: 0 | X20: 0 | Y20: -21.294037 | Z20: 2.3087563 | AA20: 0.35473861 | AB20: -0.080751504 | AC20: 0.099261868 | AD20: -2.8984711 | AE20: 7.0648651 | AF20: 27.328812 | AH20: =K20+Y20-Y20/100 -> 0.58769775 | AI20: =Y20/1010 -> -0.021083205 | AJ20: =Z20 -> 2.3087563 | AK20: =AA20 -> 0.35473861 | AL20: =AB20 -> -0.080751504 | AM20: =AC20 -> 0.099261868 | AN20: =AD20 -> -2.8984711 | AR20: =A20 -> 40816 | AS20: =AF20*4+2 -> 111.31525 | AT20: =AH20 -> 0.58769775 | AU20: =SUM(AV20:BA20) -> -0.23754899 | AV20: =AI20 -> -0.021083205 | AW20: =AJ20 -> 2.3087563 | AX20: =AK20 -> 0.35473861 | AY20: =AL20 -> -0.080751504 | AZ20: =AM20 -> 0.099261868 | BA20: =AN20 -> -2.8984711 | BC20: =AR20 -> 40816 | BD20: =AT20 -> 0.58769775 | BE20: =AU20 -> -0.23754899
... A132: 51043 | B132: -0.043141873 | C132: -0.00014191675 | D132: -0.060150045 | E132: 0.00016375639 | F132: 0.077003819 | G132: -0.017761409 | H132: 0.10657899 | I132: -0.12938709 | J132: -0.23383062 | K132: -0.0013647494 | L132: 0.028622522 | M132: 0 | N132: 0 | O132: 0.44750605 | P132: 0 | Q132: 0.30446726 | R132: 0 | S132: 0 | T132: 0 | U132: 0 | V132: 0 | W132: 0 | X132: 0 | Y132: 0.0014171204 | Z132: -0.0014470184 | AA132: 0.00054189822 | AB132: -0.00029329794 | AC132: 0.0013717805 | AD132: 0.0037302372 | AE132: -0.072867892 | AF132: 0.418171 | AH132: =K132+Y132-Y132/100 -> 3.8199787e-05 | AI132: =Y132/1010 -> 1.4030895e-06 | AJ132: =Z132 -> -0.0014470184 | AK132: =AA132 -> 0.00054189822 | AL132: =AB132 -> -0.00029329794 | AM132: =AC132 -> 0.0013717805 | AN132: =AD132 -> 0.0037302372 | AR132: =A132 -> 51043 | AS132: =AF132*4+2 -> 3.672684 | AT132: =AH132 -> 3.8199787e-05 | AU132: =SUM(AV132:BA132) -> 0.0039050027 | AV132: =AI132 -> 1.4030895e-06 | AW132: =AJ132 -> -0.0014470184 | AX132: =AK132 -> 0.00054189822 | AY132: =AL132 -> -0.00029329794 | AZ132: =AM132 -> 0.0013717805 | BA132: =AN132 -> 0.0037302372 | BC132: =AR132 -> 51043 | BD132: =AT132 -> 3.8199787e-05 | BE132: =AU132 -> 0.0039050027

Sheet EA_core_obs_with_text
A1: date | B1: g_sh | C1: b_liqtil_sh | D1: b_liqp_sh | E1: b_safetil_sh | F1: b_safep_sh | G1: mu_sh | H1: z_sh | I1: lambda_f_sh | J1: lambda_w_sh | K1: rm_sh | L1: sigma_omega_sh | M1: mu_e_sh | N1: gamma_sh | O1: pi_star_sh | P1: lr_sh | Q1: zp_sh | R1: tfp_sh | S1: gdpdef_sh | T1: corepce_sh | U1: gdp_sh | V1: gdi_sh | W1: BBB_sh | X1: AAA_sh | Y1: rm_shl1 | Z1: rm_shl2 | AA1: rm_shl3 | AB1: rm_shl4 | AC1: rm_shl5 | AD1: rm_shl6 | AE1: dettrend | AF1: detrendedMean | AH1: rm_sh | AI1: =Y1 -> rm_shl1 | AJ1: =Z1 -> rm_shl2 | AK1: =AA1 -> rm_shl3 | AL1: =AB1 -> rm_shl4 | AM1: =AC1 -> rm_shl5 | AN1: =AD1 -> rm_shl6 | AQ1: Plot | AR1: =A1 -> date | AS1: =AF1 -> detrendedMean | AT1: Monetary Policy | AU1: Fgsum | AV1: FG1 | AW1: FG2 | AX1: FG3 | AY1: FG4 | AZ1: FG5 | BA1: FG6 | BC1: date | BD1: rm_sh | BE1: Fgsum
A2: 39172 | B2: -0.0019508847 | C2: -0.00044949594 | D2: -0.13911193 | E2: 2.6700597e-07 | F2: 0.18028947 | G2: -0.0092832979 | H2: -9.5227129e-06 | I2: -0.33420427 | J2: -0.060491883 | K2: 0.024806955 | L2: -0.00020267534 | M2: 0 | N2: 0 | O2: 0.019158519 | P2: 0 | Q2: 7.7258442e-05 | R2: 0 | S2: 0 | T2: 0.50261524 | U2: 0 | V2: 0 | W2: 0 | X2: 0 | Y2: 0 | Z2: 0 | AA2: 0 | AB2: 0 | AC2: 0 | AD2: 0 | AE2: 0.036435471 | AF2: 0.22016319 | AH2: =K2+Y2-Y2/100 -> 0.024806955 | AI2: =Y2 -> 0 | AJ2: =Z2 -> 0 | AK2: =AA2 -> 0 | AL2: =AB2 -> 0 | AM2: =AC2 -> 0 | AN2: =AD2 -> 0 | AR2: =A2 -> 39172 | AS2: =AF2*4+2 -> 2.8806528 | AT2: =AH2 -> 0.024806955 | AU2: =SUM(AV2:BA2) -> 0 | AV2: =AI2 -> 0 | AW2: =AJ2 -> 0 | AX2: =AK2 -> 0 | AY2: =AL2 -> 0 | AZ2: =AM2 -> 0 | BA2: =AN2 -> 0 | BC2: =AR2 -> 39172 | BD2: =AT2 -> 0.024806955 | BE2: =AU2 -> 0
A3: 39263 | B3: -0.001910232 | C3: -0.00033353949 | D3: -0.14952585 | E3: 1.8081252e-07 | F3: 0.20476775 | G3: -0.0092487068 | H3: -1.5875485e-05 | I3: -0.40434241 | J3: -0.065233156 | K3: 0.025255502 | L3: -0.00021052273 | M3: 0 | N3: 0 | O3: 0.020245405 | P3: 0 | Q3: 9.7038271e-05 | R3: 0 | S3: 0 | T3: 0.41534977 | U3: 0 | V3: 0 | W3: 0 | X3: 0 | Y3: 0 | Z3: 0 | AA3: 0 | AB3: 0 | AC3: 0 | AD3: 0 | AE3: 0.035954254 | AF3: 0.070229362 | AH3: =K3+Y3-Y3/100 -> 0.025255502 | AI3: =Y3 -> 0 | AJ3: =Z3 -> 0 | AK3: =AA3 -> 0 | AL3: =AB3 -> 0 | AM3: =AC3 -> 0 | AN3: =AD3 -> 0 | AR3: =A3 -> 39263 | AS3: =AF3*4+2 -> 2.2809174 | AT3: =AH3 -> 0.025255502 | AU3: =SUM(AV3:BA3) -> 0 | AV3: =AI3 -> 0 | AW3: =AJ3 -> 0 | AX3: =AK3 -> 0 | AY3: =AL3 -> 0 | AZ3: =AM3 -> 0 | BA3: =AN3 -> 0 | BC3: =AR3 -> 39263 | BD3: =AT3 -> 0.025255502 | BE3: =AU3 -> 0
A4: 39355 | B4: -0.0019527526 | C4: -0.00042054317 | D4: -0.15990279 | E4: 2.0866553e-07 | F4: 0.22376056 | G4: -0.009266434 | H4: -6.2988432e-06 | I4: -0.009955934 | J4: -0.0645373 | K4: 0.023798391 | L4: -0.00017549804 | M4: 0 | N4: 0 | O4: 0.022058994 | P4: 0 | Q4: 0.00013361978 | R4: 0 | S4: 0 | T4: -0.31246178 | U4: 0 | V4: 0 | W4: 0 | X4: 0 | Y4: 0 | Z4: 0 | AA4: 0 | AB4: 0 | AC4: 0 | AD4: 0 | AE4: 0.035480661 | AF4: -0.25915581 | AH4: =K4+Y4-Y4/100 -> 0.023798391 | AI4: =Y4 -> 0 | AJ4: =Z4 -> 0 | AK4: =AA4 -> 0 | AL4: =AB4 -> 0 | AM4: =AC4 -> 0 | AN4: =AD4 -> 0 | AR4: =A4 -> 39355 | AS4: =AF4*4+2 -> 0.96337677 | AT4: =AH4 -> 0.023798391 | AU4: =SUM(AV4:BA4) -> 0 | AV4: =AI4 -> 0 | AW4: =AJ4 -> 0 | AX4: =AK4 -> 0 | AY4: =AL4 -> 0 | AZ4: =AM4 -> 0 | BA4: =AN4 -> 0 | BC4: =AR4 -> 39355 | BD4: =AT4 -> 0.023798391 | BE4: =AU4 -> 0
A5: 39447 | B5: -0.001819592 | C5: -0.00026552038 | D5: -0.1690069 | E5: 6.1493388e-08 | F5: 0.23796722 | G5: -0.0093067312 | H5: 1.4725119e-06 | I5: -0.51029866 | J5: -0.065204379 | K5: 0.024733448 | L5: -0.00022667152 | M5: 0 | N5: 0 | O5: 0.022562176 | P5: 0 | Q5: 0.00016303021 | R5: 0 | S5: 0 | T5: 1.294007 | U5: 0 | V5: 0 | W5: 0 | X5: 0 | Y5: 0 | Z5: 0 | AA5: 0 | AB5: 0 | AC5: 0 | AD5: 0 | AE5: 0.035014511 | AF5: 0.86907076 | AH5: =K5+Y5-Y5/100 -> 0.024733448 | AI5: =Y5 -> 0 | AJ5: =Z5 -> 0 | AK5: =AA5 -> 0 | AL5: =AB5 -> 0 | AM5: =AC5 -> 0 | AN5: =AD5 -> 0 | AR5: =A5 -> 39447 | AS5: =AF5*4+2 -> 5.476283 | AT5: =AH5 -> 0.024733448 | AU5: =SUM(AV5:BA5) -> 0 | AV5: =AI5 -> 0 | AW5: =AJ5 -> 0 | AX5: =AK5 -> 0 | AY5: =AL5 -> 0 | AZ5: =AM5 -> 0 | BA5: =AN5 -> 0 | BC5: =AR5 -> 39447 | BD5: =AT5 -> 0.024733448 | BE5: =AU5 -> 0
A6: 39538 | B6: -0.0017947097 | C6: -0.0003933734 | D6: -0.17379543 | E6: 4.1640913e-08 | F6: 0.24330441 | G6: -0.0094038734 | H6: -3.0191972e-05 | I6: -0.075682169 | J6: -0.059083667 | K6: 0.027431403 | L6: 4.5698247e-05 | M6: 0 | N6: 0 | O6: 0.024035226 | P6: 0 | Q6: 0.0001932567 | R6: 0 | S6: 0 | T6: 1.0447664 | U6: 0 | V6: 0 | W6: 0 | X6: 0 | Y6: 0 | Z6: 0 | AA6: 0 | AB6: 0 | AC6: 0 | AD6: 0 | AE6: 0.034555629 | AF6: 1.0750228 | AH6: =K6+Y6-Y6/100 -> 0.027431403 | AI6: =Y6 -> 0 | AJ6: =Z6 -> 0 | AK6: =AA6 -> 0 | AL6: =AB6 -> 0 | AM6: =AC6 -> 0 | AN6: =AD6 -> 0 | AR6: =A6 -> 39538 | AS6: =AF6*4+2 -> 6.3000912 | AT6: =AH6 -> 0.027431403 | AU6: =SUM(AV6:BA6) -> 0 | AV6: =AI6 -> 0 | AW6: =AJ6 -> 0 | AX6: =AK6 -> 0 | AY6: =AL6 -> 0 | AZ6: =AM6 -> 0 | BA6: =AN6 -> 0 | BC6: =AR6 -> 39538 | BD6: =AT6 -> 0.027431403 | BE6: =AU6 -> 0
A7: 39629 | B7: -0.0017283825 | C7: -0.00052098134 | D7: -0.17948205 | E7: -8.4770635e-08 | F7: 0.25457248 | G7: -0.0094675548 | H7: -2.4387526e-05 | I7: -0.53246487 | J7: -0.062762084 | K7: 0.025474549 | L7: 0.00015518565 | M7: 0 | N7: 0 | O7: 0.024579932 | P7: 0 | Q7: 0.00025217967 | R7: 0 | S7: 0 | T7: 0.55768634 | U7: 0 | V7: 0 | W7: 0 | X7: 0 | Y7: 0 | Z7: 0 | AA7: 0 | AB7: 0 | AC7: 0 | AD7: 0 | AE7: 0.034103845 | AF7: 0.10910267 | AH7: =K7+Y7-Y7/100 -> 0.025474549 | AI7: =Y7 -> 0 | AJ7: =Z7 -> 0 | AK7: =AA7 -> 0 | AL7: =AB7 -> 0 | AM7: =AC7 -> 0 | AN7: =AD7 -> 0 | AR7: =A7 -> 39629 | AS7: =AF7*4+2 -> 2.4364107 | AT7: =AH7 -> 0.025474549 | AU7: =SUM(AV7:BA7) -> 0 | AV7: =AI7 -> 0 | AW7: =AJ7 -> 0 | AX7: =AK7 -> 0 | AY7: =AL7 -> 0 | AZ7: =AM7 -> 0 | BA7: =AN7 -> 0 | BC7: =AR7 -> 39629 | BD7: =AT7 -> 0.025474549 | BE7: =AU7 -> 0
A8: 39721 | B8: -0.0015061545 | C8: -0.00082754778 | D8: -0.18355115 | E8: -2.1032052e-07 | F8: 0.26437332 | G8: -0.0096179459 | H8: -7.5678916e-06 | I8: -0.14485768 | J8: -0.050365823 | K8: 0.023972166 | L8: 0.00035591919 | M8: 0 | N8: 0 | O8: 0.026352006 | P8: 0 | Q8: 0.0002999625 | R8: 0 | S8: 0 | T8: -0.036013235 | U8: 0 | V8: 0 | W8: 0 | X8: 0 | Y8: 0 | Z8: 0 | AA8: 0 | AB8: 0 | AC8: 0 | AD8: 0 | AE8: 0.033658996 | AF8: -0.079941369 | AH8: =K8+Y8-Y8/100 -> 0.023972166 | AI8: =Y8 -> 0 | AJ8: =Z8 -> 0 | AK8: =AA8 -> 0 | AL8: =AB8 -> 0 | AM8: =AC8 -> 0 | AN8: =AD8 -> 0 | AR8: =A8 -> 39721 | AS8: =AF8*4+2 -> 1.6802345 | AT8: =AH8 -> 0.023972166 | AU8: =SUM(AV8:BA8) -> 0 | AV8: =AI8 -> 0 | AW8: =AJ8 -> 0 | AX8: =AK8 -> 0 | AY8: =AL8 -> 0 | AZ8: =AM8 -> 0 | BA8: =AN8 -> 0 | BC8: =AR8 -> 39721 | BD8: =AT8 -> 0.023972166 | BE8: =AU8 -> 0
A9: 39813 | B9: -0.0017549138 | C9: -0.00156211 | D9: -0.1933762 | E9: -1.8715314e-07 | F9: 0.25092315 | G9: -0.01007109 | H9: 4.9196496e-05 | I9: -0.040406385 | J9: -0.043813379 | K9: 0.021710964 | L9: 0.00096220758 | M9: 0 | N9: 0 | O9: 0.027999195 | P9: 0 | Q9: 0.00032064405 | R9: 0 | S9: 0 | T9: -0.34690997 | U9: 0 | V9: 0 | W9: 0 | X9: 0 | Y9: 0.00070843025 | Z9: -0.0015217668 | AA9: 0.0012434729 | AB9: -0.00011281199 | AC9: -0.00027900983 | AD9: -0.0006330498 | AE9: 0.033220923 | AF9: -0.31011519 | AH9: =K9+Y9-Y9/100 -> 0.02241231 | AI9: =Y9/1010 -> 7.0141609e-07 | AJ9: =Z9 -> -0.0015217668 | AK9: =AA9 -> 0.0012434729 | AL9: =AB9 -> -0.00011281199 | AM9: =AC9 -> -0.00027900983 | AN9: =AD9 -> -0.0006330498 | AR9: =A9 -> 39813 | AS9: =AF9*4+2 -> 0.75953925 | AT9: =AH9 -> 0.02241231 | AU9: =SUM(AV9:BA9) -> -0.0013024641 | AV9: =AI9 -> 7.0141609e-07 | AW9: =AJ9 -> -0.0015217668 | AX9: =AK9 -> 0.0012434729 | AY9: =AL9 -> -0.00011281199 | AZ9: =AM9 -> -0.00027900983 | BA9: =AN9 -> -0.0006330498 | BC9: =AR9 -> 39813 | BD9: =AT9 -> 0.02241231 | BE9: =AU9 -> -0.0013024641
A10: 39903 | B10: -0.0019454651 | C10: -0.0020700598 | D10: -0.190723 | E10: -1.6006965e-07 | F10: 0.24064261 | G10: -0.010410226 | H10: 5.9186259e-05 | I10: -0.45255197 | J10: -0.040579955 | K10: 0.025697384 | L10: 0.0014714383 | M10: 0 | N10: 0 | O10: 0.028632362 | P10: 0 | Q10: 0.00026107654 | R10: 0 | S10: 0 | T10: -0.61148125 | U10: 0 | V10: 0 | W10: 0 | X10: 0 | Y10: -0.017335051 | Z10: 0.00028225495 | AA10: 0.0015825516 | AB10: -0.00047262247 | AC10: -0.00092929223 | AD10: -0.0029323275 | AE10: 0.032789475 | AF10: -1.0185632 | AH10: =K10+Y10-Y10/100 -> 0.0085356841 | AI10: =Y10/1010 -> -1.7163416e-05 | AJ10: =Z10 -> 0.00028225495 | AK10: =AA10 -> 0.0015825516 | AL10: =AB10 -> -0.00047262247 | AM10: =AC10 -> -0.00092929223 | AN10: =AD10 -> -0.0029323275 | AR10: =A10 -> 39903 | AS10: =AF10*4+2 -> -2.074253 | AT10: =AH10 -> 0.0085356841 | AU10: =SUM(AV10:BA10) -> -0.0024865991 | AV10: =AI10 -> -1.7163416e-05 | AW10: =AJ10 -> 0.00028225495 | AX10: =AK10 -> 0.0015825516 | AY10: =AL10 -> -0.00047262247 | AZ10: =AM10 -> -0.00092929223 | BA10: =AN10 -> -0.0029323275 | BC10: =AR10 -> 39903 | BD10: =AT10 -> 0.0085356841 | BE10: =AU10 -> -0.0024865991
A11: 39994 | B11: -0.0020344507 | C11: -0.002721877 | D11: -0.17909841 | E11: -5.3592286e-08 | F11: 0.22222929 | G11: -0.010635415 | H11: -1.2502908e-05 | I11: -0.42127389 | J11: -0.029536743 | K11: 0.047202925 | L11: 0.0015929992 | M11: 0 | N11: 0 | O11: 0.029097626 | P11: 0 | Q11: 0.00016675153 | R11: 0 | S11: 0 | T11: -0.42917612 | U11: 0 | V11: 0 | W11: 0 | X11: 0 | Y11: -0.041929311 | Z11: 0.003121548 | AA11: 0.0014838274 | AB11: -0.001187285 | AC11: -0.0011340987 | AD11: -0.0063679069 | AE11: 0.032364504 | AF11: -0.80288902 | AH11: =K11+Y11-Y11/100 -> 0.0056929076 | AI11: =Y11/1010 -> -4.1514169e-05 | AJ11: =Z11 -> 0.003121548 | AK11: =AA11 -> 0.0014838274 | AL11: =AB11 -> -0.001187285 | AM11: =AC11 -> -0.0011340987 | AN11: =AD11 -> -0.0063679069 | AR11: =A11 -> 39994 | AS11: =AF11*4+2 -> -1.2115561 | AT11: =AH11 -> 0.0056929076 | AU11: =SUM(AV11:BA11) -> -0.0041254295 | AV11: =AI11 -> -4.1514169e-05 | AW11: =AJ11 -> 0.003121548 | AX11: =AK11 -> 0.0014838274 | AY11: =AL11 -> -0.001187285 | AZ11: =AM11 -> -0.0011340987 | BA11: =AN11 -> -0.0063679069 | BC11: =AR11 -> 39994 | BD11: =AT11 -> 0.0056929076 | BE11: =AU11 -> -0.0041254295
A12: 40086 | B12: -0.002067631 | C12: -0.00337687 | D12: -0.15673999 | E12: 2.3187976e-07 | F12: 0.19859034 | G12: -0.01073315 | H12: -2.8778658e-05 | I12: -0.042175304 | J12: -0.014411846 | K12: 0.069653433 | L12: 0.0015007486 | M12: 0 | N12: 0 | O12: 0.029915693 | P12: 0 | Q12: 0.00013276591 | R12: 0 | S12: 0 | T12: -1.2045993 | U12: 0 | V12: 0 | W12: 0 | X12: 0 | Y12: -0.060882389 | Z12: 0.0045827932 | AA12: 0.00087449553 | AB12: -0.0024357544 | AC12: -0.0019012159 | AD12: -0.011224735 | AE12: 0.031945867 | AF12: -1.19785 | AH12: =K12+Y12-Y12/100 -> 0.0093798676 | AI12: =Y12/1010 -> -6.0279593e-05 | AJ12: =Z12 -> 0.0045827932 | AK12: =AA12 -> 0.00087449553 | AL12: =AB12 -> -0.0024357544 | AM12: =AC12 -> -0.0019012159 | AN12: =AD12 -> -0.011224735 | AR12: =A12 -> 40086 | AS12: =AF12*4+2 -> -2.7913999 | AT12: =AH12 -> 0.0093798676 | AU12: =SUM(AV12:BA12) -> -0.010164697 | AV12: =AI12 -> -6.0279593e-05 | AW12: =AJ12 -> 0.0045827932 | AX12: =AK12 -> 0.00087449553 | AY12: =AL12 -> -0.0024357544 | AZ12: =AM12 -> -0.0019012159 | BA12: =AN12 -> -0.011224735 | BC12: =AR12 -> 40086 | BD12: =AT12 -> 0.0093798676 | BE12: =AU12 -> -0.010164697
A13: 40178 | B13: -0.0019039885 | C13: -0.0034857199 | D13: -0.13826055 | E13: 4.5224278e-07 | F13: 0.18680347 | G13: -0.010817037 | H13: -7.4483907e-06 | I13: -0.55025309 | J13: -0.0084786115 | K13: 0.085800489 | L13: 0.0014108205 | M13: 0 | N13: 0 | O13: 0.029825542 | P13: 0 | Q13: 0.00011992906 | R13: 0 | S13: 0 | T13: -0.66781616 | U13: 0 | V13: 0 | W13: 0 | X13: 0 | Y13: -0.075357566 | Z13: 0.0064716328 | AA13: 0.00040512964 | AB13: -0.0033562359 | AC13: -0.0019804733 | AD13: -0.016332099 | AE13: 0.031533427 | AF13: -1.1562081 | AH13: =K13+Y13-Y13/100 -> 0.011196499 | AI13: =Y13/1010 -> -7.4611451e-05 | AJ13: =Z13 -> 0.0064716328 | AK13: =AA13 -> 0.00040512964 | AL13: =AB13 -> -0.0033562359 | AM13: =AC13 -> -0.0019804733 | AN13: =AD13 -> -0.016332099 | AR13: =A13 -> 40178 | AS13: =AF13*4+2 -> -2.6248325 | AT13: =AH13 -> 0.011196499 | AU13: =SUM(AV13:BA13) -> -0.014866657 | AV13: =AI13 -> -7.4611451e-05 | AW13: =AJ13 -> 0.0064716328 | AX13: =AK13 -> 0.00040512964 | AY13: =AL13 -> -0.0033562359 | AZ13: =AM13 -> -0.0019804733 | BA13: =AN13 -> -0.016332099 | BC13: =AR13 -> 40178 | BD13: =AT13 -> 0.011196499 | BE13: =AU13 -> -0.014866657
A14: 40268 | B14: -0.001768788 | C14: -0.0035200668 | D14: -0.12706516 | E14: 5.26805e-07 | F14: 0.17185687 | G14: -0.010899309 | H14: -1.0561186e-05 | I14: -0.44949232 | J14: -0.011643689 | K14: 0.10182928 | L14: 0.0013920941 | M14: 0 | N14: 0 | O14: 0.030030724 | P14: 0 | Q14: 0.00010142116 | R14: 0 | S14: 0 | T14: -0.76982936 | U14: 0 | V14: 0 | W14: 0 | X14: 0 | Y14: -0.085165599 | Z14: 0.0094093821 | AA14: 0.0013787772 | AB14: -0.0031525209 | AC14: -0.0012348492 | AD14: -0.020652981 | AE14: 0.031127049 | AF14: -1.15807 | AH14: =K14+Y14-Y14/100 -> 0.017515336 | AI14: =Y14/1010 -> -8.4322375e-05 | AJ14: =Z14 -> 0.0094093821 | AK14: =AA14 -> 0.0013787772 | AL14: =AB14 -> -0.0031525209 | AM14: =AC14 -> -0.0012348492 | AN14: =AD14 -> -0.020652981 | AR14: =A14 -> 40268 | AS14: =AF14*4+2 -> -2.6322801 | AT14: =AH14 -> 0.017515336 | AU14: =SUM(AV14:BA14) -> -0.014336514 | AV14: =AI14 -> -8.4322375e-05 | AW14: =AJ14 -> 0.0094093821 | AX14: =AK14 -> 0.0013787772 | AY14: =AL14 -> -0.0031525209 | AZ14: =AM14 -> -0.0012348492 | BA14: =AN14 -> -0.020652981 | BC14: =AR14 -> 40268 | BD14: =AT14 -> 0.017515336 | BE14: =AU14 -> -0.014336514
A15: 40359 | B15: -0.0016055442 | C15: -0.0034126173 | D15: -0.12024167 | E15: 6.1831082e-07 | F15: 0.14974555 | G15: -0.010999744 | H15: 1.1225093e-05 | I15: -0.3859079 | J15: -0.010546563 | K15: 0.1137369 | L15: 0.0012674654 | M15: 0 | N15: 0 | O15: 0.03029255 | P15: 0 | Q15: 8.5443216e-05 | R15: 0 | S15: 0 | T15: -0.74550929 | U15: 0 | V15: 0 | W15: 0 | X15: 0 | Y15: -0.094219354 | Z15: 0.012620793 | AA15: 0.0037813698 | AB15: -0.0012855556 | AC15: 0.00056690679 | AD15: -0.023176605 | AE15: 0.030726605 | AF15: -1.0735987 | AH15: =K15+Y15-Y15/100 -> 0.02045974 | AI15: =Y15/1010 -> -9.3286489e-05 | AJ15: =Z15 -> 0.012620793 | AK15: =AA15 -> 0.0037813698 | AL15: =AB15 -> -0.0012855556 | AM15: =AC15 -> 0.00056690679 | AN15: =AD15 -> -0.023176605 | AR15: =A15 -> 40359 | AS15: =AF15*4+2 -> -2.2943948 | AT15: =AH15 -> 0.02045974 | AU15: =SUM(AV15:BA15) -> -0.007586378 | AV15: =AI15 -> -9.3286489e-05 | AW15: =AJ15 -> 0.012620793 | AX15: =AK15 -> 0.0037813698 | AY15: =AL15 -> -0.0012855556 | AZ15: =AM15 -> 0.00056690679 | BA15: =AN15 -> -0.023176605 | BC15: =AR15 -> 40359 | BD15: =AT15 -> 0.02045974 | BE15: =AU15 -> -0.007586378
A16: 40451 | B16: -0.0015195804 | C16: -0.0032687084 | D16: -0.1153459 | E16: 7.2160802e-07 | F16: 0.14285232 | G16: -0.011072744 | H16: 8.8154421e-06 | I16: 0.030795735 | J16: -0.015183955 | K16: 0.12312668 | L16: 0.0013868123 | M16: 0 | N16: 0 | O16: 0.031305321 | P16: 0 | Q16: 5.5392826e-05 | R16: 0 | S16: 0 | T16: -0.77668895 | U16: 0 | V16: 0 | W16: 0 | X16: 0 | Y16: -0.1056787 | Z16: 0.014564632 | AA16: 0.004651098 | AB16: -0.00028653286 | AC16: 0.0016313845 | AD16: -0.024586607 | AE16: 0.030331971 | AF16: -0.6876071 | AH16: =K16+Y16-Y16/100 -> 0.018504761 | AI16: =Y16/1010 -> -0.00010463238 | AJ16: =Z16 -> 0.014564632 | AK16: =AA16 -> 0.004651098 | AL16: =AB16 -> -0.00028653286 | AM16: =AC16 -> 0.0016313845 | AN16: =AD16 -> -0.024586607 | AR16: =A16 -> 40451 | AS16: =AF16*4+2 -> -0.75042838 | AT16: =AH16 -> 0.018504761 | AU16: =SUM(AV16:BA16) -> -0.0041306584 | AV16: =AI16 -> -0.00010463238 | AW16: =AJ16 -> 0.014564632 | AX16: =AK16 -> 0.004651098 | AY16: =AL16 -> -0.00028653286 | AZ16: =AM16 -> 0.0016313845 | BA16: =AN16 -> -0.024586607 | BC16: =AR16 -> 40451 | BD16: =AT16 -> 0.018504761 | BE16: =AU16 -> -0.0041306584
A17: 40543 | B17: -0.0013371114 | C17: -0.0030069557 | D17: -0.11680429 | E17: 7.5777917e-07 | F17: 0.1604768 | G17: -0.011130844 | H17: -1.3967529e-05 | I17: -0.53120714 | J17: -0.020569429 | K17: 0.13514114 | L17: 0.0013693178 | M17: 0 | N17: 0 | O17: 0.031637455 | P17: 0 | Q17: 2.1527973e-05 | R17: 0 | S17: 0 | T17: -0.1423499 | U17: 0 | V17: 0 | W17: 0 | X17: 0 | Y17: -0.12188145 | Z17: 0.016047211 | AA17: 0.0046091224 | AB17: -0.0002321107 | AC17: 0.0015502993 | AD17: -0.026035114 | AE17: 0.029943024 | AF17: -0.60589549 | AH17: =K17+Y17-Y17/100 -> 0.014478505 | AI17: =Y17/1010 -> -0.00012067471 | AJ17: =Z17 -> 0.016047211 | AK17: =AA17 -> 0.0046091224 | AL17: =AB17 -> -0.0002321107 | AM17: =AC17 -> 0.0015502993 | AN17: =AD17 -> -0.026035114 | AR17: =A17 -> 40543 | AS17: =AF17*4+2 -> -0.42358195 | AT17: =AH17 -> 0.014478505 | AU17: =SUM(AV17:BA17) -> -0.0041812674 | AV17: =AI17 -> -0.00012067471 | AW17: =AJ17 -> 0.016047211 | AX17: =AK17 -> 0.0046091224 | AY17: =AL17 -> -0.0002321107 | AZ17: =AM17 -> 0.0015502993 | BA17: =AN17 -> -0.026035114 | BC17: =AR17 -> 40543 | BD17: =AT17 -> 0.014478505 | BE17: =AU17 -> -0.0041812674
A18: 40633 | B18: -0.001532286 | C18: -0.0030637023 | D18: -0.12140879 | E18: 1.0029129e-06 | F18: 0.19879283 | G18: -0.01119554 | H18: -2.7882324e-05 | I18: -0.18688172 | J18: -0.015301681 | K18: 0.15058927 | L18: 0.0012852384 | M18: 0 | N18: 0 | O18: 0.032742452 | P18: 0 | Q18: 1.4912948e-05 | R18: 0 | S18: 0 | T18: -0.13549147 | U18: 0 | V18: 0 | W18: 0 | X18: 0 | Y18: -0.14325903 | Z18: 0.015494468 | AA18: 0.0021559779 | AB18: -0.0022332803 | AC18: -0.00024279061 | AD18: -0.028997077 | AE18: 0.029559647 | AF18: -0.22396376 | AH18: =K18+Y18-Y18/100 -> 0.0087628235 | AI18: =Y18/1010 -> -0.00014184063 | AJ18: =Z18 -> 0.015494468 | AK18: =AA18 -> 0.0021559779 | AL18: =AB18 -> -0.0022332803 | AM18: =AC18 -> -0.00024279061 | AN18: =AD18 -> -0.028997077 | AR18: =A18 -> 40633 | AS18: =AF18*4+2 -> 1.104145 | AT18: =AH18 -> 0.0087628235 | AU18: =SUM(AV18:BA18) -> -0.013964543 | AV18: =AI18 -> -0.00014184063 | AW18: =AJ18 -> 0.015494468 | AX18: =AK18 -> 0.0021559779 | AY18: =AL18 -> -0.0022332803 | AZ18: =AM18 -> -0.00024279061 | BA18: =AN18 -> -0.028997077 | BC18: =AR18 -> 40633 | BD18: =AT18 -> 0.0087628235 | BE18: =AU18 -> -0.013964543
A19: 40724 | B19: -0.0013887264 | C19: -0.0026312904 | D19: -0.11897872 | E19: 1.2248825e-06 | F19: 0.22837771 | G19: -0.011258261 | H19: 2.002581e-05 | I19: -0.30315083 | J19: -0.011646391 | K19: 0.16881612 | L19: 0.0013859892 | M19: 0 | N19: 0 | O19: 0.033785775 | P19: 0 | Q19: 2.0237128e-05 | R19: 0 | S19: 0 | T19: 0.07829521 | U19: 0 | V19: 0 | W19: 0 | X19: 0 | Y19: -0.1718397 | Z19: 0.016461217 | AA19: 0.00069928078 | AB19: -0.0031950007 | AC19: -0.00097890427 | AD19: -0.032208723 | AE19: 0.029181729 | AF19: -0.10335766 | AH19: =K19+Y19-Y19/100 -> -0.001305185 | AI19: =Y19/1010 -> -0.00017013832 | AJ19: =Z19 -> 0.016461217 | AK19: =AA19 -> 0.00069928078 | AL19: =AB19 -> -0.0031950007 | AM19: =AC19 -> -0.00097890427 | AN19: =AD19 -> -0.032208723 | AR19: =A19 -> 40724 | AS19: =AF19*4+2 -> 1.5865694 | AT19: =AH19 -> -0.001305185 | AU19: =SUM(AV19:BA19) -> -0.019392268 | AV19: =AI19 -> -0.00017013832 | AW19: =AJ19 -> 0.016461217 | AX19: =AK19 -> 0.00069928078 | AY19: =AL19 -> -0.0031950007 | AZ19: =AM19 -> -0.00097890427 | BA19: =AN19 -> -0.032208723 | BC19: =AR19 -> 40724 | BD19: =AT19 -> -0.001305185 | BE19: =AU19 -> -0.019392268
A20: 40816 | B20: -0.0015124037 | C20: -0.0024314791 | D20: -0.11554017 | E20: 1.2930845e-06 | F20: 0.18396915 | G20: -0.01133035 | H20: -1.4453412e-05 | I20: -0.059234404 | J20: -0.015603639 | K20: 0.19455535 | L20: 0.0014810747 | M20: 0 | N20: 0 | O20: 0.034028768 | P20: 0 | Q20: -4.934565e-06 | R20: 0 | S20: 0 | T20: -0.10252246 | U20: 0 | V20: 0 | W20: 0 | X20: 0 | Y20: -0.19596717 | Z20: 0.022855452 | AA20: 0.0035417646 | AB20: -0.00062814047 | AC20: 0.0010605802 | AD20: -0.033246181 | AE20: 0.028809157 | AF20: -0.069799206 | AH20: =K20+Y20-Y20/100 -> 0.00054784675 | AI20: =Y20/1010 -> -0.0001940269 | AJ20: =Z20 -> 0.022855452 | AK20: =AA20 -> 0.0035417646 | AL20: =AB20 -> -0.00062814047 | AM20: =AC20 -> 0.0010605802 | AN20: =AD20 -> -0.033246181 | AR20: =A20 -> 40816 | AS20: =AF20*4+2 -> 1.7208032 | AT20: =AH20 -> 0.00054784675 | AU20: =SUM(AV20:BA20) -> -0.0066105514 | AV20: =AI20 -> -0.0001940269 | AW20: =AJ20 -> 0.022855452 | AX20: =AK20 -> 0.0035417646 | AY20: =AL20 -> -0.00062814047 | AZ20: =AM20 -> 0.0010605802 | BA20: =AN20 -> -0.033246181 | BC20: =AR20 -> 40816 | BD20: =AT20 -> 0.00054784675 | BE20: =AU20 -> -0.0066105514
... A132: 51043 | B132: -0.043141873 | C132: -0.00014191675 | D132: -0.060150045 | E132: 0.00016375639 | F132: 0.077003819 | G132: -0.017761409 | H132: 0.10657899 | I132: -0.12938709 | J132: -0.23383062 | K132: -0.0013647494 | L132: 0.028622522 | M132: 0 | N132: 0 | O132: 0.44750605 | P132: 0 | Q132: 0.30446726 | R132: 0 | S132: 0 | T132: 0 | U132: 0 | V132: 0 | W132: 0 | X132: 0 | Y132: 0.0014171204 | Z132: -0.0014470184 | AA132: 0.00054189822 | AB132: -0.00029329794 | AC132: 0.0013717805 | AD132: 0.0037302372 | AE132: -0.072867892 | AF132: 0.418171 | AH132: =K132+Y132-Y132/100 -> 3.8199787e-05 | AI132: =Y132/1010 -> 1.4030895e-06 | AJ132: =Z132 -> -0.0014470184 | AK132: =AA132 -> 0.00054189822 | AL132: =AB132 -> -0.00029329794 | AM132: =AC132 -> 0.0013717805 | AN132: =AD132 -> 0.0037302372 | AR132: =A132 -> 51043 | AS132: =AF132*4+2 -> 3.672684 | AT132: =AH132 -> 3.8199787e-05 | AU132: =SUM(AV132:BA132) -> 0.0039050027 | AV132: =AI132 -> 1.4030895e-06 | AW132: =AJ132 -> -0.0014470184 | AX132: =AK132 -> 0.00054189822 | AY132: =AL132 -> -0.00029329794 | AZ132: =AM132 -> 0.0013717805 | BA132: =AN132 -> 0.0037302372 | BC132: =AR132 -> 51043 | BD132: =AT132 -> 3.8199787e-05 | BE132: =AU132 -> 0.0039050027

Sheet EA_raw_policy_shocks
A1: date | C1: Monetary Policy | D1: FG1 | E1: FG2 | F1: FG3 | G1: FG4 | H1: FG5 | I1: FG6 | L1: Date | M1: Monetary Policy | N1: FG1 | O1: FG2 | P1: FG3 | Q1: FG4 | R1: FG5 | S1: FG6
A2: 26480 | C2: -0.13372599 | D2: -7.0937759e-15 | E2: 6.1916191e-16 | F2: -4.0637422e-15 | G2: -7.7242506e-15 | H2: -7.0753749e-15 | I2: 9.7413678e-16 | M2: =C2 -> -0.13372599 | N2: =D2/10 -> -7.0937759e-16 | O2: =E2 -> 6.1916191e-16 | P2: =F2 -> -4.0637422e-15 | Q2: =G2 -> -7.7242506e-15 | R2: =H2 -> -7.0753749e-15 | S2: =I2 -> 9.7413678e-16
A3: 26572 | C3: -0.32978154 | D3: -6.9791533e-15 | E3: -2.3362694e-16 | F3: -2.8572172e-15 | G3: -7.2602506e-15 | H3: -5.9936663e-15 | I3: 1.3121579e-16 | M3: =C3 -> -0.32978154 | N3: =D3/10 -> -6.9791533e-16 | O3: =E3 -> -2.3362694e-16 | P3: =F3 -> -2.8572172e-15 | Q3: =G3 -> -7.2602506e-15 | R3: =H3 -> -5.9936663e-15 | S3: =I3 -> 1.3121579e-16
A4: 26664 | C4: 0.25187082 | D4: -8.386221e-15 | E4: 4.8258192e-16 | F4: -2.7999737e-15 | G4: -6.2051305e-15 | H4: -6.7020971e-15 | I4: 1.0800576e-16 | M4: =C4 -> 0.25187082 | N4: =D4/10 -> -8.386221e-16 | O4: =E4 -> 4.8258192e-16 | P4: =F4 -> -2.7999737e-15 | Q4: =G4 -> -6.2051305e-15 | R4: =H4 -> -6.7020971e-15 | S4: =I4 -> 1.0800576e-16
A5: 26754 | C5: 0.03359876 | D5: -7.7139114e-15 | E5: 5.2390174e-16 | F5: -1.7790139e-15 | G5: -7.4373859e-15 | H5: -7.7448034e-15 | I5: -3.6196971e-16 | M5: =C5 -> 0.03359876 | N5: =D5/10 -> -7.7139114e-16 | O5: =E5 -> 5.2390174e-16 | P5: =F5 -> -1.7790139e-15 | Q5: =G5 -> -7.4373859e-15 | R5: =H5 -> -7.7448034e-15 | S5: =I5 -> -3.6196971e-16
A6: 26845 | C6: 0.29482685 | D6: -7.6968198e-15 | E6: 2.0333413e-15 | F6: -2.3580494e-15 | G6: -7.6039765e-15 | H6: -7.1909983e-15 | I6: 5.5837779e-16 | M6: =C6 -> 0.29482685 | N6: =D6/10 -> -7.6968198e-16 | O6: =E6 -> 2.0333413e-15 | P6: =F6 -> -2.3580494e-15 | Q6: =G6 -> -7.6039765e-15 | R6: =H6 -> -7.1909983e-15 | S6: =I6 -> 5.5837779e-16
A7: 26937 | C7: 0.40092867 | D7: -6.696605e-15 | E7: 9.0186821e-16 | F7: -2.9334294e-15 | G7: -7.6070683e-15 | H7: -7.1271962e-15 | I7: -6.7705197e-17 | M7: =C7 -> 0.40092867 | N7: =D7/10 -> -6.696605e-16 | O7: =E7 -> 9.0186821e-16 | P7: =F7 -> -2.9334294e-15 | Q7: =G7 -> -7.6070683e-15 | R7: =H7 -> -7.1271962e-15 | S7: =I7 -> -6.7705197e-17
A8: 27029 | C8: -0.017830037 | D8: -7.6991443e-15 | E8: 5.7668906e-16 | F8: -2.6337783e-15 | G8: -7.7697419e-15 | H8: -8.480101e-15 | I8: -3.0600183e-16 | M8: =C8 -> -0.017830037 | N8: =D8/10 -> -7.6991443e-16 | O8: =E8 -> 5.7668906e-16 | P8: =F8 -> -2.6337783e-15 | Q8: =G8 -> -7.7697419e-15 | R8: =H8 -> -8.480101e-15 | S8: =I8 -> -3.0600183e-16
A9: 27119 | C9: 0.010781378 | D9: -8.0047356e-15 | E9: 1.0700406e-15 | F9: -2.4008864e-15 | G9: -8.6493955e-15 | H9: -8.3859727e-15 | I9: 2.3217865e-16 | M9: =C9 -> 0.010781378 | N9: =D9/10 -> -8.0047356e-16 | O9: =E9 -> 1.0700406e-15 | P9: =F9 -> -2.4008864e-15 | Q9: =G9 -> -8.6493955e-15 | R9: =H9 -> -8.3859727e-15 | S9: =I9 -> 2.3217865e-16
A10: 27210 | C10: -0.137027 | D10: -7.4558942e-15 | E10: 9.8099133e-16 | F10: -4.0956519e-15 | G10: -9.72435e-15 | H10: -9.0499551e-15 | I10: -1.0055611e-15 | M10: =C10 -> -0.137027 | N10: =D10/10 -> -7.4558942e-16 | O10: =E10 -> 9.8099133e-16 | P10: =F10 -> -4.0956519e-15 | Q10: =G10 -> -9.72435e-15 | R10: =H10 -> -9.0499551e-15 | S10: =I10 -> -1.0055611e-15
A11: 27302 | C11: 0.032328036 | D11: -7.4117278e-15 | E11: -1.1286932e-16 | F11: -3.9612004e-15 | G11: -8.5412236e-15 | H11: -8.2672821e-15 | I11: 9.3170634e-16 | M11: =C11 -> 0.032328036 | N11: =D11/10 -> -7.4117278e-16 | O11: =E11 -> -1.1286932e-16 | P11: =F11 -> -3.9612004e-15 | Q11: =G11 -> -8.5412236e-15 | R11: =H11 -> -8.2672821e-15 | S11: =I11 -> 9.3170634e-16
A12: 27394 | C12: -0.035677399 | D12: -8.753826e-15 | E12: -1.0175977e-15 | F12: -4.5950315e-15 | G12: -1.0287227e-14 | H12: -9.1584751e-15 | I12: -1.6462595e-15 | M12: =C12 -> -0.035677399 | N12: =D12/10 -> -8.753826e-16 | O12: =E12 -> -1.0175977e-15 | P12: =F12 -> -4.5950315e-15 | Q12: =G12 -> -1.0287227e-14 | R12: =H12 -> -9.1584751e-15 | S12: =I12 -> -1.6462595e-15
A13: 27484 | C13: -0.46076124 | D13: -9.015226e-15 | E13: -6.9339322e-16 | F13: -4.9091102e-15 | G13: -9.3953792e-15 | H13: -9.8120895e-15 | I13: 1.6577716e-16 | M13: =C13 -> -0.46076124 | N13: =D13/10 -> -9.015226e-16 | O13: =E13 -> -6.9339322e-16 | P13: =F13 -> -4.9091102e-15 | Q13: =G13 -> -9.3953792e-15 | R13: =H13 -> -9.8120895e-15 | S13: =I13 -> 1.6577716e-16
... A140: 39082 | C140: 0.049165061 | D140: -1.0486407e-14 | E140: 2.2068117e-15 | F140: -5.328786e-15 | G140: -1.7011581e-14 | H140: -1.6342592e-14 | I140: 3.0560804e-16 | M140: =C140 -> 0.049165061 | N140: =D140/10 -> -1.0486407e-15 | O140: =E140 -> 2.2068117e-15 | P140: =F140 -> -5.328786e-15 | Q140: =G140 -> -1.7011581e-14 | R140: =H140 -> -1.6342592e-14 | S140: =I140 -> 3.0560804e-16
A141: 39172 | B141: 1q07 | C141: 0.096451189 | D141: -9.9673708e-15 | E141: 2.2930298e-15 | F141: -5.4823221e-15 | G141: -1.7146264e-14 | H141: -1.604325e-14 | I141: 3.4385437e-16 | L141: ="20"&RIGHT(B141,2)&"Q"&LEFT(B141,1) -> 2007Q1 | M141: =C141 -> 0.096451189 | N141: =D141/10 -> -9.9673708e-16 | O141: =E141 -> 2.2930298e-15 | P141: =F141 -> -5.4823221e-15 | Q141: =G141 -> -1.7146264e-14 | R141: =H141 -> -1.604325e-14 | S141: =I141 -> 3.4385437e-16 | AE141: =M141 -> 0.096451189 | AF141: =N141 -> -9.9673708e-16 | AG141: =O141 -> 2.2930298e-15 | AH141: =P141 -> -5.4823221e-15 | AI141: =Q141 -> -1.7146264e-14 | AJ141: =R141 -> -1.604325e-14 | AK141: =S141 -> 3.4385437e-16
A142: 39263 | B142: 2q07 | C142: -0.079942737 | D142: -9.9527803e-15 | E142: 2.0189506e-15 | F142: -5.8984503e-15 | G142: -1.6954323e-14 | H142: -1.5795915e-14 | I142: 1.3532937e-16 | L142: ="20"&RIGHT(B142,2)&"Q"&LEFT(B142,1) -> 2007Q2 | M142: =C142 -> -0.079942737 | N142: =D142/10 -> -9.9527803e-16 | O142: =E142 -> 2.0189506e-15 | P142: =F142 -> -5.8984503e-15 | Q142: =G142 -> -1.6954323e-14 | R142: =H142 -> -1.5795915e-14 | S142: =I142 -> 1.3532937e-16 | AE142: =M142 -> -0.079942737 | AF142: =N142 -> -9.9527803e-16 | AG142: =O142 -> 2.0189506e-15 | AH142: =P142 -> -5.8984503e-15 | AI142: =Q142 -> -1.6954323e-14 | AJ142: =R142 -> -1.5795915e-14 | AK142: =S142 -> 1.3532937e-16
A143: 39355 | B143: 3q07 | C143: 0.036631347 | D143: -1.1471632e-14 | E143: 1.30004e-15 | F143: -5.730854e-15 | G143: -1.6034603e-14 | H143: -1.4791452e-14 | I143: 8.9944721e-16 | L143: ="20"&RIGHT(B143,2)&"Q"&LEFT(B143,1) -> 2007Q3 | M143: =C143 -> 0.036631347 | N143: =D143/10 -> -1.1471632e-15 | O143: =E143 -> 1.30004e-15 | P143: =F143 -> -5.730854e-15 | Q143: =G143 -> -1.6034603e-14 | R143: =H143 -> -1.4791452e-14 | S143: =I143 -> 8.9944721e-16 | AE143: =M143 -> 0.036631347 | AF143: =N143 -> -1.1471632e-15 | AG143: =O143 -> 1.30004e-15 | AH143: =P143 -> -5.730854e-15 | AI143: =Q143 -> -1.6034603e-14 | AJ143: =R143 -> -1.4791452e-14 | AK143: =S143 -> 8.9944721e-16
A144: 39447 | B144: 4q07 | C144: -0.073000196 | D144: -1.2732741e-14 | E144: 1.4612799e-15 | F144: -4.0269544e-15 | G144: -1.4985715e-14 | H144: -1.529939e-14 | I144: 8.3454599e-16 | L144: ="20"&RIGHT(B144,2)&"Q"&LEFT(B144,1) -> 2007Q4 | M144: =C144 -> -0.073000196 | N144: =D144/10 -> -1.2732741e-15 | O144: =E144 -> 1.4612799e-15 | P144: =F144 -> -4.0269544e-15 | Q144: =G144 -> -1.4985715e-14 | R144: =H144 -> -1.529939e-14 | S144: =I144 -> 8.3454599e-16 | AD144: =LEFT(L144,4)+1 -> 2008 | AE144: =M144 -> -0.073000196 | AF144: =N144 -> -1.2732741e-15 | AG144: =O144 -> 1.4612799e-15 | AH144: =P144 -> -4.0269544e-15 | AI144: =Q144 -> -1.4985715e-14 | AJ144: =R144 -> -1.529939e-14 | AK144: =S144 -> 8.3454599e-16
A145: 39538 | B145: 1q08 | C145: -0.12232583 | D145: -1.4382912e-14 | E145: 2.6126614e-15 | F145: -3.1597493e-15 | G145: -1.5646211e-14 | H145: -1.5686843e-14 | I145: 7.5415734e-16 | L145: ="20"&RIGHT(B145,2)&"Q"&LEFT(B145,1) -> 2008Q1 | M145: =C145 -> -0.12232583 | N145: =D145/10 -> -1.4382912e-15 | O145: =E145 -> 2.6126614e-15 | P145: =F145 -> -3.1597493e-15 | Q145: =G145 -> -1.5646211e-14 | R145: =H145 -> -1.5686843e-14 | S145: =I145 -> 7.5415734e-16 | AD145: =LEFT(L145,4)+1 -> 2009 | AE145: =M145 -> -0.12232583 | AF145: =N145 -> -1.4382912e-15 | AG145: =O145 -> 2.6126614e-15 | AH145: =P145 -> -3.1597493e-15 | AI145: =Q145 -> -1.5646211e-14 | AJ145: =R145 -> -1.5686843e-14 | AK145: =S145 -> 7.5415734e-16
A146: 39629 | B146: 2q08 | C146: 0.085616678 | D146: -1.2574437e-14 | E146: 3.865563e-15 | F146: -2.3516121e-15 | G146: -1.6436028e-14 | H146: -1.9011273e-14 | I146: 1.6098045e-16 | L146: ="20"&RIGHT(B146,2)&"Q"&LEFT(B146,1) -> 2008Q2 | M146: =C146 -> 0.085616678 | N146: =D146/10 -> -1.2574437e-15 | O146: =E146 -> 3.865563e-15 | P146: =F146 -> -2.3516121e-15 | Q146: =G146 -> -1.6436028e-14 | R146: =H146 -> -1.9011273e-14 | S146: =I146 -> 1.6098045e-16 | AD146: =LEFT(L146,4)+1 -> 2009 | AE146: =M146 -> 0.085616678 | AF146: =N146 -> -1.2574437e-15 | AG146: =O146 -> 3.865563e-15 | AH146: =P146 -> -2.3516121e-15 | AI146: =Q146 -> -1.6436028e-14 | AJ146: =R146 -> -1.9011273e-14 | AK146: =S146 -> 1.6098045e-16
A147: 39721 | B147: 3q08 | C147: 0.024114352 | D147: -1.3427455e-14 | E147: 3.8170215e-15 | F147: -3.918892e-15 | G147: -1.9226514e-14 | H147: -1.7675893e-14 | I147: 7.3930435e-16 | L147: ="20"&RIGHT(B147,2)&"Q"&LEFT(B147,1) -> 2008Q3 | M147: =C147 -> 0.024114352 | N147: =D147/10 -> -1.3427455e-15 | O147: =E147 -> 3.8170215e-15 | P147: =F147 -> -3.918892e-15 | Q147: =G147 -> -1.9226514e-14 | R147: =H147 -> -1.7675893e-14 | S147: =I147 -> 7.3930435e-16 | AD147: =LEFT(L147,4)+1 -> 2009 | AE147: =M147 -> 0.024114352 | AF147: =N147 -> -1.3427455e-15 | AG147: =O147 -> 3.8170215e-15 | AH147: =P147 -> -3.918892e-15 | AI147: =Q147 -> -1.9226514e-14 | AJ147: =R147 -> -1.7675893e-14 | AK147: =S147 -> 7.3930435e-16
A148: 39813 | B148: 4q08 | C148: 0.054270209 | D148: -0.02758659 | E148: 0.057226894 | F148: -0.045349997 | G148: 0.0040063363 | H148: 0.0096842244 | I148: 0.021546318 | L148: ="20"&RIGHT(B148,2)&"Q"&LEFT(B148,1) -> 2008Q4 | M148: =C148 -> 0.054270209 | N148: =D148/10 -> -0.002758659 | O148: =E148 -> 0.057226894 | P148: =F148 -> -0.045349997 | Q148: =G148 -> 0.0040063363 | R148: =H148 -> 0.0096842244 | S148: =I148 -> 0.021546318 | AD148: =LEFT(L148,4)+1 -> 2009 | AE148: =M148 -> 0.054270209 | AF148: =N148 -> -0.002758659 | AG148: =O148 -> 0.057226894 | AH148: =P148 -> -0.045349997 | AI148: =Q148 -> 0.0040063363 | AJ148: =R148 -> 0.0096842244 | AK148: =S148 -> 0.021546318
A149: 39903 | B149: 1q09 | C149: -0.23276322 | D149: 0.7701374 | E149: -0.13446309 | F149: 0.0085426888 | G149: 0.020965193 | H149: 0.040489408 | I149: 0.070169286 | L149: ="20"&RIGHT(B149,2)&"Q"&LEFT(B149,1) -> 2009Q1 | M149: =C149 -> -0.23276322 | N149: =D149/10 -> 0.07701374 | O149: =E149 -> -0.13446309 | P149: =F149 -> 0.0085426888 | Q149: =G149 -> 0.020965193 | R149: =H149 -> 0.040489408 | S149: =I149 -> 0.070169286 | AD149: =LEFT(L149,4)+1 -> 2010 | AE149: =M149 -> -0.23276322 | AF149: =N149 -> 0.07701374 | AG149: =O149 -> -0.13446309 | AH149: =P149 -> 0.0085426888 | AI149: =Q149 -> 0.020965193 | AJ149: =R149 -> 0.040489408 | AK149: =S149 -> 0.070169286
A150: 39994 | B150: 2q09 | C150: -0.087880247 | D150: 0.56265234 | E150: -0.072336955 | F150: 0.028689131 | G150: 0.061132871 | H150: 0.068904315 | I150: 0.087714356 | L150: ="20"&RIGHT(B150,2)&"Q"&LEFT(B150,1) -> 2009Q2 | M150: =C150 -> -0.087880247 | N150: =D150/10 -> 0.056265234 | O150: =E150 -> -0.072336955 | P150: =F150 -> 0.028689131 | Q150: =G150 -> 0.061132871 | R150: =H150 -> 0.068904315 | S150: =I150 -> 0.087714356 | AD150: =LEFT(L150,4)+1 -> 2010 | AE150: =M150 -> -0.087880247 | AF150: =N150 -> 0.056265234 | AG150: =O150 -> -0.072336955 | AH150: =P150 -> 0.028689131 | AI150: =Q150 -> 0.061132871 | AJ150: =R150 -> 0.068904315 | AK150: =S150 -> 0.087714356
A151: 40086 | B151: 3q09 | C151: -0.053379596 | D151: 0.31932821 | E151: 0.013424012 | F151: 0.081292299 | G151: 0.10392751 | H151: 0.11197047 | I151: 0.12219401 | L151: ="20"&RIGHT(B151,2)&"Q"&LEFT(B151,1) -> 2009Q3 | M151: =C151 -> -0.053379596 | N151: =D151/10 -> 0.031932821 | O151: =E151 -> 0.013424012 | P151: =F151 -> 0.081292299 | Q151: =G151 -> 0.10392751 | R151: =H151 -> 0.11197047 | S151: =I151 -> 0.12219401 | AD151: =LEFT(L151,4)+1 -> 2010 | AE151: =M151 -> -0.053379596 | AF151: =N151 -> 0.031932821 | AG151: =O151 -> 0.013424012 | AH151: =P151 -> 0.081292299 | AI151: =Q151 -> 0.10392751 | AJ151: =R151 -> 0.11197047 | AK151: =S151 -> 0.12219401
A152: 40178 | B152: 4q09 | C152: -0.033873189 | D152: 0.32518556 | E152: 0.029346754 | F152: 0.11197614 | G152: 0.12854045 | H152: 0.11538989 | I152: 0.11362157 | L152: ="20"&RIGHT(B152,2)&"Q"&LEFT(B152,1) -> 2009Q4 | M152: =C152 -> -0.033873189 | N152: =D152/10 -> 0.032518556 | O152: =E152 -> 0.029346754 | P152: =F152 -> 0.11197614 | Q152: =G152 -> 0.12854045 | R152: =H152 -> 0.11538989 | S152: =I152 -> 0.11362157 | AD152: =LEFT(L152,4)+1 -> 2010 | AE152: =M152 -> -0.033873189 | AF152: =N152 -> 0.032518556 | AG152: =O152 -> 0.029346754 | AH152: =P152 -> 0.11197614 | AI152: =Q152 -> 0.12854045 | AJ152: =R152 -> 0.11538989 | AK152: =S152 -> 0.11362157
A153: 40268 | B153: 1q10 | C153: -0.12772884 | D153: 0.23528331 | E153: 0.025662304 | F153: 0.086055391 | G153: 0.096898318 | H153: 0.08742842 | I153: 0.085280084 | L153: ="20"&RIGHT(B153,2)&"Q"&LEFT(B153,1) -> 2010Q1 | M153: =C153 -> -0.12772884 | N153: =D153/10 -> 0.023528331 | O153: =E153 -> 0.025662304 | P153: =F153 -> 0.086055391 | Q153: =G153 -> 0.096898318 | R153: =H153 -> 0.08742842 | S153: =I153 -> 0.085280084 | AD153: =LEFT(L153,4)+1 -> 2011 | AE153: =M153 -> -0.12772884 | AF153: =N153 -> 0.023528331 | AG153: =O153 -> 0.025662304 | AH153: =P153 -> 0.086055391 | AI153: =Q153 -> 0.096898318 | AJ153: =R153 -> 0.08742842 | AK153: =S153 -> 0.085280084
A154: 40359 | B154: 2q10 | C154: -0.075634628 | D154: 0.27915299 | E154: 0.0030318924 | F154: 0.02212539 | G154: 0.025268456 | H154: 0.033297534 | I154: 0.036133974 | L154: ="20"&RIGHT(B154,2)&"Q"&LEFT(B154,1) -> 2010Q2 | M154: =C154 -> -0.075634628 | N154: =D154/10 -> 0.027915299 | O154: =E154 -> 0.0030318924 | P154: =F154 -> 0.02212539 | Q154: =G154 -> 0.025268456 | R154: =H154 -> 0.033297534 | S154: =I154 -> 0.036133974 | AD154: =LEFT(L154,4)+1 -> 2011 | AE154: =M154 -> -0.075634628 | AF154: =N154 -> 0.027915299 | AG154: =O154 -> 0.0030318924 | AH154: =P154 -> 0.02212539 | AI154: =Q154 -> 0.025268456 | AJ154: =R154 -> 0.033297534 | AK154: =S154 -> 0.036133974
A155: 40451 | B155: 3q10 | C155: 0.0049105092 | D155: 0.36839622 | E155: -0.010999363 | F155: 0.025502412 | G155: 0.024168257 | H155: 0.023356494 | I155: 0.023256193 | L155: ="20"&RIGHT(B155,2)&"Q"&LEFT(B155,1) -> 2010Q3 | M155: =C155 -> 0.0049105092 | N155: =D155/10 -> 0.036839622 | O155: =E155 -> -0.010999363 | P155: =F155 -> 0.025502412 | Q155: =G155 -> 0.024168257 | R155: =H155 -> 0.023356494 | S155: =I155 -> 0.023256193 | AD155: =LEFT(L155,4)+1 -> 2011 | AE155: =M155 -> 0.0049105092 | AF155: =N155 -> 0.036839622 | AG155: =O155 -> -0.010999363 | AH155: =P155 -> 0.025502412 | AI155: =Q155 -> 0.024168257 | AJ155: =R155 -> 0.023356494 | AK155: =S155 -> 0.023256193
... A210: 45473 | B210: 2q24 | C210: 0.037578746 | D210: -0.1767428 | E210: -0.067586547 | F210: -0.040001519 | G210: -0.020410624 | H210: -0.0095734509 | I210: -0.0028966043 | L210: ="20"&RIGHT(B210,2)&"Q"&LEFT(B210,1) -> 2024Q2 | M210: =C210 -> 0.037578746 | N210: =D210/10 -> -0.01767428 | O210: =E210 -> -0.067586547 | P210: =F210 -> -0.040001519 | Q210: =G210 -> -0.020410624 | R210: =H210 -> -0.0095734509 | S210: =I210 -> -0.0028966043 | AD210: =LEFT(L210,4)+1 -> 2025 | AE210: =M210 -> 0.037578746 | AF210: =N210 -> -0.01767428 | AG210: =O210 -> -0.067586547 | AH210: =P210 -> -0.040001519 | AI210: =Q210 -> -0.020410624 | AJ210: =R210 -> -0.0095734509 | AK210: =S210 -> -0.0028966043
A211: 45565 | B211: 3q24 | L211: ="20"&RIGHT(B211,2)&"Q"&LEFT(B211,1) -> 2024Q3 | M211: =C211 -> 0 | N211: =D211/10 -> 0 | O211: =E211 -> 0 | P211: =F211 -> 0 | Q211: =G211 -> 0 | R211: =H211 -> 0 | S211: =I211 -> 0 | AD211: =LEFT(L211,4)+1 -> 2025 | AE211: =M211 -> 0 | AF211: =N211 -> 0 | AG211: =O211 -> 0 | AH211: =P211 -> 0 | AI211: =Q211 -> 0 | AJ211: =R211 -> 0 | AK211: =S211 -> 0

Sheet EA_core_obs
A1: date | B1: g_sh | C1: b_liqtil_sh | D1: b_liqp_sh | E1: b_safetil_sh | F1: b_safep_sh | G1: mu_sh | H1: z_sh | I1: lambda_f_sh | J1: lambda_w_sh | K1: rm_sh | L1: sigma_omega_sh | M1: mu_e_sh | N1: gamma_sh | O1: pi_star_sh | P1: lr_sh | Q1: zp_sh | R1: tfp_sh | S1: gdpdef_sh | T1: corepce_sh | U1: gdp_sh | V1: gdi_sh | W1: BBB_sh | X1: AAA_sh | Y1: rm_shl1 | Z1: rm_shl2 | AA1: rm_shl3 | AB1: rm_shl4 | AC1: rm_shl5 | AD1: rm_shl6 | AE1: dettrend | AF1: detrendedMean | AH1: rm_sh | AI1: =Y1 -> rm_shl1 | AJ1: =Z1 -> rm_shl2 | AK1: =AA1 -> rm_shl3 | AL1: =AB1 -> rm_shl4 | AM1: =AC1 -> rm_shl5 | AN1: =AD1 -> rm_shl6 | AQ1: Plot | AR1: =A1 -> date | AS1: =AF1 -> detrendedMean | AT1: Monetary Policy | AU1: Fgsum | AV1: FG1 | AW1: FG2 | AX1: FG3 | AY1: FG4 | AZ1: FG5 | BA1: FG6 | BC1: date | BD1: rm_sh | BE1: Fgsum
