Workbook
Name BoxPlot: "BoxPlot"
Name Bubble: "Bubble"
Name Candlestick: "Candlestick"
Name Chart: "Chart"
Name ChartImage: "ChartImage"
Name ColumnRange: "ColumnRange"
Name DLX1.USE: #REF!
Name Dumbbell: "Dumbbell"
Name fame1: #REF!
Name fame2: #REF!
Name fame3: #REF!
Name Heatmap: "Heatmap"
Name Histogram: "Histogram"
Name Map: "Map"
Name OHLC: "OHLC"
Name PieChart: "PieChart"
Name Scatter: "Scatter"
Name Series: "Series"
Name Stripe: "Stripe"
Name Table: "Table"
Name TreeMap: "TreeMap"
Name Waterfall: "Waterfall"

Sheet All Chart

Sheet drstar_Table
A1: date | B1: g_sh | C1: b_liqtil_sh | D1: b_liqp_sh | E1: b_safetil_sh | F1: b_safep_sh | G1: mu_sh | H1: z_sh | I1: lambda_f_sh | J1: lambda_w_sh | K1: rm_sh | L1: sigma_omega_sh | M1: mu_e_sh | N1: gamma_sh | O1: pi_star_sh | P1: lr_sh | Q1: zp_sh | R1: tfp_sh | S1: gdpdef_sh | T1: corepce_sh | U1: gdp_sh | V1: gdi_sh | W1: BBB_sh | X1: AAA_sh | Y1: rm_shl1 | Z1: rm_shl2 | AA1: rm_shl3 | AB1: rm_shl4 | AC1: rm_shl5 | AD1: rm_shl6 | AE1: dettrend | AF1: detrendedMean | AG1: trend | AH1: Hist | AI1: Hist Check | AJ1: r* | AK1: 1999Q1-2019Q4 | AL1: =$AF$121-$AF$38 -> -3.2029798 | AM1: 2020Q1-2024Q3 | AN1: =AF139-$AF$122 -> 1.672298
A2: 32963 | B2: 0.022857106 | C2: -1.2659806e-08 | D2: 1.8912494 | E2: -0.02240701 | F2: 1.3871634 | G2: 0.31928117 | H2: 0.00035326532 | I2: 5.7968303e-15 | J2: -9.158653e-15 | K2: -9.7580563e-15 | L2: 0.04102846 | M2: 0 | N2: 0 | O2: 4.4430119e-15 | P2: 0 | Q2: 0.034888619 | R2: 0 | S2: 0 | T2: 0 | U2: 0 | V2: 0 | W2: 0 | X2: 0 | Y2: 0 | Z2: 0 | AA2: 0 | AB2: 0 | AC2: 0 | AD2: 0 | AE2: 0.74137884 | AF2: 4.4157933 | AG2: 1.0508022 | AH2: =+AF2+$AG$2 -> 5.4665955 | AI2: 5.4665955 | AJ2: cy | AL2: =SUM($C$121:$F$121)+SUM($C$38:$F$38) -> -2.5068045 | AN2: =SUM($C$139:$F$139)-SUM($C$122:$F$122) -> 1.7776856
A3: 33054 | B3: 0.031388765 | C3: -2.8744524e-08 | D3: 1.8577923 | E3: -0.058292627 | F3: 1.3633833 | G3: 0.27078716 | H3: 0.00033297928 | I3: 5.5767535e-15 | J3: -9.4119372e-15 | K3: -8.7979062e-15 | L3: -0.017738699 | M3: 0 | N3: 0 | O3: 6.0573515e-15 | P3: 0 | Q3: 0.029167752 | R3: 0 | S3: 0 | T3: 0 | U3: 0 | V3: 0 | W3: 0 | X3: 0 | Y3: 0 | Z3: 0 | AA3: 0 | AB3: 0 | AC3: 0 | AD3: 0 | AE3: 0.72988043 | AF3: 4.2067014 | AH3: =+AF3+$AG$2 -> 5.2575036 | AI3: 5.2575036 | AJ3: Other | AL3: =AL1-AL2 -> -0.69617528 | AN3: =AN1-AN2 -> -0.10538752
A4: 33146 | B4: 0.03536748 | C4: -1.6807462e-08 | D4: 1.8815404 | E4: -0.041551059 | F4: 1.3958833 | G4: 0.26835115 | H4: 0.00064458601 | I4: 4.5936694e-15 | J4: -1.060451e-14 | K4: -1.0070513e-14 | L4: -0.0090666522 | M4: 0 | N4: 0 | O4: 7.5410462e-15 | P4: 0 | Q4: 0.027730932 | R4: 0 | S4: 0 | T4: 0 | U4: 0 | V4: 0 | W4: 0 | X4: 0 | Y4: 0 | Z4: 0 | AA4: 0 | AB4: 0 | AC4: 0 | AD4: 0 | AE4: 0.71858231 | AF4: 4.2774824 | AH4: =+AF4+$AG$2 -> 5.3282846 | AI4: 5.3282846
A5: 33238 | B5: 0.027450198 | C5: 1.9378621e-09 | D5: 1.9347906 | E5: -0.0093954249 | F5: 1.4495209 | G5: 0.26681506 | H5: 0.00045264437 | I5: 4.9913935e-15 | J5: -9.3997373e-15 | K5: -1.1302592e-14 | L5: -0.013731569 | M5: 0 | N5: 0 | O5: 8.6228976e-15 | P5: 0 | Q5: 0.02128952 | R5: 0 | S5: 0 | T5: 0 | U5: 0 | V5: 0 | W5: 0 | X5: 0 | Y5: 0 | Z5: 0 | AA5: 0 | AB5: 0 | AC5: 0 | AD5: 0 | AE5: 0.70748044 | AF5: 4.3846723 | AH5: =+AF5+$AG$2 -> 5.4354745 | AI5: 5.4354745
A6: 33328 | B6: 0.032044802 | C6: 4.0733036e-10 | D6: 1.8600488 | E6: -0.0096801325 | F6: 1.4076577 | G6: 0.22860568 | H6: 0.00027248192 | I6: 4.9339146e-15 | J6: -1.5054316e-14 | K6: -1.1217833e-14 | L6: -0.034196845 | M6: 0 | N6: 0 | O6: 1.0145715e-14 | P6: 0 | Q6: 0.014500433 | R6: 0 | S6: 0 | T6: 0 | U6: 0 | V6: 0 | W6: 0 | X6: 0 | Y6: 0 | Z6: 0 | AA6: 0 | AB6: 0 | AC6: 0 | AD6: 0 | AE6: 0.69657088 | AF6: 4.1958238 | AH6: =+AF6+$AG$2 -> 5.246626 | AI6: 5.246626
A7: 33419 | B7: 0.024927776 | C7: -5.7320426e-09 | D7: 1.8029822 | E7: -0.0093853259 | F7: 1.3804813 | G7: 0.23810998 | H7: 0.00015603003 | I7: 4.772759e-15 | J7: -1.3148657e-14 | K7: -8.8711668e-15 | L7: -0.024326299 | M7: 0 | N7: 0 | O7: 1.1371642e-14 | P7: 0 | Q7: 0.011425074 | R7: 0 | S7: 0 | T7: 0 | U7: 0 | V7: 0 | W7: 0 | X7: 0 | Y7: 0 | Z7: 0 | AA7: 0 | AB7: 0 | AC7: 0 | AD7: 0 | AE7: 0.68584979 | AF7: 4.1102205 | AH7: =+AF7+$AG$2 -> 5.1610227 | AI7: 5.1610227
A8: 33511 | B8: 0.027345833 | C8: -1.2045444e-08 | D8: 1.7910849 | E8: -0.0071588175 | F8: 1.3838698 | G8: 0.23902883 | H8: -0.00037903202 | I8: 4.6041055e-15 | J8: -1.5238373e-14 | K8: -1.0115235e-14 | L8: -0.023942685 | M8: 0 | N8: 0 | O8: 1.2969875e-14 | P8: 0 | Q8: 0.0078188552 | R8: 0 | S8: 0 | T8: 0 | U8: 0 | V8: 0 | W8: 0 | X8: 0 | Y8: 0 | Z8: 0 | AA8: 0 | AB8: 0 | AC8: 0 | AD8: 0 | AE8: 0.67531342 | AF8: 4.092981 | AH8: =+AF8+$AG$2 -> 5.1437832 | AI8: 5.1437832
A9: 33603 | B9: 0.020169641 | C9: 6.4132382e-09 | D9: 1.7637174 | E9: 0.024213456 | F9: 1.3856542 | G9: 0.22121379 | H9: -0.0002961815 | I9: 4.5862787e-15 | J9: -1.9323573e-14 | K9: -1.0014256e-14 | L9: -0.035113723 | M9: 0 | N9: 0 | O9: 1.4390821e-14 | P9: 0 | Q9: 0.018473286 | R9: 0 | S9: 0 | T9: 0 | U9: 0 | V9: 0 | W9: 0 | X9: 0 | Y9: 0 | Z9: 0 | AA9: 0 | AB9: 0 | AC9: 0 | AD9: 0 | AE9: 0.66495814 | AF9: 4.06299 | AH9: =+AF9+$AG$2 -> 5.1137922 | AI9: 5.1137922
A10: 33694 | B10: 0.02430367 | C10: -3.9929391e-09 | D10: 1.6915992 | E10: 0.027012828 | F10: 1.3506908 | G10: 0.18707553 | H10: 0.00092963257 | I10: 3.8520642e-15 | J10: -1.7076081e-14 | K10: -1.1507505e-14 | L10: 0.0014841263 | M10: 0 | N10: 0 | O10: 1.6000505e-14 | P10: 0 | Q10: 0.025856657 | R10: 0 | S10: 0 | T10: 0 | U10: 0 | V10: 0 | W10: 0 | X10: 0 | Y10: 0 | Z10: 0 | AA10: 0 | AB10: 0 | AC10: 0 | AD10: 0 | AE10: 0.65478039 | AF10: 3.9637328 | AH10: =+AF10+$AG$2 -> 5.0145349 | AI10: 5.0145349
A11: 33785 | B11: 0.014569147 | C11: -2.7279109e-09 | D11: 1.6721591 | E11: 0.03398723 | F11: 1.348484 | G11: 0.11650581 | H11: 0.00030380421 | I11: 3.656673e-15 | J11: -1.9261495e-14 | K11: -1.25036e-14 | L11: -0.052781583 | M11: 0 | N11: 0 | O11: 1.7699841e-14 | P11: 0 | Q11: 0.0089487143 | R11: 0 | S11: 0 | T11: 0 | U11: 0 | V11: 0 | W11: 0 | X11: 0 | Y11: 0 | Z11: 0 | AA11: 0 | AB11: 0 | AC11: 0 | AD11: 0 | AE11: 0.64477668 | AF11: 3.7869529 | AH11: =+AF11+$AG$2 -> 4.8377551 | AI11: 4.8377551
A12: 33877 | B12: 0.014631182 | C12: 1.2981577e-08 | D12: 1.7026994 | E12: 0.06674222 | F12: 1.3892 | G12: 0.11709162 | H12: 1.0305409e-05 | I12: 3.1462477e-15 | J12: -1.1598776e-14 | K12: -1.6017038e-14 | L12: -0.033579983 | M12: 0 | N12: 0 | O12: 1.9202818e-14 | P12: 0 | Q12: 0.0032617358 | R12: 0 | S12: 0 | T12: 0 | U12: 0 | V12: 0 | W12: 0 | X12: 0 | Y12: 0 | Z12: 0 | AA12: 0 | AB12: 0 | AC12: 0 | AD12: 0 | AE12: 0.63494362 | AF12: 3.8950001 | AH12: =+AF12+$AG$2 -> 4.9458022 | AI12: 4.9458022
A13: 33969 | B13: -0.0091678174 | C13: 3.163372e-08 | D13: 1.6598722 | E13: 0.081335429 | F13: 1.3696645 | G13: 0.026855485 | H13: 0.00029203132 | I13: 3.0056667e-15 | J13: -1.1592775e-14 | K13: -1.2689021e-14 | L13: -0.041864722 | M13: 0 | N13: 0 | O13: 2.0907691e-14 | P13: 0 | Q13: 0.00042245796 | R13: 0 | S13: 0 | T13: 0 | U13: 0 | V13: 0 | W13: 0 | X13: 0 | Y13: 0 | Z13: 0 | AA13: 0 | AB13: 0 | AC13: 0 | AD13: 0 | AE13: 0.62527792 | AF13: 3.7126876 | AH13: =+AF13+$AG$2 -> 4.7634898 | AI13: 4.7634898
A14: 34059 | B14: 0.012552441 | C14: -8.5112958e-09 | D14: 1.4143677 | E14: 0.013337835 | F14: 1.1875767 | G14: -0.04328688 | H14: -0.00031146208 | I14: 3.478245e-15 | J14: -1.2213262e-14 | K14: -1.3420644e-14 | L14: -0.024032038 | M14: 0 | N14: 0 | O14: 2.3065063e-14 | P14: 0 | Q14: -0.016107588 | R14: 0 | S14: 0 | T14: 0 | U14: 0 | V14: 0 | W14: 0 | X14: 0 | Y14: 0 | Z14: 0 | AA14: 0 | AB14: 0 | AC14: 0 | AD14: 0 | AE14: 0.61577632 | AF14: 3.159873 | AH14: =+AF14+$AG$2 -> 4.2106752 | AI14: 4.2106752
A15: 34150 | B15: 0.017364219 | C15: -1.8137702e-08 | D15: 1.2923794 | E15: -0.0090850213 | F15: 1.1079561 | G15: -0.05864888 | H15: -0.00015081061 | I15: 2.8742788e-15 | J15: -1.0224049e-14 | K15: -8.8417949e-15 | L15: -0.010839152 | M15: 0 | N15: 0 | O15: 2.4872655e-14 | P15: 0 | Q15: -0.014862895 | R15: 0 | S15: 0 | T15: 0 | U15: 0 | V15: 0 | W15: 0 | X15: 0 | Y15: 0 | Z15: 0 | AA15: 0 | AB15: 0 | AC15: 0 | AD15: 0 | AE15: 0.60643567 | AF15: 2.9305486 | AH15: =+AF15+$AG$2 -> 3.9813508 | AI15: 3.9813508
... A139: 45473 | B139: 0.023805847 | C139: 1.180587e-09 | D139: 0.36771947 | E139: 0.079310158 | F139: -1.4291997 | G139: -0.26107878 | H139: -0.0001238051 | I139: 2.9657765e-15 | J139: 2.9894859e-15 | K139: 1.9349385e-16 | L139: -0.095994205 | M139: 0 | N139: 0 | O139: 4.3891449e-14 | P139: 0 | Q139: -0.03109361 | R139: 0 | S139: 0 | T139: 0 | U139: 0 | V139: 0 | W139: 0 | X139: 0 | Y139: -2.9123808e-15 | Z139: 2.1346027e-15 | AA139: 8.5186111e-16 | AB139: 3.1604158e-16 | AC139: 2.3866541e-16 | AD139: -1.8741331e-15 | AE139: 0.10912298 | AF139: -1.2375316 | AH139: =+AF139+$AG$2 -> -0.18672942 | AI139: -0.18672942
A140: 45565 | B140: 0.022195873 | C140: 5.2171189e-10 | D140: 0.36253966 | E140: 0.066995125 | F140: -1.40025 | G140: -0.25217081 | H140: -0.00012741782 | I140: 3.2927811e-15 | J140: 3.0269323e-15 | K140: 2.480455e-16 | L140: -0.098902914 | M140: 0 | N140: 0 | O140: 4.3429426e-14 | P140: 0 | Q140: -0.028208454 | R140: 0 | S140: 0 | T140: 0 | U140: 0 | V140: 0 | W140: 0 | X140: 0 | Y140: -2.7483321e-15 | Z140: 2.1083848e-15 | AA140: 8.4941531e-16 | AB140: 3.0156634e-16 | AC140: 2.3668085e-16 | AD140: -1.9117221e-15 | AE140: 0.10778836 | AF140: -1.2201406 | AH140: =+AF140+$AG$2 -> -0.16933837
A141: 45657 | B141: 0.020692349 | C141: 2.3054934e-10 | D141: 0.35743282 | E141: 0.056592333 | F141: -1.3718867 | G141: -0.24333883 | H141: -0.0001282605 | I141: 3.5959681e-15 | J141: 3.0609833e-15 | K141: 3.0544171e-16 | L141: -0.10083382 | M141: 0 | N141: 0 | O141: 4.2969715e-14 | P141: 0 | Q141: -0.025484297 | R141: 0 | S141: 0 | T141: 0 | U141: 0 | V141: 0 | W141: 0 | X141: 0 | Y141: -2.5939269e-15 | Z141: 2.0824632e-15 | AA141: 8.4572076e-16 | AB141: 2.8688547e-16 | AC141: 2.3343461e-16 | AD141: -1.9444939e-15 | AE141: 0.10647323 | AF141: -1.2004812 | AH141: =+AF141+$AG$2 -> -0.14967902
A142: 45747 | B142: 0.019287685 | C142: 1.0188211e-10 | D142: 0.35239791 | E142: 0.047804853 | F142: -1.344098 | G142: -0.23459197 | H142: -0.00012685235 | I142: 3.8749296e-15 | J142: 3.0914721e-15 | K142: 3.6496197e-16 | L142: -0.10189865 | M142: 0 | N142: 0 | O142: 4.2512775e-14 | P142: 0 | Q142: -0.022932454 | R142: 0 | S142: 0 | T142: 0 | U142: 0 | V142: 0 | W142: 0 | X142: 0 | Y142: -2.4493006e-15 | Z142: 2.0568916e-15 | AA142: 8.4093127e-16 | AB142: 2.7220259e-16 | AC142: 2.2915649e-16 | AD142: -1.9725767e-15 | AE142: 0.10517729 | AF142: -1.1789802 | AH142: =+AF142+$AG$2 -> -0.12817798
A143: 45838 | B143: 0.017975021 | C143: 4.5022949e-11 | D143: 0.34743392 | E143: 0.040381865 | F143: -1.3168721 | G143: -0.22594061 | H143: -0.00012365006 | I143: 4.1295943e-15 | J143: 3.1182658e-15 | K143: 4.259275e-16 | L143: -0.10220359 | M143: 0 | N143: 0 | O143: 4.2059004e-14 | P143: 0 | Q143: -0.020559358 | R143: 0 | S143: 0 | T143: 0 | U143: 0 | V143: 0 | W143: 0 | X143: 0 | Y143: -2.3144286e-15 | Z143: 2.0317098e-15 | AA143: 8.351919e-16 | AB143: 2.5768971e-16 | AC143: 2.2405566e-16 | AD143: -1.9961358e-15 | AE143: 0.10390024 | AF143: -1.1560083 | AH143: =+AF143+$AG$2 -> -0.10520607
A144: 45930 | B144: 0.016748132 | C144: 1.9896393e-11 | D144: 0.34253986 | E144: 0.034111496 | F144: -1.2901977 | G144: -0.21739582 | H144: -0.00011905227 | I144: 4.360182e-15 | J144: 3.1412684e-15 | K144: 4.8770984e-16 | L144: -0.10184857 | M144: 0 | N144: 0 | O144: 4.1608744e-14 | P144: 0 | Q144: -0.018367387 | R144: 0 | S144: 0 | T144: 0 | U144: 0 | V144: 0 | W144: 0 | X144: 0 | Y144: -2.1891547e-15 | Z144: 2.0069454e-15 | AA144: 8.2863799e-16 | AB144: 2.4348939e-16 | AC144: 2.1832026e-16 | AD144: -2.0153666e-15 | AE144: 0.10264182 | AF144: -1.1318873 | AH144: =+AF144+$AG$2 -> -0.081085075
A145: 46022 | B145: 0.015601343 | C145: 8.7927459e-12 | D145: 0.33771474 | E145: 0.02881477 | F145: -1.2640637 | G145: -0.20896893 | H145: -0.00011340403 | I145: 4.5671608e-15 | J145: 3.1604226e-15 | K145: 5.497364e-16 | L145: -0.10092676 | M145: 0 | N145: 0 | O145: 4.1162283e-14 | P145: 0 | Q145: -0.016355591 | R145: 0 | S145: 0 | T145: 0 | U145: 0 | V145: 0 | W145: 0 | X145: 0 | Y145: -2.0732164e-15 | Z145: 1.9826159e-15 | AA145: 8.2139451e-16 | AB145: 2.2971716e-16 | AC145: 2.1211745e-16 | AD145: -2.0304874e-15 | AE145: 0.10140172 | AF145: -1.1068958 | AH145: =+AF145+$AG$2 -> -0.056093586
A146: 46112 | B146: 0.014529458 | C146: 3.8859424e-12 | D146: 0.33295758 | E146: 0.024340503 | F146: -1.238459 | G146: -0.2006711 | H146: -0.00010700143 | I146: 4.7512051e-15 | J146: 3.1757089e-15 | K146: 6.1149355e-16 | L146: -0.09952424 | M146: 0 | N146: 0 | O146: 4.0719858e-14 | P146: 0 | Q146: -0.014520334 | R146: 0 | S146: 0 | T146: 0 | U146: 0 | V146: 0 | W146: 0 | X146: 0 | Y146: -1.9662676e-15 | Z146: 1.9587304e-15 | AA146: 8.1357576e-16 | AB146: 2.1646404e-16 | AC146: 2.0559398e-16 | AD146: -2.0417334e-15 | AE146: 0.10017968 | AF146: -1.0812744 | AH146: =+AF146+$AG$2 -> -0.030472218
A147: 46203 | B147: 0.013527702 | C147: 1.717577e-12 | D147: 0.32826744 | E147: 0.020560986 | F147: -1.2133729 | G147: -0.19251304 | H147: -0.00010009612 | I147: 4.9131571e-15 | J147: 3.1871436e-15 | K147: 6.7252764e-16 | L147: -0.097719945 | M147: 0 | N147: 0 | O147: 4.0281665e-14 | P147: 0 | Q147: -0.012855866 | R147: 0 | S147: 0 | T147: 0 | U147: 0 | V147: 0 | W147: 0 | X147: 0 | Y147: -1.8678986e-15 | Z147: 1.9352906e-15 | AA147: 8.0528542e-16 | AB147: 2.037991e-16 | AC147: 1.9887712e-16 | AD147: -2.0493508e-15 | AE147: 0.098975431 | AF147: -1.0552303 | AH147: =+AF147+$AG$2 -> -0.0044281079
A148: 46295 | B148: 0.012591666 | C148: 7.5935093e-13 | D148: 0.32364337 | E148: 0.017368341 | F148: -1.188795 | G148: -0.18450481 | H148: -9.2899648e-05 | I148: 5.0539917e-15 | J148: 3.1947769e-15 | K148: 7.3244438e-16 | L148: -0.095585646 | M148: 0 | N148: 0 | O148: 3.9847859e-14 | P148: 0 | Q148: -0.011354815 | R148: 0 | S148: 0 | T148: 0 | U148: 0 | V148: 0 | W148: 0 | X148: 0 | Y148: -1.7776536e-15 | Z148: 1.9122929e-15 | AA148: 7.9661664e-16 | AB148: 1.9177196e-16 | AC148: 1.920758e-16 | AD148: -2.0535925e-15 | AE148: 0.097788695 | AF148: -1.0289411 | AH148: =+AF148+$AG$2 -> 0.021861088
A149: 46387 | B149: 0.011717262 | C149: 3.3589573e-13 | D149: 0.31908443 | E149: 0.014671439 | F149: -1.1647149 | G149: -0.17665562 | H149: -8.5587674e-05 | I149: 5.1747837e-15 | J149: 3.1986889e-15 | K149: 7.9090714e-16 | L149: -0.093186104 | M149: 0 | N149: 0 | O149: 3.941856e-14 | P149: 0 | Q149: -0.01000861 | R149: 0 | S149: 0 | T149: 0 | U149: 0 | V149: 0 | W149: 0 | X149: 0 | Y149: -1.695046e-15 | Z149: 1.8897289e-15 | AA149: 7.8765249e-16 | AB149: 1.8041531e-16 | AC149: 1.8528185e-16 | AD149: -2.0547132e-15 | AE149: 0.096619212 | AF149: -1.0025585 | AH149: =+AF149+$AG$2 -> 0.048243679
A150: 46477 | B150: 0.010900691 | C150: 1.4876042e-13 | D150: 0.3145897 | E150: 0.012393304 | F150: -1.1411226 | G150: -0.16897372 | H150: -7.8303977e-05 | I150: 5.2766792e-15 | J150: 3.1989865e-15 | K150: 8.4763411e-16 | L150: -0.090579296 | M150: 0 | N150: 0 | O150: 3.8993858e-14 | P150: 0 | Q150: -0.0088078512 | R150: 0 | S150: 0 | T150: 0 | U150: 0 | V150: 0 | W150: 0 | X150: 0 | Y150: -1.619571e-15 | Z150: 1.8675868e-15 | AA150: 7.7846635e-16 | AB150: 1.6974717e-16 | AC150: 1.7857146e-16 | AD150: -2.0529662e-15 | AE150: 0.095466723 | AF150: -0.97621136 | AH150: =+AF150+$AG$2 -> 0.074590821
A151: 46568 | B151: 0.010138404 | C151: 6.6056928e-14 | D151: 0.3101583 | E151: 0.010468911 | F151: -1.1180082 | G151: -0.16146632 | H151: -7.1164182e-05 | I151: 5.3608703e-15 | J151: 3.1957993e-15 | K151: 9.02395e-16 | L151: -0.087816712 | M151: 0 | N151: 0 | O151: 3.8573813e-14 | P151: 0 | Q151: -0.0077426155 | R151: 0 | S151: 0 | T151: 0 | U151: 0 | V151: 0 | W151: 0 | X151: 0 | Y151: -1.5507165e-15 | Z151: 1.8458523e-15 | AA151: 7.6912251e-16 | AB151: 1.5977309e-16 | AC151: 1.7200662e-16 | AD151: -2.0486002e-15 | AE151: 0.094330972 | AF151: -0.95000841 | AH151: =+AF151+$AG$2 -> 0.10079376
... A199: 50951 | B199: 0.00038239024 | C199: 2.030721e-16 | D199: 0.15698224 | E199: 3.1782806e-06 | F199: -0.41865214 | G199: 0.014330778 | H199: -1.2429666e-06 | I199: 3.2993309e-15 | J199: 1.7193339e-15 | K199: 1.5341422e-15 | L199: -0.01345945 | M199: 0 | N199: 0 | O199: 2.313633e-14 | P199: 0 | Q199: -0.00081741983 | R199: 0 | S199: 0 | T199: 0 | U199: 0 | V199: 0 | W199: 0 | X199: 0 | Y199: -6.1230701e-16 | Z199: 1.0611579e-15 | AA199: 4.1704245e-16 | AB199: 4.2520851e-17 | AC199: 6.2312259e-17 | AD199: -1.1732242e-15 | AE199: 0.055353085 | AF199: -0.20587859 | AH199: =+AF199+$AG$2 -> 0.84492359

Sheet Counterfactual_charts
A1: date | B1: obs_gdp | C1: obs_hours | D1: obs_wages | E1: obs_gdpdeflator | F1: obs_corepce | G1: obs_nominalrate | H1: obs_consumption | I1: obs_investment | J1: obs_BBBspread | K1: obs_longinflation | L1: obs_longrate | M1: obs_tfp | N1: obs_gdi | O1: obs_AAAspread | P1: obs_nominalrate1 | Q1: obs_nominalrate2 | R1: obs_nominalrate3 | S1: obs_nominalrate4 | T1: obs_nominalrate5 | U1: obs_nominalrate6 | V1: ex_ante_real_rate | W1: ex_post_real_rate | X1: ex_post_real_rate_core | Y1: HLW r* (25Q3) | Z1: DSGE r* wFG | AA1: Delta_Rstar_HLW | AB1: Delta_Rstar_DSGE | AC1: date | AD1: ex_ante_real_rate | AE1: Delta_Rstar_DSGE | AF1: date | AG1: ex_ante_real_rate | AH1: actual_MP_stance | AK1: CHART | AS1: date | AU1: Date | AV1: HLW | AW1: DSGE | AX1: Actual Real Rate Gap | AY1: Counterfactual Real Rate Gap | AZ1: Actual Output Growth | BA1: Counterfactual Output Growth | BB1: Output (deviation from baseline) | BC1: Inflation (deviation from baseline)
A2: 25749 | B2: 1.87 | C2: NaN | D2: 2.62 | E2: 1.81 | F2: NaN | G2: 1.99 | H2: 0.58 | I2: 5.67 | J2: NaN | K2: NaN | L2: 2.06 | M2: NaN | N2: NaN | O2: NaN | P2: NaN | Q2: NaN | R2: NaN | S2: NaN | T2: NaN | U2: NaN | W2: =+(G2-E2)*4 -> 0.72 | AC2: 21823 | AF2: =+A2 -> 25749 | AS2: =A2 -> 25749
A3: 25841 | B3: 1.02 | C3: NaN | D3: 2.03 | E3: 1.78 | F3: NaN | G3: 1.9 | H3: 0.99 | I3: 0.7 | J3: NaN | K3: NaN | L3: 2.1 | M3: NaN | N3: NaN | O3: NaN | P3: NaN | Q3: NaN | R3: NaN | S3: NaN | T3: NaN | U3: NaN | W3: =+(G3-E3)*4 -> 0.48 | AC3: 21915 | AF3: =+A3 -> 25841 | AS3: =A3 -> 25841
A4: 25933 | B4: 1.04 | C4: NaN | D4: 2.26 | E4: 1.17 | F4: NaN | G4: 1.81 | H4: 1.75 | I4: -0.04 | J4: NaN | K4: NaN | L4: 2.09 | M4: NaN | N4: NaN | O4: NaN | P4: NaN | Q4: NaN | R4: NaN | S4: NaN | T4: NaN | U4: NaN | W4: =+(G4-E4)*4 -> 2.56 | AC4: 22006 | AF4: =+A4 -> 25933 | AS4: =A4 -> 25933
A5: 26023 | B5: -0.38 | C5: NaN | D5: 0.97 | E5: 2.3 | F5: NaN | G5: 1.63 | H5: -0.11 | I5: -0.82 | J5: NaN | K5: NaN | L5: 1.97 | M5: NaN | N5: NaN | O5: NaN | P5: NaN | Q5: NaN | R5: NaN | S5: NaN | T5: NaN | U5: NaN | W5: =+(G5-E5)*4 -> -2.68 | AC5: 22097 | AF5: =+A5 -> 26023 | AS5: =A5 -> 26023
A6: 26114 | B6: 0.98 | C6: NaN | D6: 0.84 | E6: 1.13 | F6: NaN | G6: 1.48 | H6: 1.18 | I6: 2.83 | J6: NaN | K6: NaN | L6: 1.98 | M6: NaN | N6: NaN | O6: NaN | P6: NaN | Q6: NaN | R6: NaN | S6: NaN | T6: NaN | U6: NaN | W6: =+(G6-E6)*4 -> 1.4 | AC6: 22189 | AF6: =+A6 -> 26114 | AS6: =A6 -> 26114
A7: 26206 | B7: 1.84 | C7: NaN | D7: 1.95 | E7: 1.67 | F7: NaN | G7: 1.56 | H7: 1.15 | I7: 0.17 | J7: NaN | K7: NaN | L7: 2.01 | M7: NaN | N7: NaN | O7: NaN | P7: NaN | Q7: NaN | R7: NaN | S7: NaN | T7: NaN | U7: NaN | W7: =+(G7-E7)*4 -> -0.44 | AC7: 22281 | AF7: =+A7 -> 26206 | AS7: =A7 -> 26206
A8: 26298 | B8: 0.66 | C8: NaN | D8: 1.64 | E8: 1.1 | F8: NaN | G8: 1.5 | H8: 1.01 | I8: 1.6 | J8: NaN | K8: NaN | L8: 1.96 | M8: NaN | N8: NaN | O8: NaN | P8: NaN | Q8: NaN | R8: NaN | S8: NaN | T8: NaN | U8: NaN | W8: =+(G8-E8)*4 -> 1.6 | AC8: 22371 | AF8: =+A8 -> 26298 | AS8: =A8 -> 26298
A9: 26389 | B9: 1.25 | C9: NaN | D9: 1.97 | E9: 2.16 | F9: NaN | G9: 1.26 | H9: 0.92 | I9: 0.36 | J9: NaN | K9: NaN | L9: 1.9 | M9: NaN | N9: NaN | O9: NaN | P9: NaN | Q9: NaN | R9: NaN | S9: NaN | T9: NaN | U9: NaN | W9: =+(G9-E9)*4 -> -3.6 | Y9: 3.3617854 | AC9: 22462 | AF9: =+A9 -> 26389 | AS9: =A9 -> 26389
A10: 26480 | B10: 0.61 | C10: NaN | D10: 0.44 | E10: 1.59 | F10: NaN | G10: 1.19 | H10: 0.37 | I10: 1.28 | J10: NaN | K10: NaN | L10: 1.89 | M10: NaN | N10: NaN | O10: NaN | P10: NaN | Q10: NaN | R10: NaN | S10: NaN | T10: NaN | U10: NaN | W10: =+(G10-E10)*4 -> -1.6 | Y10: 2.4726543 | Z10: 3.8039334 | AC10: 22554 | AF10: =+A10 -> 26480 | AS10: =A10 -> 26480
A11: 26572 | B11: 1.12 | C11: NaN | D11: 0.92 | E11: 1.57 | F11: NaN | G11: 1.21 | H11: 2.07 | I11: 0.57 | J11: NaN | K11: NaN | L11: 1.9 | M11: NaN | N11: NaN | O11: NaN | P11: NaN | Q11: NaN | R11: NaN | S11: NaN | T11: NaN | U11: NaN | V11: 1.0149957 | W11: =+(G11-E11)*4 -> -1.44 | Y11: 2.5754349 | Z11: 3.9836896 | AC11: 22646 | AD11: =+V11 -> 1.0149957 | AF11: =+A11 -> 26572 | AG11: =+AD11 -> 1.0149957 | AS11: =A11 -> 26572
A12: 26664 | B12: 1.16 | C12: NaN | D12: 1.45 | E12: 1.54 | F12: NaN | G12: 1.6 | H12: 0.71 | I12: 2.02 | J12: NaN | K12: NaN | L12: 1.95 | M12: NaN | N12: NaN | O12: NaN | P12: NaN | Q12: NaN | R12: NaN | S12: NaN | T12: NaN | U12: NaN | V12: 0.99620506 | W12: =+(G12-E12)*4 -> 0.24 | Y12: 2.743556 | Z12: 4.3206825 | AC12: 22736 | AD12: =+V12 -> 0.99620506 | AF12: =+A12 -> 26664 | AG12: =+AD12 -> 0.99620506 | AS12: =A12 -> 26664
A13: 26754 | B13: 1.65 | C13: NaN | D13: 1.47 | E13: 3.51 | F13: NaN | G13: 1.7 | H13: 0.32 | I13: 1.26 | J13: NaN | K13: NaN | L13: 1.99 | M13: NaN | N13: NaN | O13: NaN | P13: NaN | Q13: NaN | R13: NaN | S13: NaN | T13: NaN | U13: NaN | V13: 2.382294 | W13: =+(G13-E13)*4 -> -7.24 | Y13: 3.355047 | Z13: 4.3759537 | AC13: 22827 | AD13: =+V13 -> 2.382294 | AF13: =+A13 -> 26754 | AG13: =+AD13 -> 2.382294 | AS13: =A13 -> 26754
A14: 26845 | B14: 0.5 | C14: NaN | D14: 0.77 | E14: 2.43 | F14: NaN | G14: 2.12 | H14: 0.82 | I14: 0.29 | J14: NaN | K14: NaN | L14: 2.08 | M14: NaN | N14: NaN | O14: NaN | P14: NaN | Q14: NaN | R14: NaN | S14: NaN | T14: NaN | U14: NaN | V14: 1.883329 | W14: =+(G14-E14)*4 -> -1.24 | Y14: 3.0451464 | Z14: 4.6791313 | AC14: 22919 | AD14: =+V14 -> 1.883329 | AF14: =+A14 -> 26845 | AG14: =+AD14 -> 1.883329 | AS14: =A14 -> 26845
A15: 26937 | B15: 1.19 | C15: NaN | D15: 1.51 | E15: 2.38 | F15: NaN | G15: 2.55 | H15: 0.35 | I15: 1.21 | J15: NaN | K15: NaN | L15: 2.15 | M15: NaN | N15: NaN | O15: NaN | P15: NaN | Q15: NaN | R15: NaN | S15: NaN | T15: NaN | U15: NaN | V15: 3.7119285 | W15: =+(G15-E15)*4 -> 0.68 | Y15: 3.1512224 | Z15: 4.9922555 | AC15: 23011 | AD15: =+V15 -> 3.7119285 | AF15: =+A15 -> 26937 | AG15: =+AD15 -> 3.7119285 | AS15: =A15 -> 26937
A16: 27029 | B16: 0.84 | C16: NaN | D16: 1.68 | E16: 2.32 | F16: NaN | G16: 2.77 | H16: 1.67 | I16: 0.85 | J16: NaN | K16: NaN | L16: 2.18 | M16: NaN | N16: NaN | O16: NaN | P16: NaN | Q16: NaN | R16: NaN | S16: NaN | T16: NaN | U16: NaN | V16: 5.4656472 | W16: =+(G16-E16)*4 -> 1.8 | Y16: 3.0581261 | Z16: 5.2172569 | AC16: 23101 | AD16: =+V16 -> 5.4656472 | AF16: =+A16 -> 27029 | AG16: =+AD16 -> 5.4656472 | AS16: =A16 -> 27029
A17: 27119 | B17: 0.87 | C17: NaN | D17: 0.97 | E17: 3.16 | F17: NaN | G17: 2.81 | H17: 0.42 | I17: 1.1 | J17: NaN | K17: NaN | L17: 2.34 | M17: NaN | N17: NaN | O17: NaN | P17: NaN | Q17: NaN | R17: NaN | S17: NaN | T17: NaN | U17: NaN | V17: 6.2960412 | W17: =+(G17-E17)*4 -> -1.4 | Y17: 3.0365806 | Z17: 5.3314811 | AC17: 23192 | AD17: =+V17 -> 6.2960412 | AF17: =+A17 -> 27119 | AG17: =+AD17 -> 6.2960412 | AS17: =A17 -> 27119
A18: 27210 | B18: 0.25 | C18: NaN | D18: 1.69 | E18: 3.49 | F18: NaN | G18: 2.87 | H18: 1.4 | I18: -1.62 | J18: NaN | K18: NaN | L18: 2.52 | M18: NaN | N18: NaN | O18: NaN | P18: NaN | Q18: NaN | R18: NaN | S18: NaN | T18: NaN | U18: NaN | V18: 5.9361561 | W18: =+(G18-E18)*4 -> -2.48 | Y18: 2.7779297 | Z18: 5.5611755 | AC18: 23284 | AD18: =+V18 -> 5.9361561 | AF18: =+A18 -> 27210 | AG18: =+AD18 -> 5.9361561 | AS18: =A18 -> 27210
A19: 27302 | B19: 0.63 | C19: NaN | D19: 0.52 | E19: 3.38 | F19: NaN | G19: 2.88 | H19: 0.14 | I19: 0.97 | J19: NaN | K19: NaN | L19: 2.67 | M19: NaN | N19: NaN | O19: NaN | P19: NaN | Q19: NaN | R19: NaN | S19: NaN | T19: NaN | U19: NaN | V19: 5.9219283 | W19: =+(G19-E19)*4 -> -2 | Y19: 2.8841953 | Z19: 5.695278 | AC19: 23376 | AD19: =+V19 -> 5.9219283 | AF19: =+A19 -> 27302 | AG19: =+AD19 -> 5.9219283 | AS19: =A19 -> 27302
A20: 27394 | B20: -1.79 | C20: NaN | D20: 1.26 | E20: 3.27 | F20: NaN | G20: 2.67 | H20: -0.78 | I20: -3.05 | J20: NaN | K20: NaN | L20: 2.65 | M20: NaN | N20: NaN | O20: NaN | P20: NaN | Q20: NaN | R20: NaN | S20: NaN | T20: NaN | U20: NaN | V20: 5.8587809 | W20: =+(G20-E20)*4 -> -2.4 | Y20: 2.0943443 | Z20: 5.3896745 | AC20: 23467 | AD20: =+V20 -> 5.8587809 | AF20: =+A20 -> 27394 | AG20: =+AD20 -> 5.8587809 | AS20: =A20 -> 27394
A21: 27484 | B21: -0.88 | C21: NaN | D21: 0.39 | E21: 2.77 | F21: NaN | G21: 2.2 | H21: 0.29 | I21: -1.95 | J21: NaN | K21: NaN | L21: 2.47 | M21: NaN | N21: NaN | O21: NaN | P21: NaN | Q21: NaN | R21: NaN | S21: NaN | T21: NaN | U21: NaN | V21: 5.233664 | W21: =+(G21-E21)*4 -> -2.28 | Y21: 1.9937668 | Z21: 5.0569891 | AC21: 23558 | AD21: =+V21 -> 5.233664 | AF21: =+A21 -> 27484 | AG21: =+AD21 -> 5.233664 | AS21: =A21 -> 27484
A22: 27575 | B22: 0.81 | C22: NaN | D22: 1.68 | E22: 2.32 | F22: NaN | G22: 1.76 | H22: 1.68 | I22: -1.61 | J22: NaN | K22: NaN | L22: 2.39 | M22: NaN | N22: NaN | O22: NaN | P22: NaN | Q22: NaN | R22: NaN | S22: NaN | T22: NaN | U22: NaN | V22: 3.67475 | W22: =+(G22-E22)*4 -> -2.24 | Y22: 2.201963 | Z22: 5.0199626 | AC22: 23650 | AD22: =+V22 -> 3.67475 | AF22: =+A22 -> 27575 | AG22: =+AD22 -> 3.67475 | AS22: =A22 -> 27575
... A60: 31047 | B60: 0.42 | C60: NaN | D60: 0.69 | E60: 1.11 | F60: NaN | G60: 2.53 | H60: 0.51 | I60: 1.23 | J60: NaN | K60: NaN | L60: 2.85 | M60: NaN | N60: NaN | O60: NaN | P60: NaN | Q60: NaN | R60: NaN | S60: NaN | T60: NaN | U60: NaN | V60: 6.7600301 | W60: =+(G60-E60)*4 -> 5.68 | Y60: 1.7611247 | Z60: 6.1339007 | AC60: 27119 | AD60: =+V60 -> 6.7600301 | AF60: =+A60 -> 31047 | AG60: =+AD60 -> 6.7600301 | AS60: =A60 -> 31047
A61: 31137 | B61: 0.16 | C61: 5.6 | D61: 0.43 | E61: 1.56 | F61: NaN | G61: 2.47 | H61: 0.91 | I61: -1.64 | J61: NaN | K61: NaN | L61: 2.74 | M61: NaN | N61: NaN | O61: NaN | P61: NaN | Q61: NaN | R61: NaN | S61: NaN | T61: NaN | U61: NaN | V61: 6.7806939 | W61: =+(G61-E61)*4 -> 3.64 | Y61: 1.7424814 | Z61: 5.9347699 | AC61: 27210 | AD61: =+V61 -> 6.7806939 | AF61: =+A61 -> 31137 | AG61: =+AD61 -> 6.7806939 | AS61: =A61 -> 31137
A62: 31228 | B62: 0.81 | C62: 5.52 | D62: 0.06 | E62: 1.39 | F62: NaN | G62: 2.49 | H62: 0.34 | I62: 1.35 | J62: NaN | K62: NaN | L62: 2.71 | M62: NaN | N62: NaN | O62: NaN | P62: NaN | Q62: NaN | R62: NaN | S62: NaN | T62: NaN | U62: NaN | V62: 6.3991596 | W62: =+(G62-E62)*4 -> 4.4 | Y62: 1.8260628 | Z62: 5.9211855 | AC62: 27302 | AD62: =+V62 -> 6.3991596 | AF62: =+A62 -> 31228 | AG62: =+AD62 -> 6.3991596 | AS62: =A62 -> 31228
A63: 31320 | B63: 0.63 | C63: 5.38 | D63: 0.49 | E63: 1.52 | F63: NaN | G63: 2.34 | H63: 0.38 | I63: 1.3 | J63: NaN | K63: NaN | L63: 2.67 | M63: NaN | N63: NaN | O63: NaN | P63: NaN | Q63: NaN | R63: NaN | S63: NaN | T63: NaN | U63: NaN | V63: 6.5046641 | W63: =+(G63-E63)*4 -> 3.28 | Y63: 1.5783718 | Z63: 5.7742924 | AC63: 27394 | AD63: =+V63 -> 6.5046641 | AF63: =+A63 -> 31320 | AG63: =+AD63 -> 6.5046641 | AS63: =A63 -> 31320
A64: 31412 | B64: 0.3 | C64: 5.18 | D64: -0.02 | E64: 1.49 | F64: NaN | G64: 2.16 | H64: 0.12 | I64: 0.92 | J64: NaN | K64: NaN | L64: 2.57 | M64: NaN | N64: NaN | O64: NaN | P64: NaN | Q64: NaN | R64: NaN | S64: NaN | T64: NaN | U64: NaN | V64: 5.9159244 | W64: =+(G64-E64)*4 -> 2.68 | Y64: 1.5726696 | Z64: 5.5374687 | AC64: 27484 | AD64: =+V64 -> 5.9159244 | AF64: =+A64 -> 31412 | AG64: =+AD64 -> 5.9159244 | AS64: =A64 -> 31412
A65: 31502 | B65: -0.63 | C65: 4.95 | D65: -0.39 | E65: 1.76 | F65: NaN | G65: 2.19 | H65: -0.84 | I65: -2.48 | J65: NaN | K65: NaN | L65: 2.44 | M65: NaN | N65: NaN | O65: NaN | P65: NaN | Q65: NaN | R65: NaN | S65: NaN | T65: NaN | U65: NaN | V65: 5.1987007 | W65: =+(G65-E65)*4 -> 1.72 | Y65: 1.2239614 | Z65: 5.2647753 | AC65: 27575 | AD65: =+V65 -> 5.1987007 | AF65: =+A65 -> 31502 | AG65: =+AD65 -> 5.1987007 | AS65: =A65 -> 31502
A66: 31593 | B66: 1.55 | C66: 4.78 | D66: 0.22 | E66: 1.3 | F66: NaN | G66: 2.01 | H66: 0.8 | I66: 1.99 | J66: NaN | K66: NaN | L66: 2.15 | M66: NaN | N66: NaN | O66: NaN | P66: NaN | Q66: NaN | R66: NaN | S66: NaN | T66: NaN | U66: NaN | V66: 5.2075525 | W66: =+(G66-E66)*4 -> 2.84 | Y66: 1.3749519 | Z66: 5.0448919 | AC66: 27667 | AD66: =+V66 -> 5.2075525 | AF66: =+A66 -> 31593 | AG66: =+AD66 -> 5.2075525 | AS66: =A66 -> 31593
A67: 31685 | B67: 0.18 | C67: 4.7 | D67: 0.12 | E67: 1.14 | F67: NaN | G67: 1.94 | H67: -0.17 | I67: 0.36 | J67: NaN | K67: NaN | L67: 2.1 | M67: NaN | N67: NaN | O67: NaN | P67: NaN | Q67: NaN | R67: NaN | S67: NaN | T67: NaN | U67: NaN | V67: 4.8244061 | W67: =+(G67-E67)*4 -> 3.2 | Y67: 1.2983166 | Z67: 4.8969846 | AC67: 27759 | AD67: =+V67 -> 4.8244061 | AF67: =+A67 -> 31685 | AG67: =+AD67 -> 4.8244061 | AS67: =A67 -> 31685
A68: 31777 | B68: -0.16 | C68: 4.67 | D68: 0.14 | E68: 0.85 | F68: NaN | G68: 1.97 | H68: 0.5 | I68: 0.57 | J68: NaN | K68: NaN | L68: 2.12 | M68: NaN | N68: NaN | O68: NaN | P68: NaN | Q68: NaN | R68: NaN | S68: NaN | T68: NaN | U68: NaN | V68: 4.7220469 | W68: =+(G68-E68)*4 -> 4.48 | Y68: 1.2102238 | Z68: 5.036552 | AC68: 27850 | AD68: =+V68 -> 4.7220469 | AF68: =+A68 -> 31777 | AG68: =+AD68 -> 4.7220469 | AS68: =A68 -> 31777
A69: 31867 | B69: -0.73 | C69: 4.73 | D69: 0.11 | E69: 0.84 | F69: NaN | G69: 2.03 | H69: -0.22 | I69: -1.82 | J69: NaN | K69: NaN | L69: 2.12 | M69: NaN | N69: NaN | O69: NaN | P69: NaN | Q69: NaN | R69: NaN | S69: NaN | T69: NaN | U69: NaN | V69: 5.0143179 | W69: =+(G69-E69)*4 -> 4.76 | Y69: 1.1729481 | Z69: 5.0312545 | AC69: 27941 | AD69: =+V69 -> 5.0143179 | AF69: =+A69 -> 31867 | AG69: =+AD69 -> 5.0143179 | AS69: =A69 -> 31867
A70: 31958 | B70: 1.36 | C70: 4.76 | D70: 0.96 | E70: 0.84 | F70: NaN | G70: 2.11 | H70: 1.55 | I70: 2.92 | J70: NaN | K70: NaN | L70: 2.17 | M70: NaN | N70: NaN | O70: NaN | P70: NaN | Q70: NaN | R70: NaN | S70: NaN | T70: NaN | U70: NaN | V70: 5.318176 | W70: =+(G70-E70)*4 -> 5.08 | Y70: 1.4883935 | Z70: 5.3521411 | AC70: 28033 | AD70: =+V70 -> 5.318176 | AF70: =+A70 -> 31958 | AG70: =+AD70 -> 5.318176 | AS70: =A70 -> 31958
A71: 32050 | B71: 0.82 | C71: 4.73 | D71: 0.61 | E71: 0.69 | F71: NaN | G71: 2.12 | H71: 0.75 | I71: 2.01 | J71: NaN | K71: NaN | L71: 2.37 | M71: NaN | N71: NaN | O71: NaN | P71: NaN | Q71: NaN | R71: NaN | S71: NaN | T71: NaN | U71: NaN | V71: 5.7226882 | W71: =+(G71-E71)*4 -> 5.72 | Y71: 1.5836338 | Z71: 5.4449257 | AC71: 28125 | AD71: =+V71 -> 5.7226882 | AF71: =+A71 -> 32050 | AG71: =+AD71 -> 5.7226882 | AS71: =A71 -> 32050
A72: 32142 | B72: 1.09 | C72: 4.68 | D72: 0.23 | E72: 1.23 | F72: NaN | G72: 2.11 | H72: 0.53 | I72: 1.51 | J72: NaN | K72: NaN | L72: 2.4 | M72: NaN | N72: NaN | O72: NaN | P72: NaN | Q72: NaN | R72: NaN | S72: NaN | T72: NaN | U72: NaN | V72: 5.8040639 | W72: =+(G72-E72)*4 -> 3.52 | Y72: 1.667646 | Z72: 5.3824644 | AC72: 28215 | AD72: =+V72 -> 5.8040639 | AF72: =+A72 -> 32142 | AG72: =+AD72 -> 5.8040639 | AS72: =A72 -> 32142
A73: 32233 | B73: 0.18 | C73: 4.58 | D73: 0.4 | E73: 0.95 | F73: 0.57 | G73: 1.86 | H73: -0.58 | I73: 1.05 | J73: NaN | K73: NaN | L73: 2.25 | M73: NaN | N73: NaN | O73: NaN | P73: NaN | Q73: NaN | R73: NaN | S73: NaN | T73: NaN | U73: NaN | V73: 5.4987128 | W73: =+(G73-E73)*4 -> 3.64 | X73: =+(G73-F73)*4 -> 5.16 | Y73: 1.6047869 | Z73: 5.0438207 | AC73: 28306 | AD73: =+V73 -> 5.4987128 | AF73: =+A73 -> 32233 | AG73: =+AD73 -> 5.4987128 | AS73: =A73 -> 32233
A74: 32324 | B74: 0.62 | C74: 4.49 | D74: 0.23 | E74: 1.07 | F74: 0.61 | G74: 1.82 | H74: 0.39 | I74: 1.64 | J74: NaN | K74: NaN | L74: 2.22 | M74: NaN | N74: NaN | O74: NaN | P74: NaN | Q74: NaN | R74: NaN | S74: NaN | T74: NaN | U74: NaN | V74: 4.6944193 | W74: =+(G74-E74)*4 -> 3 | X74: =+(G74-F74)*4 -> 4.84 | Y74: 1.6694676 | Z74: 5.0689868 | AC74: 28398 | AD74: =+V74 -> 4.6944193 | AF74: =+A74 -> 32324 | AG74: =+AD74 -> 4.6944193 | AS74: =A74 -> 32324
A75: 32416 | B75: 1.08 | C75: 4.44 | D75: 0.46 | E75: 0.93 | F75: 0.73 | G75: 1.99 | H75: 1.28 | I75: 1.84 | J75: NaN | K75: NaN | L75: 2.26 | M75: NaN | N75: NaN | O75: NaN | P75: NaN | Q75: NaN | R75: NaN | S75: NaN | T75: NaN | U75: NaN | V75: 4.4784821 | W75: =+(G75-E75)*4 -> 4.24 | X75: =+(G75-F75)*4 -> 5.04 | Y75: 1.8614584 | Z75: 5.2338877 | AC75: 28490 | AD75: =+V75 -> 4.4784821 | AF75: =+A75 -> 32416 | AG75: =+AD75 -> 4.4784821 | AS75: =A75 -> 32416
A76: 32508 | B76: 0.82 | C76: 4.42 | D76: 0.09 | E76: 1.31 | F76: 0.84 | G76: 2.12 | H76: 0.39 | I76: 1.38 | J76: NaN | K76: NaN | L76: 2.25 | M76: NaN | N76: NaN | O76: NaN | P76: NaN | Q76: NaN | R76: NaN | S76: NaN | T76: NaN | U76: NaN | V76: 5.1119031 | W76: =+(G76-E76)*4 -> 3.24 | X76: =+(G76-F76)*4 -> 5.12 | Y76: 1.9518661 | Z76: 5.178072 | AC76: 28580 | AD76: =+V76 -> 5.1119031 | AF76: =+A76 -> 32508 | AG76: =+AD76 -> 5.1119031 | AS76: =A76 -> 32508
A77: 32598 | B77: 0.83 | C77: 4.37 | D77: 0.7 | E77: 1.17 | F77: 0.86 | G77: 2.38 | H77: 0.63 | I77: 2.15 | J77: NaN | K77: NaN | L77: 2.35 | M77: NaN | N77: NaN | O77: NaN | P77: NaN | Q77: NaN | R77: NaN | S77: NaN | T77: NaN | U77: NaN | V77: 5.4495343 | W77: =+(G77-E77)*4 -> 4.84 | X77: =+(G77-F77)*4 -> 6.08 | Y77: 2.0873396 | Z77: 5.417534 | AC77: 28671 | AD77: =+V77 -> 5.4495343 | AF77: =+A77 -> 32598 | AG77: =+AD77 -> 5.4495343 | AS77: =A77 -> 32598
...

Sheet Ex_post_real_rate_gaps
A1: date | B1: obs_gdp | C1: obs_hours | D1: obs_wages | E1: obs_gdpdeflator | F1: obs_corepce | G1: obs_nominalrate | H1: obs_consumption | I1: obs_investment | J1: obs_BBBspread | K1: obs_longinflation | L1: obs_longrate | M1: obs_tfp | N1: obs_gdi | O1: obs_AAAspread | P1: obs_nominalrate1 | Q1: obs_nominalrate2 | R1: obs_nominalrate3 | S1: obs_nominalrate4 | T1: obs_nominalrate5 | U1: obs_nominalrate6 | V1: ex_ante_real_rate | W1: ex_post_real_rate | X1: ex_post_real_rate_core | Y1: HLW r* (25Q3) | Z1: DSGE r* wFG | AA1: Delta_Rstar_HLW | AB1: Delta_Rstar_DSGE | AC1: date | AD1: ex_ante_real_rate | AE1: actual_MP_stance
A2: 25749 | B2: 1.87 | C2: NaN | D2: 2.62 | E2: 1.81 | F2: NaN | G2: 1.99 | H2: 0.58 | I2: 5.67 | J2: NaN | K2: NaN | L2: 2.06 | M2: NaN | N2: NaN | O2: NaN | P2: NaN | Q2: NaN | R2: NaN | S2: NaN | T2: NaN | U2: NaN | W2: =+(G2-E2)*4 -> 0.72 | AC2: 21823
A3: 25841 | B3: 1.02 | C3: NaN | D3: 2.03 | E3: 1.78 | F3: NaN | G3: 1.9 | H3: 0.99 | I3: 0.7 | J3: NaN | K3: NaN | L3: 2.1 | M3: NaN | N3: NaN | O3: NaN | P3: NaN | Q3: NaN | R3: NaN | S3: NaN | T3: NaN | U3: NaN | W3: =+(G3-E3)*4 -> 0.48 | AC3: 21915
A4: 25933 | B4: 1.04 | C4: NaN | D4: 2.26 | E4: 1.17 | F4: NaN | G4: 1.81 | H4: 1.75 | I4: -0.04 | J4: NaN | K4: NaN | L4: 2.09 | M4: NaN | N4: NaN | O4: NaN | P4: NaN | Q4: NaN | R4: NaN | S4: NaN | T4: NaN | U4: NaN | W4: =+(G4-E4)*4 -> 2.56 | AC4: 22006
A5: 26023 | B5: -0.38 | C5: NaN | D5: 0.97 | E5: 2.3 | F5: NaN | G5: 1.63 | H5: -0.11 | I5: -0.82 | J5: NaN | K5: NaN | L5: 1.97 | M5: NaN | N5: NaN | O5: NaN | P5: NaN | Q5: NaN | R5: NaN | S5: NaN | T5: NaN | U5: NaN | W5: =+(G5-E5)*4 -> -2.68 | AC5: 22097
A6: 26114 | B6: 0.98 | C6: NaN | D6: 0.84 | E6: 1.13 | F6: NaN | G6: 1.48 | H6: 1.18 | I6: 2.83 | J6: NaN | K6: NaN | L6: 1.98 | M6: NaN | N6: NaN | O6: NaN | P6: NaN | Q6: NaN | R6: NaN | S6: NaN | T6: NaN | U6: NaN | W6: =+(G6-E6)*4 -> 1.4 | AC6: 22189
A7: 26206 | B7: 1.84 | C7: NaN | D7: 1.95 | E7: 1.67 | F7: NaN | G7: 1.56 | H7: 1.15 | I7: 0.17 | J7: NaN | K7: NaN | L7: 2.01 | M7: NaN | N7: NaN | O7: NaN | P7: NaN | Q7: NaN | R7: NaN | S7: NaN | T7: NaN | U7: NaN | W7: =+(G7-E7)*4 -> -0.44 | AC7: 22281
A8: 26298 | B8: 0.66 | C8: NaN | D8: 1.64 | E8: 1.1 | F8: NaN | G8: 1.5 | H8: 1.01 | I8: 1.6 | J8: NaN | K8: NaN | L8: 1.96 | M8: NaN | N8: NaN | O8: NaN | P8: NaN | Q8: NaN | R8: NaN | S8: NaN | T8: NaN | U8: NaN | W8: =+(G8-E8)*4 -> 1.6 | AC8: 22371
A9: 26389 | B9: 1.25 | C9: NaN | D9: 1.97 | E9: 2.16 | F9: NaN | G9: 1.26 | H9: 0.92 | I9: 0.36 | J9: NaN | K9: NaN | L9: 1.9 | M9: NaN | N9: NaN | O9: NaN | P9: NaN | Q9: NaN | R9: NaN | S9: NaN | T9: NaN | U9: NaN | W9: =+(G9-E9)*4 -> -3.6 | Y9: 3.3617854 | AC9: 22462
A10: 26480 | B10: 0.61 | C10: NaN | D10: 0.44 | E10: 1.59 | F10: NaN | G10: 1.19 | H10: 0.37 | I10: 1.28 | J10: NaN | K10: NaN | L10: 1.89 | M10: NaN | N10: NaN | O10: NaN | P10: NaN | Q10: NaN | R10: NaN | S10: NaN | T10: NaN | U10: NaN | W10: =+(G10-E10)*4 -> -1.6 | Y10: 2.4726543 | Z10: 3.8039334 | AC10: 22554
A11: 26572 | B11: 1.12 | C11: NaN | D11: 0.92 | E11: 1.57 | F11: NaN | G11: 1.21 | H11: 2.07 | I11: 0.57 | J11: NaN | K11: NaN | L11: 1.9 | M11: NaN | N11: NaN | O11: NaN | P11: NaN | Q11: NaN | R11: NaN | S11: NaN | T11: NaN | U11: NaN | V11: 1.0149957 | W11: =+(G11-E11)*4 -> -1.44 | Y11: 2.5754349 | Z11: 3.9836896 | AC11: 22646 | AD11: =+V11 -> 1.0149957
A12: 26664 | B12: 1.16 | C12: NaN | D12: 1.45 | E12: 1.54 | F12: NaN | G12: 1.6 | H12: 0.71 | I12: 2.02 | J12: NaN | K12: NaN | L12: 1.95 | M12: NaN | N12: NaN | O12: NaN | P12: NaN | Q12: NaN | R12: NaN | S12: NaN | T12: NaN | U12: NaN | V12: 0.99620506 | W12: =+(G12-E12)*4 -> 0.24 | Y12: 2.743556 | Z12: 4.3206825 | AC12: 22736 | AD12: =+V12 -> 0.99620506
A13: 26754 | B13: 1.65 | C13: NaN | D13: 1.47 | E13: 3.51 | F13: NaN | G13: 1.7 | H13: 0.32 | I13: 1.26 | J13: NaN | K13: NaN | L13: 1.99 | M13: NaN | N13: NaN | O13: NaN | P13: NaN | Q13: NaN | R13: NaN | S13: NaN | T13: NaN | U13: NaN | V13: 2.382294 | W13: =+(G13-E13)*4 -> -7.24 | Y13: 3.355047 | Z13: 4.3759537 | AC13: 22827 | AD13: =+V13 -> 2.382294
A14: 26845 | B14: 0.5 | C14: NaN | D14: 0.77 | E14: 2.43 | F14: NaN | G14: 2.12 | H14: 0.82 | I14: 0.29 | J14: NaN | K14: NaN | L14: 2.08 | M14: NaN | N14: NaN | O14: NaN | P14: NaN | Q14: NaN | R14: NaN | S14: NaN | T14: NaN | U14: NaN | V14: 1.883329 | W14: =+(G14-E14)*4 -> -1.24 | Y14: 3.0451464 | Z14: 4.6791313 | AC14: 22919 | AD14: =+V14 -> 1.883329
A15: 26937 | B15: 1.19 | C15: NaN | D15: 1.51 | E15: 2.38 | F15: NaN | G15: 2.55 | H15: 0.35 | I15: 1.21 | J15: NaN | K15: NaN | L15: 2.15 | M15: NaN | N15: NaN | O15: NaN | P15: NaN | Q15: NaN | R15: NaN | S15: NaN | T15: NaN | U15: NaN | V15: 3.7119285 | W15: =+(G15-E15)*4 -> 0.68 | Y15: 3.1512224 | Z15: 4.9922555 | AC15: 23011 | AD15: =+V15 -> 3.7119285
A16: 27029 | B16: 0.84 | C16: NaN | D16: 1.68 | E16: 2.32 | F16: NaN | G16: 2.77 | H16: 1.67 | I16: 0.85 | J16: NaN | K16: NaN | L16: 2.18 | M16: NaN | N16: NaN | O16: NaN | P16: NaN | Q16: NaN | R16: NaN | S16: NaN | T16: NaN | U16: NaN | V16: 5.4656472 | W16: =+(G16-E16)*4 -> 1.8 | Y16: 3.0581261 | Z16: 5.2172569 | AC16: 23101 | AD16: =+V16 -> 5.4656472
A17: 27119 | B17: 0.87 | C17: NaN | D17: 0.97 | E17: 3.16 | F17: NaN | G17: 2.81 | H17: 0.42 | I17: 1.1 | J17: NaN | K17: NaN | L17: 2.34 | M17: NaN | N17: NaN | O17: NaN | P17: NaN | Q17: NaN | R17: NaN | S17: NaN | T17: NaN | U17: NaN | V17: 6.2960412 | W17: =+(G17-E17)*4 -> -1.4 | Y17: 3.0365806 | Z17: 5.3314811 | AC17: 23192 | AD17: =+V17 -> 6.2960412
A18: 27210 | B18: 0.25 | C18: NaN | D18: 1.69 | E18: 3.49 | F18: NaN | G18: 2.87 | H18: 1.4 | I18: -1.62 | J18: NaN | K18: NaN | L18: 2.52 | M18: NaN | N18: NaN | O18: NaN | P18: NaN | Q18: NaN | R18: NaN | S18: NaN | T18: NaN | U18: NaN | V18: 5.9361561 | W18: =+(G18-E18)*4 -> -2.48 | Y18: 2.7779297 | Z18: 5.5611755 | AC18: 23284 | AD18: =+V18 -> 5.9361561
A19: 27302 | B19: 0.63 | C19: NaN | D19: 0.52 | E19: 3.38 | F19: NaN | G19: 2.88 | H19: 0.14 | I19: 0.97 | J19: NaN | K19: NaN | L19: 2.67 | M19: NaN | N19: NaN | O19: NaN | P19: NaN | Q19: NaN | R19: NaN | S19: NaN | T19: NaN | U19: NaN | V19: 5.9219283 | W19: =+(G19-E19)*4 -> -2 | Y19: 2.8841953 | Z19: 5.695278 | AC19: 23376 | AD19: =+V19 -> 5.9219283
A20: 27394 | B20: -1.79 | C20: NaN | D20: 1.26 | E20: 3.27 | F20: NaN | G20: 2.67 | H20: -0.78 | I20: -3.05 | J20: NaN | K20: NaN | L20: 2.65 | M20: NaN | N20: NaN | O20: NaN | P20: NaN | Q20: NaN | R20: NaN | S20: NaN | T20: NaN | U20: NaN | V20: 5.8587809 | W20: =+(G20-E20)*4 -> -2.4 | Y20: 2.0943443 | Z20: 5.3896745 | AC20: 23467 | AD20: =+V20 -> 5.8587809
A21: 27484 | B21: -0.88 | C21: NaN | D21: 0.39 | E21: 2.77 | F21: NaN | G21: 2.2 | H21: 0.29 | I21: -1.95 | J21: NaN | K21: NaN | L21: 2.47 | M21: NaN | N21: NaN | O21: NaN | P21: NaN | Q21: NaN | R21: NaN | S21: NaN | T21: NaN | U21: NaN | V21: 5.233664 | W21: =+(G21-E21)*4 -> -2.28 | Y21: 1.9937668 | Z21: 5.0569891 | AC21: 23558 | AD21: =+V21 -> 5.233664
A22: 27575 | B22: 0.81 | C22: NaN | D22: 1.68 | E22: 2.32 | F22: NaN | G22: 1.76 | H22: 1.68 | I22: -1.61 | J22: NaN | K22: NaN | L22: 2.39 | M22: NaN | N22: NaN | O22: NaN | P22: NaN | Q22: NaN | R22: NaN | S22: NaN | T22: NaN | U22: NaN | V22: 3.67475 | W22: =+(G22-E22)*4 -> -2.24 | Y22: 2.201963 | Z22: 5.0199626 | AC22: 23650 | AD22: =+V22 -> 3.67475
... A60: 31047 | B60: 0.42 | C60: NaN | D60: 0.69 | E60: 1.11 | F60: NaN | G60: 2.53 | H60: 0.51 | I60: 1.23 | J60: NaN | K60: NaN | L60: 2.85 | M60: NaN | N60: NaN | O60: NaN | P60: NaN | Q60: NaN | R60: NaN | S60: NaN | T60: NaN | U60: NaN | V60: 6.7600301 | W60: =+(G60-E60)*4 -> 5.68 | Y60: 1.7611247 | Z60: 6.1339007 | AC60: 27119 | AD60: =+V60 -> 6.7600301
A61: 31137 | B61: 0.16 | C61: 5.6 | D61: 0.43 | E61: 1.56 | F61: NaN | G61: 2.47 | H61: 0.91 | I61: -1.64 | J61: NaN | K61: NaN | L61: 2.74 | M61: NaN | N61: NaN | O61: NaN | P61: NaN | Q61: NaN | R61: NaN | S61: NaN | T61: NaN | U61: NaN | V61: 6.7806939 | W61: =+(G61-E61)*4 -> 3.64 | Y61: 1.7424814 | Z61: 5.9347699 | AC61: 27210 | AD61: =+V61 -> 6.7806939
A62: 31228 | B62: 0.81 | C62: 5.52 | D62: 0.06 | E62: 1.39 | F62: NaN | G62: 2.49 | H62: 0.34 | I62: 1.35 | J62: NaN | K62: NaN | L62: 2.71 | M62: NaN | N62: NaN | O62: NaN | P62: NaN | Q62: NaN | R62: NaN | S62: NaN | T62: NaN | U62: NaN | V62: 6.3991596 | W62: =+(G62-E62)*4 -> 4.4 | Y62: 1.8260628 | Z62: 5.9211855 | AC62: 27302 | AD62: =+V62 -> 6.3991596
A63: 31320 | B63: 0.63 | C63: 5.38 | D63: 0.49 | E63: 1.52 | F63: NaN | G63: 2.34 | H63: 0.38 | I63: 1.3 | J63: NaN | K63: NaN | L63: 2.67 | M63: NaN | N63: NaN | O63: NaN | P63: NaN | Q63: NaN | R63: NaN | S63: NaN | T63: NaN | U63: NaN | V63: 6.5046641 | W63: =+(G63-E63)*4 -> 3.28 | Y63: 1.5783718 | Z63: 5.7742924 | AC63: 27394 | AD63: =+V63 -> 6.5046641
A64: 31412 | B64: 0.3 | C64: 5.18 | D64: -0.02 | E64: 1.49 | F64: NaN | G64: 2.16 | H64: 0.12 | I64: 0.92 | J64: NaN | K64: NaN | L64: 2.57 | M64: NaN | N64: NaN | O64: NaN | P64: NaN | Q64: NaN | R64: NaN | S64: NaN | T64: NaN | U64: NaN | V64: 5.9159244 | W64: =+(G64-E64)*4 -> 2.68 | Y64: 1.5726696 | Z64: 5.5374687 | AC64: 27484 | AD64: =+V64 -> 5.9159244
A65: 31502 | B65: -0.63 | C65: 4.95 | D65: -0.39 | E65: 1.76 | F65: NaN | G65: 2.19 | H65: -0.84 | I65: -2.48 | J65: NaN | K65: NaN | L65: 2.44 | M65: NaN | N65: NaN | O65: NaN | P65: NaN | Q65: NaN | R65: NaN | S65: NaN | T65: NaN | U65: NaN | V65: 5.1987007 | W65: =+(G65-E65)*4 -> 1.72 | Y65: 1.2239614 | Z65: 5.2647753 | AC65: 27575 | AD65: =+V65 -> 5.1987007
A66: 31593 | B66: 1.55 | C66: 4.78 | D66: 0.22 | E66: 1.3 | F66: NaN | G66: 2.01 | H66: 0.8 | I66: 1.99 | J66: NaN | K66: NaN | L66: 2.15 | M66: NaN | N66: NaN | O66: NaN | P66: NaN | Q66: NaN | R66: NaN | S66: NaN | T66: NaN | U66: NaN | V66: 5.2075525 | W66: =+(G66-E66)*4 -> 2.84 | Y66: 1.3749519 | Z66: 5.0448919 | AC66: 27667 | AD66: =+V66 -> 5.2075525
A67: 31685 | B67: 0.18 | C67: 4.7 | D67: 0.12 | E67: 1.14 | F67: NaN | G67: 1.94 | H67: -0.17 | I67: 0.36 | J67: NaN | K67: NaN | L67: 2.1 | M67: NaN | N67: NaN | O67: NaN | P67: NaN | Q67: NaN | R67: NaN | S67: NaN | T67: NaN | U67: NaN | V67: 4.8244061 | W67: =+(G67-E67)*4 -> 3.2 | Y67: 1.2983166 | Z67: 4.8969846 | AC67: 27759 | AD67: =+V67 -> 4.8244061
A68: 31777 | B68: -0.16 | C68: 4.67 | D68: 0.14 | E68: 0.85 | F68: NaN | G68: 1.97 | H68: 0.5 | I68: 0.57 | J68: NaN | K68: NaN | L68: 2.12 | M68: NaN | N68: NaN | O68: NaN | P68: NaN | Q68: NaN | R68: NaN | S68: NaN | T68: NaN | U68: NaN | V68: 4.7220469 | W68: =+(G68-E68)*4 -> 4.48 | Y68: 1.2102238 | Z68: 5.036552 | AC68: 27850 | AD68: =+V68 -> 4.7220469
A69: 31867 | B69: -0.73 | C69: 4.73 | D69: 0.11 | E69: 0.84 | F69: NaN | G69: 2.03 | H69: -0.22 | I69: -1.82 | J69: NaN | K69: NaN | L69: 2.12 | M69: NaN | N69: NaN | O69: NaN | P69: NaN | Q69: NaN | R69: NaN | S69: NaN | T69: NaN | U69: NaN | V69: 5.0143179 | W69: =+(G69-E69)*4 -> 4.76 | Y69: 1.1729481 | Z69: 5.0312545 | AC69: 27941 | AD69: =+V69 -> 5.0143179
A70: 31958 | B70: 1.36 | C70: 4.76 | D70: 0.96 | E70: 0.84 | F70: NaN | G70: 2.11 | H70: 1.55 | I70: 2.92 | J70: NaN | K70: NaN | L70: 2.17 | M70: NaN | N70: NaN | O70: NaN | P70: NaN | Q70: NaN | R70: NaN | S70: NaN | T70: NaN | U70: NaN | V70: 5.318176 | W70: =+(G70-E70)*4 -> 5.08 | Y70: 1.4883935 | Z70: 5.3521411 | AC70: 28033 | AD70: =+V70 -> 5.318176
A71: 32050 | B71: 0.82 | C71: 4.73 | D71: 0.61 | E71: 0.69 | F71: NaN | G71: 2.12 | H71: 0.75 | I71: 2.01 | J71: NaN | K71: NaN | L71: 2.37 | M71: NaN | N71: NaN | O71: NaN | P71: NaN | Q71: NaN | R71: NaN | S71: NaN | T71: NaN | U71: NaN | V71: 5.7226882 | W71: =+(G71-E71)*4 -> 5.72 | Y71: 1.5836338 | Z71: 5.4449257 | AC71: 28125 | AD71: =+V71 -> 5.7226882
A72: 32142 | B72: 1.09 | C72: 4.68 | D72: 0.23 | E72: 1.23 | F72: NaN | G72: 2.11 | H72: 0.53 | I72: 1.51 | J72: NaN | K72: NaN | L72: 2.4 | M72: NaN | N72: NaN | O72: NaN | P72: NaN | Q72: NaN | R72: NaN | S72: NaN | T72: NaN | U72: NaN | V72: 5.8040639 | W72: =+(G72-E72)*4 -> 3.52 | Y72: 1.667646 | Z72: 5.3824644 | AC72: 28215 | AD72: =+V72 -> 5.8040639
A73: 32233 | B73: 0.18 | C73: 4.58 | D73: 0.4 | E73: 0.95 | F73: 0.57 | G73: 1.86 | H73: -0.58 | I73: 1.05 | J73: NaN | K73: NaN | L73: 2.25 | M73: NaN | N73: NaN | O73: NaN | P73: NaN | Q73: NaN | R73: NaN | S73: NaN | T73: NaN | U73: NaN | V73: 5.4987128 | W73: =+(G73-E73)*4 -> 3.64 | X73: =+(G73-F73)*4 -> 5.16 | Y73: 1.6047869 | Z73: 5.0438207 | AC73: 28306 | AD73: =+V73 -> 5.4987128
A74: 32324 | B74: 0.62 | C74: 4.49 | D74: 0.23 | E74: 1.07 | F74: 0.61 | G74: 1.82 | H74: 0.39 | I74: 1.64 | J74: NaN | K74: NaN | L74: 2.22 | M74: NaN | N74: NaN | O74: NaN | P74: NaN | Q74: NaN | R74: NaN | S74: NaN | T74: NaN | U74: NaN | V74: 4.6944193 | W74: =+(G74-E74)*4 -> 3 | X74: =+(G74-F74)*4 -> 4.84 | Y74: 1.6694676 | Z74: 5.0689868 | AC74: 28398 | AD74: =+V74 -> 4.6944193
A75: 32416 | B75: 1.08 | C75: 4.44 | D75: 0.46 | E75: 0.93 | F75: 0.73 | G75: 1.99 | H75: 1.28 | I75: 1.84 | J75: NaN | K75: NaN | L75: 2.26 | M75: NaN | N75: NaN | O75: NaN | P75: NaN | Q75: NaN | R75: NaN | S75: NaN | T75: NaN | U75: NaN | V75: 4.4784821 | W75: =+(G75-E75)*4 -> 4.24 | X75: =+(G75-F75)*4 -> 5.04 | Y75: 1.8614584 | Z75: 5.2338877 | AC75: 28490 | AD75: =+V75 -> 4.4784821
A76: 32508 | B76: 0.82 | C76: 4.42 | D76: 0.09 | E76: 1.31 | F76: 0.84 | G76: 2.12 | H76: 0.39 | I76: 1.38 | J76: NaN | K76: NaN | L76: 2.25 | M76: NaN | N76: NaN | O76: NaN | P76: NaN | Q76: NaN | R76: NaN | S76: NaN | T76: NaN | U76: NaN | V76: 5.1119031 | W76: =+(G76-E76)*4 -> 3.24 | X76: =+(G76-F76)*4 -> 5.12 | Y76: 1.9518661 | Z76: 5.178072 | AC76: 28580 | AD76: =+V76 -> 5.1119031
A77: 32598 | B77: 0.83 | C77: 4.37 | D77: 0.7 | E77: 1.17 | F77: 0.86 | G77: 2.38 | H77: 0.63 | I77: 2.15 | J77: NaN | K77: NaN | L77: 2.35 | M77: NaN | N77: NaN | O77: NaN | P77: NaN | Q77: NaN | R77: NaN | S77: NaN | T77: NaN | U77: NaN | V77: 5.4495343 | W77: =+(G77-E77)*4 -> 4.84 | X77: =+(G77-F77)*4 -> 6.08 | Y77: 2.0873396 | Z77: 5.417534 | AC77: 28671 | AD77: =+V77 -> 5.4495343
...

Sheet ConvenienceYield_fullsample
A1: Date | B1: ConvenienceYield_EA | C1: Euro area Convenience Yield | D1: ConvenienceYield_US | E1: US Convenience Yield | F1: Euro area Convenience Yield
A2: 25933 | B2: 0.19705207 | C2: 0.78820828
A3: 26023 | B3: 0.25928649 | C3: 1.0371459
A4: 26114 | B4: 0.0071246574 | C4: 0.02849863
A5: 26206 | B5: 0.074842244 | C5: 0.29936898 | D5: 0.020592286 | E5: 0.082369144
A6: 26298 | B6: 0.12684548 | C6: 0.50738191 | D6: -0.27546809 | E6: -1.1018723
A7: 26389 | B7: 0.090544924 | C7: 0.3621797 | D7: -0.26937696 | E7: -1.0775078
A8: 26480 | B8: -0.064440652 | C8: -0.25776261 | D8: -0.1959892 | E8: -0.7839568
A9: 26572 | B9: -0.090438669 | C9: -0.36175467 | D9: -0.12756202 | E9: -0.51024809
A10: 26664 | B10: 0.084285096 | C10: 0.33714038 | D10: -0.09161451 | E10: -0.36645804
A11: 26754 | B11: 0.19941552 | C11: 0.79766206 | D11: -0.26337683 | E11: -1.0535073
A12: 26845 | B12: 0.072136016 | C12: 0.28854406 | D12: -0.059254174 | E12: -0.2370167
A13: 26937 | B13: 0.32860025 | C13: 1.314401 | D13: -0.09063779 | E13: -0.36255116
A14: 27029 | B14: 0.43112249 | C14: 1.7244899 | D14: 0.043436992 | E14: 0.17374797
A15: 27119 | B15: 0.57994139 | C15: 2.3197656 | D15: 0.19347952 | E15: 0.77391809
A16: 27210 | B16: 0.43512458 | C16: 1.7404983 | D16: 0.099058446 | E16: 0.39623379
... A217: 45565 | B217: 0.068277438 | C217: 0.27310975 | D217: 0.12220019 | E217: 0.48880075
A218: 45657 | D218: 0.10860395 | E218: 0.43441581
A219: 45747 | D219: 0.060178762 | E219: 0.24071505
A220: 45838 | D220: 0.063904098 | E220: 0.25561639

Sheet EA_output_obs_with_text
A1: date | B1: g_sh | C1: b_liqtil_sh | D1: b_liqp_sh | E1: b_safetil_sh | F1: b_safep_sh | G1: mu_sh | H1: z_sh | I1: lambda_f_sh | J1: lambda_w_sh | K1: rm_sh | L1: sigma_omega_sh | M1: mu_e_sh | N1: gamma_sh | O1: pi_star_sh | P1: lr_sh | Q1: zp_sh | R1: tfp_sh | S1: gdpdef_sh | T1: corepce_sh | U1: gdp_sh | V1: gdi_sh | W1: BBB_sh | X1: AAA_sh | Y1: rm_shl1 | Z1: rm_shl2 | AA1: rm_shl3 | AB1: rm_shl4 | AC1: rm_shl5 | AD1: rm_shl6 | AE1: dettrend | AF1: detrendedMean | AH1: rm_sh | AI1: =Y1 -> rm_shl1 | AJ1: =Z1 -> rm_shl2 | AK1: =AA1 -> rm_shl3 | AL1: =AB1 -> rm_shl4 | AM1: =AC1 -> rm_shl5 | AN1: =AD1 -> rm_shl6 | AQ1: Plot | AR1: =A1 -> date | AS1: =AF1 -> detrendedMean | AT1: Surprise Policy (t) | AU1: Fgsum | AV1: Anticipated (t+1|t) | AW1: Anticipated (t+2|t) | AX1: Anticipated (t+3|t) | AY1: Anticipated (t+4|t) | AZ1: Anticipated (t+5|t) | BA1: Anticipated (t+6|t) | BB1: Combined | BC1: date | BD1: rm_sh | BE1: Fgsum
A2: 39172 | B2: 0.79440409 | C2: 0.02411441 | D2: -0.18874911 | E2: 1.9449427 | F2: -0.70213708 | G2: -4.2282539 | H2: -0.014989197 | I2: -0.08556396 | J2: 0.0021457165 | K2: 0.75451741 | L2: 1.2749568 | M2: 0 | N2: 0 | O2: -1.162726 | P2: 0 | Q2: -0.10386809 | R2: 0 | S2: 0 | T2: 0 | U2: 0 | V2: 0 | W2: 0 | X2: 0 | Y2: 0 | Z2: 0 | AA2: 0 | AB2: 0 | AC2: 0 | AD2: 0 | AE2: -7.2979494 | AF2: -8.9891556 | AH2: =K2+Y2-Y2/100 -> 0.75451741 | AI2: =Y2 -> 0 | AJ2: =Z2 -> 0 | AK2: =AA2 -> 0 | AL2: =AB2 -> 0 | AM2: =AC2 -> 0 | AN2: =AD2 -> 0 | AR2: =A2 -> 39172 | AS2: =AF2*4+2 -> -33.956622 | AU2: =SUM(AV2:BA2) -> 0 | AV2: =AI2 -> 0 | AW2: =AJ2 -> 0 | AX2: =AK2 -> 0 | AY2: =AL2 -> 0 | AZ2: =AM2 -> 0 | BA2: =AN2 -> 0 | BB2: =SUM(AT2:BA2) -> 0 | BC2: =AR2 -> 39172 | BD2: =AT2-$AT$2 -> 0 | BE2: =AU2-$AU$2 -> 0
A3: 39263 | B3: 0.54565261 | C3: 0.047237273 | D3: -0.24871527 | E3: 2.3787568 | F3: -0.64132794 | G3: -4.514584 | H3: -0.0029421649 | I3: -0.098584141 | J3: 0.001271583 | K3: 0.85061535 | L3: 1.3178767 | M3: 0 | N3: 0 | O3: -1.1139904 | P3: 0 | Q3: -0.091694204 | R3: 0 | S3: 0 | T3: 0 | U3: 0 | V3: 0 | W3: 0 | X3: 0 | Y3: 0 | Z3: 0 | AA3: 0 | AB3: 0 | AC3: 0 | AD3: 0 | AE3: -7.3083574 | AF3: -8.8787852 | AH3: =K3+Y3-Y3/100 -> 0.85061535 | AI3: =Y3 -> 0 | AJ3: =Z3 -> 0 | AK3: =AA3 -> 0 | AL3: =AB3 -> 0 | AM3: =AC3 -> 0 | AN3: =AD3 -> 0 | AR3: =A3 -> 39263 | AS3: =AF3*4+2 -> -33.515141 | AU3: =SUM(AV3:BA3) -> 0 | AV3: =AI3 -> 0 | AW3: =AJ3 -> 0 | AX3: =AK3 -> 0 | AY3: =AL3 -> 0 | AZ3: =AM3 -> 0 | BA3: =AN3 -> 0 | BB3: =SUM(AT3:BA3) -> 0 | BC3: =AR3 -> 39263 | BD3: =AT3-$AT$2 -> 0 | BE3: =AU3 -> 0
A4: 39355 | B4: 0.54705815 | C4: 0.028123435 | D4: -0.36446568 | E4: 2.5384113 | F4: -0.58576346 | G4: -4.7104491 | H4: 0.0068425824 | I4: -0.10249897 | J4: -9.7226422e-05 | K4: 0.76040116 | L4: 1.356224 | M4: 0 | N4: 0 | O4: -0.93968395 | P4: 0 | Q4: -0.013590541 | R4: 0 | S4: 0 | T4: 0 | U4: 0 | V4: 0 | W4: 0 | X4: 0 | Y4: 0 | Z4: 0 | AA4: 0 | AB4: 0 | AC4: 0 | AD4: 0 | AE4: -7.3186178 | AF4: -8.7981061 | AH4: =K4+Y4-Y4/100 -> 0.76040116 | AI4: =Y4 -> 0 | AJ4: =Z4 -> 0 | AK4: =AA4 -> 0 | AL4: =AB4 -> 0 | AM4: =AC4 -> 0 | AN4: =AD4 -> 0 | AR4: =A4 -> 39355 | AS4: =AF4*4+2 -> -33.192424 | AU4: =SUM(AV4:BA4) -> 0 | AV4: =AI4 -> 0 | AW4: =AJ4 -> 0 | AX4: =AK4 -> 0 | AY4: =AL4 -> 0 | AZ4: =AM4 -> 0 | BA4: =AN4 -> 0 | BB4: =SUM(AT4:BA4) -> 0 | BC4: =AR4 -> 39355 | BD4: =AT4-$AT$2 -> 0 | BE4: =AU4 -> 0
A5: 39447 | B5: 0.41308918 | C5: 0.047267991 | D5: -0.60637151 | E5: 2.932617 | F5: -0.58276727 | G5: -4.8678855 | H5: 0.00043125868 | I5: -0.10810363 | J5: -0.00011608262 | K5: 0.81504165 | L5: 1.4063924 | M5: 0 | N5: 0 | O5: -0.89426047 | P5: 0 | Q5: -0.028454827 | R5: 0 | S5: 0 | T5: 0 | U5: 0 | V5: 0 | W5: 0 | X5: 0 | Y5: 0 | Z5: 0 | AA5: 0 | AB5: 0 | AC5: 0 | AD5: 0 | AE5: -7.3287315 | AF5: -8.8018512 | AH5: =K5+Y5-Y5/100 -> 0.81504165 | AI5: =Y5 -> 0 | AJ5: =Z5 -> 0 | AK5: =AA5 -> 0 | AL5: =AB5 -> 0 | AM5: =AC5 -> 0 | AN5: =AD5 -> 0 | AR5: =A5 -> 39447 | AS5: =AF5*4+2 -> -33.207405 | AU5: =SUM(AV5:BA5) -> 0 | AV5: =AI5 -> 0 | AW5: =AJ5 -> 0 | AX5: =AK5 -> 0 | AY5: =AL5 -> 0 | AZ5: =AM5 -> 0 | BA5: =AN5 -> 0 | BB5: =SUM(AT5:BA5) -> 0 | BC5: =AR5 -> 39447 | BD5: =AT5-$AT$2 -> 0 | BE5: =AU5 -> 0
A6: 39538 | B6: 0.38144958 | C6: 0.040044207 | D6: -0.76261568 | E6: 2.9440803 | F6: -0.60451552 | G6: -4.9183402 | H6: -0.0049381687 | I6: -0.11784446 | J6: 0.0030439982 | K6: 0.97095784 | L6: 1.408865 | M6: 0 | N6: 0 | O6: -0.71988047 | P6: 0 | Q6: 0.013774859 | R6: 0 | S6: 0 | T6: 0 | U6: 0 | V6: 0 | W6: 0 | X6: 0 | Y6: 0 | Z6: 0 | AA6: 0 | AB6: 0 | AC6: 0 | AD6: 0 | AE6: -7.3386994 | AF6: -8.7046181 | AH6: =K6+Y6-Y6/100 -> 0.97095784 | AI6: =Y6 -> 0 | AJ6: =Z6 -> 0 | AK6: =AA6 -> 0 | AL6: =AB6 -> 0 | AM6: =AC6 -> 0 | AN6: =AD6 -> 0 | AR6: =A6 -> 39538 | AS6: =AF6*4+2 -> -32.818472 | AU6: =SUM(AV6:BA6) -> 0 | AV6: =AI6 -> 0 | AW6: =AJ6 -> 0 | AX6: =AK6 -> 0 | AY6: =AL6 -> 0 | AZ6: =AM6 -> 0 | BA6: =AN6 -> 0 | BB6: =SUM(AT6:BA6) -> 0 | BC6: =AR6 -> 39538 | BD6: =AT6-$AT$2 -> 0 | BE6: =AU6 -> 0
A7: 39629 | B7: 0.27911994 | C7: 0.055219855 | D7: -0.87797518 | E7: 2.9986394 | F7: -0.64437232 | G7: -5.0257811 | H7: -0.0041234996 | I7: -0.11677837 | J7: 0.00044371178 | K7: 0.74062639 | L7: 1.4092967 | M7: 0 | N7: 0 | O7: -0.68379726 | P7: 0 | Q7: 0.087977681 | R7: 0 | S7: 0 | T7: 0 | U7: 0 | V7: 0 | W7: 0 | X7: 0 | Y7: 0 | Z7: 0 | AA7: 0 | AB7: 0 | AC7: 0 | AD7: 0 | AE7: -7.3485225 | AF7: -9.1300265 | AH7: =K7+Y7-Y7/100 -> 0.74062639 | AI7: =Y7 -> 0 | AJ7: =Z7 -> 0 | AK7: =AA7 -> 0 | AL7: =AB7 -> 0 | AM7: =AC7 -> 0 | AN7: =AD7 -> 0 | AR7: =A7 -> 39629 | AS7: =AF7*4+2 -> -34.520106 | AU7: =SUM(AV7:BA7) -> 0 | AV7: =AI7 -> 0 | AW7: =AJ7 -> 0 | AX7: =AK7 -> 0 | AY7: =AL7 -> 0 | AZ7: =AM7 -> 0 | BA7: =AN7 -> 0 | BB7: =SUM(AT7:BA7) -> 0 | BC7: =AR7 -> 39629 | BD7: =AT7-$AT$2 -> 0 | BE7: =AU7 -> 0
A8: 39721 | B8: -0.027537173 | C8: 0.069966171 | D8: -0.94524939 | E8: 2.8937613 | F8: -0.66448329 | G8: -5.0063443 | H8: -0.023667347 | I8: -0.098479418 | J8: 0.0045890535 | K8: 0.44959469 | L8: 1.3685364 | M8: 0 | N8: 0 | O8: -0.49492961 | P8: 0 | Q8: 0.17729326 | R8: 0 | S8: 0 | T8: 0 | U8: 0 | V8: 0 | W8: 0 | X8: 0 | Y8: 0 | Z8: 0 | AA8: 0 | AB8: 0 | AC8: 0 | AD8: 0 | AE8: -7.3582018 | AF8: -9.6551515 | AH8: =K8+Y8-Y8/100 -> 0.44959469 | AI8: =Y8 -> 0 | AJ8: =Z8 -> 0 | AK8: =AA8 -> 0 | AL8: =AB8 -> 0 | AM8: =AC8 -> 0 | AN8: =AD8 -> 0 | AR8: =A8 -> 39721 | AS8: =AF8*4+2 -> -36.620606 | AT8: =AH8-$AH$8 -> 0 | AU8: =SUM(AV8:BA8) -> 0 | AV8: =AI8 -> 0 | AW8: =AJ8 -> 0 | AX8: =AK8 -> 0 | AY8: =AL8 -> 0 | AZ8: =AM8 -> 0 | BA8: =AN8 -> 0 | BB8: =SUM(AT8:BA8) -> 0 | BC8: =AR8 -> 39721 | BD8: =AT8-$AT$2 -> 0 | BE8: =AU8 -> 0
A9: 39813 | B9: -0.099277021 | C9: 0.017249607 | D9: -1.3049743 | E9: 2.1501178 | F9: -0.84702014 | G9: -4.4528781 | H9: 0.027128099 | I9: -0.078488213 | J9: 0.0033151854 | K9: 0.32622877 | L9: 1.241816 | M9: 0 | N9: 0 | O9: -0.2507942 | P9: 0 | Q9: 0.46263743 | R9: 0 | S9: 0 | T9: 0 | U9: 0 | V9: 0 | W9: 0 | X9: 0 | Y9: 0.096951586 | Z9: -0.014225866 | AA9: -0.026628583 | AB9: -0.0060620762 | AC9: -0.0037695085 | AD9: -0.0032380133 | AE9: -7.3677382 | AF9: -10.12965 | AH9: =K9+Y9-Y9/100 -> 0.42221084 | AI9: =Y9/1010 -> 9.5991669e-05 | AJ9: =Z9 -> -0.014225866 | AK9: =AA9 -> -0.026628583 | AL9: =AB9 -> -0.0060620762 | AM9: =AC9 -> -0.0037695085 | AN9: =AD9 -> -0.0032380133 | AR9: =A9 -> 39813 | AS9: =AF9*4+2 -> -38.518599 | AT9: =AH9-$AH$8 -> -0.027383852 | AU9: =SUM(AV9:BA9) -> -0.053828055 | AV9: =AI9 -> 9.5991669e-05 | AW9: =AJ9 -> -0.014225866 | AX9: =AK9 -> -0.026628583 | AY9: =AL9 -> -0.0060620762 | AZ9: =AM9 -> -0.0037695085 | BA9: =AN9 -> -0.0032380133 | BB9: =SUM(AT9:AU9) -> -0.081211908 | BC9: =AR9 -> 39813 | BD9: =AT9-$AT$2 -> -0.027383852 | BE9: =AU9 -> -0.053828055
A10: 39903 | B10: -0.67955928 | C10: -0.04411321 | D10: -1.4120102 | E10: 1.1343119 | F10: -1.0676786 | G10: -4.0521954 | H10: 0.068855711 | I10: -0.048194982 | J10: -0.0027616026 | K10: 0.52735071 | L10: 1.0659297 | M10: 0 | N10: 0 | O10: -0.18402324 | P10: 0 | Q10: 0.60718337 | R10: 0 | S10: 0 | T10: 0 | U10: 0 | V10: 0 | W10: 0 | X10: 0 | Y10: 0.085468601 | Z10: -0.078568102 | AA10: -0.066043133 | AB10: -0.025775416 | AC10: -0.018493377 | AD10: -0.020410625 | AE10: -7.3771328 | AF10: -11.58786 | AH10: =K10+Y10-Y10/100 -> 0.61196463 | AI10: =Y10/1010 -> 8.4622378e-05 | AJ10: =Z10 -> -0.078568102 | AK10: =AA10 -> -0.066043133 | AL10: =AB10 -> -0.025775416 | AM10: =AC10 -> -0.018493377 | AN10: =AD10 -> -0.020410625 | AR10: =A10 -> 39903 | AS10: =AF10*4+2 -> -44.35144 | AT10: =AH10-$AH$8 -> 0.16236993 | AU10: =SUM(AV10:BA10) -> -0.20920603 | AV10: =AI10 -> 8.4622378e-05 | AW10: =AJ10 -> -0.078568102 | AX10: =AK10 -> -0.066043133 | AY10: =AL10 -> -0.025775416 | AZ10: =AM10 -> -0.018493377 | BA10: =AN10 -> -0.020410625 | BB10: =SUM(AT10:AU10) -> -0.046836096 | BC10: =AR10 -> 39903 | BD10: =AT10-$AT$2 -> 0.16236993 | BE10: =AU10 -> -0.20920603
A11: 39994 | B11: -0.62404783 | C11: -0.036317994 | D11: -1.2041256 | E11: 0.54841505 | F11: -1.2345088 | G11: -3.81943 | H11: 0.0099364832 | I11: -0.0020104602 | J11: -0.0044683656 | K11: 0.56962848 | L11: 0.92830503 | M11: 0 | N11: 0 | O11: -0.16251692 | P11: 0 | Q11: 0.34641923 | R11: 0 | S11: 0 | T11: 0 | U11: 0 | V11: 0 | W11: 0 | X11: 0 | Y11: 0.1089347 | Z11: -0.11513068 | AA11: -0.084555692 | AB11: -0.035476589 | AC11: -0.021715243 | AD11: -0.043017455 | AE11: -7.3863865 | AF11: -12.262069 | AH11: =K11+Y11-Y11/100 -> 0.67747384 | AI11: =Y11/1010 -> 0.00010785614 | AJ11: =Z11 -> -0.11513068 | AK11: =AA11 -> -0.084555692 | AL11: =AB11 -> -0.035476589 | AM11: =AC11 -> -0.021715243 | AN11: =AD11 -> -0.043017455 | AR11: =A11 -> 39994 | AS11: =AF11*4+2 -> -47.048277 | AT11: =AH11-$AH$8 -> 0.22787914 | AU11: =SUM(AV11:BA11) -> -0.2997878 | AV11: =AI11 -> 0.00010785614 | AW11: =AJ11 -> -0.11513068 | AX11: =AK11 -> -0.084555692 | AY11: =AL11 -> -0.035476589 | AZ11: =AM11 -> -0.021715243 | BA11: =AN11 -> -0.043017455 | BB11: =SUM(AT11:AU11) -> -0.071908661 | BC11: =AR11 -> 39994 | BD11: =AT11-$AT$2 -> 0.22787914 | BE11: =AU11 -> -0.2997878
