Workbook
Name BoxPlot: "BoxPlot"
Name Bubble: "Bubble"
Name Candlestick: "Candlestick"
Name Chart: "Chart"
Name ChartImage: "ChartImage"
Name ColumnRange: "ColumnRange"
Name Dumbbell: "Dumbbell"
Name Heatmap: "Heatmap"
Name Histogram: "Histogram"
Name Map: "Map"
Name OHLC: "OHLC"
Name PieChart: "PieChart"
Name Scatter: "Scatter"
Name Series: "Series"
Name Stripe: "Stripe"
Name Table: "Table"
Name TreeMap: "TreeMap"
Name Waterfall: "Waterfall"

Sheet Delta
A1: date | B1: g_sh | C1: b_liqtil_sh | D1: b_liqp_sh | E1: b_safetil_sh | F1: b_safep_sh | G1: mu_sh | H1: z_sh | I1: lambda_f_sh | J1: lambda_w_sh | K1: rm_sh | L1: sigma_omega_sh | M1: mu_e_sh | N1: gamma_sh | O1: pi_star_sh | P1: lr_sh | Q1: zp_sh | R1: tfp_sh | S1: gdpdef_sh | T1: corepce_sh | U1: gdp_sh | V1: gdi_sh | W1: BBB_sh | X1: AAA_sh | Y1: rm_shl1 | Z1: rm_shl2 | AA1: rm_shl3 | AB1: rm_shl4 | AC1: rm_shl5 | AD1: rm_shl6 | AE1: dettrend | AF1: detrendedMean | AJ1: Chart | AK1: Date | AL1: Government | AM1: Transitory Liquidity | AN1: Permanent Liquidity | AO1: Transitory Safety | AP1: Permanent Safety | AQ1: Investment specific technology | AR1: TFP | AS1: Permanent TFP | AT1: Others
A2: 39172 | B2: =wFG!B2-woFG!B2 -> -0.0040182309 | C2: =wFG!C2-woFG!C2 -> -3.4387815e-09 | D2: =wFG!D2-woFG!D2 -> 0.00015769102 | E2: =wFG!E2-woFG!E2 -> -1.4191222e-05 | F2: =wFG!F2-woFG!F2 -> -0.069762248 | G2: =wFG!G2-woFG!G2 -> -0.010250825 | H2: =wFG!H2-woFG!H2 -> 0.0091536634 | I2: =wFG!I2-woFG!I2 -> -1.2691985e-16 | ... AF2: =wFG!AF2-woFG!AF2 -> -0.066011156 | AK2: =+A2 -> 39172 | AL2: =+B2 -> -0.0040182309 | AM2: =+C2 -> -3.4387815e-09 | AN2: =+D2 -> 0.00015769102 | AO2: =+E2 -> -1.4191222e-05 | AP2: =+F2 -> -0.069762248 | AQ2: =+G2 -> -0.010250825 | AR2: =+H2 -> 0.0091536634 | AS2: =+Q2 -> 0.015634467 | AT2: =+AF2-SUM(AL2:AS2) -> -0.0069114782
A3: 39263 | B3: =wFG!B3-woFG!B3 -> -0.0040255062 | C3: =wFG!C3-woFG!C3 -> -7.1807698e-09 | D3: =wFG!D3-woFG!D3 -> 0.00029989416 | E3: =wFG!E3-woFG!E3 -> -2.0146497e-05 | F3: =wFG!F3-woFG!F3 -> -0.070613879 | G3: =wFG!G3-woFG!G3 -> -0.010212772 | H3: =wFG!H3-woFG!H3 -> 0.0094219779 | I3: =wFG!I3-woFG!I3 -> -1.2734572e-16 | ... AF3: =wFG!AF3-woFG!AF3 -> -0.064900863 | AK3: =+A3 -> 39263 | AL3: =+B3 -> -0.0040255062 | AM3: =+C3 -> -7.1807698e-09 | AN3: =+D3 -> 0.00029989416 | AO3: =+E3 -> -2.0146497e-05 | AP3: =+F3 -> -0.070613879 | AQ3: =+G3 -> -0.010212772 | AR3: =+H3 -> 0.0094219779 | AS3: =+Q3 -> 0.016937439 | AT3: =+AF3-SUM(AL3:AS3) -> -0.0066878636
A4: 39355 | B4: =wFG!B4-woFG!B4 -> -0.0040315024 | C4: =wFG!C4-woFG!C4 -> -1.2346094e-08 | D4: =wFG!D4-woFG!D4 -> 0.00050874443 | E4: =wFG!E4-woFG!E4 -> -2.6772113e-05 | F4: =wFG!F4-woFG!F4 -> -0.071420982 | G4: =wFG!G4-woFG!G4 -> -0.010163341 | H4: =wFG!H4-woFG!H4 -> 0.0097164833 | I4: =wFG!I4-woFG!I4 -> -1.2784653e-16 | ... AF4: =wFG!AF4-woFG!AF4 -> -0.063480464 | AK4: =+A4 -> 39355 | AL4: =+B4 -> -0.0040315024 | AM4: =+C4 -> -1.2346094e-08 | AN4: =+D4 -> 0.00050874443 | AO4: =+E4 -> -2.6772113e-05 | AP4: =+F4 -> -0.071420982 | AQ4: =+G4 -> -0.010163341 | AR4: =+H4 -> 0.0097164833 | AS4: =+Q4 -> 0.018388223 | AT4: =+AF4-SUM(AL4:AS4) -> -0.006451305
A5: 39447 | B5: =wFG!B5-woFG!B5 -> -0.0040360771 | C5: =wFG!C5-woFG!C5 -> -1.9785729e-08 | D5: =wFG!D5-woFG!D5 -> 0.0008131951 | E5: =wFG!E5-woFG!E5 -> -3.4024382e-05 | F5: =wFG!F5-woFG!F5 -> -0.072174086 | G5: =wFG!G5-woFG!G5 -> -0.010100535 | H5: =wFG!H5-woFG!H5 -> 0.010040548 | I5: =wFG!I5-woFG!I5 -> -1.2847645e-16 | ... AF5: =wFG!AF5-woFG!AF5 -> -0.061682039 | AK5: =+A5 -> 39447 | AL5: =+B5 -> -0.0040360771 | AM5: =+C5 -> -1.9785729e-08 | AN5: =+D5 -> 0.0008131951 | AO5: =+E5 -> -3.4024382e-05 | AP5: =+F5 -> -0.072174086 | AQ5: =+G5 -> -0.010100535 | AR5: =+H5 -> 0.010040548 | AS5: =+Q5 -> 0.0200091 | AT5: =+AF5-SUM(AL5:AS5) -> -0.0062001403
A6: 39538 | B6: =wFG!B6-woFG!B6 -> -0.0040391822 | C6: =wFG!C6-woFG!C6 -> -3.0965542e-08 | D6: =wFG!D6-woFG!D6 -> 0.0012548505 | E6: =wFG!E6-woFG!E6 -> -4.1743389e-05 | F6: =wFG!F6-woFG!F6 -> -0.072863326 | G6: =wFG!G6-woFG!G6 -> -0.010021748 | H6: =wFG!H6-woFG!H6 -> 0.010398312 | I6: =wFG!I6-woFG!I6 -> -1.2932768e-16 | ... AF6: =wFG!AF6-woFG!AF6 -> -0.059417603 | AK6: =+A6 -> 39538 | AL6: =+B6 -> -0.0040391822 | AM6: =+C6 -> -3.0965542e-08 | AN6: =+D6 -> 0.0012548505 | AO6: =+E6 -> -4.1743389e-05 | AP6: =+F6 -> -0.072863326 | AQ6: =+G6 -> -0.010021748 | AR6: =+H6 -> 0.010398312 | AS6: =+Q6 -> 0.021827772 | AT6: =+AF6-SUM(AL6:AS6) -> -0.0059325078
A7: 39629 | B7: =wFG!B7-woFG!B7 -> -0.0040410778 | C7: =wFG!C7-woFG!C7 -> -4.8436926e-08 | D7: =wFG!D7-woFG!D7 -> 0.001893881 | E7: =wFG!E7-woFG!E7 -> -4.9545743e-05 | F7: =wFG!F7-woFG!F7 -> -0.073478816 | G7: =wFG!G7-woFG!G7 -> -0.0099234896 | H7: =wFG!H7-woFG!H7 -> 0.010795259 | I7: =wFG!I7-woFG!I7 -> -1.3054616e-16 | ... AF7: =wFG!AF7-woFG!AF7 -> -0.056570899 | AK7: =+A7 -> 39629 | AL7: =+B7 -> -0.0040410778 | AM7: =+C7 -> -4.8436926e-08 | AN7: =+D7 -> 0.001893881 | AO7: =+E7 -> -4.9545743e-05 | AP7: =+F7 -> -0.073478816 | AQ7: =+G7 -> -0.0099234896 | AR7: =+H7 -> 0.010795259 | AS7: =+Q7 -> 0.023879296 | AT7: =+AF7-SUM(AL7:AS7) -> -0.0056463565
A8: 39721 | B8: =wFG!B8-woFG!B8 -> -0.004042635 | C8: =wFG!C8-woFG!C8 -> -7.6672542e-08 | D8: =wFG!D8-woFG!D8 -> 0.0028181785 | E8: =wFG!E8-woFG!E8 -> -5.6622373e-05 | F8: =wFG!F8-woFG!F8 -> -0.074010944 | G8: =wFG!G8-woFG!G8 -> -0.0098010655 | H8: =wFG!H8-woFG!H8 -> 0.011239 | I8: =wFG!I8-woFG!I8 -> -1.3231451e-16 | ... AF8: =wFG!AF8-woFG!AF8 -> -0.052986244 | AK8: =+A8 -> 39721 | AL8: =+B8 -> -0.004042635 | AM8: =+C8 -> -7.6672542e-08 | AN8: =+D8 -> 0.0028181785 | AO8: =+E8 -> -5.6622373e-05 | AP8: =+F8 -> -0.074010944 | AQ8: =+G8 -> -0.0098010655 | AR8: =+H8 -> 0.011239 | AS8: =+Q8 -> 0.026207544 | AT8: =+AF8-SUM(AL8:AS8) -> -0.0053396227
A9: 39813 | B9: =wFG!B9-woFG!B9 -> -0.0040461194 | C9: =wFG!C9-woFG!C9 -> -8.5162635e-08 | D9: =wFG!D9-woFG!D9 -> 0.0036739114 | E9: =wFG!E9-woFG!E9 -> -3.5714307e-05 | F9: =wFG!F9-woFG!F9 -> -0.074718525 | G9: =wFG!G9-woFG!G9 -> -0.0094543542 | H9: =wFG!H9-woFG!H9 -> 0.011738409 | I9: =wFG!I9-woFG!I9 -> -1.358333e-16 | ... AF9: =wFG!AF9-woFG!AF9 -> -0.049200961 | AK9: =+A9 -> 39813 | AL9: =+B9 -> -0.0040461194 | AM9: =+C9 -> -8.5162635e-08 | AN9: =+D9 -> 0.0036739114 | AO9: =+E9 -> -3.5714307e-05 | AP9: =+F9 -> -0.074718525 | AQ9: =+G9 -> -0.0094543542 | AR9: =+H9 -> 0.011738409 | AS9: =+Q9 -> 0.028710685 | AT9: =+AF9-SUM(AL9:AS9) -> -0.0050691688
A10: 39903 | B10: =wFG!B10-woFG!B10 -> -0.0040301047 | C10: =wFG!C10-woFG!C10 -> -6.060245e-08 | D10: =wFG!D10-woFG!D10 -> 0.0028889888 | E10: =wFG!E10-woFG!E10 -> -3.3891705e-05 | F10: =wFG!F10-woFG!F10 -> -0.078000085 | G10: =wFG!G10-woFG!G10 -> -0.0098535346 | H10: =wFG!H10-woFG!H10 -> 0.012224861 | I10: =wFG!I10-woFG!I10 -> -1.3543634e-16 | ... AF10: =wFG!AF10-woFG!AF10 -> -0.052400948 | AK10: =+A10 -> 39903 | AL10: =+B10 -> -0.0040301047 | AM10: =+C10 -> -6.060245e-08 | AN10: =+D10 -> 0.0028889888 | AO10: =+E10 -> -3.3891705e-05 | AP10: =+F10 -> -0.078000085 | AQ10: =+G10 -> -0.0098535346 | AR10: =+H10 -> 0.012224861 | AS10: =+Q10 -> 0.029216069 | AT10: =+AF10-SUM(AL10:AS10) -> -0.0048131909
A11: 39994 | B11: =wFG!B11-woFG!B11 -> -0.0040190833 | C11: =wFG!C11-woFG!C11 -> -4.6865574e-08 | D11: =wFG!D11-woFG!D11 -> 0.0023742 | E11: =wFG!E11-woFG!E11 -> -3.214449e-05 | F11: =wFG!F11-woFG!F11 -> -0.081375452 | G11: =wFG!G11-woFG!G11 -> -0.010237584 | H11: =wFG!H11-woFG!H11 -> 0.012733707 | I11: =wFG!I11-woFG!I11 -> -1.3540199e-16 | ... AF11: =wFG!AF11-woFG!AF11 -> -0.055177946 | AK11: =+A11 -> 39994 | AL11: =+B11 -> -0.0040190833 | AM11: =+C11 -> -4.6865574e-08 | AN11: =+D11 -> 0.0023742 | AO11: =+E11 -> -3.214449e-05 | AP11: =+F11 -> -0.081375452 | AQ11: =+G11 -> -0.010237584 | AR11: =+H11 -> 0.012733707 | AS11: =+Q11 -> 0.029915032 | AT11: =+AF11-SUM(AL11:AS11) -> -0.0045365746
A12: 40086 | B12: =wFG!B12-woFG!B12 -> -0.0040108679 | C12: =wFG!C12-woFG!C12 -> -3.937379e-08 | D12: =wFG!D12-woFG!D12 -> 0.0020473107 | E12: =wFG!E12-woFG!E12 -> -3.0611931e-05 | F12: =wFG!F12-woFG!F12 -> -0.084857317 | G12: =wFG!G12-woFG!G12 -> -0.010611279 | H12: =wFG!H12-woFG!H12 -> 0.013262774 | I12: =wFG!I12-woFG!I12 -> -1.3566985e-16 | ... AF12: =wFG!AF12-woFG!AF12 -> -0.057695853 | AK12: =+A12 -> 40086 | AL12: =+B12 -> -0.0040108679 | AM12: =+C12 -> -3.937379e-08 | AN12: =+D12 -> 0.0020473107 | AO12: =+E12 -> -3.0611931e-05 | AP12: =+F12 -> -0.084857317 | AQ12: =+G12 -> -0.010611279 | AR12: =+H12 -> 0.013262774 | AS12: =+Q12 -> 0.030747313 | AT12: =+AF12-SUM(AL12:AS12) -> -0.0042431352
A13: 40178 | B13: =wFG!B13-woFG!B13 -> -0.0040042994 | C13: =wFG!C13-woFG!C13 -> -3.5554502e-08 | D13: =wFG!D13-woFG!D13 -> 0.0018542439 | E13: =wFG!E13-woFG!E13 -> -2.9284453e-05 | F13: =wFG!F13-woFG!F13 -> -0.088457388 | G13: =wFG!G13-woFG!G13 -> -0.010977679 | H13: =wFG!H13-woFG!H13 -> 0.013810977 | I13: =wFG!I13-woFG!I13 -> -1.3615529e-16 | ... AF13: =wFG!AF13-woFG!AF13 -> -0.060061075 | AK13: =+A13 -> 40178 | AL13: =+B13 -> -0.0040042994 | AM13: =+C13 -> -3.5554502e-08 | AN13: =+D13 -> 0.0018542439 | AO13: =+E13 -> -2.9284453e-05 | AP13: =+F13 -> -0.088457388 | AQ13: =+G13 -> -0.010977679 | AR13: =+H13 -> 0.013810977 | AS13: =+Q13 -> 0.031677673 | AT13: =+AF13-SUM(AL13:AS13) -> -0.0039352821
... A132: 51043 | B132: =wFG!B132-woFG!B132 -> -0.0084951169 | C132: =wFG!C132-woFG!C132 -> -9.5428319e-16 | D132: =wFG!D132-woFG!D132 -> -0.014676732 | E132: =wFG!E132-woFG!E132 -> -1.6434539e-13 | F132: =wFG!F132-woFG!F132 -> -0.14920292 | G132: =wFG!G132-woFG!G132 -> 0.018149787 | H132: =wFG!H132-woFG!H132 -> -0.0017202076 | I132: =wFG!I132-woFG!I132 -> 4.1772073e-17 | ... AF132: =wFG!AF132-woFG!AF132 -> -0.09478486 | AK132: =+A132 -> 51043 | AL132: =+B132 -> -0.0084951169 | AM132: =+C132 -> -9.5428319e-16 | AN132: =+D132 -> -0.014676732 | AO132: =+E132 -> -1.6434539e-13 | AP132: =+F132 -> -0.14920292 | AQ132: =+G132 -> 0.018149787 | AR132: =+H132 -> -0.0017202076 | AS132: =+Q132 -> 0.07004557 | AT132: =+AF132-SUM(AL132:AS132) -> -0.0088852424

Sheet wFG
A1: date | B1: g_sh | C1: b_liqtil_sh | D1: b_liqp_sh | E1: b_safetil_sh | F1: b_safep_sh | G1: mu_sh | H1: z_sh | I1: lambda_f_sh | J1: lambda_w_sh | K1: rm_sh | L1: sigma_omega_sh | M1: mu_e_sh | N1: gamma_sh | O1: pi_star_sh | P1: lr_sh | Q1: zp_sh | R1: tfp_sh | S1: gdpdef_sh | T1: corepce_sh | U1: gdp_sh | V1: gdi_sh | W1: BBB_sh | X1: AAA_sh | Y1: rm_shl1 | Z1: rm_shl2 | AA1: rm_shl3 | AB1: rm_shl4 | AC1: rm_shl5 | AD1: rm_shl6 | AE1: dettrend | AF1: detrendedMean
A2: 39172 | B2: -0.1136608 | C2: 1.3149136e-06 | D2: -0.14805647 | E2: 0.0010320217 | F2: 0.49989434 | G2: -0.046535517 | H2: 0.1348957 | I2: 3.2757224e-17 | J2: 4.6015928e-16 | K2: 1.49127e-14 | L2: -0.021460482 | M2: 0 | N2: 0 | O2: 1.6714588e-13 | P2: 0 | Q2: 0.016175142 | R2: 0 | S2: 0 | T2: 0 | U2: 0 | V2: 0 | W2: 0 | X2: 0 | Y2: 0 | Z2: 0 | AA2: 0 | AB2: 0 | AC2: 0 | AD2: 0 | AE2: 0.032509986 | AF2: 0.35479523
A3: 39263 | B3: -0.10393453 | C3: 9.9853958e-07 | D3: -0.168084 | E3: 0.0011083014 | F3: 0.55099943 | G3: -0.0394921 | H3: 0.1181582 | I3: 1.9791939e-16 | J3: 1.6929746e-15 | K3: 1.3782584e-14 | L3: -0.015191242 | M3: 0 | N3: 0 | O3: 1.6794526e-13 | P3: 0 | Q3: -0.12032189 | R3: 0 | S3: 0 | T3: 0 | U3: 0 | V3: 0 | W3: 0 | X3: 0 | Y3: 0 | Z3: 0 | AA3: 0 | AB3: 0 | AC3: 0 | AD3: 0 | AE3: 0.032110116 | AF3: 0.25535329
A4: 39355 | B4: -0.10834914 | C4: 7.4870962e-07 | D4: -0.33960205 | E4: 0.001344726 | F4: 0.55825445 | G4: -0.056755706 | H4: 0.13713848 | I4: -1.0056274e-16 | J4: 2.7546436e-15 | K4: 1.4317306e-14 | L4: -0.048840946 | M4: 0 | N4: 0 | O4: 1.687315e-13 | P4: 0 | Q4: -0.1544971 | R4: 0 | S4: 0 | T4: 0 | U4: 0 | V4: 0 | W4: 0 | X4: 0 | Y4: 0 | Z4: 0 | AA4: 0 | AB4: 0 | AC4: 0 | AD4: 0 | AE4: 0.031715429 | AF4: 0.020408898
A5: 39447 | B5: -0.10542078 | C5: 9.2705622e-07 | D5: -0.47688337 | E5: 0.0013066357 | F5: 0.53311641 | G5: -0.069494744 | H5: 0.14007743 | I5: -6.1410961e-16 | J5: 3.3744854e-15 | K5: 1.5913286e-14 | L5: -0.082827574 | M5: 0 | N5: 0 | O5: 1.6848229e-13 | P5: 0 | Q5: -0.12684545 | R5: 0 | S5: 0 | T5: 0 | U5: 0 | V5: 0 | W5: 0 | X5: 0 | Y5: 0 | Z5: 0 | AA5: 0 | AB5: 0 | AC5: 0 | AD5: 0 | AE5: 0.031325857 | AF5: -0.15564466
A6: 39538 | B6: -0.10708851 | C6: -6.951079e-07 | D6: -0.6373972 | E6: -6.9906396e-05 | F6: 0.47917861 | G6: -0.063279754 | H6: 0.15166681 | I6: -3.3654739e-16 | J6: 4.0417279e-15 | K6: 1.7171333e-14 | L6: -0.096206959 | M6: 0 | N6: 0 | O6: 1.6836824e-13 | P6: 0 | Q6: -0.24518845 | R6: 0 | S6: 0 | T6: 0 | U6: 0 | V6: 0 | W6: 0 | X6: 0 | Y6: 0 | Z6: 0 | AA6: 0 | AB6: 0 | AC6: 0 | AD6: 0 | AE6: 0.030941331 | AF6: -0.48744472
A7: 39629 | B7: -0.11005887 | C7: -8.3140169e-07 | D7: -0.60089367 | E7: -0.00055720817 | F7: 0.51071482 | G7: -0.064217593 | H7: 0.14725971 | I7: -2.230672e-16 | J7: 5.1511512e-15 | K7: 1.8457271e-14 | L7: -0.097981847 | M7: 0 | N7: 0 | O7: 1.6841175e-13 | P7: 0 | Q7: -0.28425779 | R7: 0 | S7: 0 | T7: 0 | U7: 0 | V7: 0 | W7: 0 | X7: 0 | Y7: 0 | Z7: 0 | AA7: 0 | AB7: 0 | AC7: 0 | AD7: 0 | AE7: 0.030561784 | AF7: -0.4694315
A8: 39721 | B8: -0.095576151 | C8: -2.7227548e-06 | D8: -0.70883476 | E8: -0.0017157731 | F8: 0.48140153 | G8: -0.056146435 | H8: 0.14669397 | I8: -7.9082999e-16 | J8: 5.9907226e-15 | K8: 1.6409196e-14 | L8: -0.097148869 | M8: 0 | N8: 0 | O8: 1.6674685e-13 | P8: 0 | Q8: -0.33074136 | R8: 0 | S8: 0 | T8: 0 | U8: 0 | V8: 0 | W8: 0 | X8: 0 | Y8: 0 | Z8: 0 | AA8: 0 | AB8: 0 | AC8: 0 | AD8: 0 | AE8: 0.030187149 | AF8: -0.63188341
A9: 39813 | B9: -0.062796059 | C9: -6.4937485e-06 | D9: -1.3052323 | E9: -0.0033446426 | F9: 0.18028868 | G9: 0.0051103001 | H9: 0.20604349 | I9: 1.3384412e-15 | J9: 6.5599875e-15 | K9: 1.4327031e-14 | L9: -0.1771831 | M9: 0 | N9: 0 | O9: 1.6878166e-13 | P9: 0 | Q9: -0.53437859 | R9: 0 | S9: 0 | T9: 0 | U9: 0 | V9: 0 | W9: 0 | X9: 0 | Y9: -1.7409995e-15 | Z9: -1.3696936e-15 | AA9: -3.4921307e-16 | AB9: -1.1441474e-16 | AC9: -7.7682647e-17 | AD9: -1.590058e-16 | AE9: 0.029817361 | AF9: -1.6616814
A10: 39903 | B10: -0.048434584 | C10: -5.081427e-06 | D10: -1.0841321 | E10: -0.0033354405 | F10: 0.22792314 | G10: -0.079065711 | H10: 0.19404587 | I10: 1.5745905e-15 | J10: 8.8883075e-15 | K10: 1.1135896e-14 | L10: -0.22548549 | M10: 0 | N10: 0 | O10: 1.7110755e-13 | P10: 0 | Q10: -0.54306394 | R10: 0 | S10: 0 | T10: 0 | U10: 0 | V10: 0 | W10: 0 | X10: 0 | Y10: -2.5513635e-15 | Z10: -2.3014758e-15 | AA10: -1.1821438e-15 | AB10: -2.3301426e-16 | AC10: -5.5350642e-16 | AD10: -1.2160989e-15 | AE10: 0.029452356 | AF10: -1.5321009
A11: 39994 | B11: -0.036765571 | C11: -3.4644481e-06 | D11: -0.87506873 | E11: -0.0030217148 | F11: 0.23573741 | G11: -0.10521662 | H11: 0.15345819 | I11: 1.3534648e-15 | J11: 8.7624816e-15 | K11: 9.7304029e-15 | L11: -0.15466516 | M11: 0 | N11: 0 | O11: 1.6667863e-13 | P11: 0 | Q11: -0.44595367 | R11: 0 | S11: 0 | T11: 0 | U11: 0 | V11: 0 | W11: 0 | X11: 0 | Y11: -2.5237791e-15 | Z11: -2.3104953e-15 | AA11: -1.9096677e-15 | AB11: -1.0755362e-15 | AC11: -4.8725675e-16 | AD11: -2.8413426e-15 | AE11: 0.029092069 | AF11: -1.2024073
A12: 40086 | B12: -0.052618199 | C12: 7.7119382e-07 | D12: -0.66704285 | E12: -0.0024179339 | F12: 0.1873241 | G12: -0.19104248 | H12: 0.12598003 | I12: 1.2416099e-15 | J12: 9.2135726e-15 | K12: 9.8036629e-15 | L12: -0.058618211 | M12: 0 | N12: 0 | O12: 1.5761032e-13 | P12: 0 | Q12: -0.49762978 | R12: 0 | S12: 0 | T12: 0 | U12: 0 | V12: 0 | W12: 0 | X12: 0 | Y12: -1.504655e-15 | Z12: -1.4334078e-15 | AA12: -1.1360414e-15 | AB12: -7.7620564e-16 | AC12: -2.4403192e-16 | AD12: -4.1857439e-15 | AE12: 0.028736438 | AF12: -1.1273281
A13: 40178 | B13: -0.039747872 | C13: -6.4464365e-07 | D13: -0.58072914 | E13: -0.0025576397 | F13: 0.14490357 | G13: -0.18308683 | H13: 0.068534479 | I13: -2.9983289e-17 | J13: 9.8462438e-15 | K13: 7.0367936e-15 | L13: 0.003574826 | M13: 0 | N13: 0 | O13: 1.5039332e-13 | P13: 0 | Q13: -0.40725865 | R13: 0 | S13: 0 | T13: 0 | U13: 0 | V13: 0 | W13: 0 | X13: 0 | Y13: -1.7120435e-15 | Z13: -1.4335119e-15 | AA13: -1.7119932e-15 | AB13: -8.3423365e-16 | AC13: -4.0814107e-16 | AD13: -5.7364053e-15 | AE13: 0.0283854 | AF13: -0.96798249
... A132: 51043 | B132: -0.10167284 | C132: -8.6598704e-16 | D132: -0.084380696 | E132: 2.650087e-13 | F132: -0.0212235 | G132: 0.032280766 | H132: -0.015995439 | I132: -3.8486274e-15 | J132: 3.4708904e-14 | K132: -1.7178281e-15 | L132: -0.031331457 | M132: 0 | N132: 0 | O132: 8.7621229e-14 | P132: 0 | Q132: -0.056793815 | R132: 0 | S132: 0 | T132: 0 | U132: 0 | V132: 0 | W132: 0 | X132: 0 | Y132: 1.2035264e-15 | Z132: -5.4451894e-16 | AA132: 1.2800666e-15 | AB132: 7.2902014e-16 | AC132: 2.2148417e-15 | AD132: 2.7041751e-15 | AE132: 0.0069705452 | AF132: -0.27214644

Sheet woFG
A1: date | B1: g_sh | C1: b_liqtil_sh | D1: b_liqp_sh | E1: b_safetil_sh | F1: b_safep_sh | G1: mu_sh | H1: z_sh | I1: lambda_f_sh | J1: lambda_w_sh | K1: rm_sh | L1: sigma_omega_sh | M1: mu_e_sh | N1: gamma_sh | O1: pi_star_sh | P1: lr_sh | Q1: zp_sh | R1: tfp_sh | S1: gdpdef_sh | T1: corepce_sh | U1: gdp_sh | V1: gdi_sh | W1: BBB_sh | X1: AAA_sh | Y1: rm_shl1 | Z1: rm_shl2 | AA1: rm_shl3 | AB1: rm_shl4 | AC1: rm_shl5 | AD1: rm_shl6 | AE1: dettrend | AF1: detrendedMean
A2: 39172 | B2: -0.10964257 | C2: 1.3183524e-06 | D2: -0.14821416 | E2: 0.001046213 | F2: 0.56965658 | G2: -0.036284692 | H2: 0.12574204 | I2: 1.5967708e-16 | J2: 8.1607197e-16 | K2: 1.5293854e-14 | L2: -0.021349635 | M2: 0 | N2: 0 | O2: 1.6220935e-13 | P2: 0 | Q2: 0.00054067528 | R2: 0 | S2: 0 | T2: 0 | U2: 0 | V2: 0 | W2: 0 | X2: 0 | Y2: 0 | Z2: 0 | AA2: 0 | AB2: 0 | AC2: 0 | AD2: 0 | AE2: 0.039310617 | AF2: 0.42080639
A3: 39263 | B3: -0.099909021 | C3: 1.0057203e-06 | D3: -0.1683839 | E3: 0.0011284479 | F3: 0.62161331 | G3: -0.029279328 | H3: 0.10873622 | I3: 3.2526511e-16 | J3: 2.0376259e-15 | K3: 1.4189885e-14 | L3: -0.01523229 | M3: 0 | N3: 0 | O3: 1.62842e-13 | P3: 0 | Q3: -0.13725933 | R3: 0 | S3: 0 | T3: 0 | U3: 0 | V3: 0 | W3: 0 | X3: 0 | Y3: 0 | Z3: 0 | AA3: 0 | AB3: 0 | AC3: 0 | AD3: 0 | AE3: 0.038839027 | AF3: 0.32025415
A4: 39355 | B4: -0.10431763 | C4: 7.6105572e-07 | D4: -0.3401108 | E4: 0.0013714981 | F4: 0.62967544 | G4: -0.046592365 | H4: 0.127422 | I4: 2.7283797e-17 | J4: 3.0870596e-15 | K4: 1.4752681e-14 | L4: -0.04904763 | M4: 0 | N4: 0 | O4: 1.6344937e-13 | P4: 0 | Q4: -0.17288533 | R4: 0 | S4: 0 | T4: 0 | U4: 0 | V4: 0 | W4: 0 | X4: 0 | Y4: 0 | Z4: 0 | AA4: 0 | AB4: 0 | AC4: 0 | AD4: 0 | AE4: 0.038373418 | AF4: 0.083889363
A5: 39447 | B5: -0.10138471 | C5: 9.4684195e-07 | D5: -0.47769657 | E5: 0.00134066 | F5: 0.6052905 | G5: -0.059394209 | H5: 0.13003689 | I5: -4.8563316e-16 | J5: 3.693597e-15 | K5: 1.6378821e-14 | L5: -0.083215288 | M5: 0 | N5: 0 | O5: 1.6300799e-13 | P5: 0 | Q5: -0.14685455 | R5: 0 | S5: 0 | T5: 0 | U5: 0 | V5: 0 | W5: 0 | X5: 0 | Y5: 0 | Z5: 0 | AA5: 0 | AB5: 0 | AC5: 0 | AD5: 0 | AE5: 0.037913711 | AF5: -0.093962617
A6: 39538 | B6: -0.10304933 | C6: -6.6414235e-07 | D6: -0.63865205 | E6: -2.8163007e-05 | F6: 0.55204194 | G6: -0.053258006 | H6: 0.1412685 | I6: -2.0721971e-16 | J6: 4.3463616e-15 | K6: 1.7669266e-14 | L6: -0.096792949 | M6: 0 | N6: 0 | O6: 1.6268725e-13 | P6: 0 | Q6: -0.26701622 | R6: 0 | S6: 0 | T6: 0 | U6: 0 | V6: 0 | W6: 0 | X6: 0 | Y6: 0 | Z6: 0 | AA6: 0 | AB6: 0 | AC6: 0 | AD6: 0 | AE6: 0.037459829 | AF6: -0.42802712
A7: 39629 | B7: -0.1060178 | C7: -7.8296477e-07 | D7: -0.60278756 | E7: -0.00050766243 | F7: 0.58419364 | G7: -0.054294104 | H7: 0.13646445 | I7: -9.2521046e-17 | J7: 5.4400188e-15 | K7: 1.8989974e-14 | L7: -0.098785401 | M7: 0 | N7: 0 | O7: 1.6250825e-13 | P7: 0 | Q7: -0.30813708 | R7: 0 | S7: 0 | T7: 0 | U7: 0 | V7: 0 | W7: 0 | X7: 0 | Y7: 0 | Z7: 0 | AA7: 0 | AB7: 0 | AC7: 0 | AD7: 0 | AE7: 0.037011695 | AF7: -0.4128606
A8: 39721 | B8: -0.091533516 | C8: -2.6460822e-06 | D8: -0.71165294 | E8: -0.0016591507 | F8: 0.55541248 | G8: -0.046345369 | H8: 0.13545497 | I8: -6.5851549e-16 | J8: 6.2624064e-15 | K8: 1.6979144e-14 | L8: -0.09819133 | M8: 0 | N8: 0 | O8: 1.6060358e-13 | P8: 0 | Q8: -0.3569489 | R8: 0 | S8: 0 | T8: 0 | U8: 0 | V8: 0 | W8: 0 | X8: 0 | Y8: 0 | Z8: 0 | AA8: 0 | AB8: 0 | AC8: 0 | AD8: 0 | AE8: 0.036569233 | AF8: -0.57889717
A9: 39813 | B9: -0.058749939 | C9: -6.4085859e-06 | D9: -1.3089063 | E9: -0.0033089283 | F9: 0.25500721 | G9: 0.014564654 | H9: 0.19430508 | I9: 1.4742745e-15 | J9: 6.8130938e-15 | K9: 1.4937577e-14 | L9: -0.17842893 | M9: 0 | N9: 0 | O9: 1.623632e-13 | P9: 0 | Q9: -0.56308927 | R9: 0 | S9: 0 | T9: 0 | U9: 0 | V9: 0 | W9: 0 | X9: 0 | Y9: -1.70279e-15 | Z9: -1.3330053e-15 | AA9: -3.1643201e-16 | AB9: -7.712993e-17 | AC9: -3.9984866e-17 | AD9: -1.2217523e-16 | AE9: 0.036132369 | AF9: -1.6124804
A10: 39903 | B10: -0.044404479 | C10: -5.0208246e-06 | D10: -1.0870211 | E10: -0.0033015488 | F10: 0.30592323 | G10: -0.069212176 | H10: 0.18182101 | I10: 1.7100269e-15 | J10: 9.1212085e-15 | K10: 1.1762849e-14 | L10: -0.22692097 | M10: 0 | N10: 0 | O10: 1.6445771e-13 | P10: 0 | Q10: -0.57228001 | R10: 0 | S10: 0 | T10: 0 | U10: 0 | V10: 0 | W10: 0 | X10: 0 | Y10: -2.494925e-15 | Z10: -2.2493729e-15 | AA10: -1.1378771e-15 | AB10: -1.8458777e-16 | AC10: -5.056671e-16 | AD10: -1.137727e-15 | AE10: 0.03570103 | AF10: -1.4797
A11: 39994 | B11: -0.032746488 | C11: -3.4175825e-06 | D11: -0.87744293 | E11: -0.0029895703 | F11: 0.31711286 | G11: -0.094979034 | H11: 0.14072448 | I11: 1.4888668e-15 | J11: 8.9739095e-15 | K11: 1.0370549e-14 | L11: -0.15631166 | M11: 0 | N11: 0 | O11: 1.5978674e-13 | P11: 0 | Q11: -0.47586871 | R11: 0 | S11: 0 | T11: 0 | U11: 0 | V11: 0 | W11: 0 | X11: 0 | Y11: -2.4500923e-15 | Z11: -2.2434419e-15 | AA11: -1.8539376e-15 | AB11: -1.0156948e-15 | AC11: -4.2881414e-16 | AD11: -2.7177984e-15 | AE11: 0.035275142 | AF11: -1.1472293
A12: 40086 | B12: -0.048607332 | C12: 8.1056761e-07 | D12: -0.66909016 | E12: -0.0023873219 | F12: 0.27218141 | G12: -0.1804312 | H12: 0.11271726 | I12: 1.3772797e-15 | J12: 9.4022112e-15 | K12: 1.0455075e-14 | L12: -0.060493272 | M12: 0 | N12: 0 | O12: 1.5046583e-13 | P12: 0 | Q12: -0.52837709 | R12: 0 | S12: 0 | T12: 0 | U12: 0 | V12: 0 | W12: 0 | X12: 0 | Y12: -1.4140976e-15 | Z12: -1.3514312e-15 | AA12: -1.0686252e-15 | AB12: -7.0453129e-16 | AC12: -1.7447249e-16 | AD12: -4.0140876e-15 | AE12: 0.034854635 | AF12: -1.0696323
A13: 40178 | B13: -0.035743573 | C13: -6.0908915e-07 | D13: -0.58258338 | E13: -0.0025283552 | F13: 0.23336096 | G13: -0.17210915 | H13: 0.054723502 | I13: 1.06172e-16 | J13: 1.0010734e-14 | K13: 7.6983612e-15 | L13: 0.0014560719 | M13: 0 | N13: 0 | O13: 1.429857e-13 | P13: 0 | Q13: -0.43893632 | R13: 0 | S13: 0 | T13: 0 | U13: 0 | V13: 0 | W13: 0 | X13: 0 | Y13: -1.6045884e-15 | Z13: -1.3363341e-15 | AA13: -1.6324863e-15 | AB13: -7.5018981e-16 | AC13: -3.2689612e-16 | AD13: -5.5141253e-15 | AE13: 0.034439436 | AF13: -0.90792142
... A132: 51043 | B132: -0.093177725 | C132: 8.8296151e-17 | D132: -0.069703964 | E132: 4.2935409e-13 | F132: 0.12797942 | G132: 0.014130979 | H132: -0.014275232 | I132: -3.8903994e-15 | J132: 3.6528468e-14 | K132: 1.2088296e-16 | L132: -0.024231686 | M132: 0 | N132: 0 | O132: 6.7630182e-14 | P132: 0 | Q132: -0.12683938 | R132: 0 | S132: 0 | T132: 0 | U132: 0 | V132: 0 | W132: 0 | X132: 0 | Y132: 5.7250971e-16 | Z132: 5.5463659e-16 | AA132: 7.2400266e-16 | AB132: 7.8623195e-16 | AC132: 4.3930205e-16 | AD132: -2.1831824e-15 | AE132: 0.0087560164 | AF132: -0.17736158

Sheet DSGE HVD difference
A1: date | B1: =+[1]wFG_rstar_shock_decomposition!E1 -> g | C1: =+[1]wFG_rstar_shock_decomposition!F1 -> b_liq | D1: =+[1]wFG_rstar_shock_decomposition!G1 -> b_safe | E1: =+[1]wFG_rstar_shock_decomposition!H1 -> FF | F1: =+[1]wFG_rstar_shock_decomposition!I1 -> z | G1: =+[1]wFG_rstar_shock_decomposition!J1 -> p-mkp | H1: =+[1]wFG_rstar_shock_decomposition!K1 -> w-mkp | I1: =+[1]wFG_rstar_shock_decomposition!L1 -> pol | ... T1: =+[1]wFG_rstar_shock_decomposition!W1 -> dt | U1: DSGE r* | X1: Chart | Y1: Date | Z1: Government | AA1: Liquidity | AB1: Safety | AC1: Technology | AD1: Financial Frictions | AE1: Investment Specific Technology | AF1: Price Markups | AG1: Wage Markups | AH1: Others | AI1: DSGE r* (with FG) | AJ1: Growth | AK1: Safety+Liquidity | AL1: Government | AM1: Others | AN1: Total | AO1: Growth | AP1: Safety+Liquidity | AQ1: Government | AR1: Others | AS1: Total
A2: 39172 | B2: ='DSGE HVD wFG'!B2-'DSGE HVD woFG'!B2 -> -0.0011864273 | C2: ='DSGE HVD wFG'!C2-'DSGE HVD woFG'!C2 -> 0.0069004926 | D2: ='DSGE HVD wFG'!D2-'DSGE HVD woFG'!D2 -> 0.24643353 | E2: ='DSGE HVD wFG'!E2-'DSGE HVD woFG'!E2 -> 0.0037480445 | F2: ='DSGE HVD wFG'!F2-'DSGE HVD woFG'!F2 -> 0.02110511 | G2: ='DSGE HVD wFG'!G2-'DSGE HVD woFG'!G2 -> 4.7328043e-17 | H2: ='DSGE HVD wFG'!H2-'DSGE HVD woFG'!H2 -> -1.0554555e-16 | I2: ='DSGE HVD wFG'!I2-'DSGE HVD woFG'!I2 -> 9.9990244e-16 | ... U2: ='DSGE HVD wFG'!U2-'DSGE HVD woFG'!U2 -> 0.37553775 | Y2: =+A2 -> 39172 | Z2: =+B2 -> -0.0011864273 | AA2: =+C2 -> 0.0069004926 | AB2: =+D2 -> 0.24643353 | AC2: =+F2+S2 -> 0.11573476 | AD2: =+E2 -> 0.0037480445 | AE2: =+Q2 -> 0.0076980972 | AF2: =+G2 -> 4.7328043e-17 | AG2: =+H2 -> -1.0554555e-16 | AH2: =+SUM(T2,I2:P2) -> -0.0037907481 | AI2: =+SUM(Z2:AH2) -> 0.37553775 | AJ2: =SUM(AC2+AE2) -> 0.12343286 | AK2: =AB2+AA2+AD2 -> 0.25708207 | AL2: =Z2 -> -0.0011864273 | AM2: =AH2 -> -0.0037907481 | AN2: =SUM(AJ2:AM2) -> 0.37553775
A3: 39263 | B3: ='DSGE HVD wFG'!B3-'DSGE HVD woFG'!B3 -> -0.00092186698 | C3: ='DSGE HVD wFG'!C3-'DSGE HVD woFG'!C3 -> 0.011714961 | D3: ='DSGE HVD wFG'!D3-'DSGE HVD woFG'!D3 -> 0.26664786 | E3: ='DSGE HVD wFG'!E3-'DSGE HVD woFG'!E3 -> 0.0051548792 | F3: ='DSGE HVD wFG'!F3-'DSGE HVD woFG'!F3 -> 0.023464263 | G3: ='DSGE HVD wFG'!G3-'DSGE HVD woFG'!G3 -> 4.3050326e-17 | H3: ='DSGE HVD wFG'!H3-'DSGE HVD woFG'!H3 -> -5.4333616e-17 | I3: ='DSGE HVD wFG'!I3-'DSGE HVD woFG'!I3 -> 9.0143759e-16 | ... U3: ='DSGE HVD wFG'!U3-'DSGE HVD woFG'!U3 -> 0.42088163 | Y3: =+A3 -> 39263 | Z3: =+B3 -> -0.00092186698 | AA3: =+C3 -> 0.011714961 | AB3: =+D3 -> 0.26664786 | AC3: =+F3+S3 -> 0.13323039 | AD3: =+E3 -> 0.0051548792 | AE3: =+Q3 -> 0.0088060448 | AF3: =+G3 -> 4.3050326e-17 | AG3: =+H3 -> -5.4333616e-17 | AH3: =+SUM(T3,I3:P3) -> -0.0037506317 | AI3: =+SUM(Z3:AH3) -> 0.42088163 | AJ3: =SUM(AC3+AE3) -> 0.14203644 | AK3: =AB3+AA3+AD3 -> 0.2835177 | AL3: =Z3 -> -0.00092186698 | AM3: =AH3 -> -0.0037506317 | AN3: =SUM(AJ3:AM3) -> 0.42088163 | AO3: =(AJ3-AJ2)/($AN3-$AN2) -> 0.41027758 | AP3: =(AK3-AK2)/($AN3-$AN2) -> 0.58300317 | AQ3: =(AL3-AL2)/($AN3-$AN2) -> 0.0058345315 | AR3: =(AM3-AM2)/($AN3-$AN2) -> 0.00088471517 | AS3: =(AN3-AN2)/($AN3-$AN2) -> 1
A4: 39355 | B4: ='DSGE HVD wFG'!B4-'DSGE HVD woFG'!B4 -> -0.00062993997 | C4: ='DSGE HVD wFG'!C4-'DSGE HVD woFG'!C4 -> 0.018729916 | D4: ='DSGE HVD wFG'!D4-'DSGE HVD woFG'!D4 -> 0.28890318 | E4: ='DSGE HVD wFG'!E4-'DSGE HVD woFG'!E4 -> 0.0067903528 | F4: ='DSGE HVD wFG'!F4-'DSGE HVD woFG'!F4 -> 0.026167988 | G4: ='DSGE HVD wFG'!G4-'DSGE HVD woFG'!G4 -> 3.6162972e-17 | H4: ='DSGE HVD wFG'!H4-'DSGE HVD woFG'!H4 -> 6.080685e-18 | I4: ='DSGE HVD wFG'!I4-'DSGE HVD woFG'!I4 -> 7.8684767e-16 | ... U4: ='DSGE HVD wFG'!U4-'DSGE HVD woFG'!U4 -> 0.47351226 | Y4: =+A4 -> 39355 | Z4: =+B4 -> -0.00062993997 | AA4: =+C4 -> 0.018729916 | AB4: =+D4 -> 0.28890318 | AC4: =+F4+S4 -> 0.15336717 | AD4: =+E4 -> 0.0067903528 | AE4: =+Q4 -> 0.010062544 | AF4: =+G4 -> 3.6162972e-17 | AG4: =+H4 -> 6.080685e-18 | AH4: =+SUM(T4,I4:P4) -> -0.0037109619 | AI4: =+SUM(Z4:AH4) -> 0.47351226 | AJ4: =SUM(AC4+AE4) -> 0.16342971 | AK4: =AB4+AA4+AD4 -> 0.31442345 | AL4: =Z4 -> -0.00062993997 | AM4: =AH4 -> -0.0037109619 | AN4: =SUM(AJ4:AM4) -> 0.47351226 | AO4: =(AJ4-AJ3)/($AN4-$AN3) -> 0.40647957 | AP4: =(AK4-AK3)/($AN4-$AN3) -> 0.58721997 | AQ4: =(AL4-AL3)/($AN4-$AN3) -> 0.0055467134 | AR4: =(AM4-AM3)/($AN4-$AN3) -> 0.00075374063 | AS4: =(AN4-AN3)/($AN4-$AN3) -> 1
A5: 39447 | B5: ='DSGE HVD wFG'!B5-'DSGE HVD woFG'!B5 -> -0.00030916176 | C5: ='DSGE HVD wFG'!C5-'DSGE HVD woFG'!C5 -> 0.028882484 | D5: ='DSGE HVD wFG'!D5-'DSGE HVD woFG'!D5 -> 0.31337762 | E5: ='DSGE HVD wFG'!E5-'DSGE HVD woFG'!E5 -> 0.0086883073 | F5: ='DSGE HVD wFG'!F5-'DSGE HVD woFG'!F5 -> 0.029272511 | G5: ='DSGE HVD wFG'!G5-'DSGE HVD woFG'!G5 -> 2.4653946e-17 | H5: ='DSGE HVD wFG'!H5-'DSGE HVD woFG'!H5 -> 7.691003e-17 | I5: ='DSGE HVD wFG'!I5-'DSGE HVD woFG'!I5 -> 6.5498469e-16 | ... U5: ='DSGE HVD wFG'!U5-'DSGE HVD woFG'!U5 -> 0.53512032 | Y5: =+A5 -> 39447 | Z5: =+B5 -> -0.00030916176 | AA5: =+C5 -> 0.028882484 | AB5: =+D5 -> 0.31337762 | AC5: =+F5+S5 -> 0.17664882 | AD5: =+E5 -> 0.0086883073 | AE5: =+Q5 -> 0.011503981 | AF5: =+G5 -> 2.4653946e-17 | AG5: =+H5 -> 7.691003e-17 | AH5: =+SUM(T5,I5:P5) -> -0.0036717333 | AI5: =+SUM(Z5:AH5) -> 0.53512032 | AJ5: =SUM(AC5+AE5) -> 0.1881528 | AK5: =AB5+AA5+AD5 -> 0.35094841 | AL5: =Z5 -> -0.00030916176 | AM5: =AH5 -> -0.0036717333 | AN5: =SUM(AJ5:AM5) -> 0.53512032 | AO5: =(AJ5-AJ4)/($AN5-$AN4) -> 0.40129641 | AP5: =(AK5-AK4)/($AN5-$AN4) -> 0.59286009 | AQ5: =(AL5-AL4)/($AN5-$AN4) -> 0.005206757 | AR5: =(AM5-AM4)/($AN5-$AN4) -> 0.00063674438 | AS5: =(AN5-AN4)/($AN5-$AN4) -> 1
A6: 39538 | B6: ='DSGE HVD wFG'!B6-'DSGE HVD woFG'!B6 -> 3.8674394e-05 | C6: ='DSGE HVD wFG'!C6-'DSGE HVD woFG'!C6 -> 0.043514232 | D6: ='DSGE HVD wFG'!D6-'DSGE HVD woFG'!D6 -> 0.34023861 | E6: ='DSGE HVD wFG'!E6-'DSGE HVD woFG'!E6 -> 0.010886958 | F6: ='DSGE HVD wFG'!F6-'DSGE HVD woFG'!F6 -> 0.032852592 | G6: ='DSGE HVD wFG'!G6-'DSGE HVD woFG'!G6 -> 5.0161777e-18 | H6: ='DSGE HVD wFG'!H6-'DSGE HVD woFG'!H6 -> 1.5945558e-16 | I6: ='DSGE HVD wFG'!I6-'DSGE HVD woFG'!I6 -> 5.0535185e-16 | ... U6: ='DSGE HVD wFG'!U6-'DSGE HVD woFG'!U6 -> 0.60797114 | Y6: =+A6 -> 39538 | Z6: =+B6 -> 3.8674394e-05 | AA6: =+C6 -> 0.043514232 | AB6: =+D6 -> 0.34023861 | AC6: =+F6+S6 -> 0.20374295 | AD6: =+E6 -> 0.010886958 | AE6: =+Q6 -> 0.013182656 | AF6: =+G6 -> 5.0161777e-18 | AG6: =+H6 -> 1.5945558e-16 | AH6: =+SUM(T6,I6:P6) -> -0.0036329407 | AI6: =+SUM(Z6:AH6) -> 0.60797114 | AJ6: =SUM(AC6+AE6) -> 0.2169256 | AK6: =AB6+AA6+AD6 -> 0.3946398 | AL6: =Z6 -> 3.8674394e-05 | AM6: =AH6 -> -0.0036329407 | AN6: =SUM(AJ6:AM6) -> 0.60797114 | AO6: =(AJ6-AJ5)/($AN6-$AN5) -> 0.39495507 | AP6: =(AK6-AK5)/($AN6-$AN5) -> 0.5997378 | AQ6: =(AL6-AL5)/($AN6-$AN5) -> 0.0047746365 | AR6: =(AM6-AM5)/($AN6-$AN5) -> 0.00053249353 | AS6: =(AN6-AN5)/($AN6-$AN5) -> 1
A7: 39629 | B7: ='DSGE HVD wFG'!B7-'DSGE HVD woFG'!B7 -> 0.0004016145 | C7: ='DSGE HVD wFG'!C7-'DSGE HVD woFG'!C7 -> 0.064557925 | D7: ='DSGE HVD wFG'!D7-'DSGE HVD woFG'!D7 -> 0.36962872 | E7: ='DSGE HVD wFG'!E7-'DSGE HVD woFG'!E7 -> 0.013428644 | F7: ='DSGE HVD wFG'!F7-'DSGE HVD woFG'!F7 -> 0.037018989 | G7: ='DSGE HVD wFG'!G7-'DSGE HVD woFG'!G7 -> -2.852015e-17 | H7: ='DSGE HVD wFG'!H7-'DSGE HVD woFG'!H7 -> 2.5508236e-16 | I7: ='DSGE HVD wFG'!I7-'DSGE HVD woFG'!I7 -> 3.3877526e-16 | ... U7: ='DSGE HVD wFG'!U7-'DSGE HVD woFG'!U7 -> 0.69515869 | Y7: =+A7 -> 39629 | Z7: =+B7 -> 0.0004016145 | AA7: =+C7 -> 0.064557925 | AB7: =+D7 -> 0.36962872 | AC7: =+F7+S7 -> 0.23556095 | AD7: =+E7 -> 0.013428644 | AE7: =+Q7 -> 0.015175411 | AF7: =+G7 -> -2.852015e-17 | AG7: =+H7 -> 2.5508236e-16 | AH7: =+SUM(T7,I7:P7) -> -0.0035945789 | AI7: =+SUM(Z7:AH7) -> 0.69515869 | AJ7: =SUM(AC7+AE7) -> 0.25073637 | AK7: =AB7+AA7+AD7 -> 0.44761529 | AL7: =Z7 -> 0.0004016145 | AM7: =AH7 -> -0.0035945789 | AN7: =SUM(AJ7:AM7) -> 0.69515869 | AO7: =(AJ7-AJ6)/($AN7-$AN6) -> 0.38779347 | AP7: =(AK7-AK6)/($AN7-$AN6) -> 0.60760378 | AQ7: =(AL7-AL6)/($AN7-$AN6) -> 0.0041627514 | AR7: =(AM7-AM6)/($AN7-$AN6) -> 0.00043999136 | AS7: =(AN7-AN6)/($AN7-$AN6) -> 1
A8: 39721 | B8: ='DSGE HVD wFG'!B8-'DSGE HVD woFG'!B8 -> 0.00074506451 | C8: ='DSGE HVD wFG'!C8-'DSGE HVD woFG'!C8 -> 0.094824502 | D8: ='DSGE HVD wFG'!D8-'DSGE HVD woFG'!D8 -> 0.40165262 | E8: ='DSGE HVD wFG'!E8-'DSGE HVD woFG'!E8 -> 0.01635523 | F8: ='DSGE HVD wFG'!F8-'DSGE HVD woFG'!F8 -> 0.041948411 | G8: ='DSGE HVD wFG'!G8-'DSGE HVD woFG'!G8 -> -8.401627e-17 | H8: ='DSGE HVD wFG'!H8-'DSGE HVD woFG'!H8 -> 3.6526932e-16 | I8: ='DSGE HVD wFG'!I8-'DSGE HVD woFG'!I8 -> 1.5813371e-16 | ... U8: ='DSGE HVD wFG'!U8-'DSGE HVD woFG'!U8 -> 0.8009563 | Y8: =+A8 -> 39721 | Z8: =+B8 -> 0.00074506451 | AA8: =+C8 -> 0.094824502 | AB8: =+D8 -> 0.40165262 | AC8: =+F8+S8 -> 0.27334145 | AD8: =+E8 -> 0.01635523 | AE8: =+Q8 -> 0.017594074 | AF8: =+G8 -> -8.401627e-17 | AG8: =+H8 -> 3.6526932e-16 | AH8: =+SUM(T8,I8:P8) -> -0.0035566429 | AI8: =+SUM(Z8:AH8) -> 0.8009563 | AJ8: =SUM(AC8+AE8) -> 0.29093553 | AK8: =AB8+AA8+AD8 -> 0.51283235 | AL8: =Z8 -> 0.00074506451 | AM8: =AH8 -> -0.0035566429 | AN8: =SUM(AJ8:AM8) -> 0.8009563 | AO8: =(AJ8-AJ7)/($AN8-$AN7) -> 0.37996285 | AP8: =(AK8-AK7)/($AN8-$AN7) -> 0.61643228 | AQ8: =(AL8-AL7)/($AN8-$AN7) -> 0.0032462926 | AR8: =(AM8-AM7)/($AN8-$AN7) -> 0.00035857209 | AS8: =(AN8-AN7)/($AN8-$AN7) -> 1
A9: 39813 | B9: ='DSGE HVD wFG'!B9-'DSGE HVD woFG'!B9 -> 0.0010145207 | C9: ='DSGE HVD wFG'!C9-'DSGE HVD woFG'!C9 -> 0.12791594 | D9: ='DSGE HVD wFG'!D9-'DSGE HVD woFG'!D9 -> 0.43125937 | E9: ='DSGE HVD wFG'!E9-'DSGE HVD woFG'!E9 -> 0.019763205 | F9: ='DSGE HVD wFG'!F9-'DSGE HVD woFG'!F9 -> 0.047829544 | G9: ='DSGE HVD wFG'!G9-'DSGE HVD woFG'!G9 -> -1.8972141e-16 | H9: ='DSGE HVD wFG'!H9-'DSGE HVD woFG'!H9 -> 4.8883823e-16 | I9: ='DSGE HVD wFG'!I9-'DSGE HVD woFG'!I9 -> -5.8268673e-17 | ... U9: ='DSGE HVD wFG'!U9-'DSGE HVD woFG'!U9 -> 0.91711418 | Y9: =+A9 -> 39813 | Z9: =+B9 -> 0.0010145207 | AA9: =+C9 -> 0.12791594 | AB9: =+D9 -> 0.43125937 | AC9: =+F9+S9 -> 0.31519731 | AD9: =+E9 -> 0.019763205 | AE9: =+Q9 -> 0.025482966 | AF9: =+G9 -> -1.8972141e-16 | AG9: =+H9 -> 4.8883823e-16 | AH9: =+SUM(T9,I9:P9) -> -0.0035191274 | AI9: =+SUM(Z9:AH9) -> 0.91711418 | AJ9: =SUM(AC9+AE9) -> 0.34068027 | AK9: =AB9+AA9+AD9 -> 0.57893852 | AL9: =Z9 -> 0.0010145207 | AM9: =AH9 -> -0.0035191274 | AN9: =SUM(AJ9:AM9) -> 0.91711418 | AO9: =(AJ9-AJ8)/($AN9-$AN8) -> 0.42825113 | AP9: =(AK9-AK8)/($AN9-$AN8) -> 0.56910615 | AQ9: =(AL9-AL8)/($AN9-$AN8) -> 0.0023197409 | AR9: =(AM9-AM8)/($AN9-$AN8) -> 0.00032296925 | AS9: =(AN9-AN8)/($AN9-$AN8) -> 1
A10: 39903 | B10: ='DSGE HVD wFG'!B10-'DSGE HVD woFG'!B10 -> 0.0016912713 | C10: ='DSGE HVD wFG'!C10-'DSGE HVD woFG'!C10 -> 0.13477207 | D10: ='DSGE HVD wFG'!D10-'DSGE HVD woFG'!D10 -> 0.41208044 | E10: ='DSGE HVD wFG'!E10-'DSGE HVD woFG'!E10 -> 0.021487743 | F10: ='DSGE HVD wFG'!F10-'DSGE HVD woFG'!F10 -> 0.05326098 | G10: ='DSGE HVD wFG'!G10-'DSGE HVD woFG'!G10 -> -2.0170817e-16 | H10: ='DSGE HVD wFG'!H10-'DSGE HVD woFG'!H10 -> 6.32863e-16 | I10: ='DSGE HVD wFG'!I10-'DSGE HVD woFG'!I10 -> 5.3524895e-16 | ... U10: ='DSGE HVD wFG'!U10-'DSGE HVD woFG'!U10 -> 0.90251511 | Y10: =+A10 -> 39903 | Z10: =+B10 -> 0.0016912713 | AA10: =+C10 -> 0.13477207 | AB10: =+D10 -> 0.41208044 | AC10: =+F10+S10 -> 0.31973957 | AD10: =+E10 -> 0.021487743 | AE10: =+Q10 -> 0.016226034 | AF10: =+G10 -> -2.0170817e-16 | AG10: =+H10 -> 6.32863e-16 | AH10: =+SUM(T10,I10:P10) -> -0.0034820277 | AI10: =+SUM(Z10:AH10) -> 0.90251511 | AJ10: =SUM(AC10+AE10) -> 0.33596561 | AK10: =AB10+AA10+AD10 -> 0.56834025 | AL10: =Z10 -> 0.0016912713 | AM10: =AH10 -> -0.0034820277 | AN10: =SUM(AJ10:AM10) -> 0.90251511 | AO10: =(AJ10-AJ9)/($AN10-$AN9) -> 0.3229427 | AP10: =(AK10-AK9)/($AN10-$AN9) -> 0.72595425 | AQ10: =(AL10-AL9)/($AN10-$AN9) -> -0.046355716 | AR10: =(AM10-AM9)/($AN10-$AN9) -> -0.0025412405 | AS10: =(AN10-AN9)/($AN10-$AN9) -> 1
A11: 39994 | B11: ='DSGE HVD wFG'!B11-'DSGE HVD woFG'!B11 -> 0.0023846668 | C11: ='DSGE HVD wFG'!C11-'DSGE HVD woFG'!C11 -> 0.11730058 | D11: ='DSGE HVD wFG'!D11-'DSGE HVD woFG'!D11 -> 0.34499254 | E11: ='DSGE HVD wFG'!E11-'DSGE HVD woFG'!E11 -> 0.022304744 | F11: ='DSGE HVD wFG'!F11-'DSGE HVD woFG'!F11 -> 0.058037301 | G11: ='DSGE HVD wFG'!G11-'DSGE HVD woFG'!G11 -> -1.6854844e-16 | H11: ='DSGE HVD wFG'!H11-'DSGE HVD woFG'!H11 -> 7.8529001e-16 | I11: ='DSGE HVD wFG'!I11-'DSGE HVD woFG'!I11 -> 1.1252812e-15 | ... U11: ='DSGE HVD wFG'!U11-'DSGE HVD woFG'!U11 -> 0.76565627 | Y11: =+A11 -> 39994 | Z11: =+B11 -> 0.0023846668 | AA11: =+C11 -> 0.11730058 | AB11: =+D11 -> 0.34499254 | AC11: =+F11+S11 -> 0.28642085 | AD11: =+E11 -> 0.022304744 | AE11: =+Q11 -> -0.0043017649 | AF11: =+G11 -> -1.6854844e-16 | AG11: =+H11 -> 7.8529001e-16 | AH11: =+SUM(T11,I11:P11) -> -0.0034453386 | AI11: =+SUM(Z11:AH11) -> 0.76565627 | AJ11: =SUM(AC11+AE11) -> 0.28211908 | AK11: =AB11+AA11+AD11 -> 0.48459786 | AL11: =Z11 -> 0.0023846668 | AM11: =AH11 -> -0.0034453386 | AN11: =SUM(AJ11:AM11) -> 0.76565627 | AO11: =(AJ11-AJ10)/($AN11-$AN10) -> 0.39344573 | AP11: =(AK11-AK10)/($AN11-$AN10) -> 0.61188885 | AQ11: =(AL11-AL10)/($AN11-$AN10) -> -0.0050665015 | AR11: =(AM11-AM10)/($AN11-$AN10) -> -0.00026807935 | AS11: =(AN11-AN10)/($AN11-$AN10) -> 1
A12: 40086 | B12: ='DSGE HVD wFG'!B12-'DSGE HVD woFG'!B12 -> 0.0033919902 | C12: ='DSGE HVD wFG'!C12-'DSGE HVD woFG'!C12 -> 0.020836234 | D12: ='DSGE HVD wFG'!D12-'DSGE HVD woFG'!D12 -> 0.16076017 | E12: ='DSGE HVD wFG'!E12-'DSGE HVD woFG'!E12 -> 0.020600003 | F12: ='DSGE HVD wFG'!F12-'DSGE HVD woFG'!F12 -> 0.059679868 | G12: ='DSGE HVD wFG'!G12-'DSGE HVD woFG'!G12 -> -6.847031e-19 | H12: ='DSGE HVD wFG'!H12-'DSGE HVD woFG'!H12 -> 9.333398e-16 | I12: ='DSGE HVD wFG'!I12-'DSGE HVD woFG'!I12 -> 1.5271984e-15 | ... U12: ='DSGE HVD wFG'!U12-'DSGE HVD woFG'!U12 -> 0.29975386 | Y12: =+A12 -> 40086 | Z12: =+B12 -> 0.0033919902 | AA12: =+C12 -> 0.020836234 | AB12: =+D12 -> 0.16076017 | AC12: =+F12+S12 -> 0.14997876 | AD12: =+E12 -> 0.020600003 | AE12: =+Q12 -> -0.052404241 | AF12: =+G12 -> -6.847031e-19 | AG12: =+H12 -> 9.333398e-16 | AH12: =+SUM(T12,I12:P12) -> -0.0034090555 | AI12: =+SUM(Z12:AH12) -> 0.29975386 | AJ12: =SUM(AC12+AE12) -> 0.097574515 | AK12: =AB12+AA12+AD12 -> 0.20219641 | AL12: =Z12 -> 0.0033919902 | AM12: =AH12 -> -0.0034090555 | AN12: =SUM(AJ12:AM12) -> 0.29975386 | AO12: =(AJ12-AJ11)/($AN12-$AN11) -> 0.39610134 | AP12: =(AK12-AK11)/($AN12-$AN11) -> 0.60613863 | AQ12: =(AL12-AL11)/($AN12-$AN11) -> -0.0021620909 | AR12: =(AM12-AM11)/($AN12-$AN11) -> -7.7877144e-05 | AS12: =(AN12-AN11)/($AN12-$AN11) -> 1
A13: 40178 | B13: ='DSGE HVD wFG'!B13-'DSGE HVD woFG'!B13 -> 0.0030605586 | C13: ='DSGE HVD wFG'!C13-'DSGE HVD woFG'!C13 -> 0.020674156 | D13: ='DSGE HVD wFG'!D13-'DSGE HVD woFG'!D13 -> 0.093349238 | E13: ='DSGE HVD wFG'!E13-'DSGE HVD woFG'!E13 -> 0.02205116 | F13: ='DSGE HVD wFG'!F13-'DSGE HVD woFG'!F13 -> 0.062434689 | G13: ='DSGE HVD wFG'!G13-'DSGE HVD woFG'!G13 -> -6.7266173e-17 | H13: ='DSGE HVD wFG'!H13-'DSGE HVD woFG'!H13 -> 1.0545544e-15 | I13: ='DSGE HVD wFG'!I13-'DSGE HVD woFG'!I13 -> 5.8801008e-16 | ... U13: ='DSGE HVD wFG'!U13-'DSGE HVD woFG'!U13 -> 0.19653733 | Y13: =+A13 -> 40178 | Z13: =+B13 -> 0.0030605586 | AA13: =+C13 -> 0.020674156 | AB13: =+D13 -> 0.093349238 | AC13: =+F13+S13 -> 0.12058252 | AD13: =+E13 -> 0.02205116 | AE13: =+Q13 -> -0.059807128 | AF13: =+G13 -> -6.7266173e-17 | AG13: =+H13 -> 1.0545544e-15 | AH13: =+SUM(T13,I13:P13) -> -0.0033731734 | AI13: =+SUM(Z13:AH13) -> 0.19653733 | AJ13: =SUM(AC13+AE13) -> 0.06077539 | AK13: =AB13+AA13+AD13 -> 0.13607455 | AL13: =Z13 -> 0.0030605586 | AM13: =AH13 -> -0.0033731734 | AN13: =SUM(AJ13:AM13) -> 0.19653733 | AO13: =(AJ13-AJ12)/($AN13-$AN12) -> 0.35652356 | AP13: =(AK13-AK12)/($AN13-$AN12) -> 0.64061305 | AQ13: =(AL13-AL12)/($AN13-$AN12) -> 0.003211032 | AR13: =(AM13-AM12)/($AN13-$AN12) -> -0.00034763878 | AS13: =(AN13-AN12)/($AN13-$AN12) -> 1
A14: 40268 | B14: ='DSGE HVD wFG'!B14-'DSGE HVD woFG'!B14 -> 0.0031556837 | C14: ='DSGE HVD wFG'!C14-'DSGE HVD woFG'!C14 -> -0.017786708 | D14: ='DSGE HVD wFG'!D14-'DSGE HVD woFG'!D14 -> -0.028112409 | E14: ='DSGE HVD wFG'!E14-'DSGE HVD woFG'!E14 -> 0.022042997 | F14: ='DSGE HVD wFG'!F14-'DSGE HVD woFG'!F14 -> 0.062874442 | G14: ='DSGE HVD wFG'!G14-'DSGE HVD woFG'!G14 -> -3.6265365e-17 | H14: ='DSGE HVD wFG'!H14-'DSGE HVD woFG'!H14 -> 1.16861e-15 | I14: ='DSGE HVD wFG'!I14-'DSGE HVD woFG'!I14 -> 1.289679e-16 | ... U14: ='DSGE HVD wFG'!U14-'DSGE HVD woFG'!U14 -> -0.063698989 | Y14: =+A14 -> 40268 | Z14: =+B14 -> 0.0031556837 | AA14: =+C14 -> -0.017786708 | AB14: =+D14 -> -0.028112409 | AC14: =+F14+S14 -> 0.042146369 | AD14: =+E14 -> 0.022042997 | AE14: =+Q14 -> -0.081807234 | AF14: =+G14 -> -3.6265365e-17 | AG14: =+H14 -> 1.16861e-15 | AH14: =+SUM(T14,I14:P14) -> -0.0033376877 | AI14: =+SUM(Z14:AH14) -> -0.063698989 | AJ14: =SUM(AC14+AE14) -> -0.039660866 | AK14: =AB14+AA14+AD14 -> -0.023856119 | AL14: =Z14 -> 0.0031556837 | AM14: =AH14 -> -0.0033376877 | AN14: =SUM(AJ14:AM14) -> -0.063698989 | AO14: =(AJ14-AJ13)/($AN14-$AN13) -> 0.3859425 | AP14: =(AK14-AK13)/($AN14-$AN13) -> 0.61455939 | AQ14: =(AL14-AL13)/($AN14-$AN13) -> -0.00036553364 | AR14: =(AM14-AM13)/($AN14-$AN13) -> -0.00013635961 | AS14: =(AN14-AN13)/($AN14-$AN13) -> 1
... A132: 51043 | B132: ='DSGE HVD wFG'!B132-'DSGE HVD woFG'!B132 -> -0.0091257145 | C132: ='DSGE HVD wFG'!C132-'DSGE HVD woFG'!C132 -> -0.014583144 | D132: ='DSGE HVD wFG'!D132-'DSGE HVD woFG'!D132 -> -0.11143848 | E132: ='DSGE HVD wFG'!E132-'DSGE HVD woFG'!E132 -> -0.0056458107 | F132: ='DSGE HVD wFG'!F132-'DSGE HVD woFG'!F132 -> -0.0010839859 | G132: ='DSGE HVD wFG'!G132-'DSGE HVD woFG'!G132 -> 4.6419936e-17 | H132: ='DSGE HVD wFG'!H132-'DSGE HVD woFG'!H132 -> -1.5050107e-15 | I132: ='DSGE HVD wFG'!I132-'DSGE HVD woFG'!I132 -> -2.8366411e-15 | ... U132: ='DSGE HVD wFG'!U132-'DSGE HVD woFG'!U132 -> -0.059419551 | Y132: =+A132 -> 51043 | Z132: =+B132 -> -0.0091257145 | AA132: =+C132 -> -0.014583144 | AB132: =+D132 -> -0.11143848 | AC132: =+F132+S132 -> 0.063195869 | AD132: =+E132 -> -0.0056458107 | AE132: =+Q132 -> 0.019166914 | AF132: =+G132 -> 4.6419936e-17 | AG132: =+H132 -> -1.5050107e-15 | AH132: =+SUM(T132,I132:P132) -> -0.00098918665 | AI132: =+SUM(Z132:AH132) -> -0.059419551 | AJ132: =SUM(AC132+AE132) -> 0.082362783 | AK132: =AB132+AA132+AD132 -> -0.13166743 | AL132: =Z132 -> -0.0091257145 | AM132: =AH132 -> -0.00098918665 | AN132: =SUM(AJ132:AM132) -> -0.059419551 | AO132: =(AJ132-AJ131)/($AN132-$AN131) -> -1.3314887 | AP132: =(AK132-AK131)/($AN132-$AN131) -> 2.1499785 | AQ132: =(AL132-AL131)/($AN132-$AN131) -> 0.166057 | AR132: =(AM132-AM131)/($AN132-$AN131) -> 0.015453203 | AS132: =(AN132-AN131)/($AN132-$AN131) -> 1

Sheet DSGE HVD wFG
A1: date | B1: =+[1]wFG_rstar_shock_decomposition!E1 -> g | C1: =+[1]wFG_rstar_shock_decomposition!F1 -> b_liq | D1: =+[1]wFG_rstar_shock_decomposition!G1 -> b_safe | E1: =+[1]wFG_rstar_shock_decomposition!H1 -> FF | F1: =+[1]wFG_rstar_shock_decomposition!I1 -> z | G1: =+[1]wFG_rstar_shock_decomposition!J1 -> p-mkp | H1: =+[1]wFG_rstar_shock_decomposition!K1 -> w-mkp | I1: =+[1]wFG_rstar_shock_decomposition!L1 -> pol | ... T1: =+[1]wFG_rstar_shock_decomposition!W1 -> dt | U1: DSGE r* | X1: Chart | Y1: Date | Z1: Government | AA1: Liquidity | AB1: Safety | AC1: Technology | AD1: Financial Frictions | AE1: Investment Specific Technology | AF1: Price Markups | AG1: Wage Markups | AH1: Others | AI1: DSGE r* (with FG) | AJ1: Growth | AK1: Safety+Liquidity | AL1: Government | AM1: Others | AN1: Total | AO1: Growth | AP1: Safety+Liquidity | AQ1: Government | AR1: Others | AS1: Total
A2: 39172 | B2: =+[1]wFG_rstar_shock_decomposition!E2 -> -0.10116499 | C2: =+[1]wFG_rstar_shock_decomposition!F2 -> -0.14808542 | D2: =+[1]wFG_rstar_shock_decomposition!G2 -> 0.49991388 | E2: =+[1]wFG_rstar_shock_decomposition!H2 -> -0.023433525 | F2: =+[1]wFG_rstar_shock_decomposition!I2 -> 0.13159807 | G2: =+[1]wFG_rstar_shock_decomposition!J2 -> 3.835998e-16 | H2: =+[1]wFG_rstar_shock_decomposition!K2 -> -3.6594233e-15 | I2: =+[1]wFG_rstar_shock_decomposition!L2 -> 1.4552564e-14 | ... T2: =+[1]wFG_rstar_shock_decomposition!W2 -> 0.028537733 | U2: =+[1]wFG_rstar_shock_decomposition!D2 -> 0.35147615 | Y2: =+A2 -> 39172 | Z2: =+B2 -> -0.10116499 | AA2: =+C2 -> -0.14808542 | AB2: =+D2 -> 0.49991388 | AC2: =+F2+S2 -> 0.14174747 | AD2: =+E2 -> -0.023433525 | AE2: =+Q2 -> -0.046038989 | AF2: =+G2 -> 3.835998e-16 | AG2: =+H2 -> -3.6594233e-15 | AH2: =+SUM(T2,I2:P2) -> 0.028537733 | AI2: =+SUM(Z2:AH2) -> 0.35147615 | AJ2: =SUM(AC2+AE2) -> 0.095708486 | AK2: =AB2+AA2+AD2 -> 0.32839493 | AL2: =Z2 -> -0.10116499 | AM2: =AH2 -> 0.028537733 | AN2: =SUM(AJ2:AM2) -> 0.35147615
A3: 39263 | B3: =+[1]wFG_rstar_shock_decomposition!E3 -> -0.091415602 | C3: =+[1]wFG_rstar_shock_decomposition!F3 -> -0.16817797 | D3: =+[1]wFG_rstar_shock_decomposition!G3 -> 0.55181563 | E3: =+[1]wFG_rstar_shock_decomposition!H3 -> -0.017256471 | F3: =+[1]wFG_rstar_shock_decomposition!I3 -> 0.11475644 | G3: =+[1]wFG_rstar_shock_decomposition!J3 -> 5.4879435e-16 | H3: =+[1]wFG_rstar_shock_decomposition!K3 -> -2.4440355e-15 | I3: =+[1]wFG_rstar_shock_decomposition!L3 -> 1.3433653e-14 | ... T3: =+[1]wFG_rstar_shock_decomposition!W3 -> 0.028175116 | U3: =+[1]wFG_rstar_shock_decomposition!D3 -> 0.25186851 | Y3: =+A3 -> 39263 | Z3: =+B3 -> -0.091415602 | AA3: =+C3 -> -0.16817797 | AB3: =+D3 -> 0.55181563 | AC3: =+F3+S3 -> -0.012256044 | AD3: =+E3 -> -0.017256471 | AE3: =+Q3 -> -0.039016157 | AF3: =+G3 -> 5.4879435e-16 | AG3: =+H3 -> -2.4440355e-15 | AH3: =+SUM(T3,I3:P3) -> 0.028175116 | AI3: =+SUM(Z3:AH3) -> 0.25186851 | AJ3: =SUM(AC3+AE3) -> -0.051272201 | AK3: =AB3+AA3+AD3 -> 0.36638119 | AL3: =Z3 -> -0.091415602 | AM3: =AH3 -> 0.028175116 | AN3: =SUM(AJ3:AM3) -> 0.25186851 | AO3: =(AJ3-AJ2)/($AN3-$AN2) -> 1.4755964 | AP3: =(AK3-AK2)/($AN3-$AN2) -> -0.38135894 | AQ3: =(AL3-AL2)/($AN3-$AN2) -> -0.097877908 | AR3: =(AM3-AM2)/($AN3-$AN2) -> 0.0036404606 | AS3: =(AN3-AN2)/($AN3-$AN2) -> 1
A4: 39355 | B4: =+[1]wFG_rstar_shock_decomposition!E4 -> -0.095807612 | C4: =+[1]wFG_rstar_shock_decomposition!F4 -> -0.33979271 | D4: =+[1]wFG_rstar_shock_decomposition!G4 -> 0.56002226 | E4: =+[1]wFG_rstar_shock_decomposition!H4 -> -0.051006152 | F4: =+[1]wFG_rstar_shock_decomposition!I4 -> 0.13362002 | G4: =+[1]wFG_rstar_shock_decomposition!J4 -> 2.5037011e-16 | H4: =+[1]wFG_rstar_shock_decomposition!K4 -> -1.4001092e-15 | I4: =+[1]wFG_rstar_shock_decomposition!L4 -> 1.3980609e-14 | ... T4: =+[1]wFG_rstar_shock_decomposition!W4 -> 0.027817345 | U4: =+[1]wFG_rstar_shock_decomposition!D4 -> 0.016615982 | Y4: =+A4 -> 39355 | Z4: =+B4 -> -0.095807612 | AA4: =+C4 -> -0.33979271 | AB4: =+D4 -> 0.56002226 | AC4: =+F4+S4 -> -0.028311233 | AD4: =+E4 -> -0.051006152 | AE4: =+Q4 -> -0.056305913 | AF4: =+G4 -> 2.5037011e-16 | AG4: =+H4 -> -1.4001092e-15 | AH4: =+SUM(T4,I4:P4) -> 0.027817345 | AI4: =+SUM(Z4:AH4) -> 0.016615982 | AJ4: =SUM(AC4+AE4) -> -0.084617145 | AK4: =AB4+AA4+AD4 -> 0.16922339 | AL4: =Z4 -> -0.095807612 | AM4: =AH4 -> 0.027817345 | AN4: =SUM(AJ4:AM4) -> 0.016615982 | AO4: =(AJ4-AJ3)/($AN4-$AN3) -> 0.14174107 | AP4: =(AK4-AK3)/($AN4-$AN3) -> 0.83806879 | AQ4: =(AL4-AL3)/($AN4-$AN3) -> 0.018669343 | AR4: =(AM4-AM3)/($AN4-$AN3) -> 0.0015207924 | AS4: =(AN4-AN3)/($AN4-$AN3) -> 1
A5: 39447 | B5: =+[1]wFG_rstar_shock_decomposition!E5 -> -0.092857246 | C5: =+[1]wFG_rstar_shock_decomposition!F5 -> -0.47721599 | D5: =+[1]wFG_rstar_shock_decomposition!G5 -> 0.53555175 | E5: =+[1]wFG_rstar_shock_decomposition!H5 -> -0.085101434 | F5: =+[1]wFG_rstar_shock_decomposition!I5 -> 0.13642795 | G5: =+[1]wFG_rstar_shock_decomposition!J5 -> -2.6306488e-16 | H5: =+[1]wFG_rstar_shock_decomposition!K5 -> -7.9837506e-16 | I5: =+[1]wFG_rstar_shock_decomposition!L5 -> 1.5589942e-14 | ... T5: =+[1]wFG_rstar_shock_decomposition!W5 -> 0.027464357 | U5: =+[1]wFG_rstar_shock_decomposition!D5 -> -0.15992205 | Y5: =+A5 -> 39447 | Z5: =+B5 -> -0.092857246 | AA5: =+C5 -> -0.47721599 | AB5: =+D5 -> 0.53555175 | AC5: =+F5+S5 -> 0.0013142414 | AD5: =+E5 -> -0.085101434 | AE5: =+Q5 -> -0.069077731 | AF5: =+G5 -> -2.6306488e-16 | AG5: =+H5 -> -7.9837506e-16 | AH5: =+SUM(T5,I5:P5) -> 0.027464357 | AI5: =+SUM(Z5:AH5) -> -0.15992205 | AJ5: =SUM(AC5+AE5) -> -0.067763489 | AK5: =AB5+AA5+AD5 -> -0.026765674 | AL5: =Z5 -> -0.092857246 | AM5: =AH5 -> 0.027464357 | AN5: =SUM(AJ5:AM5) -> -0.15992205 | AO5: =(AJ5-AJ4)/($AN5-$AN4) -> -0.095467565 | AP5: =(AK5-AK4)/($AN5-$AN4) -> 1.1101804 | AQ5: =(AL5-AL4)/($AN5-$AN4) -> -0.016712354 | AR5: =(AM5-AM4)/($AN5-$AN4) -> 0.0019995064 | AS5: =(AN5-AN4)/($AN5-$AN4) -> 1
A6: 39538 | B6: =+[1]wFG_rstar_shock_decomposition!E6 -> -0.094503573 | C6: =+[1]wFG_rstar_shock_decomposition!F6 -> -0.63793934 | D6: =+[1]wFG_rstar_shock_decomposition!G6 -> 0.48092883 | E6: =+[1]wFG_rstar_shock_decomposition!H6 -> -0.09859914 | F6: =+[1]wFG_rstar_shock_decomposition!I6 -> 0.14786982 | G6: =+[1]wFG_rstar_shock_decomposition!J6 -> 1.4712008e-17 | H6: =+[1]wFG_rstar_shock_decomposition!K6 -> -1.4965976e-16 | I6: =+[1]wFG_rstar_shock_decomposition!L6 -> 1.6862544e-14 | ... T6: =+[1]wFG_rstar_shock_decomposition!W6 -> 0.027116084 | U6: =+[1]wFG_rstar_shock_decomposition!D6 -> -0.49242688 | Y6: =+A6 -> 39538 | Z6: =+B6 -> -0.094503573 | AA6: =+C6 -> -0.63793934 | AB6: =+D6 -> 0.48092883 | AC6: =+F6+S6 -> -0.10652621 | AD6: =+E6 -> -0.09859914 | AE6: =+Q6 -> -0.06290353 | AF6: =+G6 -> 1.4712008e-17 | AG6: =+H6 -> -1.4965976e-16 | AH6: =+SUM(T6,I6:P6) -> 0.027116084 | AI6: =+SUM(Z6:AH6) -> -0.49242688 | AJ6: =SUM(AC6+AE6) -> -0.16942974 | AK6: =AB6+AA6+AD6 -> -0.25560965 | AL6: =Z6 -> -0.094503573 | AM6: =AH6 -> 0.027116084 | AN6: =SUM(AJ6:AM6) -> -0.49242688 | AO6: =(AJ6-AJ5)/($AN6-$AN5) -> 0.30575871 | AP6: =(AK6-AK5)/($AN6-$AN5) -> 0.68824258 | AQ6: =(AL6-AL5)/($AN6-$AN5) -> 0.0049512883 | AR6: =(AM6-AM5)/($AN6-$AN5) -> 0.0010474221 | AS6: =(AN6-AN5)/($AN6-$AN5) -> 1
A7: 39629 | B7: =+[1]wFG_rstar_shock_decomposition!E7 -> -0.09745303 | C7: =+[1]wFG_rstar_shock_decomposition!F7 -> -0.60173872 | D7: =+[1]wFG_rstar_shock_decomposition!G7 -> 0.51265011 | E7: =+[1]wFG_rstar_shock_decomposition!H7 -> -0.10050311 | F7: =+[1]wFG_rstar_shock_decomposition!I7 -> 0.14329593 | G7: =+[1]wFG_rstar_shock_decomposition!J7 -> 1.2858785e-16 | H7: =+[1]wFG_rstar_shock_decomposition!K7 -> 9.4075693e-16 | I7: =+[1]wFG_rstar_shock_decomposition!L7 -> 1.8164319e-14 | ... T7: =+[1]wFG_rstar_shock_decomposition!W7 -> 0.026772462 | U7: =+[1]wFG_rstar_shock_decomposition!D7 -> -0.47539679 | Y7: =+A7 -> 39629 | Z7: =+B7 -> -0.09745303 | AA7: =+C7 -> -0.60173872 | AB7: =+D7 -> 0.51265011 | AC7: =+F7+S7 -> -0.1512325 | AD7: =+E7 -> -0.10050311 | AE7: =+Q7 -> -0.063892001 | AF7: =+G7 -> 1.2858785e-16 | AG7: =+H7 -> 9.4075693e-16 | AH7: =+SUM(T7,I7:P7) -> 0.026772462 | AI7: =+SUM(Z7:AH7) -> -0.47539679 | AJ7: =SUM(AC7+AE7) -> -0.2151245 | AK7: =AB7+AA7+AD7 -> -0.18959172 | AL7: =Z7 -> -0.09745303 | AM7: =AH7 -> 0.026772462 | AN7: =SUM(AJ7:AM7) -> -0.47539679 | AO7: =(AJ7-AJ6)/($AN7-$AN6) -> -2.6831775 | AP7: =(AK7-AK6)/($AN7-$AN6) -> 3.8765457 | AQ7: =(AL7-AL6)/($AN7-$AN6) -> -0.17319089 | AR7: =(AM7-AM6)/($AN7-$AN6) -> -0.020177304 | AS7: =(AN7-AN6)/($AN7-$AN6) -> 1
A8: 39721 | B8: =+[1]wFG_rstar_shock_decomposition!E8 -> -0.082949481 | C8: =+[1]wFG_rstar_shock_decomposition!F8 -> -0.71012197 | D8: =+[1]wFG_rstar_shock_decomposition!G8 -> 0.48282661 | E8: =+[1]wFG_rstar_shock_decomposition!H8 -> -0.09981108 | F8: =+[1]wFG_rstar_shock_decomposition!I8 -> 0.1425402 | G8: =+[1]wFG_rstar_shock_decomposition!J8 -> -4.384962e-16 | H8: =+[1]wFG_rstar_shock_decomposition!K8 -> 1.7607749e-15 | I8: =+[1]wFG_rstar_shock_decomposition!L8 -> 1.6133421e-14 | ... T8: =+[1]wFG_rstar_shock_decomposition!W8 -> 0.026433429 | U8: =+[1]wFG_rstar_shock_decomposition!D8 -> -0.63918806 | Y8: =+A8 -> 39721 | Z8: =+B8 -> -0.082949481 | AA8: =+C8 -> -0.71012197 | AB8: =+D8 -> 0.48282661 | AC8: =+F8+S8 -> -0.1996818 | AD8: =+E8 -> -0.09981108 | AE8: =+Q8 -> -0.055883769 | AF8: =+G8 -> -4.384962e-16 | AG8: =+H8 -> 1.7607749e-15 | AH8: =+SUM(T8,I8:P8) -> 0.026433429 | AI8: =+SUM(Z8:AH8) -> -0.63918806 | AJ8: =SUM(AC8+AE8) -> -0.25556557 | AK8: =AB8+AA8+AD8 -> -0.32710643 | AL8: =Z8 -> -0.082949481 | AM8: =AH8 -> 0.026433429 | AN8: =SUM(AJ8:AM8) -> -0.63918806 | AO8: =(AJ8-AJ7)/($AN8-$AN7) -> 0.24690615 | AP8: =(AK8-AK7)/($AN8-$AN7) -> 0.83957292 | AQ8: =(AL8-AL7)/($AN8-$AN7) -> -0.088548977 | AR8: =(AM8-AM7)/($AN8-$AN7) -> 0.0020699117 | AS8: =(AN8-AN7)/($AN8-$AN7) -> 1
A9: 39813 | B9: =+[1]wFG_rstar_shock_decomposition!E9 -> -0.050147653 | C9: =+[1]wFG_rstar_shock_decomposition!F9 -> -1.3069466 | D9: =+[1]wFG_rstar_shock_decomposition!G9 -> 0.18081285 | E9: =+[1]wFG_rstar_shock_decomposition!H9 -> -0.17998264 | F9: =+[1]wFG_rstar_shock_decomposition!I9 -> 0.20167215 | G9: =+[1]wFG_rstar_shock_decomposition!J9 -> 1.6922843e-15 | H9: =+[1]wFG_rstar_shock_decomposition!K9 -> 2.3099358e-15 | I9: =+[1]wFG_rstar_shock_decomposition!L9 -> 1.4070252e-14 | ... T9: =+[1]wFG_rstar_shock_decomposition!W9 -> 0.02609892 | U9: =+[1]wFG_rstar_shock_decomposition!D9 -> -1.6704626 | Y9: =+A9 -> 39813 | Z9: =+B9 -> -0.050147653 | AA9: =+C9 -> -1.3069466 | AB9: =+D9 -> 0.18081285 | AC9: =+F9+S9 -> -0.34549921 | AD9: =+E9 -> -0.17998264 | AE9: =+Q9 -> 0.0052017786 | AF9: =+G9 -> 1.6922843e-15 | AG9: =+H9 -> 2.3099358e-15 | AH9: =+SUM(T9,I9:P9) -> 0.02609892 | AI9: =+SUM(Z9:AH9) -> -1.6704626 | AJ9: =SUM(AC9+AE9) -> -0.34029744 | AK9: =AB9+AA9+AD9 -> -1.3061164 | AL9: =Z9 -> -0.050147653 | AM9: =AH9 -> 0.02609892 | AN9: =SUM(AJ9:AM9) -> -1.6704626 | AO9: =(AJ9-AJ8)/($AN9-$AN8) -> 0.082162281 | AP9: =(AK9-AK8)/($AN9-$AN8) -> 0.94932043 | AQ9: =(AL9-AL8)/($AN9-$AN8) -> -0.031807077 | AR9: =(AM9-AM8)/($AN9-$AN8) -> 0.00032436405 | AS9: =(AN9-AN8)/($AN9-$AN8) -> 1
A10: 39903 | B10: =+[1]wFG_rstar_shock_decomposition!E10 -> -0.035773165 | C10: =+[1]wFG_rstar_shock_decomposition!F10 -> -1.085552 | D10: =+[1]wFG_rstar_shock_decomposition!G10 -> 0.23032624 | E10: =+[1]wFG_rstar_shock_decomposition!H10 -> -0.22841274 | F10: =+[1]wFG_rstar_shock_decomposition!I10 -> 0.18945894 | G10: =+[1]wFG_rstar_shock_decomposition!J10 -> 1.9281286e-15 | H10: =+[1]wFG_rstar_shock_decomposition!K10 -> 4.6174674e-15 | I10: =+[1]wFG_rstar_shock_decomposition!L10 -> 1.0887621e-14 | ... T10: =+[1]wFG_rstar_shock_decomposition!W10 -> 0.025768875 | U10: =+[1]wFG_rstar_shock_decomposition!D10 -> -1.5393325 | Y10: =+A10 -> 39903 | Z10: =+B10 -> -0.035773165 | AA10: =+C10 -> -1.085552 | AB10: =+D10 -> 0.23032624 | AC10: =+F10+S10 -> -0.36687725 | AD10: =+E10 -> -0.22841274 | AE10: =+Q10 -> -0.078812432 | AF10: =+G10 -> 1.9281286e-15 | AG10: =+H10 -> 4.6174674e-15 | AH10: =+SUM(T10,I10:P10) -> 0.025768875 | AI10: =+SUM(Z10:AH10) -> -1.5393325 | AJ10: =SUM(AC10+AE10) -> -0.44568968 | AK10: =AB10+AA10+AD10 -> -1.0836385 | AL10: =Z10 -> -0.035773165 | AM10: =AH10 -> 0.025768875 | AN10: =SUM(AJ10:AM10) -> -1.5393325 | AO10: =(AJ10-AJ9)/($AN10-$AN9) -> -0.80372286 | AP10: =(AK10-AK9)/($AN10-$AN9) -> 1.6966197 | AQ10: =(AL10-AL9)/($AN10-$AN9) -> 0.10962006 | AR10: =(AM10-AM9)/($AN10-$AN9) -> -0.0025169303 | AS10: =(AN10-AN9)/($AN10-$AN9) -> 1
A11: 39994 | B11: =+[1]wFG_rstar_shock_decomposition!E11 -> -0.02408911 | C11: =+[1]wFG_rstar_shock_decomposition!F11 -> -0.87630027 | D11: =+[1]wFG_rstar_shock_decomposition!G11 -> 0.24041406 | E11: =+[1]wFG_rstar_shock_decomposition!H11 -> -0.15773268 | F11: =+[1]wFG_rstar_shock_decomposition!I11 -> 0.14864202 | G11: =+[1]wFG_rstar_shock_decomposition!J11 -> 1.7068416e-15 | H11: =+[1]wFG_rstar_shock_decomposition!K11 -> 4.4703201e-15 | I11: =+[1]wFG_rstar_shock_decomposition!L11 -> 9.4894502e-15 | ... T11: =+[1]wFG_rstar_shock_decomposition!W11 -> 0.025443232 | U11: =+[1]wFG_rstar_shock_decomposition!D11 -> -1.2082231 | Y11: =+A11 -> 39994 | Z11: =+B11 -> -0.02408911 | AA11: =+C11 -> -0.87630027 | AB11: =+D11 -> 0.24041406 | AC11: =+F11+S11 -> -0.31115498 | AD11: =+E11 -> -0.15773268 | AE11: =+Q11 -> -0.10480332 | AF11: =+G11 -> 1.7068416e-15 | AG11: =+H11 -> 4.4703201e-15 | AH11: =+SUM(T11,I11:P11) -> 0.025443232 | AI11: =+SUM(Z11:AH11) -> -1.2082231 | AJ11: =SUM(AC11+AE11) -> -0.4159583 | AK11: =AB11+AA11+AD11 -> -0.79361889 | AL11: =Z11 -> -0.02408911 | AM11: =AH11 -> 0.025443232 | AN11: =SUM(AJ11:AM11) -> -1.2082231 | AO11: =(AJ11-AJ10)/($AN11-$AN10) -> 0.089793219 | AP11: =(AK11-AK10)/($AN11-$AN10) -> 0.87590268 | AQ11: =(AL11-AL10)/($AN11-$AN10) -> 0.035287597 | AR11: =(AM11-AM10)/($AN11-$AN10) -> -0.00098349179 | AS11: =(AN11-AN10)/($AN11-$AN10) -> 1
A12: 40086 | B12: =+[1]wFG_rstar_shock_decomposition!E12 -> -0.039925577 | C12: =+[1]wFG_rstar_shock_decomposition!F12 -> -0.66815748 | D12: =+[1]wFG_rstar_shock_decomposition!G12 -> 0.19466108 | E12: =+[1]wFG_rstar_shock_decomposition!H12 -> -0.061837083 | F12: =+[1]wFG_rstar_shock_decomposition!I12 -> 0.12092164 | G12: =+[1]wFG_rstar_shock_decomposition!J12 -> 1.5949461e-15 | H12: =+[1]wFG_rstar_shock_decomposition!K12 -> 4.8995216e-15 | I12: =+[1]wFG_rstar_shock_decomposition!L12 -> 9.569358e-15 | ... T12: =+[1]wFG_rstar_shock_decomposition!W12 -> 0.02512193 | U12: =+[1]wFG_rstar_shock_decomposition!D12 -> -1.1317976 | Y12: =+A12 -> 40086 | Z12: =+B12 -> -0.039925577 | AA12: =+C12 -> -0.66815748 | AB12: =+D12 -> 0.19466108 | AC12: =+F12+S12 -> -0.3911912 | AD12: =+E12 -> -0.061837083 | AE12: =+Q12 -> -0.19046931 | AF12: =+G12 -> 1.5949461e-15 | AG12: =+H12 -> 4.8995216e-15 | AH12: =+SUM(T12,I12:P12) -> 0.02512193 | AI12: =+SUM(Z12:AH12) -> -1.1317976 | AJ12: =SUM(AC12+AE12) -> -0.58166051 | AK12: =AB12+AA12+AD12 -> -0.53533348 | AL12: =Z12 -> -0.039925577 | AM12: =AH12 -> 0.02512193 | AN12: =SUM(AJ12:AM12) -> -1.1317976 | AO12: =(AJ12-AJ11)/($AN12-$AN11) -> -2.1681553 | AP12: =(AK12-AK11)/($AN12-$AN11) -> 3.379574 | AQ12: =(AL12-AL11)/($AN12-$AN11) -> -0.20721461 | AR12: =(AM12-AM11)/($AN12-$AN11) -> -0.0042041224 | AS12: =(AN12-AN11)/($AN12-$AN11) -> 1
A13: 40178 | B13: =+[1]wFG_rstar_shock_decomposition!E13 -> -0.027038449 | C13: =+[1]wFG_rstar_shock_decomposition!F13 -> -0.58178559 | D13: =+[1]wFG_rstar_shock_decomposition!G13 -> 0.15426067 | E13: =+[1]wFG_rstar_shock_decomposition!H13 -> 0.00019437639 | F13: =+[1]wFG_rstar_shock_decomposition!I13 -> 0.063221109 | G13: =+[1]wFG_rstar_shock_decomposition!J13 -> 3.2339767e-16 | H13: =+[1]wFG_rstar_shock_decomposition!K13 -> 5.509702e-15 | I13: =+[1]wFG_rstar_shock_decomposition!L13 -> 6.8087841e-15 | ... T13: =+[1]wFG_rstar_shock_decomposition!W13 -> 0.02480491 | U13: =+[1]wFG_rstar_shock_decomposition!D13 -> -0.97113352 | Y13: =+A13 -> 40178 | Z13: =+B13 -> -0.027038449 | AA13: =+C13 -> -0.58178559 | AB13: =+D13 -> 0.15426067 | AC13: =+F13+S13 -> -0.35921644 | AD13: =+E13 -> 0.00019437639 | AE13: =+Q13 -> -0.182353 | AF13: =+G13 -> 3.2339767e-16 | AG13: =+H13 -> 5.509702e-15 | AH13: =+SUM(T13,I13:P13) -> 0.02480491 | AI13: =+SUM(Z13:AH13) -> -0.97113352 | AJ13: =SUM(AC13+AE13) -> -0.54156944 | AK13: =AB13+AA13+AD13 -> -0.42733054 | AL13: =Z13 -> -0.027038449 | AM13: =AH13 -> 0.02480491 | AN13: =SUM(AJ13:AM13) -> -0.97113352 | AO13: =(AJ13-AJ12)/($AN13-$AN12) -> 0.24953347 | AP13: =(AK13-AK12)/($AN13-$AN12) -> 0.6722281 | AQ13: =(AL13-AL12)/($AN13-$AN12) -> 0.080211611 | AR13: =(AM13-AM12)/($AN13-$AN12) -> -0.0019731848 | AS13: =(AN13-AN12)/($AN13-$AN12) -> 1
