Workbook
Name BoxPlot: "BoxPlot"
Name Bubble: "Bubble"
Name Candlestick: "Candlestick"
Name Chart: "Chart"
Name ChartImage: "ChartImage"
Name ColumnRange: "ColumnRange"
Name Dumbbell: "Dumbbell"
Name Heatmap: "Heatmap"
Name Histogram: "Histogram"
Name Map: "Map"
Name OHLC: "OHLC"
Name PieChart: "PieChart"
Name Scatter: "Scatter"
Name Series: "Series"
Name Stripe: "Stripe"
Name Table: "Table"
Name TreeMap: "TreeMap"
Name Waterfall: "Waterfall"

Sheet Allcharts

Sheet US_output_policy
A1: date | B1: g_sh | C1: b_liqtil_sh | D1: b_liqp_sh | E1: b_safetil_sh | F1: b_safep_sh | G1: mu_sh | H1: z_sh | I1: lambda_f_sh | J1: lambda_w_sh | K1: rm_sh | L1: sigma_omega_sh | M1: mu_e_sh | N1: gamma_sh | O1: pi_star_sh | P1: lr_sh | Q1: zp_sh | R1: tfp_sh | S1: gdpdef_sh | T1: corepce_sh | U1: gdp_sh | V1: gdi_sh | W1: BBB_sh | X1: AAA_sh | Y1: rm_shl1 | Z1: rm_shl2 | AA1: rm_shl3 | AB1: rm_shl4 | AC1: rm_shl5 | AD1: rm_shl6 | AE1: dettrend | AF1: detrendedMean | AH1: rm_sh | AI1: =Y1 -> rm_shl1 | AJ1: =Z1 -> rm_shl2 | AK1: =AA1 -> rm_shl3 | AL1: =AB1 -> rm_shl4 | AM1: =AC1 -> rm_shl5 | AN1: =AD1 -> rm_shl6 | AQ1: Plot | AR1: =A1 -> date | AS1: =AF1 -> detrendedMean | AT1: Monetary Policy | AU1: Fgsum | AV1: FG1 | AW1: FG2 | AX1: FG3 | AY1: FG4 | AZ1: FG5 | BA1: FG6 | BC1: date | BD1: rm_sh | BE1: Fgsum
A2: 39172 | B2: -1.0215877 | C2: 0.14738424 | D2: -0.044907453 | E2: 0.56515568 | F2: 0.33471877 | G2: 1.4053436 | H2: 0.54693072 | I2: -0.65393335 | J2: 0.64232717 | K2: 1.7750614 | L2: 1.2826525 | M2: 0 | N2: 0 | O2: 0.3278555 | P2: 0 | Q2: 0.11087454 | R2: 0 | S2: 0 | T2: 0 | U2: 0 | V2: 0 | W2: 0 | X2: 0 | Y2: 0 | Z2: 0 | AA2: 0 | AB2: 0 | AC2: 0 | AD2: 0 | AE2: 0.13099711 | AF2: 5.5488727 | AH2: =K2 -> 1.7750614 | AI2: =Y2 -> 0 | AJ2: =Z2 -> 0 | AK2: =AA2 -> 0 | AL2: =AB2 -> 0 | AM2: =AC2 -> 0 | AN2: =AD2 -> 0 | AR2: =A2 -> 39172 | AS2: =AF2*4+2 -> 24.195491 | AT2: =AH2 -> 1.7750614 | AU2: =SUM(AV2:BA2) -> 0 | AV2: =AI2 -> 0 | AW2: =AJ2 -> 0 | AX2: =AK2 -> 0 | AY2: =AL2 -> 0 | AZ2: =AM2 -> 0 | BA2: =AN2 -> 0 | BC2: =AR2 -> 39172 | BD2: =AT2 -> 1.7750614 | BE2: =AU2 -> 0
A3: 39263 | B3: -0.87702165 | C3: 0.14867978 | D3: -0.050839217 | E3: 0.5967583 | F3: 0.35694143 | G3: 1.4459149 | H3: 0.10615582 | I3: -0.67075329 | J3: 0.60096046 | K3: 1.5688765 | L3: 1.2418066 | M3: 0 | N3: 0 | O3: 0.33267031 | P3: 0 | Q3: 0.070231968 | R3: 0 | S3: 0 | T3: 0 | U3: 0 | V3: 0 | W3: 0 | X3: 0 | Y3: 0 | Z3: 0 | AA3: 0 | AB3: 0 | AC3: 0 | AD3: 0 | AE3: 0.13039267 | AF3: 5.0007746 | AH3: =K3 -> 1.5688765 | AI3: =Y3 -> 0 | AJ3: =Z3 -> 0 | AK3: =AA3 -> 0 | AL3: =AB3 -> 0 | AM3: =AC3 -> 0 | AN3: =AD3 -> 0 | AR3: =A3 -> 39263 | AS3: =AF3*4+2 -> 22.003098 | AT3: =AH3 -> 1.5688765 | AU3: =SUM(AV3:BA3) -> 0 | AV3: =AI3 -> 0 | AW3: =AJ3 -> 0 | AX3: =AK3 -> 0 | AY3: =AL3 -> 0 | AZ3: =AM3 -> 0 | BA3: =AN3 -> 0 | BC3: =AR3 -> 39263 | BD3: =AT3 -> 1.5688765 | BE3: =AU3 -> 0
A4: 39355 | B4: -1.040355 | C4: 0.13425109 | D4: -0.14587387 | E4: 0.69031317 | F4: 0.37191894 | G4: 1.4503632 | H4: 0.31183503 | I4: -0.6798581 | J4: 0.61019793 | K4: 1.5086958 | L4: 1.1510338 | M4: 0 | N4: 0 | O4: 0.37118543 | P4: 0 | Q4: 0.037371485 | R4: 0 | S4: 0 | T4: 0 | U4: 0 | V4: 0 | W4: 0 | X4: 0 | Y4: 0 | Z4: 0 | AA4: 0 | AB4: 0 | AC4: 0 | AD4: 0 | AE4: 0.12978091 | AF4: 4.9008599 | AH4: =K4 -> 1.5086958 | AI4: =Y4 -> 0 | AJ4: =Z4 -> 0 | AK4: =AA4 -> 0 | AL4: =AB4 -> 0 | AM4: =AC4 -> 0 | AN4: =AD4 -> 0 | AR4: =A4 -> 39355 | AS4: =AF4*4+2 -> 21.603439 | AT4: =AH4 -> 1.5086958 | AU4: =SUM(AV4:BA4) -> 0 | AV4: =AI4 -> 0 | AW4: =AJ4 -> 0 | AX4: =AK4 -> 0 | AY4: =AL4 -> 0 | AZ4: =AM4 -> 0 | BA4: =AN4 -> 0 | BC4: =AR4 -> 39355 | BD4: =AT4 -> 1.5086958 | BE4: =AU4 -> 0
A5: 39447 | B5: -0.99330901 | C5: 0.14258815 | D5: -0.26310356 | E5: 0.73768743 | F5: 0.36639612 | G5: 1.4317096 | H5: 0.21867959 | I5: -0.68920012 | J5: 0.66599438 | K5: 1.7274198 | L5: 1.0093212 | M5: 0 | N5: 0 | O5: 0.40724837 | P5: 0 | Q5: 0.016106972 | R5: 0 | S5: 0 | T5: 0 | U5: 0 | V5: 0 | W5: 0 | X5: 0 | Y5: 0 | Z5: 0 | AA5: 0 | AB5: 0 | AC5: 0 | AD5: 0 | AE5: 0.12916218 | AF5: 4.9067011 | AH5: =K5 -> 1.7274198 | AI5: =Y5 -> 0 | AJ5: =Z5 -> 0 | AK5: =AA5 -> 0 | AL5: =AB5 -> 0 | AM5: =AC5 -> 0 | AN5: =AD5 -> 0 | AR5: =A5 -> 39447 | AS5: =AF5*4+2 -> 21.626804 | AT5: =AH5 -> 1.7274198 | AU5: =SUM(AV5:BA5) -> 0 | AV5: =AI5 -> 0 | AW5: =AJ5 -> 0 | AX5: =AK5 -> 0 | AY5: =AL5 -> 0 | AZ5: =AM5 -> 0 | BA5: =AN5 -> 0 | BC5: =AR5 -> 39447 | BD5: =AT5 -> 1.7274198 | BE5: =AU5 -> 0
A6: 39538 | B6: -1.0476842 | C6: 0.03061779 | D6: -0.40243934 | E6: 0.39311962 | F6: 0.33629364 | G6: 1.42832 | H6: 0.27379584 | I6: -0.67868028 | J6: 0.70115772 | K6: 2.0053504 | L6: 0.85487701 | M6: 0 | N6: 0 | O6: 0.44493982 | P6: 0 | Q6: -0.019590161 | R6: 0 | S6: 0 | T6: 0 | U6: 0 | V6: 0 | W6: 0 | X6: 0 | Y6: 0 | Z6: 0 | AA6: 0 | AB6: 0 | AC6: 0 | AD6: 0 | AE6: 0.12853685 | AF6: 4.4486148 | AH6: =K6 -> 2.0053504 | AI6: =Y6 -> 0 | AJ6: =Z6 -> 0 | AK6: =AA6 -> 0 | AL6: =AB6 -> 0 | AM6: =AC6 -> 0 | AN6: =AD6 -> 0 | AR6: =A6 -> 39538 | AS6: =AF6*4+2 -> 19.794459 | AT6: =AH6 -> 2.0053504 | AU6: =SUM(AV6:BA6) -> 0 | AV6: =AI6 -> 0 | AW6: =AJ6 -> 0 | AX6: =AK6 -> 0 | AY6: =AL6 -> 0 | AZ6: =AM6 -> 0 | BA6: =AN6 -> 0 | BC6: =AR6 -> 39538 | BD6: =AT6 -> 2.0053504 | BE6: =AU6 -> 0
A7: 39629 | B7: -1.1086433 | C7: -0.033609602 | D7: -0.44750789 | E7: 0.09339584 | F7: 0.34011857 | G7: 1.4242313 | H7: 0.099730651 | I7: -0.64918611 | J7: 0.69311266 | K7: 2.3003353 | L7: 0.71023288 | M7: 0 | N7: 0 | O7: 0.48647302 | P7: 0 | Q7: -0.047607001 | R7: 0 | S7: 0 | T7: 0 | U7: 0 | V7: 0 | W7: 0 | X7: 0 | Y7: 0 | Z7: 0 | AA7: 0 | AB7: 0 | AC7: 0 | AD7: 0 | AE7: 0.12790526 | AF7: 3.9889816 | AH7: =K7 -> 2.3003353 | AI7: =Y7 -> 0 | AJ7: =Z7 -> 0 | AK7: =AA7 -> 0 | AL7: =AB7 -> 0 | AM7: =AC7 -> 0 | AN7: =AD7 -> 0 | AR7: =A7 -> 39629 | AS7: =AF7*4+2 -> 17.955926 | AT7: =AH7 -> 2.3003353 | AU7: =SUM(AV7:BA7) -> 0 | AV7: =AI7 -> 0 | AW7: =AJ7 -> 0 | AX7: =AK7 -> 0 | AY7: =AL7 -> 0 | AZ7: =AM7 -> 0 | BA7: =AN7 -> 0 | BC7: =AR7 -> 39629 | BD7: =AT7 -> 2.3003353 | BE7: =AU7 -> 0
A8: 39721 | B8: -0.80373451 | C8: -0.20400532 | D8: -0.52579161 | E8: -0.37809506 | F8: 0.32715602 | G8: 1.4371073 | H8: 0.049769223 | I8: -0.6241057 | J8: 0.72601851 | K8: 1.9637541 | L8: 0.57993927 | M8: 0 | N8: 0 | O8: 0.49767707 | P8: 0 | Q8: -0.074978682 | R8: 0 | S8: 0 | T8: 0 | U8: 0 | V8: 0 | W8: 0 | X8: 0 | Y8: 0 | Z8: 0 | AA8: 0 | AB8: 0 | AC8: 0 | AD8: 0 | AE8: 0.12726775 | AF8: 3.0979785 | AH8: =K8 -> 1.9637541 | AI8: =Y8 -> 0 | AJ8: =Z8 -> 0 | AK8: =AA8 -> 0 | AL8: =AB8 -> 0 | AM8: =AC8 -> 0 | AN8: =AD8 -> 0 | AR8: =A8 -> 39721 | AS8: =AF8*4+2 -> 14.391914 | AT8: =AH8 -> 1.9637541 | AU8: =SUM(AV8:BA8) -> 0 | AV8: =AI8 -> 0 | AW8: =AJ8 -> 0 | AX8: =AK8 -> 0 | AY8: =AL8 -> 0 | AZ8: =AM8 -> 0 | BA8: =AN8 -> 0 | BC8: =AR8 -> 39721 | BD8: =AT8 -> 1.9637541 | BE8: =AU8 -> 0
A9: 39813 | B9: -0.21677727 | C9: -0.56638658 | D9: -0.87656555 | E9: -1.0760328 | F9: 0.163132 | G9: 1.567453 | H9: 0.77708187 | I9: -0.52720457 | J9: 0.77689645 | K9: 1.3356925 | L9: 0.32530383 | M9: 0 | N9: 0 | O9: 0.56267499 | P9: 0 | Q9: -0.12285996 | R9: 0 | S9: 0 | T9: 0 | U9: 0 | V9: 0 | W9: 0 | X9: 0 | Y9: -0.18334085 | Z9: -0.085809019 | AA9: -0.014995051 | AB9: -0.0025678522 | AC9: -0.0010749068 | AD9: -0.0015146036 | AE9: 0.12662465 | AF9: 1.9597303 | AH9: =K9 -> 1.3356925 | AI9: =Y9 -> -0.18334085 | AJ9: =Z9 -> -0.085809019 | AK9: =AA9 -> -0.014995051 | AL9: =AB9 -> -0.0025678522 | AM9: =AC9 -> -0.0010749068 | AN9: =AD9 -> -0.0015146036 | AR9: =A9 -> 39813 | AS9: =AF9*4+2 -> 9.8389213 | AT9: =AH9 -> 1.3356925 | AU9: =SUM(AV9:BA9) -> -0.28930228 | AV9: =AI9 -> -0.18334085 | AW9: =AJ9 -> -0.085809019 | AX9: =AK9 -> -0.014995051 | AY9: =AL9 -> -0.0025678522 | AZ9: =AM9 -> -0.0010749068 | BA9: =AN9 -> -0.0015146036 | BC9: =AR9 -> 39813 | BD9: =AT9 -> 1.3356925 | BE9: =AU9 -> -0.28930228
A10: 39903 | B10: -0.13539004 | C10: -0.65246513 | D10: -0.91826335 | E10: -1.4441778 | F10: 0.115455 | G10: 1.5230468 | H10: 0.27896396 | I10: -0.40325188 | J10: 0.66681609 | K10: 0.39863999 | L10: 0.0012907793 | M10: 0 | N10: 0 | O10: 0.65980691 | P10: 0 | Q10: -0.15244255 | R10: 0 | S10: 0 | T10: 0 | U10: 0 | V10: 0 | W10: 0 | X10: 0 | Y10: -0.40182322 | Z10: -0.21133372 | AA10: -0.064564658 | AB10: -0.0076746478 | AC10: -0.0097111472 | AD10: -0.013463276 | AE10: 0.12597629 | AF10: -0.64456556 | AH10: =K10 -> 0.39863999 | AI10: =Y10 -> -0.40182322 | AJ10: =Z10 -> -0.21133372 | AK10: =AA10 -> -0.064564658 | AL10: =AB10 -> -0.0076746478 | AM10: =AC10 -> -0.0097111472 | AN10: =AD10 -> -0.013463276 | AR10: =A10 -> 39903 | AS10: =AF10*4+2 -> -0.57826224 | AT10: =AH10 -> 0.39863999 | AU10: =SUM(AV10:BA10) -> -0.70857067 | AV10: =AI10 -> -0.40182322 | AW10: =AJ10 -> -0.21133372 | AX10: =AK10 -> -0.064564658 | AY10: =AL10 -> -0.0076746478 | AZ10: =AM10 -> -0.0097111472 | BA10: =AN10 -> -0.013463276 | BC10: =AR10 -> 39903 | BD10: =AT10 -> 0.39863999 | BE10: =AU10 -> -0.70857067
A11: 39994 | B11: -0.073128195 | C11: -0.59127453 | D11: -0.82556116 | E11: -1.5731642 | F11: 0.099746456 | G11: 1.4374342 | H11: -0.35522693 | I11: -0.28293943 | J11: 0.84351191 | K11: -0.30041232 | L11: -0.18272965 | M11: 0 | N11: 0 | O11: 0.6458429 | P11: 0 | Q11: -0.16787271 | R11: 0 | S11: 0 | T11: 0 | U11: 0 | V11: 0 | W11: 0 | X11: 0 | Y11: -0.51335586 | Z11: -0.31584038 | AA11: -0.13962108 | AB11: -0.03410106 | AC11: -0.016607341 | AD11: -0.041339223 | AE11: 0.12532296 | AF11: -2.2613156 | AH11: =K11 -> -0.30041232 | AI11: =Y11 -> -0.51335586 | AJ11: =Z11 -> -0.31584038 | AK11: =AA11 -> -0.13962108 | AL11: =AB11 -> -0.03410106 | AM11: =AC11 -> -0.016607341 | AN11: =AD11 -> -0.041339223 | AR11: =A11 -> 39994 | AS11: =AF11*4+2 -> -7.0452625 | AT11: =AH11 -> -0.30041232 | AU11: =SUM(AV11:BA11) -> -1.0608649 | AV11: =AI11 -> -0.51335586 | AW11: =AJ11 -> -0.31584038 | AX11: =AK11 -> -0.13962108 | AY11: =AL11 -> -0.03410106 | AZ11: =AM11 -> -0.016607341 | BA11: =AN11 -> -0.041339223 | BC11: =AR11 -> 39994 | BD11: =AT11 -> -0.30041232 | BE11: =AU11 -> -1.0608649
A12: 40086 | B12: -0.53090932 | C12: -0.26450707 | D12: -0.67212326 | E12: -1.5028278 | F12: 0.069033869 | G12: 1.1961043 | H12: -0.54411897 | I12: -0.18186777 | J12: 0.89049329 | K12: -0.56877654 | L12: -0.18360036 | M12: 0 | N12: 0 | O12: 0.48885426 | P12: 0 | Q12: -0.2019199 | R12: 0 | S12: 0 | T12: 0 | U12: 0 | V12: 0 | W12: 0 | X12: 0 | Y12: -0.43225273 | Z12: -0.32122089 | AA12: -0.17245864 | AB12: -0.050099817 | AC12: -0.0204331 | AD12: -0.08404302 | AE12: 0.12466498 | AF12: -2.9620085 | AH12: =K12 -> -0.56877654 | AI12: =Y12 -> -0.43225273 | AJ12: =Z12 -> -0.32122089 | AK12: =AA12 -> -0.17245864 | AL12: =AB12 -> -0.050099817 | AM12: =AC12 -> -0.0204331 | AN12: =AD12 -> -0.08404302 | AR12: =A12 -> 40086 | AS12: =AF12*4+2 -> -9.8480338 | AT12: =AH12 -> -0.56877654 | AU12: =SUM(AV12:BA12) -> -1.0805082 | AV12: =AI12 -> -0.43225273 | AW12: =AJ12 -> -0.32122089 | AX12: =AK12 -> -0.17245864 | AY12: =AL12 -> -0.050099817 | AZ12: =AM12 -> -0.0204331 | BA12: =AN12 -> -0.08404302 | BC12: =AR12 -> 40086 | BD12: =AT12 -> -0.56877654 | BE12: =AU12 -> -1.0805082
A13: 40178 | B13: -0.25242317 | C13: -0.21161538 | D13: -0.55513346 | E13: -1.5319895 | F13: 0.034934349 | G13: 0.99553621 | H13: -1.0349527 | I13: -0.1401452 | J13: 0.90746758 | K13: -1.1530786 | L13: -0.071269525 | M13: 0 | N13: 0 | O13: 0.29361464 | P13: 0 | Q13: -0.2238056 | R13: 0 | S13: 0 | T13: 0 | U13: 0 | V13: 0 | W13: 0 | X13: 0 | Y13: -0.35928238 | Z13: -0.28959157 | AA13: -0.22762518 | AB13: -0.069279424 | AC13: -0.028449793 | AD13: -0.14778106 | AE13: 0.12400264 | AF13: -3.9408671 | AH13: =K13 -> -1.1530786 | AI13: =Y13 -> -0.35928238 | AJ13: =Z13 -> -0.28959157 | AK13: =AA13 -> -0.22762518 | AL13: =AB13 -> -0.069279424 | AM13: =AC13 -> -0.028449793 | AN13: =AD13 -> -0.14778106 | AR13: =A13 -> 40178 | AS13: =AF13*4+2 -> -13.763469 | AT13: =AH13 -> -1.1530786 | AU13: =SUM(AV13:BA13) -> -1.1220094 | AV13: =AI13 -> -0.35928238 | AW13: =AJ13 -> -0.28959157 | AX13: =AK13 -> -0.22762518 | AY13: =AL13 -> -0.069279424 | AZ13: =AM13 -> -0.028449793 | BA13: =AN13 -> -0.14778106 | BC13: =AR13 -> 40178 | BD13: =AT13 -> -1.1530786 | BE13: =AU13 -> -1.1220094
... A132: 51043 | B132: -1.1485256 | C132: 0.00012590441 | D132: -0.042684349 | E132: -0.00047395337 | F132: 0.10831097 | G132: -0.17615887 | H132: 0.054636968 | I132: 0.15047017 | J132: 0.26718227 | K132: 0.0018162856 | L132: 0.37632535 | M132: 0 | N132: 0 | O132: 0.54539942 | P132: 0 | Q132: -0.20667783 | R132: 0 | S132: 0 | T132: 0 | U132: 0 | V132: 0 | W132: 0 | X132: 0 | Y132: -0.0016294185 | Z132: 0.0019674278 | AA132: -0.00054863095 | AB132: 0.00047969275 | AC132: -0.0015716835 | AD132: -0.0046451761 | AE132: 0.053433982 | AF132: -0.022767062 | AH132: =K132 -> 0.0018162856 | AI132: =Y132 -> -0.0016294185 | AJ132: =Z132 -> 0.0019674278 | AK132: =AA132 -> -0.00054863095 | AL132: =AB132 -> 0.00047969275 | AM132: =AC132 -> -0.0015716835 | AN132: =AD132 -> -0.0046451761 | AR132: =A132 -> 51043 | AS132: =AF132*4+2 -> 1.9089318 | AT132: =AH132 -> 0.0018162856 | AU132: =SUM(AV132:BA132) -> -0.0059477884 | AV132: =AI132 -> -0.0016294185 | AW132: =AJ132 -> 0.0019674278 | AX132: =AK132 -> -0.00054863095 | AY132: =AL132 -> 0.00047969275 | AZ132: =AM132 -> -0.0015716835 | BA132: =AN132 -> -0.0046451761 | BC132: =AR132 -> 51043 | BD132: =AT132 -> 0.0018162856 | BE132: =AU132 -> -0.0059477884

Sheet US_output_with_textbckup
A1: date | B1: g_sh | C1: b_liqtil_sh | D1: b_liqp_sh | E1: b_safetil_sh | F1: b_safep_sh | G1: mu_sh | H1: z_sh | I1: lambda_f_sh | J1: lambda_w_sh | K1: rm_sh | L1: sigma_omega_sh | M1: mu_e_sh | N1: gamma_sh | O1: pi_star_sh | P1: lr_sh | Q1: zp_sh | R1: tfp_sh | S1: gdpdef_sh | T1: corepce_sh | U1: gdp_sh | V1: gdi_sh | W1: BBB_sh | X1: AAA_sh | Y1: rm_shl1 | Z1: rm_shl2 | AA1: rm_shl3 | AB1: rm_shl4 | AC1: rm_shl5 | AD1: rm_shl6 | AE1: dettrend | AF1: detrendedMean | AH1: rm_sh | AI1: =Y1 -> rm_shl1 | AJ1: =Z1 -> rm_shl2 | AK1: =AA1 -> rm_shl3 | AL1: =AB1 -> rm_shl4 | AM1: =AC1 -> rm_shl5 | AN1: =AD1 -> rm_shl6 | AQ1: Plot | AR1: =A1 -> date | AS1: Monetary Policy | AT1: FG1 | AU1: FG2 | AV1: FG3 | AW1: FG4 | AX1: FG5 | AY1: FG6 | BA1: date | BB1: rm_sh | BC1: Fgsum
A2: 39172 | B2: -1.0215877 | C2: 0.14738424 | D2: -0.044907453 | E2: 0.56515568 | F2: 0.33471877 | G2: 1.4053436 | H2: 0.54693072 | I2: -0.65393335 | J2: 0.64232717 | K2: 1.7750614 | L2: 1.2826525 | M2: 0 | N2: 0 | O2: 0.3278555 | P2: 0 | Q2: 0.11087454 | R2: 0 | S2: 0 | T2: 0 | U2: 0 | V2: 0 | W2: 0 | X2: 0 | Y2: 0 | Z2: 0 | AA2: 0 | AB2: 0 | AC2: 0 | AD2: 0 | AE2: 0.13099711 | AF2: 5.5488727 | AH2: =K2 -> 1.7750614 | AI2: =Y2 -> 0 | AJ2: =Z2 -> 0 | AK2: =AA2 -> 0 | AL2: =AB2 -> 0 | AM2: =AC2 -> 0 | AN2: =AD2 -> 0 | AR2: =A2 -> 39172 | AS2: 0 | AT2: =AI2 -> 0 | AU2: =AJ2 -> 0 | AV2: =AK2 -> 0 | AW2: =AL2 -> 0 | AX2: =AM2 -> 0 | AY2: =AN2 -> 0 | BA2: =AR2 -> 39172 | BB2: =AS2 -> 0 | BC2: =#REF! -> #REF!
A3: 39263 | B3: -0.87702165 | C3: 0.14867978 | D3: -0.050839217 | E3: 0.5967583 | F3: 0.35694143 | G3: 1.4459149 | H3: 0.10615582 | I3: -0.67075329 | J3: 0.60096046 | K3: 1.5688765 | L3: 1.2418066 | M3: 0 | N3: 0 | O3: 0.33267031 | P3: 0 | Q3: 0.070231968 | R3: 0 | S3: 0 | T3: 0 | U3: 0 | V3: 0 | W3: 0 | X3: 0 | Y3: 0 | Z3: 0 | AA3: 0 | AB3: 0 | AC3: 0 | AD3: 0 | AE3: 0.13039267 | AF3: 5.0007746 | AH3: =K3 -> 1.5688765 | AI3: =Y3 -> 0 | AJ3: =Z3 -> 0 | AK3: =AA3 -> 0 | AL3: =AB3 -> 0 | AM3: =AC3 -> 0 | AN3: =AD3 -> 0 | AR3: =A3 -> 39263 | AS3: 0 | AT3: =AI3 -> 0 | AU3: =AJ3 -> 0 | AV3: =AK3 -> 0 | AW3: =AL3 -> 0 | AX3: =AM3 -> 0 | AY3: =AN3 -> 0 | BA3: =AR3 -> 39263 | BB3: =AS3 -> 0 | BC3: =#REF! -> #REF!
A4: 39355 | B4: -1.040355 | C4: 0.13425109 | D4: -0.14587387 | E4: 0.69031317 | F4: 0.37191894 | G4: 1.4503632 | H4: 0.31183503 | I4: -0.6798581 | J4: 0.61019793 | K4: 1.5086958 | L4: 1.1510338 | M4: 0 | N4: 0 | O4: 0.37118543 | P4: 0 | Q4: 0.037371485 | R4: 0 | S4: 0 | T4: 0 | U4: 0 | V4: 0 | W4: 0 | X4: 0 | Y4: 0 | Z4: 0 | AA4: 0 | AB4: 0 | AC4: 0 | AD4: 0 | AE4: 0.12978091 | AF4: 4.9008599 | AH4: =K4 -> 1.5086958 | AI4: =Y4 -> 0 | AJ4: =Z4 -> 0 | AK4: =AA4 -> 0 | AL4: =AB4 -> 0 | AM4: =AC4 -> 0 | AN4: =AD4 -> 0 | AR4: =A4 -> 39355 | AS4: 0 | AT4: =AI4 -> 0 | AU4: =AJ4 -> 0 | AV4: =AK4 -> 0 | AW4: =AL4 -> 0 | AX4: =AM4 -> 0 | AY4: =AN4 -> 0 | BA4: =AR4 -> 39355 | BB4: =AS4 -> 0 | BC4: =#REF! -> #REF!
A5: 39447 | B5: -0.99330901 | C5: 0.14258815 | D5: -0.26310356 | E5: 0.73768743 | F5: 0.36639612 | G5: 1.4317096 | H5: 0.21867959 | I5: -0.68920012 | J5: 0.66599438 | K5: 1.7274198 | L5: 1.0093212 | M5: 0 | N5: 0 | O5: 0.40724837 | P5: 0 | Q5: 0.016106972 | R5: 0 | S5: 0 | T5: 0 | U5: 0 | V5: 0 | W5: 0 | X5: 0 | Y5: 0 | Z5: 0 | AA5: 0 | AB5: 0 | AC5: 0 | AD5: 0 | AE5: 0.12916218 | AF5: 4.9067011 | AH5: =K5 -> 1.7274198 | AI5: =Y5 -> 0 | AJ5: =Z5 -> 0 | AK5: =AA5 -> 0 | AL5: =AB5 -> 0 | AM5: =AC5 -> 0 | AN5: =AD5 -> 0 | AR5: =A5 -> 39447 | AS5: 0 | AT5: =AI5 -> 0 | AU5: =AJ5 -> 0 | AV5: =AK5 -> 0 | AW5: =AL5 -> 0 | AX5: =AM5 -> 0 | AY5: =AN5 -> 0 | BA5: =AR5 -> 39447 | BB5: =AS5 -> 0 | BC5: =#REF! -> #REF!
A6: 39538 | B6: -1.0476842 | C6: 0.03061779 | D6: -0.40243934 | E6: 0.39311962 | F6: 0.33629364 | G6: 1.42832 | H6: 0.27379584 | I6: -0.67868028 | J6: 0.70115772 | K6: 2.0053504 | L6: 0.85487701 | M6: 0 | N6: 0 | O6: 0.44493982 | P6: 0 | Q6: -0.019590161 | R6: 0 | S6: 0 | T6: 0 | U6: 0 | V6: 0 | W6: 0 | X6: 0 | Y6: 0 | Z6: 0 | AA6: 0 | AB6: 0 | AC6: 0 | AD6: 0 | AE6: 0.12853685 | AF6: 4.4486148 | AH6: =K6 -> 2.0053504 | AI6: =Y6 -> 0 | AJ6: =Z6 -> 0 | AK6: =AA6 -> 0 | AL6: =AB6 -> 0 | AM6: =AC6 -> 0 | AN6: =AD6 -> 0 | AR6: =A6 -> 39538 | AS6: 0 | AT6: =AI6 -> 0 | AU6: =AJ6 -> 0 | AV6: =AK6 -> 0 | AW6: =AL6 -> 0 | AX6: =AM6 -> 0 | AY6: =AN6 -> 0 | BA6: =AR6 -> 39538 | BB6: =AS6 -> 0 | BC6: =#REF! -> #REF!
A7: 39629 | B7: -1.1086433 | C7: -0.033609602 | D7: -0.44750789 | E7: 0.09339584 | F7: 0.34011857 | G7: 1.4242313 | H7: 0.099730651 | I7: -0.64918611 | J7: 0.69311266 | K7: 2.3003353 | L7: 0.71023288 | M7: 0 | N7: 0 | O7: 0.48647302 | P7: 0 | Q7: -0.047607001 | R7: 0 | S7: 0 | T7: 0 | U7: 0 | V7: 0 | W7: 0 | X7: 0 | Y7: 0 | Z7: 0 | AA7: 0 | AB7: 0 | AC7: 0 | AD7: 0 | AE7: 0.12790526 | AF7: 3.9889816 | AH7: =K7 -> 2.3003353 | AI7: =Y7 -> 0 | AJ7: =Z7 -> 0 | AK7: =AA7 -> 0 | AL7: =AB7 -> 0 | AM7: =AC7 -> 0 | AN7: =AD7 -> 0 | AR7: =A7 -> 39629 | AS7: 0 | AT7: =AI7 -> 0 | AU7: =AJ7 -> 0 | AV7: =AK7 -> 0 | AW7: =AL7 -> 0 | AX7: =AM7 -> 0 | AY7: =AN7 -> 0 | BA7: =AR7 -> 39629 | BB7: =AS7 -> 0 | BC7: =#REF! -> #REF!
A8: 39721 | B8: -0.80373451 | C8: -0.20400532 | D8: -0.52579161 | E8: -0.37809506 | F8: 0.32715602 | G8: 1.4371073 | H8: 0.049769223 | I8: -0.6241057 | J8: 0.72601851 | K8: 1.9637541 | L8: 0.57993927 | M8: 0 | N8: 0 | O8: 0.49767707 | P8: 0 | Q8: -0.074978682 | R8: 0 | S8: 0 | T8: 0 | U8: 0 | V8: 0 | W8: 0 | X8: 0 | Y8: 0 | Z8: 0 | AA8: 0 | AB8: 0 | AC8: 0 | AD8: 0 | AE8: 0.12726775 | AF8: 3.0979785 | AH8: =K8 -> 1.9637541 | AI8: =Y8 -> 0 | AJ8: =Z8 -> 0 | AK8: =AA8 -> 0 | AL8: =AB8 -> 0 | AM8: =AC8 -> 0 | AN8: =AD8 -> 0 | AR8: =A8 -> 39721 | AS8: =AH8-$AH$8 -> 0 | AT8: =AI8 -> 0 | AU8: =AJ8 -> 0 | AV8: =AK8 -> 0 | AW8: =AL8 -> 0 | AX8: =AM8 -> 0 | AY8: =AN8 -> 0 | BA8: =AR8 -> 39721 | BB8: =AS8 -> 0 | BC8: =#REF! -> #REF!
A9: 39813 | B9: -0.21677727 | C9: -0.56638658 | D9: -0.87656555 | E9: -1.0760328 | F9: 0.163132 | G9: 1.567453 | H9: 0.77708187 | I9: -0.52720457 | J9: 0.77689645 | K9: 1.3356925 | L9: 0.32530383 | M9: 0 | N9: 0 | O9: 0.56267499 | P9: 0 | Q9: -0.12285996 | R9: 0 | S9: 0 | T9: 0 | U9: 0 | V9: 0 | W9: 0 | X9: 0 | Y9: -0.18334085 | Z9: -0.085809019 | AA9: -0.014995051 | AB9: -0.0025678522 | AC9: -0.0010749068 | AD9: -0.0015146036 | AE9: 0.12662465 | AF9: 1.9597303 | AH9: =K9 -> 1.3356925 | AI9: =Y9 -> -0.18334085 | AJ9: =Z9 -> -0.085809019 | AK9: =AA9 -> -0.014995051 | AL9: =AB9 -> -0.0025678522 | AM9: =AC9 -> -0.0010749068 | AN9: =AD9 -> -0.0015146036 | AR9: =A9 -> 39813 | AS9: =AH9-$AH$8 -> -0.62806164 | AT9: =AI9 -> -0.18334085 | AU9: =AJ9 -> -0.085809019 | AV9: =AK9 -> -0.014995051 | AW9: =AL9 -> -0.0025678522 | AX9: =AM9 -> -0.0010749068 | AY9: =AN9 -> -0.0015146036 | BA9: =AR9 -> 39813 | BB9: =AS9 -> -0.62806164 | BC9: =#REF! -> #REF!
A10: 39903 | B10: -0.13539004 | C10: -0.65246513 | D10: -0.91826335 | E10: -1.4441778 | F10: 0.115455 | G10: 1.5230468 | H10: 0.27896396 | I10: -0.40325188 | J10: 0.66681609 | K10: 0.39863999 | L10: 0.0012907793 | M10: 0 | N10: 0 | O10: 0.65980691 | P10: 0 | Q10: -0.15244255 | R10: 0 | S10: 0 | T10: 0 | U10: 0 | V10: 0 | W10: 0 | X10: 0 | Y10: -0.40182322 | Z10: -0.21133372 | AA10: -0.064564658 | AB10: -0.0076746478 | AC10: -0.0097111472 | AD10: -0.013463276 | AE10: 0.12597629 | AF10: -0.64456556 | AH10: =K10 -> 0.39863999 | AI10: =Y10 -> -0.40182322 | AJ10: =Z10 -> -0.21133372 | AK10: =AA10 -> -0.064564658 | AL10: =AB10 -> -0.0076746478 | AM10: =AC10 -> -0.0097111472 | AN10: =AD10 -> -0.013463276 | AR10: =A10 -> 39903 | AS10: =AH10-$AH$8 -> -1.5651141 | AT10: =AI10 -> -0.40182322 | AU10: =AJ10 -> -0.21133372 | AV10: =AK10 -> -0.064564658 | AW10: =AL10 -> -0.0076746478 | AX10: =AM10 -> -0.0097111472 | AY10: =AN10 -> -0.013463276 | BA10: =AR10 -> 39903 | BB10: =AS10 -> -1.5651141 | BC10: =#REF! -> #REF!
A11: 39994 | B11: -0.073128195 | C11: -0.59127453 | D11: -0.82556116 | E11: -1.5731642 | F11: 0.099746456 | G11: 1.4374342 | H11: -0.35522693 | I11: -0.28293943 | J11: 0.84351191 | K11: -0.30041232 | L11: -0.18272965 | M11: 0 | N11: 0 | O11: 0.6458429 | P11: 0 | Q11: -0.16787271 | R11: 0 | S11: 0 | T11: 0 | U11: 0 | V11: 0 | W11: 0 | X11: 0 | Y11: -0.51335586 | Z11: -0.31584038 | AA11: -0.13962108 | AB11: -0.03410106 | AC11: -0.016607341 | AD11: -0.041339223 | AE11: 0.12532296 | AF11: -2.2613156 | AH11: =K11 -> -0.30041232 | AI11: =Y11 -> -0.51335586 | AJ11: =Z11 -> -0.31584038 | AK11: =AA11 -> -0.13962108 | AL11: =AB11 -> -0.03410106 | AM11: =AC11 -> -0.016607341 | AN11: =AD11 -> -0.041339223 | AR11: =A11 -> 39994 | AS11: =AH11-$AH$8 -> -2.2641664 | AT11: =AI11 -> -0.51335586 | AU11: =AJ11 -> -0.31584038 | AV11: =AK11 -> -0.13962108 | AW11: =AL11 -> -0.03410106 | AX11: =AM11 -> -0.016607341 | AY11: =AN11 -> -0.041339223 | BA11: =AR11 -> 39994 | BB11: =AS11 -> -2.2641664 | BC11: =#REF! -> #REF!
A12: 40086 | B12: -0.53090932 | C12: -0.26450707 | D12: -0.67212326 | E12: -1.5028278 | F12: 0.069033869 | G12: 1.1961043 | H12: -0.54411897 | I12: -0.18186777 | J12: 0.89049329 | K12: -0.56877654 | L12: -0.18360036 | M12: 0 | N12: 0 | O12: 0.48885426 | P12: 0 | Q12: -0.2019199 | R12: 0 | S12: 0 | T12: 0 | U12: 0 | V12: 0 | W12: 0 | X12: 0 | Y12: -0.43225273 | Z12: -0.32122089 | AA12: -0.17245864 | AB12: -0.050099817 | AC12: -0.0204331 | AD12: -0.08404302 | AE12: 0.12466498 | AF12: -2.9620085 | AH12: =K12 -> -0.56877654 | AI12: =Y12 -> -0.43225273 | AJ12: =Z12 -> -0.32122089 | AK12: =AA12 -> -0.17245864 | AL12: =AB12 -> -0.050099817 | AM12: =AC12 -> -0.0204331 | AN12: =AD12 -> -0.08404302 | AR12: =A12 -> 40086 | AS12: =AH12-$AH$8 -> -2.5325307 | AT12: =AI12 -> -0.43225273 | AU12: =AJ12 -> -0.32122089 | AV12: =AK12 -> -0.17245864 | AW12: =AL12 -> -0.050099817 | AX12: =AM12 -> -0.0204331 | AY12: =AN12 -> -0.08404302 | BA12: =AR12 -> 40086 | BB12: =AS12 -> -2.5325307 | BC12: =#REF! -> #REF!
A13: 40178 | B13: -0.25242317 | C13: -0.21161538 | D13: -0.55513346 | E13: -1.5319895 | F13: 0.034934349 | G13: 0.99553621 | H13: -1.0349527 | I13: -0.1401452 | J13: 0.90746758 | K13: -1.1530786 | L13: -0.071269525 | M13: 0 | N13: 0 | O13: 0.29361464 | P13: 0 | Q13: -0.2238056 | R13: 0 | S13: 0 | T13: 0 | U13: 0 | V13: 0 | W13: 0 | X13: 0 | Y13: -0.35928238 | Z13: -0.28959157 | AA13: -0.22762518 | AB13: -0.069279424 | AC13: -0.028449793 | AD13: -0.14778106 | AE13: 0.12400264 | AF13: -3.9408671 | AH13: =K13 -> -1.1530786 | AI13: =Y13 -> -0.35928238 | AJ13: =Z13 -> -0.28959157 | AK13: =AA13 -> -0.22762518 | AL13: =AB13 -> -0.069279424 | AM13: =AC13 -> -0.028449793 | AN13: =AD13 -> -0.14778106 | AR13: =A13 -> 40178 | AS13: =AH13-$AH$8 -> -3.1168327 | AT13: =AI13 -> -0.35928238 | AU13: =AJ13 -> -0.28959157 | AV13: =AK13 -> -0.22762518 | AW13: =AL13 -> -0.069279424 | AX13: =AM13 -> -0.028449793 | AY13: =AN13 -> -0.14778106 | BA13: =AR13 -> 40178 | BB13: =AS13 -> -3.1168327 | BC13: =#REF! -> #REF!
A14: 40268 | B14: -0.33874738 | C14: -0.10632206 | D14: -0.44967817 | E14: -1.4913585 | F14: -0.010181156 | G14: 0.69241508 | H14: -0.74172809 | I14: -0.11958877 | J14: 0.84768893 | K14: -1.5087443 | L14: -0.0038602509 | M14: 0 | N14: 0 | O14: 0.19290541 | P14: 0 | Q14: -0.279538 | R14: 0 | S14: 0 | T14: 0 | U14: 0 | V14: 0 | W14: 0 | X14: 0 | Y14: -0.27734524 | Z14: -0.19522988 | AA14: -0.22127803 | AB14: -0.074980746 | AC14: -0.026938269 | AD14: -0.2361105 | AE14: 0.12333622 | AF14: -4.2252837 | AH14: =K14 -> -1.5087443 | AI14: =Y14 -> -0.27734524 | AJ14: =Z14 -> -0.19522988 | AK14: =AA14 -> -0.22127803 | AL14: =AB14 -> -0.074980746 | AM14: =AC14 -> -0.026938269 | AN14: =AD14 -> -0.2361105 | AR14: =A14 -> 40268 | AS14: =AH14-$AH$8 -> -3.4724984 | AT14: =AI14 -> -0.27734524 | AU14: =AJ14 -> -0.19522988 | AV14: =AK14 -> -0.22127803 | AW14: =AL14 -> -0.074980746 | AX14: =AM14 -> -0.026938269 | AY14: =AN14 -> -0.2361105 | BA14: =AR14 -> 40268 | BB14: =AS14 -> -3.4724984 | BC14: =#REF! -> #REF!
A15: 40359 | B15: -0.35320502 | C15: 0.1284906 | D15: -0.48133731 | E15: -1.2669877 | F15: -0.1610503 | G15: 0.44814344 | H15: -0.50176464 | I15: -0.1039252 | J15: 0.89953939 | K15: -1.4722494 | L15: 0.12890494 | M15: 0 | N15: 0 | O15: 0.031533582 | P15: 0 | Q15: -0.34419421 | R15: 0 | S15: 0 | T15: 0 | U15: 0 | V15: 0 | W15: 0 | X15: 0 | Y15: -0.10109961 | Z15: -0.059472477 | AA15: -0.12320261 | AB15: -0.036630312 | AC15: 0.010559019 | AD15: -0.33688892 | AE15: 0.122666 | AF15: -3.5721707 | AH15: =K15 -> -1.4722494 | AI15: =Y15 -> -0.10109961 | AJ15: =Z15 -> -0.059472477 | AK15: =AA15 -> -0.12320261 | AL15: =AB15 -> -0.036630312 | AM15: =AC15 -> 0.010559019 | AN15: =AD15 -> -0.33688892 | AR15: =A15 -> 40359 | AS15: =AH15-$AH$8 -> -3.4360035 | AT15: =AI15 -> -0.10109961 | AU15: =AJ15 -> -0.059472477 | AV15: =AK15 -> -0.12320261 | AW15: =AL15 -> -0.036630312 | AX15: =AM15 -> 0.010559019 | AY15: =AN15 -> -0.33688892 | BA15: =AR15 -> 40359 | BB15: =AS15 -> -3.4360035 | BC15: =#REF! -> #REF!
A16: 40451 | B16: -0.18159418 | C16: 0.13350859 | D16: -0.52650157 | E16: -1.0309365 | F16: -0.24665644 | G16: 0.16785317 | H16: -0.67012212 | I16: -0.076108514 | J16: 0.9217927 | K16: -1.59298 | L16: 0.15284787 | M16: 0 | N16: 0 | O16: -0.052534263 | P16: 0 | Q16: -0.37563281 | R16: 0 | S16: 0 | T16: 0 | U16: 0 | V16: 0 | W16: 0 | X16: 0 | Y16: -0.013065689 | Z16: 0.033369509 | AA16: -0.038560426 | AB16: 0.0060221368 | AC16: 0.061731846 | AD16: -0.44696724 | AE16: 0.12199225 | AF16: -3.6525417 | AH16: =K16 -> -1.59298 | AI16: =Y16 -> -0.013065689 | AJ16: =Z16 -> 0.033369509 | AK16: =AA16 -> -0.038560426 | AL16: =AB16 -> 0.0060221368 | AM16: =AC16 -> 0.061731846 | AN16: =AD16 -> -0.44696724 | AR16: =A16 -> 40451 | AS16: =AH16-$AH$8 -> -3.5567341 | AT16: =AI16 -> -0.013065689 | AU16: =AJ16 -> 0.033369509 | AV16: =AK16 -> -0.038560426 | AW16: =AL16 -> 0.0060221368 | AX16: =AM16 -> 0.061731846 | AY16: =AN16 -> -0.44696724 | BA16: =AR16 -> 40451 | BB16: =AS16 -> -3.5567341 | BC16: =#REF! -> #REF!
A17: 40543 | B17: -0.67462173 | C17: 0.071741193 | D17: -0.53275634 | E17: -0.81967091 | F17: -0.27434821 | G17: -0.032583 | H17: -0.60380231 | I17: -0.073918489 | J17: 0.92659326 | K17: -1.7387402 | L17: 0.23867936 | M17: 0 | N17: 0 | O17: -0.13992718 | P17: 0 | Q17: -0.40801408 | R17: 0 | S17: 0 | T17: 0 | U17: 0 | V17: 0 | W17: 0 | X17: 0 | Y17: 0.029830564 | Z17: 0.098258457 | AA17: 0.048896882 | AB17: 0.052191984 | AC17: 0.10898808 | AD17: -0.55805791 | AE17: 0.12131523 | AF17: -4.1599454 | AH17: =K17 -> -1.7387402 | AI17: =Y17 -> 0.029830564 | AJ17: =Z17 -> 0.098258457 | AK17: =AA17 -> 0.048896882 | AL17: =AB17 -> 0.052191984 | AM17: =AC17 -> 0.10898808 | AN17: =AD17 -> -0.55805791 | AR17: =A17 -> 40543 | AS17: =AH17-$AH$8 -> -3.7024944 | AT17: =AI17 -> 0.029830564 | AU17: =AJ17 -> 0.098258457 | AV17: =AK17 -> 0.048896882 | AW17: =AL17 -> 0.052191984 | AX17: =AM17 -> 0.10898808 | AY17: =AN17 -> -0.55805791 | BA17: =AR17 -> 40543 | BB17: =AS17 -> -3.7024944 | BC17: =#REF! -> #REF!
A18: 40633 | B18: -0.93230197 | C18: 0.039774018 | D18: -0.44687427 | E18: -0.83190869 | F18: -0.28233932 | G18: -0.29215817 | H18: -0.18609297 | I18: -0.088269937 | J18: 1.0024035 | K18: -1.6968653 | L18: 0.26709511 | M18: 0 | N18: 0 | O18: -0.21240008 | P18: 0 | Q18: -0.43294472 | R18: 0 | S18: 0 | T18: 0 | U18: 0 | V18: 0 | W18: 0 | X18: 0 | Y18: 0.032516825 | Z18: 0.10590467 | AA18: 0.097443157 | AB18: 0.087569484 | AC18: 0.16036278 | AD18: -0.65569136 | AE18: 0.12063519 | AF18: -4.1441421 | AH18: =K18 -> -1.6968653 | AI18: =Y18 -> 0.032516825 | AJ18: =Z18 -> 0.10590467 | AK18: =AA18 -> 0.097443157 | AL18: =AB18 -> 0.087569484 | AM18: =AC18 -> 0.16036278 | AN18: =AD18 -> -0.65569136 | AR18: =A18 -> 40633 | AS18: =AH18-$AH$8 -> -3.6606194 | AT18: =AI18 -> 0.032516825 | AU18: =AJ18 -> 0.10590467 | AV18: =AK18 -> 0.097443157 | AW18: =AL18 -> 0.087569484 | AX18: =AM18 -> 0.16036278 | AY18: =AN18 -> -0.65569136 | BA18: =AR18 -> 40633 | BB18: =AS18 -> -3.6606194 | BC18: =#REF! -> #REF!
A19: 40724 | B19: -0.90587513 | C19: 0.098363709 | D19: -0.48611675 | E19: -0.71317116 | F19: -0.33380644 | G19: -0.50539638 | H19: -0.3271888 | I19: -0.14068208 | J19: 0.93559777 | K19: -1.6665226 | L19: 0.37356818 | M19: 0 | N19: 0 | O19: -0.28612682 | P19: 0 | Q19: -0.5059314 | R19: 0 | S19: 0 | T19: 0 | U19: 0 | V19: 0 | W19: 0 | X19: 0 | Y19: 0.1010403 | Z19: 0.14363434 | AA19: 0.15678932 | AB19: 0.13734152 | AC19: 0.24024031 | AD19: -0.72192533 | AE19: 0.11995239 | AF19: -4.286215 | AH19: =K19 -> -1.6665226 | AI19: =Y19 -> 0.1010403 | AJ19: =Z19 -> 0.14363434 | AK19: =AA19 -> 0.15678932 | AL19: =AB19 -> 0.13734152 | AM19: =AC19 -> 0.24024031 | AN19: =AD19 -> -0.72192533 | AR19: =A19 -> 40724 | AS19: =AH19-$AH$8 -> -3.6302767 | AT19: =AI19 -> 0.1010403 | AU19: =AJ19 -> 0.14363434 | AV19: =AK19 -> 0.15678932 | AW19: =AL19 -> 0.13734152 | AX19: =AM19 -> 0.24024031 | AY19: =AN19 -> -0.72192533 | BA19: =AR19 -> 40724 | BB19: =AS19 -> -3.6302767 | BC19: =#REF! -> #REF!
... A132: 51043 | B132: -1.1485256 | C132: 0.00012590441 | D132: -0.042684349 | E132: -0.00047395337 | F132: 0.10831097 | G132: -0.17615887 | H132: 0.054636968 | I132: 0.15047017 | J132: 0.26718227 | K132: 0.0018162856 | L132: 0.37632535 | M132: 0 | N132: 0 | O132: 0.54539942 | P132: 0 | Q132: -0.20667783 | R132: 0 | S132: 0 | T132: 0 | U132: 0 | V132: 0 | W132: 0 | X132: 0 | Y132: -0.0016294185 | Z132: 0.0019674278 | AA132: -0.00054863095 | AB132: 0.00047969275 | AC132: -0.0015716835 | AD132: -0.0046451761 | AE132: 0.053433982 | AF132: -0.022767062 | AH132: =K132 -> 0.0018162856 | AI132: =Y132 -> -0.0016294185 | AJ132: =Z132 -> 0.0019674278 | AK132: =AA132 -> -0.00054863095 | AL132: =AB132 -> 0.00047969275 | AM132: =AC132 -> -0.0015716835 | AN132: =AD132 -> -0.0046451761 | AR132: =A132 -> 51043 | AS132: =AH132-$AH$8 -> -1.9619378 | AT132: =AI132 -> -0.0016294185 | AU132: =AJ132 -> 0.0019674278 | AV132: =AK132 -> -0.00054863095 | AW132: =AL132 -> 0.00047969275 | AX132: =AM132 -> -0.0015716835 | AY132: =AN132 -> -0.0046451761 | BA132: =AR132 -> 51043 | BB132: =AS132 -> -1.9619378 | BC132: =#REF! -> #REF!

Sheet US_nominal_obs_with_text
A1: date | B1: g_sh | C1: b_liqtil_sh | D1: b_liqp_sh | E1: b_safetil_sh | F1: b_safep_sh | G1: mu_sh | H1: z_sh | I1: lambda_f_sh | J1: lambda_w_sh | K1: rm_sh | L1: sigma_omega_sh | M1: mu_e_sh | N1: gamma_sh | O1: pi_star_sh | P1: lr_sh | Q1: zp_sh | R1: tfp_sh | S1: gdpdef_sh | T1: corepce_sh | U1: gdp_sh | V1: gdi_sh | W1: BBB_sh | X1: AAA_sh | Y1: rm_shl1 | Z1: rm_shl2 | AA1: rm_shl3 | AB1: rm_shl4 | AC1: rm_shl5 | AD1: rm_shl6 | AE1: dettrend | AF1: detrendedMean | AH1: rm_sh | AI1: =Y1 -> rm_shl1 | AJ1: =Z1 -> rm_shl2 | AK1: =AA1 -> rm_shl3 | AL1: =AB1 -> rm_shl4 | AM1: =AC1 -> rm_shl5 | AN1: =AD1 -> rm_shl6 | AQ1: Plot | AR1: =A1 -> date | AS1: =AF1 -> detrendedMean | AT1: Monetary Policy | AU1: Combined FG | AV1: FG1 | AW1: FG2 | AX1: FG3 | AY1: FG4 | AZ1: FG5 | BA1: FG6 | BC1: date | BD1: rm_sh | BE1: Fgsum
A2: 39172 | B2: -0.11401048 | C2: 0.20535128 | D2: -0.30209741 | E2: 0.8474755 | F2: 0.90070432 | G2: 0.041937669 | H2: 0.80119869 | I2: 0.5101117 | J2: -1.027226 | K2: -1.0879287 | L2: 0.1797764 | M2: 0 | N2: 0 | O2: 0.56068505 | P2: 0 | Q2: 0.069366088 | R2: 0 | S2: 0 | T2: 0 | U2: 0 | V2: 0 | W2: 0 | X2: 0 | Y2: 0 | Z2: 0 | AA2: 0 | AB2: 0 | AC2: 0 | AD2: 0 | AE2: -0.23818946 | AF2: 1.3471547 | AH2: =K2 -> -1.0879287 | AI2: =Y2 -> 0 | AJ2: =Z2 -> 0 | AK2: =AA2 -> 0 | AL2: =AB2 -> 0 | AM2: =AC2 -> 0 | AN2: =AD2 -> 0 | AR2: =A2 -> 39172 | AS2: =AF2*4+2 -> 7.3886186 | AT2: =AH2 -> -1.0879287 | AU2: =SUM(AV2:BA2) -> 0 | AV2: =AI2 -> 0 | AW2: =AJ2 -> 0 | AX2: =AK2 -> 0 | AY2: =AL2 -> 0 | AZ2: =AM2 -> 0 | BA2: =AN2 -> 0 | BC2: =AR2 -> 39172 | BD2: =AT2 -> -1.0879287 | BE2: =AU2 -> 0
A3: 39263 | B3: -0.0829638 | C3: 0.1979316 | D3: -0.30632052 | E3: 0.84832418 | F3: 0.93236416 | G3: 0.051456625 | H3: 0.50404739 | I3: 0.45107844 | J3: -1.1432998 | K3: -0.57113226 | L3: 0.129534 | M3: 0 | N3: 0 | O3: 0.56999491 | P3: 0 | Q3: 0.0021416526 | R3: 0 | S3: 0 | T3: 0 | U3: 0 | V3: 0 | W3: 0 | X3: 0 | Y3: 0 | Z3: 0 | AA3: 0 | AB3: 0 | AC3: 0 | AD3: 0 | AE3: -0.23600196 | AF3: 1.3471547 | AH3: =K3 -> -0.57113226 | AI3: =Y3 -> 0 | AJ3: =Z3 -> 0 | AK3: =AA3 -> 0 | AL3: =AB3 -> 0 | AM3: =AC3 -> 0 | AN3: =AD3 -> 0 | AR3: =A3 -> 39263 | AS3: =AF3*4+2 -> 7.3886186 | AT3: =AH3 -> -0.57113226 | AU3: =SUM(AV3:BA3) -> 0 | AV3: =AI3 -> 0 | AW3: =AJ3 -> 0 | AX3: =AK3 -> 0 | AY3: =AL3 -> 0 | AZ3: =AM3 -> 0 | BA3: =AN3 -> 0 | BC3: =AR3 -> 39263 | BD3: =AT3 -> -0.57113226 | BE3: =AU3 -> 0
A4: 39355 | B4: -0.15392337 | C4: 0.16990305 | D4: -0.44946874 | E4: 0.9398166 | F4: 0.95374823 | G4: 0.063708809 | H4: 0.61741563 | I4: 0.42669807 | J4: -1.2125307 | K4: -0.64943507 | L4: 0.11571594 | M4: 0 | N4: 0 | O4: 0.61141748 | P4: 0 | Q4: -0.032081448 | R4: 0 | S4: 0 | T4: 0 | U4: 0 | V4: 0 | W4: 0 | X4: 0 | Y4: 0 | Z4: 0 | AA4: 0 | AB4: 0 | AC4: 0 | AD4: 0 | AE4: -0.23382987 | AF4: 1.1671547 | AH4: =K4 -> -0.64943507 | AI4: =Y4 -> 0 | AJ4: =Z4 -> 0 | AK4: =AA4 -> 0 | AL4: =AB4 -> 0 | AM4: =AC4 -> 0 | AN4: =AD4 -> 0 | AR4: =A4 -> 39355 | AS4: =AF4*4+2 -> 6.6686186 | AT4: =AH4 -> -0.64943507 | AU4: =SUM(AV4:BA4) -> 0 | AV4: =AI4 -> 0 | AW4: =AJ4 -> 0 | AX4: =AK4 -> 0 | AY4: =AL4 -> 0 | AZ4: =AM4 -> 0 | BA4: =AN4 -> 0 | BC4: =AR4 -> 39355 | BD4: =AT4 -> -0.64943507 | BE4: =AU4 -> 0
A5: 39447 | B5: -0.15363652 | C5: 0.17558103 | D5: -0.630747 | E5: 0.96697803 | F5: 0.94364037 | G5: 0.062024371 | H5: 0.59346198 | I5: 0.45002707 | J5: -1.1937889 | K5: -1.0906308 | L5: 0.088389876 | M5: 0 | N5: 0 | O5: 0.64479227 | P5: 0 | Q5: -0.027263892 | R5: 0 | S5: 0 | T5: 0 | U5: 0 | V5: 0 | W5: 0 | X5: 0 | Y5: 0 | Z5: 0 | AA5: 0 | AB5: 0 | AC5: 0 | AD5: 0 | AE5: -0.23167323 | AF5: 0.59715465 | AH5: =K5 -> -1.0906308 | AI5: =Y5 -> 0 | AJ5: =Z5 -> 0 | AK5: =AA5 -> 0 | AL5: =AB5 -> 0 | AM5: =AC5 -> 0 | AN5: =AD5 -> 0 | AR5: =A5 -> 39447 | AS5: =AF5*4+2 -> 4.3886186 | AT5: =AH5 -> -1.0906308 | AU5: =SUM(AV5:BA5) -> 0 | AV5: =AI5 -> 0 | AW5: =AJ5 -> 0 | AX5: =AK5 -> 0 | AY5: =AL5 -> 0 | AZ5: =AM5 -> 0 | BA5: =AN5 -> 0 | BC5: =AR5 -> 39447 | BD5: =AT5 -> -1.0906308 | BE5: =AU5 -> 0
A6: 39538 | B6: -0.17654154 | C6: 0.014279886 | D6: -0.84968192 | E6: 0.45145768 | F6: 0.89491982 | G6: 0.049151621 | H6: 0.65422473 | I6: 0.36489 | J6: -1.1859989 | K6: -1.3356229 | L6: 0.025228524 | M6: 0 | N6: 0 | O6: 0.67497521 | P6: 0 | Q6: -0.074595448 | R6: 0 | S6: 0 | T6: 0 | U6: 0 | V6: 0 | W6: 0 | X6: 0 | Y6: 0 | Z6: 0 | AA6: 0 | AB6: 0 | AC6: 0 | AD6: 0 | AE6: -0.22953208 | AF6: -0.72284535 | AH6: =K6 -> -1.3356229 | AI6: =Y6 -> 0 | AJ6: =Z6 -> 0 | AK6: =AA6 -> 0 | AL6: =AB6 -> 0 | AM6: =AC6 -> 0 | AN6: =AD6 -> 0 | AR6: =A6 -> 39538 | AS6: =AF6*4+2 -> -0.89138139 | AT6: =AH6 -> -1.3356229 | AU6: =SUM(AV6:BA6) -> 0 | AV6: =AI6 -> 0 | AW6: =AJ6 -> 0 | AX6: =AK6 -> 0 | AY6: =AL6 -> 0 | AZ6: =AM6 -> 0 | BA6: =AN6 -> 0 | BC6: =AR6 -> 39538 | BD6: =AT6 -> -1.3356229 | BE6: =AU6 -> 0
A7: 39629 | B7: -0.20191707 | C7: -0.072830785 | D7: -0.92562239 | E7: 0.024837465 | F7: 0.89781248 | G7: 0.039769291 | H7: 0.5553546 | I7: 0.2809677 | J7: -1.2640069 | K7: -1.497997 | L7: -0.053407566 | M7: 0 | N7: 0 | O7: 0.70510088 | P7: 0 | Q7: -0.083499592 | R7: 0 | S7: 0 | T7: 0 | U7: 0 | V7: 0 | W7: 0 | X7: 0 | Y7: 0 | Z7: 0 | AA7: 0 | AB7: 0 | AC7: 0 | AD7: 0 | AE7: -0.22740646 | AF7: -1.8228453 | AH7: =K7 -> -1.497997 | AI7: =Y7 -> 0 | AJ7: =Z7 -> 0 | AK7: =AA7 -> 0 | AL7: =AB7 -> 0 | AM7: =AC7 -> 0 | AN7: =AD7 -> 0 | AR7: =A7 -> 39629 | AS7: =AF7*4+2 -> -5.2913814 | AT7: =AH7 -> -1.497997 | AU7: =SUM(AV7:BA7) -> 0 | AV7: =AI7 -> 0 | AW7: =AJ7 -> 0 | AX7: =AK7 -> 0 | AY7: =AL7 -> 0 | AZ7: =AM7 -> 0 | BA7: =AN7 -> 0 | BC7: =AR7 -> 39629 | BD7: =AT7 -> -1.497997 | BE7: =AU7 -> 0
A8: 39721 | B8: -0.089411128 | C8: -0.30391018 | D8: -1.0525338 | E8: -0.62106526 | F8: 0.87518085 | G8: 0.032332229 | H8: 0.50940327 | I8: 0.31075263 | J8: -1.2818167 | K8: -0.60798148 | L8: -0.12702577 | M8: 0 | N8: 0 | O8: 0.70140354 | P8: 0 | Q8: -0.082877244 | R8: 0 | S8: 0 | T8: 0 | U8: 0 | V8: 0 | W8: 0 | X8: 0 | Y8: 0 | Z8: 0 | AA8: 0 | AB8: 0 | AC8: 0 | AD8: 0 | AE8: -0.22529638 | AF8: -1.9628453 | AH8: =K8 -> -0.60798148 | AI8: =Y8 -> 0 | AJ8: =Z8 -> 0 | AK8: =AA8 -> 0 | AL8: =AB8 -> 0 | AM8: =AC8 -> 0 | AN8: =AD8 -> 0 | AR8: =A8 -> 39721 | AS8: =AF8*4+2 -> -5.8513814 | AT8: =AH8 -> -0.60798148 | AU8: =SUM(AV8:BA8) -> 0 | AV8: =AI8 -> 0 | AW8: =AJ8 -> 0 | AX8: =AK8 -> 0 | AY8: =AL8 -> 0 | AZ8: =AM8 -> 0 | BA8: =AN8 -> 0 | BC8: =AR8 -> 39721 | BD8: =AT8 -> -0.60798148 | BE8: =AU8 -> 0
A9: 39813 | B9: 0.13485818 | C9: -0.79217761 | D9: -1.6043944 | E9: -1.5547182 | F9: 0.61745713 | G9: 0.036130617 | H9: 1.0808468 | I9: -0.041293101 | J9: -1.2454774 | K9: 0.12813139 | L9: -0.1382118 | M9: 0 | N9: 0 | O9: 0.75204073 | P9: 0 | Q9: -0.13766645 | R9: 0 | S9: 0 | T9: 0 | U9: 0 | V9: 0 | W9: 0 | X9: 0 | Y9: -0.25638525 | Z9: -0.12030565 | AA9: -0.021104289 | AB9: -0.0036357936 | AC9: -0.0015368701 | AD9: -0.0022014941 | AE9: -0.22320187 | AF9: -3.3928453 | AH9: =K9 -> 0.12813139 | AI9: =Y9 -> -0.25638525 | AJ9: =Z9 -> -0.12030565 | AK9: =AA9 -> -0.021104289 | AL9: =AB9 -> -0.0036357936 | AM9: =AC9 -> -0.0015368701 | AN9: =AD9 -> -0.0022014941 | AR9: =A9 -> 39813 | AS9: =AF9*4+2 -> -11.571381 | AT9: =AH9 -> 0.12813139 | AU9: =SUM(AV9:BA9) -> -0.40516934 | AV9: =AI9 -> -0.25638525 | AW9: =AJ9 -> -0.12030565 | AX9: =AK9 -> -0.021104289 | AY9: =AL9 -> -0.0036357936 | AZ9: =AM9 -> -0.0015368701 | BA9: =AN9 -> -0.0022014941 | BC9: =AR9 -> 39813 | BD9: =AT9 -> 0.12813139 | BE9: =AU9 -> -0.40516934
A10: 39903 | B10: 0.16168339 | C10: -0.87584388 | D10: -1.6876661 | E10: -1.9921387 | F10: 0.53457376 | G10: 0.07776 | H10: 0.8672465 | I10: -0.18521718 | J10: -1.5674078 | K10: 0.96091862 | L10: -0.21059841 | M10: 0 | N10: 0 | O10: 0.83058518 | P10: 0 | Q10: -0.10143052 | R10: 0 | S10: 0 | T10: 0 | U10: 0 | V10: 0 | W10: 0 | X10: 0 | Y10: 0.11106692 | Z10: -0.29123047 | AA10: -0.089995246 | AB10: -0.010718854 | AC10: -0.013823975 | AD10: -0.019485595 | AE10: -0.22112295 | AF10: -3.7228453 | AH10: =K10 -> 0.96091862 | AI10: =Y10 -> 0.11106692 | AJ10: =Z10 -> -0.29123047 | AK10: =AA10 -> -0.089995246 | AL10: =AB10 -> -0.010718854 | AM10: =AC10 -> -0.013823975 | AN10: =AD10 -> -0.019485595 | AR10: =A10 -> 39903 | AS10: =AF10*4+2 -> -12.891381 | AT10: =AH10 -> 0.96091862 | AU10: =SUM(AV10:BA10) -> -0.31418722 | AV10: =AI10 -> 0.11106692 | AW10: =AJ10 -> -0.29123047 | AX10: =AK10 -> -0.089995246 | AY10: =AL10 -> -0.010718854 | AZ10: =AM10 -> -0.013823975 | BA10: =AN10 -> -0.019485595 | BC10: =AR10 -> 39903 | BD10: =AT10 -> 0.96091862 | BE10: =AU10 -> -0.31418722
A11: 39994 | B11: 0.14543892 | C11: -0.75459901 | D11: -1.5585879 | E11: -2.0853044 | F11: 0.50176509 | G11: 0.062438847 | H11: 0.35467143 | I11: -0.18173936 | J11: -1.3758204 | K11: 1.0274072 | L11: -0.39438341 | M11: 0 | N11: 0 | O11: 0.79029194 | P11: 0 | Q11: -0.013172518 | R11: 0 | S11: 0 | T11: 0 | U11: 0 | V11: 0 | W11: 0 | X11: 0 | Y11: 0.33599819 | Z11: -0.036183899 | AA11: -0.19193871 | AB11: -0.047698813 | AC11: -0.023130777 | AD11: -0.059238196 | AE11: -0.21905963 | AF11: -3.7228453 | AH11: =K11 -> 1.0274072 | AI11: =Y11 -> 0.33599819 | AJ11: =Z11 -> -0.036183899 | AK11: =AA11 -> -0.19193871 | AL11: =AB11 -> -0.047698813 | AM11: =AC11 -> -0.023130777 | AN11: =AD11 -> -0.059238196 | AR11: =A11 -> 39994 | AS11: =AF11*4+2 -> -12.891381 | AT11: =AH11 -> 1.0274072 | AU11: =SUM(AV11:BA11) -> -0.022192205 | AV11: =AI11 -> 0.33599819 | AW11: =AJ11 -> -0.036183899 | AX11: =AK11 -> -0.19193871 | AY11: =AL11 -> -0.047698813 | AZ11: =AM11 -> -0.023130777 | BA11: =AN11 -> -0.059238196 | BC11: =AR11 -> 39994 | BD11: =AT11 -> 1.0274072 | BE11: =AU11 -> -0.022192205
A12: 40086 | B12: -0.062353511 | C12: -0.27312012 | D12: -1.3292818 | E12: -1.9060385 | F12: 0.44642715 | G12: 0.012925012 | H12: 0.080859986 | I12: -0.15167571 | J12: -1.3163403 | K12: 0.56616084 | L12: -0.54183291 | M12: 0 | N12: 0 | O12: 0.61082403 | P12: 0 | Q12: 0.0016531346 | R12: 0 | S12: 0 | T12: 0 | U12: 0 | V12: 0 | W12: 0 | X12: 0 | Y12: 0.41404851 | Z12: 0.26792166 | AA12: -0.14115197 | AB12: -0.068417176 | AC12: -0.027625262 | AD12: -0.11881657 | AE12: -0.21701192 | AF12: -3.7528453 | AH12: =K12 -> 0.56616084 | AI12: =Y12 -> 0.41404851 | AJ12: =Z12 -> 0.26792166 | AK12: =AA12 -> -0.14115197 | AL12: =AB12 -> -0.068417176 | AM12: =AC12 -> -0.027625262 | AN12: =AD12 -> -0.11881657 | AR12: =A12 -> 40086 | AS12: =AF12*4+2 -> -13.011381 | AT12: =AH12 -> 0.56616084 | AU12: =SUM(AV12:BA12) -> 0.32595919 | AV12: =AI12 -> 0.41404851 | AW12: =AJ12 -> 0.26792166 | AX12: =AK12 -> -0.14115197 | AY12: =AL12 -> -0.068417176 | AZ12: =AM12 -> -0.027625262 | BA12: =AN12 -> -0.11881657 | BC12: =AR12 -> 40086 | BD12: =AT12 -> 0.56616084 | BE12: =AU12 -> 0.32595919
A13: 40178 | B13: 0.00050746881 | C13: -0.19682351 | D13: -1.1508529 | E13: -1.8816935 | F13: 0.38547561 | G13: -0.095120943 | H13: -0.39911134 | I13: 0.063178418 | J13: -1.2794913 | K13: 1.0641138 | L13: -0.57081218 | M13: 0 | N13: 0 | O13: 0.41206864 | P13: 0 | Q13: 0.055765932 | R13: 0 | S13: 0 | T13: 0 | U13: 0 | V13: 0 | W13: 0 | X13: 0 | Y13: 0.019309171 | Z13: 0.3039599 | AA13: 0.017642377 | AB13: -0.071919374 | AC13: -0.037899564 | AD13: -0.20616227 | AE13: -0.2149798 | AF13: -3.7828453 | AH13: =K13 -> 1.0641138 | AI13: =Y13 -> 0.019309171 | AJ13: =Z13 -> 0.3039599 | AK13: =AA13 -> 0.017642377 | AL13: =AB13 -> -0.071919374 | AM13: =AC13 -> -0.037899564 | AN13: =AD13 -> -0.20616227 | AR13: =A13 -> 40178 | AS13: =AF13*4+2 -> -13.131381 | AT13: =AH13 -> 1.0641138 | AU13: =SUM(AV13:BA13) -> 0.024930243 | AV13: =AI13 -> 0.019309171 | AW13: =AJ13 -> 0.3039599 | AX13: =AK13 -> 0.017642377 | AY13: =AL13 -> -0.071919374 | AZ13: =AM13 -> -0.037899564 | BA13: =AN13 -> -0.20616227 | BC13: =AR13 -> 40178 | BD13: =AT13 -> 1.0641138 | BE13: =AU13 -> 0.024930243
... A132: 51043 | B132: -0.15667678 | C132: -0.0002117682 | D132: -0.16260993 | E132: -5.0202682e-05 | F132: 0.2514027 | G132: 0.011259126 | H132: 0.073990792 | I132: -0.15141055 | J132: -0.28232529 | K132: -0.0012069852 | L132: -0.0052149979 | M132: 0 | N132: 0 | O132: 0.40992744 | P132: 0 | Q132: 0.15161488 | R132: 0 | S132: 0 | T132: 0 | U132: 0 | V132: 0 | W132: 0 | X132: 0 | Y132: 0.0017353699 | Z132: -0.0014038441 | AA132: 0.00070264928 | AB132: -0.00022776197 | AC132: 0.001659447 | AD132: 0.0040525021 | AE132: -0.066359325 | AF132: 0.078647472 | AH132: =K132 -> -0.0012069852 | AI132: =Y132 -> 0.0017353699 | AJ132: =Z132 -> -0.0014038441 | AK132: =AA132 -> 0.00070264928 | AL132: =AB132 -> -0.00022776197 | AM132: =AC132 -> 0.001659447 | AN132: =AD132 -> 0.0040525021 | AR132: =A132 -> 51043 | AS132: =AF132*4+2 -> 2.3145899 | AT132: =AH132 -> -0.0012069852 | AU132: =SUM(AV132:BA132) -> 0.0065183623 | AV132: =AI132 -> 0.0017353699 | AW132: =AJ132 -> -0.0014038441 | AX132: =AK132 -> 0.00070264928 | AY132: =AL132 -> -0.00022776197 | AZ132: =AM132 -> 0.001659447 | BA132: =AN132 -> 0.0040525021 | BC132: =AR132 -> 51043 | BD132: =AT132 -> -0.0012069852 | BE132: =AU132 -> 0.0065183623

Sheet US_output_with_text_backup
A1: date | B1: g_sh | C1: b_liqtil_sh | D1: b_liqp_sh | E1: b_safetil_sh | F1: b_safep_sh | G1: mu_sh | H1: z_sh | I1: lambda_f_sh | J1: lambda_w_sh | K1: rm_sh | L1: sigma_omega_sh | M1: mu_e_sh | N1: gamma_sh | O1: pi_star_sh | P1: lr_sh | Q1: zp_sh | R1: tfp_sh | S1: gdpdef_sh | T1: corepce_sh | U1: gdp_sh | V1: gdi_sh | W1: BBB_sh | X1: AAA_sh | Y1: rm_shl1 | Z1: rm_shl2 | AA1: rm_shl3 | AB1: rm_shl4 | AC1: rm_shl5 | AD1: rm_shl6 | AE1: dettrend | AF1: detrendedMean | AH1: rm_sh | AI1: =Y1 -> rm_shl1 | AJ1: =Z1 -> rm_shl2 | AK1: =AA1 -> rm_shl3 | AL1: =AB1 -> rm_shl4 | AM1: =AC1 -> rm_shl5 | AN1: =AD1 -> rm_shl6 | AQ1: Plot | AR1: =A1 -> date | AS1: =AF1 -> detrendedMean | AT1: Monetary Policy | AU1: Fgsum | AV1: FG1 | AW1: FG2 | AX1: FG3 | AY1: FG4 | AZ1: FG5 | BA1: FG6 | BC1: date | BD1: rm_sh | BE1: Fgsum
A2: 39172 | B2: -1.0215877 | C2: 0.14738424 | D2: -0.044907453 | E2: 0.56515568 | F2: 0.33471877 | G2: 1.4053436 | H2: 0.54693072 | I2: -0.65393335 | J2: 0.64232717 | K2: 1.7750614 | L2: 1.2826525 | M2: 0 | N2: 0 | O2: 0.3278555 | P2: 0 | Q2: 0.11087454 | R2: 0 | S2: 0 | T2: 0 | U2: 0 | V2: 0 | W2: 0 | X2: 0 | Y2: 0 | Z2: 0 | AA2: 0 | AB2: 0 | AC2: 0 | AD2: 0 | AE2: 0.13099711 | AF2: 5.5488727 | AH2: =K2 -> 1.7750614 | AI2: =Y2 -> 0 | AJ2: =Z2 -> 0 | AK2: =AA2 -> 0 | AL2: =AB2 -> 0 | AM2: =AC2 -> 0 | AN2: =AD2 -> 0 | AR2: =A2 -> 39172 | AS2: =AF2*4+2 -> 24.195491 | AT2: =AH2 -> 1.7750614 | AU2: =SUM(AV2:BA2) -> 0 | AV2: =AI2 -> 0 | AW2: =AJ2 -> 0 | AX2: =AK2 -> 0 | AY2: =AL2 -> 0 | AZ2: =AM2 -> 0 | BA2: =AN2 -> 0 | BC2: =AR2 -> 39172 | BD2: =AT2 -> 1.7750614 | BE2: =AU2 -> 0
A3: 39263 | B3: -0.87702165 | C3: 0.14867978 | D3: -0.050839217 | E3: 0.5967583 | F3: 0.35694143 | G3: 1.4459149 | H3: 0.10615582 | I3: -0.67075329 | J3: 0.60096046 | K3: 1.5688765 | L3: 1.2418066 | M3: 0 | N3: 0 | O3: 0.33267031 | P3: 0 | Q3: 0.070231968 | R3: 0 | S3: 0 | T3: 0 | U3: 0 | V3: 0 | W3: 0 | X3: 0 | Y3: 0 | Z3: 0 | AA3: 0 | AB3: 0 | AC3: 0 | AD3: 0 | AE3: 0.13039267 | AF3: 5.0007746 | AH3: =K3 -> 1.5688765 | AI3: =Y3 -> 0 | AJ3: =Z3 -> 0 | AK3: =AA3 -> 0 | AL3: =AB3 -> 0 | AM3: =AC3 -> 0 | AN3: =AD3 -> 0 | AR3: =A3 -> 39263 | AS3: =AF3*4+2 -> 22.003098 | AT3: =AH3 -> 1.5688765 | AU3: =SUM(AV3:BA3) -> 0 | AV3: =AI3 -> 0 | AW3: =AJ3 -> 0 | AX3: =AK3 -> 0 | AY3: =AL3 -> 0 | AZ3: =AM3 -> 0 | BA3: =AN3 -> 0 | BC3: =AR3 -> 39263 | BD3: =AT3 -> 1.5688765 | BE3: =AU3 -> 0
A4: 39355 | B4: -1.040355 | C4: 0.13425109 | D4: -0.14587387 | E4: 0.69031317 | F4: 0.37191894 | G4: 1.4503632 | H4: 0.31183503 | I4: -0.6798581 | J4: 0.61019793 | K4: 1.5086958 | L4: 1.1510338 | M4: 0 | N4: 0 | O4: 0.37118543 | P4: 0 | Q4: 0.037371485 | R4: 0 | S4: 0 | T4: 0 | U4: 0 | V4: 0 | W4: 0 | X4: 0 | Y4: 0 | Z4: 0 | AA4: 0 | AB4: 0 | AC4: 0 | AD4: 0 | AE4: 0.12978091 | AF4: 4.9008599 | AH4: =K4 -> 1.5086958 | AI4: =Y4 -> 0 | AJ4: =Z4 -> 0 | AK4: =AA4 -> 0 | AL4: =AB4 -> 0 | AM4: =AC4 -> 0 | AN4: =AD4 -> 0 | AR4: =A4 -> 39355 | AS4: =AF4*4+2 -> 21.603439 | AT4: =AH4 -> 1.5086958 | AU4: =SUM(AV4:BA4) -> 0 | AV4: =AI4 -> 0 | AW4: =AJ4 -> 0 | AX4: =AK4 -> 0 | AY4: =AL4 -> 0 | AZ4: =AM4 -> 0 | BA4: =AN4 -> 0 | BC4: =AR4 -> 39355 | BD4: =AT4 -> 1.5086958 | BE4: =AU4 -> 0
A5: 39447 | B5: -0.99330901 | C5: 0.14258815 | D5: -0.26310356 | E5: 0.73768743 | F5: 0.36639612 | G5: 1.4317096 | H5: 0.21867959 | I5: -0.68920012 | J5: 0.66599438 | K5: 1.7274198 | L5: 1.0093212 | M5: 0 | N5: 0 | O5: 0.40724837 | P5: 0 | Q5: 0.016106972 | R5: 0 | S5: 0 | T5: 0 | U5: 0 | V5: 0 | W5: 0 | X5: 0 | Y5: 0 | Z5: 0 | AA5: 0 | AB5: 0 | AC5: 0 | AD5: 0 | AE5: 0.12916218 | AF5: 4.9067011 | AH5: =K5 -> 1.7274198 | AI5: =Y5 -> 0 | AJ5: =Z5 -> 0 | AK5: =AA5 -> 0 | AL5: =AB5 -> 0 | AM5: =AC5 -> 0 | AN5: =AD5 -> 0 | AR5: =A5 -> 39447 | AS5: =AF5*4+2 -> 21.626804 | AT5: =AH5 -> 1.7274198 | AU5: =SUM(AV5:BA5) -> 0 | AV5: =AI5 -> 0 | AW5: =AJ5 -> 0 | AX5: =AK5 -> 0 | AY5: =AL5 -> 0 | AZ5: =AM5 -> 0 | BA5: =AN5 -> 0 | BC5: =AR5 -> 39447 | BD5: =AT5 -> 1.7274198 | BE5: =AU5 -> 0
A6: 39538 | B6: -1.0476842 | C6: 0.03061779 | D6: -0.40243934 | E6: 0.39311962 | F6: 0.33629364 | G6: 1.42832 | H6: 0.27379584 | I6: -0.67868028 | J6: 0.70115772 | K6: 2.0053504 | L6: 0.85487701 | M6: 0 | N6: 0 | O6: 0.44493982 | P6: 0 | Q6: -0.019590161 | R6: 0 | S6: 0 | T6: 0 | U6: 0 | V6: 0 | W6: 0 | X6: 0 | Y6: 0 | Z6: 0 | AA6: 0 | AB6: 0 | AC6: 0 | AD6: 0 | AE6: 0.12853685 | AF6: 4.4486148 | AH6: =K6 -> 2.0053504 | AI6: =Y6 -> 0 | AJ6: =Z6 -> 0 | AK6: =AA6 -> 0 | AL6: =AB6 -> 0 | AM6: =AC6 -> 0 | AN6: =AD6 -> 0 | AR6: =A6 -> 39538 | AS6: =AF6*4+2 -> 19.794459 | AT6: =AH6 -> 2.0053504 | AU6: =SUM(AV6:BA6) -> 0 | AV6: =AI6 -> 0 | AW6: =AJ6 -> 0 | AX6: =AK6 -> 0 | AY6: =AL6 -> 0 | AZ6: =AM6 -> 0 | BA6: =AN6 -> 0 | BC6: =AR6 -> 39538 | BD6: =AT6 -> 2.0053504 | BE6: =AU6 -> 0
A7: 39629 | B7: -1.1086433 | C7: -0.033609602 | D7: -0.44750789 | E7: 0.09339584 | F7: 0.34011857 | G7: 1.4242313 | H7: 0.099730651 | I7: -0.64918611 | J7: 0.69311266 | K7: 2.3003353 | L7: 0.71023288 | M7: 0 | N7: 0 | O7: 0.48647302 | P7: 0 | Q7: -0.047607001 | R7: 0 | S7: 0 | T7: 0 | U7: 0 | V7: 0 | W7: 0 | X7: 0 | Y7: 0 | Z7: 0 | AA7: 0 | AB7: 0 | AC7: 0 | AD7: 0 | AE7: 0.12790526 | AF7: 3.9889816 | AH7: =K7 -> 2.3003353 | AI7: =Y7 -> 0 | AJ7: =Z7 -> 0 | AK7: =AA7 -> 0 | AL7: =AB7 -> 0 | AM7: =AC7 -> 0 | AN7: =AD7 -> 0 | AR7: =A7 -> 39629 | AS7: =AF7*4+2 -> 17.955926 | AT7: =AH7 -> 2.3003353 | AU7: =SUM(AV7:BA7) -> 0 | AV7: =AI7 -> 0 | AW7: =AJ7 -> 0 | AX7: =AK7 -> 0 | AY7: =AL7 -> 0 | AZ7: =AM7 -> 0 | BA7: =AN7 -> 0 | BC7: =AR7 -> 39629 | BD7: =AT7 -> 2.3003353 | BE7: =AU7 -> 0
A8: 39721 | B8: -0.80373451 | C8: -0.20400532 | D8: -0.52579161 | E8: -0.37809506 | F8: 0.32715602 | G8: 1.4371073 | H8: 0.049769223 | I8: -0.6241057 | J8: 0.72601851 | K8: 1.9637541 | L8: 0.57993927 | M8: 0 | N8: 0 | O8: 0.49767707 | P8: 0 | Q8: -0.074978682 | R8: 0 | S8: 0 | T8: 0 | U8: 0 | V8: 0 | W8: 0 | X8: 0 | Y8: 0 | Z8: 0 | AA8: 0 | AB8: 0 | AC8: 0 | AD8: 0 | AE8: 0.12726775 | AF8: 3.0979785 | AH8: =K8 -> 1.9637541 | AI8: =Y8 -> 0 | AJ8: =Z8 -> 0 | AK8: =AA8 -> 0 | AL8: =AB8 -> 0 | AM8: =AC8 -> 0 | AN8: =AD8 -> 0 | AR8: =A8 -> 39721 | AS8: =AF8*4+2 -> 14.391914 | AT8: =AH8 -> 1.9637541 | AU8: =SUM(AV8:BA8) -> 0 | AV8: =AI8 -> 0 | AW8: =AJ8 -> 0 | AX8: =AK8 -> 0 | AY8: =AL8 -> 0 | AZ8: =AM8 -> 0 | BA8: =AN8 -> 0 | BC8: =AR8 -> 39721 | BD8: =AT8 -> 1.9637541 | BE8: =AU8 -> 0
A9: 39813 | B9: -0.21677727 | C9: -0.56638658 | D9: -0.87656555 | E9: -1.0760328 | F9: 0.163132 | G9: 1.567453 | H9: 0.77708187 | I9: -0.52720457 | J9: 0.77689645 | K9: 1.3356925 | L9: 0.32530383 | M9: 0 | N9: 0 | O9: 0.56267499 | P9: 0 | Q9: -0.12285996 | R9: 0 | S9: 0 | T9: 0 | U9: 0 | V9: 0 | W9: 0 | X9: 0 | Y9: -0.18334085 | Z9: -0.085809019 | AA9: -0.014995051 | AB9: -0.0025678522 | AC9: -0.0010749068 | AD9: -0.0015146036 | AE9: 0.12662465 | AF9: 1.9597303 | AH9: =K9 -> 1.3356925 | AI9: =Y9 -> -0.18334085 | AJ9: =Z9 -> -0.085809019 | AK9: =AA9 -> -0.014995051 | AL9: =AB9 -> -0.0025678522 | AM9: =AC9 -> -0.0010749068 | AN9: =AD9 -> -0.0015146036 | AR9: =A9 -> 39813 | AS9: =AF9*4+2 -> 9.8389213 | AT9: =AH9 -> 1.3356925 | AU9: =SUM(AV9:BA9) -> -0.28930228 | AV9: =AI9 -> -0.18334085 | AW9: =AJ9 -> -0.085809019 | AX9: =AK9 -> -0.014995051 | AY9: =AL9 -> -0.0025678522 | AZ9: =AM9 -> -0.0010749068 | BA9: =AN9 -> -0.0015146036 | BC9: =AR9 -> 39813 | BD9: =AT9 -> 1.3356925 | BE9: =AU9 -> -0.28930228
A10: 39903 | B10: -0.13539004 | C10: -0.65246513 | D10: -0.91826335 | E10: -1.4441778 | F10: 0.115455 | G10: 1.5230468 | H10: 0.27896396 | I10: -0.40325188 | J10: 0.66681609 | K10: 0.39863999 | L10: 0.0012907793 | M10: 0 | N10: 0 | O10: 0.65980691 | P10: 0 | Q10: -0.15244255 | R10: 0 | S10: 0 | T10: 0 | U10: 0 | V10: 0 | W10: 0 | X10: 0 | Y10: -0.40182322 | Z10: -0.21133372 | AA10: -0.064564658 | AB10: -0.0076746478 | AC10: -0.0097111472 | AD10: -0.013463276 | AE10: 0.12597629 | AF10: -0.64456556 | AH10: =K10 -> 0.39863999 | AI10: =Y10 -> -0.40182322 | AJ10: =Z10 -> -0.21133372 | AK10: =AA10 -> -0.064564658 | AL10: =AB10 -> -0.0076746478 | AM10: =AC10 -> -0.0097111472 | AN10: =AD10 -> -0.013463276 | AR10: =A10 -> 39903 | AS10: =AF10*4+2 -> -0.57826224 | AT10: =AH10 -> 0.39863999 | AU10: =SUM(AV10:BA10) -> -0.70857067 | AV10: =AI10 -> -0.40182322 | AW10: =AJ10 -> -0.21133372 | AX10: =AK10 -> -0.064564658 | AY10: =AL10 -> -0.0076746478 | AZ10: =AM10 -> -0.0097111472 | BA10: =AN10 -> -0.013463276 | BC10: =AR10 -> 39903 | BD10: =AT10 -> 0.39863999 | BE10: =AU10 -> -0.70857067
A11: 39994 | B11: -0.073128195 | C11: -0.59127453 | D11: -0.82556116 | E11: -1.5731642 | F11: 0.099746456 | G11: 1.4374342 | H11: -0.35522693 | I11: -0.28293943 | J11: 0.84351191 | K11: -0.30041232 | L11: -0.18272965 | M11: 0 | N11: 0 | O11: 0.6458429 | P11: 0 | Q11: -0.16787271 | R11: 0 | S11: 0 | T11: 0 | U11: 0 | V11: 0 | W11: 0 | X11: 0 | Y11: -0.51335586 | Z11: -0.31584038 | AA11: -0.13962108 | AB11: -0.03410106 | AC11: -0.016607341 | AD11: -0.041339223 | AE11: 0.12532296 | AF11: -2.2613156 | AH11: =K11 -> -0.30041232 | AI11: =Y11 -> -0.51335586 | AJ11: =Z11 -> -0.31584038 | AK11: =AA11 -> -0.13962108 | AL11: =AB11 -> -0.03410106 | AM11: =AC11 -> -0.016607341 | AN11: =AD11 -> -0.041339223 | AR11: =A11 -> 39994 | AS11: =AF11*4+2 -> -7.0452625 | AT11: =AH11 -> -0.30041232 | AU11: =SUM(AV11:BA11) -> -1.0608649 | AV11: =AI11 -> -0.51335586 | AW11: =AJ11 -> -0.31584038 | AX11: =AK11 -> -0.13962108 | AY11: =AL11 -> -0.03410106 | AZ11: =AM11 -> -0.016607341 | BA11: =AN11 -> -0.041339223 | BC11: =AR11 -> 39994 | BD11: =AT11 -> -0.30041232 | BE11: =AU11 -> -1.0608649
A12: 40086 | B12: -0.53090932 | C12: -0.26450707 | D12: -0.67212326 | E12: -1.5028278 | F12: 0.069033869 | G12: 1.1961043 | H12: -0.54411897 | I12: -0.18186777 | J12: 0.89049329 | K12: -0.56877654 | L12: -0.18360036 | M12: 0 | N12: 0 | O12: 0.48885426 | P12: 0 | Q12: -0.2019199 | R12: 0 | S12: 0 | T12: 0 | U12: 0 | V12: 0 | W12: 0 | X12: 0 | Y12: -0.43225273 | Z12: -0.32122089 | AA12: -0.17245864 | AB12: -0.050099817 | AC12: -0.0204331 | AD12: -0.08404302 | AE12: 0.12466498 | AF12: -2.9620085 | AH12: =K12 -> -0.56877654 | AI12: =Y12 -> -0.43225273 | AJ12: =Z12 -> -0.32122089 | AK12: =AA12 -> -0.17245864 | AL12: =AB12 -> -0.050099817 | AM12: =AC12 -> -0.0204331 | AN12: =AD12 -> -0.08404302 | AR12: =A12 -> 40086 | AS12: =AF12*4+2 -> -9.8480338 | AT12: =AH12 -> -0.56877654 | AU12: =SUM(AV12:BA12) -> -1.0805082 | AV12: =AI12 -> -0.43225273 | AW12: =AJ12 -> -0.32122089 | AX12: =AK12 -> -0.17245864 | AY12: =AL12 -> -0.050099817 | AZ12: =AM12 -> -0.0204331 | BA12: =AN12 -> -0.08404302 | BC12: =AR12 -> 40086 | BD12: =AT12 -> -0.56877654 | BE12: =AU12 -> -1.0805082
A13: 40178 | B13: -0.25242317 | C13: -0.21161538 | D13: -0.55513346 | E13: -1.5319895 | F13: 0.034934349 | G13: 0.99553621 | H13: -1.0349527 | I13: -0.1401452 | J13: 0.90746758 | K13: -1.1530786 | L13: -0.071269525 | M13: 0 | N13: 0 | O13: 0.29361464 | P13: 0 | Q13: -0.2238056 | R13: 0 | S13: 0 | T13: 0 | U13: 0 | V13: 0 | W13: 0 | X13: 0 | Y13: -0.35928238 | Z13: -0.28959157 | AA13: -0.22762518 | AB13: -0.069279424 | AC13: -0.028449793 | AD13: -0.14778106 | AE13: 0.12400264 | AF13: -3.9408671 | AH13: =K13 -> -1.1530786 | AI13: =Y13 -> -0.35928238 | AJ13: =Z13 -> -0.28959157 | AK13: =AA13 -> -0.22762518 | AL13: =AB13 -> -0.069279424 | AM13: =AC13 -> -0.028449793 | AN13: =AD13 -> -0.14778106 | AR13: =A13 -> 40178 | AS13: =AF13*4+2 -> -13.763469 | AT13: =AH13 -> -1.1530786 | AU13: =SUM(AV13:BA13) -> -1.1220094 | AV13: =AI13 -> -0.35928238 | AW13: =AJ13 -> -0.28959157 | AX13: =AK13 -> -0.22762518 | AY13: =AL13 -> -0.069279424 | AZ13: =AM13 -> -0.028449793 | BA13: =AN13 -> -0.14778106 | BC13: =AR13 -> 40178 | BD13: =AT13 -> -1.1530786 | BE13: =AU13 -> -1.1220094
... A132: 51043 | B132: -1.1485256 | C132: 0.00012590441 | D132: -0.042684349 | E132: -0.00047395337 | F132: 0.10831097 | G132: -0.17615887 | H132: 0.054636968 | I132: 0.15047017 | J132: 0.26718227 | K132: 0.0018162856 | L132: 0.37632535 | M132: 0 | N132: 0 | O132: 0.54539942 | P132: 0 | Q132: -0.20667783 | R132: 0 | S132: 0 | T132: 0 | U132: 0 | V132: 0 | W132: 0 | X132: 0 | Y132: -0.0016294185 | Z132: 0.0019674278 | AA132: -0.00054863095 | AB132: 0.00047969275 | AC132: -0.0015716835 | AD132: -0.0046451761 | AE132: 0.053433982 | AF132: -0.022767062 | AH132: =K132 -> 0.0018162856 | AI132: =Y132 -> -0.0016294185 | AJ132: =Z132 -> 0.0019674278 | AK132: =AA132 -> -0.00054863095 | AL132: =AB132 -> 0.00047969275 | AM132: =AC132 -> -0.0015716835 | AN132: =AD132 -> -0.0046451761 | AR132: =A132 -> 51043 | AS132: =AF132*4+2 -> 1.9089318 | AT132: =AH132 -> 0.0018162856 | AU132: =SUM(AV132:BA132) -> -0.0059477884 | AV132: =AI132 -> -0.0016294185 | AW132: =AJ132 -> 0.0019674278 | AX132: =AK132 -> -0.00054863095 | AY132: =AL132 -> 0.00047969275 | AZ132: =AM132 -> -0.0015716835 | BA132: =AN132 -> -0.0046451761 | BC132: =AR132 -> 51043 | BD132: =AT132 -> 0.0018162856 | BE132: =AU132 -> -0.0059477884

Sheet US_output_with_text_backup_1
A1: date | B1: g_sh | C1: b_liqtil_sh | D1: b_liqp_sh | E1: b_safetil_sh | F1: b_safep_sh | G1: mu_sh | H1: z_sh | I1: lambda_f_sh | J1: lambda_w_sh | K1: rm_sh | L1: sigma_omega_sh | M1: mu_e_sh | N1: gamma_sh | O1: pi_star_sh | P1: lr_sh | Q1: zp_sh | R1: tfp_sh | S1: gdpdef_sh | T1: corepce_sh | U1: gdp_sh | V1: gdi_sh | W1: BBB_sh | X1: AAA_sh | Y1: rm_shl1 | Z1: rm_shl2 | AA1: rm_shl3 | AB1: rm_shl4 | AC1: rm_shl5 | AD1: rm_shl6 | AE1: dettrend | AF1: detrendedMean | AH1: rm_sh | AI1: =Y1 -> rm_shl1 | AJ1: =Z1 -> rm_shl2 | AK1: =AA1 -> rm_shl3 | AL1: =AB1 -> rm_shl4 | AM1: =AC1 -> rm_shl5 | AN1: =AD1 -> rm_shl6 | AQ1: Plot | AR1: =A1 -> date | AS1: =AF1 -> detrendedMean | AT1: Monetary Policy | AU1: Fgsum | AV1: FG1 | AW1: FG2 | AX1: FG3 | AY1: FG4 | AZ1: FG5 | BA1: FG6 | BC1: date | BD1: rm_sh | BE1: Fgsum
A2: 39172 | B2: -1.0215877 | C2: 0.14738424 | D2: -0.044907453 | E2: 0.56515568 | F2: 0.33471877 | G2: 1.4053436 | H2: 0.54693072 | I2: -0.65393335 | J2: 0.64232717 | K2: 1.7750614 | L2: 1.2826525 | M2: 0 | N2: 0 | O2: 0.3278555 | P2: 0 | Q2: 0.11087454 | R2: 0 | S2: 0 | T2: 0 | U2: 0 | V2: 0 | W2: 0 | X2: 0 | Y2: 0 | Z2: 0 | AA2: 0 | AB2: 0 | AC2: 0 | AD2: 0 | AE2: 0.13099711 | AF2: 5.5488727 | AH2: =K2 -> 1.7750614 | AI2: =Y2 -> 0 | AJ2: =Z2 -> 0 | AK2: =AA2 -> 0 | AL2: =AB2 -> 0 | AM2: =AC2 -> 0 | AN2: =AD2 -> 0 | AR2: =A2 -> 39172 | AS2: =AF2*4+2 -> 24.195491 | AT2: =AH2 -> 1.7750614 | AU2: =SUM(AV2:BA2) -> 0 | AV2: =AI2 -> 0 | AW2: =AJ2 -> 0 | AX2: =AK2 -> 0 | AY2: =AL2 -> 0 | AZ2: =AM2 -> 0 | BA2: =AN2 -> 0 | BC2: =AR2 -> 39172 | BD2: =AT2 -> 1.7750614 | BE2: =AU2 -> 0
A3: 39263 | B3: -0.87702165 | C3: 0.14867978 | D3: -0.050839217 | E3: 0.5967583 | F3: 0.35694143 | G3: 1.4459149 | H3: 0.10615582 | I3: -0.67075329 | J3: 0.60096046 | K3: 1.5688765 | L3: 1.2418066 | M3: 0 | N3: 0 | O3: 0.33267031 | P3: 0 | Q3: 0.070231968 | R3: 0 | S3: 0 | T3: 0 | U3: 0 | V3: 0 | W3: 0 | X3: 0 | Y3: 0 | Z3: 0 | AA3: 0 | AB3: 0 | AC3: 0 | AD3: 0 | AE3: 0.13039267 | AF3: 5.0007746 | AH3: =K3 -> 1.5688765 | AI3: =Y3 -> 0 | AJ3: =Z3 -> 0 | AK3: =AA3 -> 0 | AL3: =AB3 -> 0 | AM3: =AC3 -> 0 | AN3: =AD3 -> 0 | AR3: =A3 -> 39263 | AS3: =AF3*4+2 -> 22.003098 | AT3: =AH3 -> 1.5688765 | AU3: =SUM(AV3:BA3) -> 0 | AV3: =AI3 -> 0 | AW3: =AJ3 -> 0 | AX3: =AK3 -> 0 | AY3: =AL3 -> 0 | AZ3: =AM3 -> 0 | BA3: =AN3 -> 0 | BC3: =AR3 -> 39263 | BD3: =AT3 -> 1.5688765 | BE3: =AU3 -> 0
